Workbook

Sheet Read Me
A1: 🎯 Project 54.7 — Daily Wager Workbook
A2: 52.4% pays the house. 54.7% pays you.
A5: Built | B5: 2026-06-28 14:08
A7: HOW IT WORKS
A8: 1. | B8: The model's win probability for every market is locked. It does not change when odds move.
A9: 2. | B9: Type the price YOUR sportsbook is showing into the yellow “✏ Your Odds” cells (American odds, e.g. -110 or +135).
A10: 3. | B10: Implied %, Your Edge (EV), the ¼-Kelly stake and the Verdict recompute instantly — in Excel or Google Sheets, offline.
A11: 4. | B11: Set your Bankroll and Kelly fraction once on the Settings tab; every stake on every tab follows it.
A12: 5. | B12: After a game, type the closing line into the ✏ Closing column on the Games tab — CLV % shows whether you beat the close (the earliest honest sign an edge is real).
A14: READING THE VERDICT
A15: Pass | B15: Model says there's no edge at your price — skip it.
A16: Thin | B16: Positive but below your min-edge threshold.
A17: ✅ Sharp band | B17: 2–6% EV — where the model's edge has actually held up (good closing-line value). The sweet spot.
A18: Strong | B18: 6–8% EV — bigger, rarer.
A19: ⚠ Verify | B19: 8%+ EV usually means a stale or oddball price, not free money. Double-check the line before trusting it.
A21: WHY EDIT YOUR OWN ODDS?
B22: Every other tool de-vigs a sharp book for you and locks the math in an app whose lines go stale. Here the number is yours, so nothing can be out of date — and the math is in front of you.
A24: THE DEAL | B24: Personal research. Not financial advice. No bankroll promises. If gambling stops being fun, stop — call 1-800-GAMBLER.
B25: We publish our losses too — see the Track Record tab. We tell you when to pass. The trigger is always yours.

Sheet Settings
A1: ⚙ Settings
A2: Bankroll ($) | B2: 1000
A3: Kelly fraction | B3: 0.25
A4: Min edge to flag (EV) | B4: 0.02
A5: Max stake (% of bankroll) | B5: 0.05
A7: Default ¼-Kelly is deliberate: full Kelly is mathematically optimal but brutal on variance, and edges are always overestimated. Quarter-Kelly keeps ~most of the growth at a fraction of the risk.

Sheet Top Plays
A1: ⭐ Top Plays — biggest model edges today
A2: Ranked at the posted price. Swap in your book's number and watch the edge update. Nothing here is a lock.
A4: Date | B4: Matchup | C4: Start | D4: Market | E4: Selection | F4: Model Win% | G4: Model Fair | H4: ✏ Your Odds | I4: Implied% | J4: Your Edge (EV) | K4: ¼-Kelly % | L4: Stake $ | M4: Verdict | N4: Model read | O4: ✏ Closing | P4: CLV %
A5: 2026-06-29 | B5: Cincinnati Reds @ Milwaukee Brewers | C5: 23:40 | D5: Spread | E5: Milwaukee Brewers -1.5 | F5: 0.48629787 | G5: 106 | H5: 135 | I5: =IF($H$5="","",IF($H$5<0,-$H$5/(-$H$5+100),100/($H$5+100))) | J5: =IF($H$5="","",$F$5*IF($H$5<0,-100/$H$5,$H$5/100)-(1-$F$5)) | K5: =IF($H$5="","",MAX(0,($F$5*IF($H$5<0,-100/$H$5,$H$5/100)-(1-$F$5))/IF($H$5<0,-100/$H$5,$H$5/100))*'Settings'!$B$3) | L5: =IF($H$5="","",ROUND(MIN($K$5,'Settings'!$B$5)*'Settings'!$B$2,2)) | M5: =IF($J$5="","",IF($J$5<0,"Pass",IF($J$5<'Settings'!$B$4,"Thin",IF($J$5<0.06,"✅ Sharp band",IF($J$5<0.08,"Strong","⚠ Verify (stale?)"))))) | N5: Model 48.6% (fair +106). Your call. | P5: =IF(OR($H$5="",$O$5=""),"",(1+IF($H$5<0,-100/$H$5,$H$5/100))/(1+IF($O$5<0,-100/$O$5,$O$5/100))-1)
A6: 2026-06-28 | B6: New York Liberty @ Golden State Valkyries | C6: 23:00 | D6: Total | E6: Over 165.5 | F6: 0.52419355 | G6: -110 | H6: 117 | I6: =IF($H$6="","",IF($H$6<0,-$H$6/(-$H$6+100),100/($H$6+100))) | J6: =IF($H$6="","",$F$6*IF($H$6<0,-100/$H$6,$H$6/100)-(1-$F$6)) | K6: =IF($H$6="","",MAX(0,($F$6*IF($H$6<0,-100/$H$6,$H$6/100)-(1-$F$6))/IF($H$6<0,-100/$H$6,$H$6/100))*'Settings'!$B$3) | L6: =IF($H$6="","",ROUND(MIN($K$6,'Settings'!$B$5)*'Settings'!$B$2,2)) | M6: =IF($J$6="","",IF($J$6<0,"Pass",IF($J$6<'Settings'!$B$4,"Thin",IF($J$6<0.06,"✅ Sharp band",IF($J$6<0.08,"Strong","⚠ Verify (stale?)"))))) | N6: Model 52.4% (fair -110). Your call. | P6: =IF(OR($H$6="",$O$6=""),"",(1+IF($H$6<0,-100/$H$6,$H$6/100))/(1+IF($O$6<0,-100/$O$6,$O$6/100))-1)
A7: 2026-06-28 | B7: Cincinnati Reds @ Pittsburgh Pirates | C7: 17:35 | D7: Moneyline | E7: Pittsburgh Pirates | F7: 0.63259427 | G7: -172 | H7: -127 | I7: =IF($H$7="","",IF($H$7<0,-$H$7/(-$H$7+100),100/($H$7+100))) | J7: =IF($H$7="","",$F$7*IF($H$7<0,-100/$H$7,$H$7/100)-(1-$F$7)) | K7: =IF($H$7="","",MAX(0,($F$7*IF($H$7<0,-100/$H$7,$H$7/100)-(1-$F$7))/IF($H$7<0,-100/$H$7,$H$7/100))*'Settings'!$B$3) | L7: =IF($H$7="","",ROUND(MIN($K$7,'Settings'!$B$5)*'Settings'!$B$2,2)) | M7: =IF($J$7="","",IF($J$7<0,"Pass",IF($J$7<'Settings'!$B$4,"Thin",IF($J$7<0.06,"✅ Sharp band",IF($J$7<0.08,"Strong","⚠ Verify (stale?)"))))) | N7: Model 63.3% (fair -172). Your call. | P7: =IF(OR($H$7="",$O$7=""),"",(1+IF($H$7<0,-100/$H$7,$H$7/100))/(1+IF($O$7<0,-100/$O$7,$O$7/100))-1)
A8: 2026-06-28 | B8: Chicago Cubs @ Milwaukee Brewers | C8: 18:10 | D8: Total | E8: Over 8.5 | F8: 0.54153846 | G8: -118 | H8: 108 | I8: =IF($H$8="","",IF($H$8<0,-$H$8/(-$H$8+100),100/($H$8+100))) | J8: =IF($H$8="","",$F$8*IF($H$8<0,-100/$H$8,$H$8/100)-(1-$F$8)) | K8: =IF($H$8="","",MAX(0,($F$8*IF($H$8<0,-100/$H$8,$H$8/100)-(1-$F$8))/IF($H$8<0,-100/$H$8,$H$8/100))*'Settings'!$B$3) | L8: =IF($H$8="","",ROUND(MIN($K$8,'Settings'!$B$5)*'Settings'!$B$2,2)) | M8: =IF($J$8="","",IF($J$8<0,"Pass",IF($J$8<'Settings'!$B$4,"Thin",IF($J$8<0.06,"✅ Sharp band",IF($J$8<0.08,"Strong","⚠ Verify (stale?)"))))) | N8: Model 54.2% (fair -118). Your call. | P8: =IF(OR($H$8="",$O$8=""),"",(1+IF($H$8<0,-100/$H$8,$H$8/100))/(1+IF($O$8<0,-100/$O$8,$O$8/100))-1)
A9: 2026-06-29 | B9: Pittsburgh Pirates @ Philadelphia Phillies | C9: 22:40 | D9: Moneyline | E9: Pittsburgh Pirates | F9: 0.5427451 | G9: -119 | H9: 104 | I9: =IF($H$9="","",IF($H$9<0,-$H$9/(-$H$9+100),100/($H$9+100))) | J9: =IF($H$9="","",$F$9*IF($H$9<0,-100/$H$9,$H$9/100)-(1-$F$9)) | K9: =IF($H$9="","",MAX(0,($F$9*IF($H$9<0,-100/$H$9,$H$9/100)-(1-$F$9))/IF($H$9<0,-100/$H$9,$H$9/100))*'Settings'!$B$3) | L9: =IF($H$9="","",ROUND(MIN($K$9,'Settings'!$B$5)*'Settings'!$B$2,2)) | M9: =IF($J$9="","",IF($J$9<0,"Pass",IF($J$9<'Settings'!$B$4,"Thin",IF($J$9<0.06,"✅ Sharp band",IF($J$9<0.08,"Strong","⚠ Verify (stale?)"))))) | N9: Model 54.3% (fair -119). Your call. | P9: =IF(OR($H$9="",$O$9=""),"",(1+IF($H$9<0,-100/$H$9,$H$9/100))/(1+IF($O$9<0,-100/$O$9,$O$9/100))-1)
A10: 2026-06-28 | B10: Seattle Mariners @ Cleveland Guardians | C10: 17:40 | D10: Moneyline | E10: Seattle Mariners | F10: 0.51488372 | G10: -106 | H10: 115 | I10: =IF($H$10="","",IF($H$10<0,-$H$10/(-$H$10+100),100/($H$10+100))) | J10: =IF($H$10="","",$F$10*IF($H$10<0,-100/$H$10,$H$10/100)-(1-$F$10)) | K10: =IF($H$10="","",MAX(0,($F$10*IF($H$10<0,-100/$H$10,$H$10/100)-(1-$F$10))/IF($H$10<0,-100/$H$10,$H$10/100))*'Settings'!$B$3) | L10: =IF($H$10="","",ROUND(MIN($K$10,'Settings'!$B$5)*'Settings'!$B$2,2)) | M10: =IF($J$10="","",IF($J$10<0,"Pass",IF($J$10<'Settings'!$B$4,"Thin",IF($J$10<0.06,"✅ Sharp band",IF($J$10<0.08,"Strong","⚠ Verify (stale?)"))))) | N10: Model 51.5% (fair -106). Your call. | P10: =IF(OR($H$10="",$O$10=""),"",(1+IF($H$10<0,-100/$H$10,$H$10/100))/(1+IF($O$10<0,-100/$O$10,$O$10/100))-1)
A11: 2026-06-29 | B11: Washington Nationals @ Boston Red Sox | C11: 23:10 | D11: Spread | E11: Boston Red Sox -1.5 | F11: 0.42438462 | G11: 136 | H11: 160 | I11: =IF($H$11="","",IF($H$11<0,-$H$11/(-$H$11+100),100/($H$11+100))) | J11: =IF($H$11="","",$F$11*IF($H$11<0,-100/$H$11,$H$11/100)-(1-$F$11)) | K11: =IF($H$11="","",MAX(0,($F$11*IF($H$11<0,-100/$H$11,$H$11/100)-(1-$F$11))/IF($H$11<0,-100/$H$11,$H$11/100))*'Settings'!$B$3) | L11: =IF($H$11="","",ROUND(MIN($K$11,'Settings'!$B$5)*'Settings'!$B$2,2)) | M11: =IF($J$11="","",IF($J$11<0,"Pass",IF($J$11<'Settings'!$B$4,"Thin",IF($J$11<0.06,"✅ Sharp band",IF($J$11<0.08,"Strong","⚠ Verify (stale?)"))))) | N11: Model 42.4% (fair +136). Your call. | P11: =IF(OR($H$11="",$O$11=""),"",(1+IF($H$11<0,-100/$H$11,$H$11/100))/(1+IF($O$11<0,-100/$O$11,$O$11/100))-1)
A12: 2026-06-29 | B12: Miami Marlins @ Colorado Rockies | C12: 00:40 | D12: Moneyline | E12: Colorado Rockies | F12: 0.4727897 | G12: 112 | H12: 133 | I12: =IF($H$12="","",IF($H$12<0,-$H$12/(-$H$12+100),100/($H$12+100))) | J12: =IF($H$12="","",$F$12*IF($H$12<0,-100/$H$12,$H$12/100)-(1-$F$12)) | K12: =IF($H$12="","",MAX(0,($F$12*IF($H$12<0,-100/$H$12,$H$12/100)-(1-$F$12))/IF($H$12<0,-100/$H$12,$H$12/100))*'Settings'!$B$3) | L12: =IF($H$12="","",ROUND(MIN($K$12,'Settings'!$B$5)*'Settings'!$B$2,2)) | M12: =IF($J$12="","",IF($J$12<0,"Pass",IF($J$12<'Settings'!$B$4,"Thin",IF($J$12<0.06,"✅ Sharp band",IF($J$12<0.08,"Strong","⚠ Verify (stale?)"))))) | N12: Model 47.3% (fair +112). Your call. | P12: =IF(OR($H$12="",$O$12=""),"",(1+IF($H$12<0,-100/$H$12,$H$12/100))/(1+IF($O$12<0,-100/$O$12,$O$12/100))-1)
A13: 2026-06-28 | B13: New York Liberty @ Golden State Valkyries | C13: 23:00 | D13: Moneyline | E13: Golden State Valkyries | F13: 0.59060737 | G13: -144 | H13: -117 | I13: =IF($H$13="","",IF($H$13<0,-$H$13/(-$H$13+100),100/($H$13+100))) | J13: =IF($H$13="","",$F$13*IF($H$13<0,-100/$H$13,$H$13/100)-(1-$F$13)) | K13: =IF($H$13="","",MAX(0,($F$13*IF($H$13<0,-100/$H$13,$H$13/100)-(1-$F$13))/IF($H$13<0,-100/$H$13,$H$13/100))*'Settings'!$B$3) | L13: =IF($H$13="","",ROUND(MIN($K$13,'Settings'!$B$5)*'Settings'!$B$2,2)) | M13: =IF($J$13="","",IF($J$13<0,"Pass",IF($J$13<'Settings'!$B$4,"Thin",IF($J$13<0.06,"✅ Sharp band",IF($J$13<0.08,"Strong","⚠ Verify (stale?)"))))) | N13: Model 59.1% (fair -144). Your call. | P13: =IF(OR($H$13="",$O$13=""),"",(1+IF($H$13<0,-100/$H$13,$H$13/100))/(1+IF($O$13<0,-100/$O$13,$O$13/100))-1)
A14: 2026-06-28 | B14: Arizona Diamondbacks @ Tampa Bay Rays | C14: 17:40 | D14: Moneyline | E14: Arizona Diamondbacks | F14: 0.37761404 | G14: 165 | H14: 185 | I14: =IF($H$14="","",IF($H$14<0,-$H$14/(-$H$14+100),100/($H$14+100))) | J14: =IF($H$14="","",$F$14*IF($H$14<0,-100/$H$14,$H$14/100)-(1-$F$14)) | K14: =IF($H$14="","",MAX(0,($F$14*IF($H$14<0,-100/$H$14,$H$14/100)-(1-$F$14))/IF($H$14<0,-100/$H$14,$H$14/100))*'Settings'!$B$3) | L14: =IF($H$14="","",ROUND(MIN($K$14,'Settings'!$B$5)*'Settings'!$B$2,2)) | M14: =IF($J$14="","",IF($J$14<0,"Pass",IF($J$14<'Settings'!$B$4,"Thin",IF($J$14<0.06,"✅ Sharp band",IF($J$14<0.08,"Strong","⚠ Verify (stale?)"))))) | N14: Model 37.8% (fair +165). Your call. | P14: =IF(OR($H$14="",$O$14=""),"",(1+IF($H$14<0,-100/$H$14,$H$14/100))/(1+IF($O$14<0,-100/$O$14,$O$14/100))-1)
A15: 2026-06-28 | B15: Colorado Rockies @ Minnesota Twins | C15: 18:10 | D15: Moneyline | E15: Colorado Rockies | F15: 0.4286 | G15: 133 | H15: 150 | I15: =IF($H$15="","",IF($H$15<0,-$H$15/(-$H$15+100),100/($H$15+100))) | J15: =IF($H$15="","",$F$15*IF($H$15<0,-100/$H$15,$H$15/100)-(1-$F$15)) | K15: =IF($H$15="","",MAX(0,($F$15*IF($H$15<0,-100/$H$15,$H$15/100)-(1-$F$15))/IF($H$15<0,-100/$H$15,$H$15/100))*'Settings'!$B$3) | L15: =IF($H$15="","",ROUND(MIN($K$15,'Settings'!$B$5)*'Settings'!$B$2,2)) | M15: =IF($J$15="","",IF($J$15<0,"Pass",IF($J$15<'Settings'!$B$4,"Thin",IF($J$15<0.06,"✅ Sharp band",IF($J$15<0.08,"Strong","⚠ Verify (stale?)"))))) | N15: Model 42.9% (fair +133). Your call. | P15: =IF(OR($H$15="",$O$15=""),"",(1+IF($H$15<0,-100/$H$15,$H$15/100))/(1+IF($O$15<0,-100/$O$15,$O$15/100))-1)
A16: 2026-06-28 | B16: Portland Fire @ Washington Mystics | C16: 19:00 | D16: Total | E16: Over 167.5 | F16: 0.5512 | G16: -123 | H16: -106 | I16: =IF($H$16="","",IF($H$16<0,-$H$16/(-$H$16+100),100/($H$16+100))) | J16: =IF($H$16="","",$F$16*IF($H$16<0,-100/$H$16,$H$16/100)-(1-$F$16)) | K16: =IF($H$16="","",MAX(0,($F$16*IF($H$16<0,-100/$H$16,$H$16/100)-(1-$F$16))/IF($H$16<0,-100/$H$16,$H$16/100))*'Settings'!$B$3) | L16: =IF($H$16="","",ROUND(MIN($K$16,'Settings'!$B$5)*'Settings'!$B$2,2)) | M16: =IF($J$16="","",IF($J$16<0,"Pass",IF($J$16<'Settings'!$B$4,"Thin",IF($J$16<0.06,"✅ Sharp band",IF($J$16<0.08,"Strong","⚠ Verify (stale?)"))))) | N16: Model 55.1% (fair -123). Your call. | P16: =IF(OR($H$16="",$O$16=""),"",(1+IF($H$16<0,-100/$H$16,$H$16/100))/(1+IF($O$16<0,-100/$O$16,$O$16/100))-1)
A17: 2026-06-29 | B17: Washington Nationals @ Boston Red Sox | C17: 23:10 | D17: Total | E17: Over 8.5 | F17: 0.57045349 | G17: -133 | H17: -115 | I17: =IF($H$17="","",IF($H$17<0,-$H$17/(-$H$17+100),100/($H$17+100))) | J17: =IF($H$17="","",$F$17*IF($H$17<0,-100/$H$17,$H$17/100)-(1-$F$17)) | K17: =IF($H$17="","",MAX(0,($F$17*IF($H$17<0,-100/$H$17,$H$17/100)-(1-$F$17))/IF($H$17<0,-100/$H$17,$H$17/100))*'Settings'!$B$3) | L17: =IF($H$17="","",ROUND(MIN($K$17,'Settings'!$B$5)*'Settings'!$B$2,2)) | M17: =IF($J$17="","",IF($J$17<0,"Pass",IF($J$17<'Settings'!$B$4,"Thin",IF($J$17<0.06,"✅ Sharp band",IF($J$17<0.08,"Strong","⚠ Verify (stale?)"))))) | N17: Model 57.0% (fair -133). Your call. | P17: =IF(OR($H$17="",$O$17=""),"",(1+IF($H$17<0,-100/$H$17,$H$17/100))/(1+IF($O$17<0,-100/$O$17,$O$17/100))-1)
A18: 2026-06-29 | B18: Detroit Tigers @ New York Yankees | C18: 23:05 | D18: Moneyline | E18: Detroit Tigers | F18: 0.45613734 | G18: 119 | H18: 133 | I18: =IF($H$18="","",IF($H$18<0,-$H$18/(-$H$18+100),100/($H$18+100))) | J18: =IF($H$18="","",$F$18*IF($H$18<0,-100/$H$18,$H$18/100)-(1-$F$18)) | K18: =IF($H$18="","",MAX(0,($F$18*IF($H$18<0,-100/$H$18,$H$18/100)-(1-$F$18))/IF($H$18<0,-100/$H$18,$H$18/100))*'Settings'!$B$3) | L18: =IF($H$18="","",ROUND(MIN($K$18,'Settings'!$B$5)*'Settings'!$B$2,2)) | M18: =IF($J$18="","",IF($J$18<0,"Pass",IF($J$18<'Settings'!$B$4,"Thin",IF($J$18<0.06,"✅ Sharp band",IF($J$18<0.08,"Strong","⚠ Verify (stale?)"))))) | N18: Model 45.6% (fair +119). Your call. | P18: =IF(OR($H$18="",$O$18=""),"",(1+IF($H$18<0,-100/$H$18,$H$18/100))/(1+IF($O$18<0,-100/$O$18,$O$18/100))-1)
A19: 2026-06-28 | B19: Texas Rangers @ Toronto Blue Jays | C19: 17:37 | D19: Moneyline | E19: Texas Rangers | F19: 0.48738532 | G19: 105 | H19: 118 | I19: =IF($H$19="","",IF($H$19<0,-$H$19/(-$H$19+100),100/($H$19+100))) | J19: =IF($H$19="","",$F$19*IF($H$19<0,-100/$H$19,$H$19/100)-(1-$F$19)) | K19: =IF($H$19="","",MAX(0,($F$19*IF($H$19<0,-100/$H$19,$H$19/100)-(1-$F$19))/IF($H$19<0,-100/$H$19,$H$19/100))*'Settings'!$B$3) | L19: =IF($H$19="","",ROUND(MIN($K$19,'Settings'!$B$5)*'Settings'!$B$2,2)) | M19: =IF($J$19="","",IF($J$19<0,"Pass",IF($J$19<'Settings'!$B$4,"Thin",IF($J$19<0.06,"✅ Sharp band",IF($J$19<0.08,"Strong","⚠ Verify (stale?)"))))) | N19: Model 48.7% (fair +105). Your call. | P19: =IF(OR($H$19="",$O$19=""),"",(1+IF($H$19<0,-100/$H$19,$H$19/100))/(1+IF($O$19<0,-100/$O$19,$O$19/100))-1)
A20: 2026-06-28 | B20: Washington Nationals @ Baltimore Orioles | C20: 17:35 | D20: Spread | E20: Baltimore Orioles -1.5 | F20: 0.50802885 | G20: -103 | H20: 108 | I20: =IF($H$20="","",IF($H$20<0,-$H$20/(-$H$20+100),100/($H$20+100))) | J20: =IF($H$20="","",$F$20*IF($H$20<0,-100/$H$20,$H$20/100)-(1-$F$20)) | K20: =IF($H$20="","",MAX(0,($F$20*IF($H$20<0,-100/$H$20,$H$20/100)-(1-$F$20))/IF($H$20<0,-100/$H$20,$H$20/100))*'Settings'!$B$3) | L20: =IF($H$20="","",ROUND(MIN($K$20,'Settings'!$B$5)*'Settings'!$B$2,2)) | M20: =IF($J$20="","",IF($J$20<0,"Pass",IF($J$20<'Settings'!$B$4,"Thin",IF($J$20<0.06,"✅ Sharp band",IF($J$20<0.08,"Strong","⚠ Verify (stale?)"))))) | N20: Model 50.8% (fair -103). Your call. | P20: =IF(OR($H$20="",$O$20=""),"",(1+IF($H$20<0,-100/$H$20,$H$20/100))/(1+IF($O$20<0,-100/$O$20,$O$20/100))-1)
A21: 2026-06-29 | B21: Texas Rangers @ Cleveland Guardians | C21: 23:10 | D21: Moneyline | E21: Texas Rangers | F21: 0.49384977 | G21: 102 | H21: 113 | I21: =IF($H$21="","",IF($H$21<0,-$H$21/(-$H$21+100),100/($H$21+100))) | J21: =IF($H$21="","",$F$21*IF($H$21<0,-100/$H$21,$H$21/100)-(1-$F$21)) | K21: =IF($H$21="","",MAX(0,($F$21*IF($H$21<0,-100/$H$21,$H$21/100)-(1-$F$21))/IF($H$21<0,-100/$H$21,$H$21/100))*'Settings'!$B$3) | L21: =IF($H$21="","",ROUND(MIN($K$21,'Settings'!$B$5)*'Settings'!$B$2,2)) | M21: =IF($J$21="","",IF($J$21<0,"Pass",IF($J$21<'Settings'!$B$4,"Thin",IF($J$21<0.06,"✅ Sharp band",IF($J$21<0.08,"Strong","⚠ Verify (stale?)"))))) | N21: Model 49.4% (fair +102). Your call. | P21: =IF(OR($H$21="",$O$21=""),"",(1+IF($H$21<0,-100/$H$21,$H$21/100))/(1+IF($O$21<0,-100/$O$21,$O$21/100))-1)
A22: 2026-06-28 | B22: Philadelphia Phillies @ New York Mets | C22: 17:40 | D22: Spread | E22: New York Mets +1.5 | F22: 0.55322254 | G22: -124 | H22: -113 | I22: =IF($H$22="","",IF($H$22<0,-$H$22/(-$H$22+100),100/($H$22+100))) | J22: =IF($H$22="","",$F$22*IF($H$22<0,-100/$H$22,$H$22/100)-(1-$F$22)) | K22: =IF($H$22="","",MAX(0,($F$22*IF($H$22<0,-100/$H$22,$H$22/100)-(1-$F$22))/IF($H$22<0,-100/$H$22,$H$22/100))*'Settings'!$B$3) | L22: =IF($H$22="","",ROUND(MIN($K$22,'Settings'!$B$5)*'Settings'!$B$2,2)) | M22: =IF($J$22="","",IF($J$22<0,"Pass",IF($J$22<'Settings'!$B$4,"Thin",IF($J$22<0.06,"✅ Sharp band",IF($J$22<0.08,"Strong","⚠ Verify (stale?)"))))) | N22: Model 55.3% (fair -124). Your call. | P22: =IF(OR($H$22="",$O$22=""),"",(1+IF($H$22<0,-100/$H$22,$H$22/100))/(1+IF($O$22<0,-100/$O$22,$O$22/100))-1)
A23: 2026-06-28 | B23: Minnesota Lynx @ Dallas Wings | C23: 18:00 | D23: Moneyline | E23: Minnesota Lynx | F23: 0.61465574 | G23: -160 | H23: -144 | I23: =IF($H$23="","",IF($H$23<0,-$H$23/(-$H$23+100),100/($H$23+100))) | J23: =IF($H$23="","",$F$23*IF($H$23<0,-100/$H$23,$H$23/100)-(1-$F$23)) | K23: =IF($H$23="","",MAX(0,($F$23*IF($H$23<0,-100/$H$23,$H$23/100)-(1-$F$23))/IF($H$23<0,-100/$H$23,$H$23/100))*'Settings'!$B$3) | L23: =IF($H$23="","",ROUND(MIN($K$23,'Settings'!$B$5)*'Settings'!$B$2,2)) | M23: =IF($J$23="","",IF($J$23<0,"Pass",IF($J$23<'Settings'!$B$4,"Thin",IF($J$23<0.06,"✅ Sharp band",IF($J$23<0.08,"Strong","⚠ Verify (stale?)"))))) | N23: Model 61.5% (fair -160). Your call. | P23: =IF(OR($H$23="",$O$23=""),"",(1+IF($H$23<0,-100/$H$23,$H$23/100))/(1+IF($O$23<0,-100/$O$23,$O$23/100))-1)
A24: 2026-06-29 | B24: Cincinnati Reds @ Milwaukee Brewers | C24: 23:40 | D24: Total | E24: Over 8.5 | F24: 0.54319048 | G24: -119 | H24: -110 | I24: =IF($H$24="","",IF($H$24<0,-$H$24/(-$H$24+100),100/($H$24+100))) | J24: =IF($H$24="","",$F$24*IF($H$24<0,-100/$H$24,$H$24/100)-(1-$F$24)) | K24: =IF($H$24="","",MAX(0,($F$24*IF($H$24<0,-100/$H$24,$H$24/100)-(1-$F$24))/IF($H$24<0,-100/$H$24,$H$24/100))*'Settings'!$B$3) | L24: =IF($H$24="","",ROUND(MIN($K$24,'Settings'!$B$5)*'Settings'!$B$2,2)) | M24: =IF($J$24="","",IF($J$24<0,"Pass",IF($J$24<'Settings'!$B$4,"Thin",IF($J$24<0.06,"✅ Sharp band",IF($J$24<0.08,"Strong","⚠ Verify (stale?)"))))) | N24: Model 54.3% (fair -119). Your call. | P24: =IF(OR($H$24="",$O$24=""),"",(1+IF($H$24<0,-100/$H$24,$H$24/100))/(1+IF($O$24<0,-100/$O$24,$O$24/100))-1)
A25: 2026-06-28 | B25: Kansas City Royals @ Chicago White Sox | C25: 18:10 | D25: Moneyline | E25: Chicago White Sox | F25: 0.57798987 | G25: -137 | H25: -127 | I25: =IF($H$25="","",IF($H$25<0,-$H$25/(-$H$25+100),100/($H$25+100))) | J25: =IF($H$25="","",$F$25*IF($H$25<0,-100/$H$25,$H$25/100)-(1-$F$25)) | K25: =IF($H$25="","",MAX(0,($F$25*IF($H$25<0,-100/$H$25,$H$25/100)-(1-$F$25))/IF($H$25<0,-100/$H$25,$H$25/100))*'Settings'!$B$3) | L25: =IF($H$25="","",ROUND(MIN($K$25,'Settings'!$B$5)*'Settings'!$B$2,2)) | M25: =IF($J$25="","",IF($J$25<0,"Pass",IF($J$25<'Settings'!$B$4,"Thin",IF($J$25<0.06,"✅ Sharp band",IF($J$25<0.08,"Strong","⚠ Verify (stale?)"))))) | N25: Model 57.8% (fair -137). Your call. | P25: =IF(OR($H$25="",$O$25=""),"",(1+IF($H$25<0,-100/$H$25,$H$25/100))/(1+IF($O$25<0,-100/$O$25,$O$25/100))-1)
A26: 2026-06-29 | B26: Pittsburgh Pirates @ Philadelphia Phillies | C26: 22:40 | D26: Spread | E26: Pittsburgh Pirates -1.5 | F26: 0.43020833 | G26: 132 | H26: 140 | I26: =IF($H$26="","",IF($H$26<0,-$H$26/(-$H$26+100),100/($H$26+100))) | J26: =IF($H$26="","",$F$26*IF($H$26<0,-100/$H$26,$H$26/100)-(1-$F$26)) | K26: =IF($H$26="","",MAX(0,($F$26*IF($H$26<0,-100/$H$26,$H$26/100)-(1-$F$26))/IF($H$26<0,-100/$H$26,$H$26/100))*'Settings'!$B$3) | L26: =IF($H$26="","",ROUND(MIN($K$26,'Settings'!$B$5)*'Settings'!$B$2,2)) | M26: =IF($J$26="","",IF($J$26<0,"Pass",IF($J$26<'Settings'!$B$4,"Thin",IF($J$26<0.06,"✅ Sharp band",IF($J$26<0.08,"Strong","⚠ Verify (stale?)"))))) | N26: Model 43.0% (fair +132). Your call. | P26: =IF(OR($H$26="",$O$26=""),"",(1+IF($H$26<0,-100/$H$26,$H$26/100))/(1+IF($O$26<0,-100/$O$26,$O$26/100))-1)
A27: 2026-06-28 | B27: Portland Fire @ Washington Mystics | C27: 19:00 | D27: Moneyline | E27: Portland Fire | F27: 0.29921739 | G27: 234 | H27: 245 | I27: =IF($H$27="","",IF($H$27<0,-$H$27/(-$H$27+100),100/($H$27+100))) | J27: =IF($H$27="","",$F$27*IF($H$27<0,-100/$H$27,$H$27/100)-(1-$F$27)) | K27: =IF($H$27="","",MAX(0,($F$27*IF($H$27<0,-100/$H$27,$H$27/100)-(1-$F$27))/IF($H$27<0,-100/$H$27,$H$27/100))*'Settings'!$B$3) | L27: =IF($H$27="","",ROUND(MIN($K$27,'Settings'!$B$5)*'Settings'!$B$2,2)) | M27: =IF($J$27="","",IF($J$27<0,"Pass",IF($J$27<'Settings'!$B$4,"Thin",IF($J$27<0.06,"✅ Sharp band",IF($J$27<0.08,"Strong","⚠ Verify (stale?)"))))) | N27: Model 29.9% (fair +234). Your call. | P27: =IF(OR($H$27="",$O$27=""),"",(1+IF($H$27<0,-100/$H$27,$H$27/100))/(1+IF($O$27<0,-100/$O$27,$O$27/100))-1)
A28: 2026-06-29 | B28: New York Mets @ Toronto Blue Jays | C28: 23:07 | D28: Moneyline | E28: New York Mets | F28: 0.49456731 | G28: 102 | H28: 108 | I28: =IF($H$28="","",IF($H$28<0,-$H$28/(-$H$28+100),100/($H$28+100))) | J28: =IF($H$28="","",$F$28*IF($H$28<0,-100/$H$28,$H$28/100)-(1-$F$28)) | K28: =IF($H$28="","",MAX(0,($F$28*IF($H$28<0,-100/$H$28,$H$28/100)-(1-$F$28))/IF($H$28<0,-100/$H$28,$H$28/100))*'Settings'!$B$3) | L28: =IF($H$28="","",ROUND(MIN($K$28,'Settings'!$B$5)*'Settings'!$B$2,2)) | M28: =IF($J$28="","",IF($J$28<0,"Pass",IF($J$28<'Settings'!$B$4,"Thin",IF($J$28<0.06,"✅ Sharp band",IF($J$28<0.08,"Strong","⚠ Verify (stale?)"))))) | N28: Model 49.5% (fair +102). Your call. | P28: =IF(OR($H$28="",$O$28=""),"",(1+IF($H$28<0,-100/$H$28,$H$28/100))/(1+IF($O$28<0,-100/$O$28,$O$28/100))-1)
A29: 2026-06-29 | B29: Pittsburgh Pirates @ Philadelphia Phillies | C29: 22:40 | D29: Total | E29: Over 8.5 | F29: 0.53753333 | G29: -116 | H29: -110 | I29: =IF($H$29="","",IF($H$29<0,-$H$29/(-$H$29+100),100/($H$29+100))) | J29: =IF($H$29="","",$F$29*IF($H$29<0,-100/$H$29,$H$29/100)-(1-$F$29)) | K29: =IF($H$29="","",MAX(0,($F$29*IF($H$29<0,-100/$H$29,$H$29/100)-(1-$F$29))/IF($H$29<0,-100/$H$29,$H$29/100))*'Settings'!$B$3) | L29: =IF($H$29="","",ROUND(MIN($K$29,'Settings'!$B$5)*'Settings'!$B$2,2)) | M29: =IF($J$29="","",IF($J$29<0,"Pass",IF($J$29<'Settings'!$B$4,"Thin",IF($J$29<0.06,"✅ Sharp band",IF($J$29<0.08,"Strong","⚠ Verify (stale?)"))))) | N29: Model 53.8% (fair -116). Your call. | P29: =IF(OR($H$29="",$O$29=""),"",(1+IF($H$29<0,-100/$H$29,$H$29/100))/(1+IF($O$29<0,-100/$O$29,$O$29/100))-1)

Sheet MLB Games
A1: MLB — game markets
A2: Moneyline · Total · Spread. Yellow = your price.
A4: Date | B4: Matchup | C4: Start | D4: Market | E4: Selection | F4: Model Win% | G4: Model Fair | H4: ✏ Your Odds | I4: Implied% | J4: Your Edge (EV) | K4: ¼-Kelly % | L4: Stake $ | M4: Verdict | N4: Model read | O4: ✏ Closing | P4: CLV %
A5: 2026-06-28 | B5: Washington Nationals @ Baltimore Orioles | C5: 17:35 | D5: Moneyline | E5: Washington Nationals | F5: 0.34545455 | G5: 189 | H5: 186 | I5: =IF($H$5="","",IF($H$5<0,-$H$5/(-$H$5+100),100/($H$5+100))) | J5: =IF($H$5="","",$F$5*IF($H$5<0,-100/$H$5,$H$5/100)-(1-$F$5)) | K5: =IF($H$5="","",MAX(0,($F$5*IF($H$5<0,-100/$H$5,$H$5/100)-(1-$F$5))/IF($H$5<0,-100/$H$5,$H$5/100))*'Settings'!$B$3) | L5: =IF($H$5="","",ROUND(MIN($K$5,'Settings'!$B$5)*'Settings'!$B$2,2)) | M5: =IF($J$5="","",IF($J$5<0,"Pass",IF($J$5<'Settings'!$B$4,"Thin",IF($J$5<0.06,"✅ Sharp band",IF($J$5<0.08,"Strong","⚠ Verify (stale?)"))))) | N5: Model 34.5% (fair +189). Your call. | P5: =IF(OR($H$5="",$O$5=""),"",(1+IF($H$5<0,-100/$H$5,$H$5/100))/(1+IF($O$5<0,-100/$O$5,$O$5/100))-1)
A6: 2026-06-28 | B6: Washington Nationals @ Baltimore Orioles | C6: 17:35 | D6: Moneyline | E6: Baltimore Orioles | F6: 0.65456619 | G6: -189 | H6: -178 | I6: =IF($H$6="","",IF($H$6<0,-$H$6/(-$H$6+100),100/($H$6+100))) | J6: =IF($H$6="","",$F$6*IF($H$6<0,-100/$H$6,$H$6/100)-(1-$F$6)) | K6: =IF($H$6="","",MAX(0,($F$6*IF($H$6<0,-100/$H$6,$H$6/100)-(1-$F$6))/IF($H$6<0,-100/$H$6,$H$6/100))*'Settings'!$B$3) | L6: =IF($H$6="","",ROUND(MIN($K$6,'Settings'!$B$5)*'Settings'!$B$2,2)) | M6: =IF($J$6="","",IF($J$6<0,"Pass",IF($J$6<'Settings'!$B$4,"Thin",IF($J$6<0.06,"✅ Sharp band",IF($J$6<0.08,"Strong","⚠ Verify (stale?)"))))) | N6: Model 65.5% (fair -189). Your call. | P6: =IF(OR($H$6="",$O$6=""),"",(1+IF($H$6<0,-100/$H$6,$H$6/100))/(1+IF($O$6<0,-100/$O$6,$O$6/100))-1)
A7: 2026-06-28 | B7: Washington Nationals @ Baltimore Orioles | C7: 17:35 | D7: Total | E7: Over 10 | F7: 0.5276 | G7: -112 | H7: 127 | I7: =IF($H$7="","",IF($H$7<0,-$H$7/(-$H$7+100),100/($H$7+100))) | J7: =IF($H$7="","",$F$7*IF($H$7<0,-100/$H$7,$H$7/100)-(1-$F$7)) | K7: =IF($H$7="","",MAX(0,($F$7*IF($H$7<0,-100/$H$7,$H$7/100)-(1-$F$7))/IF($H$7<0,-100/$H$7,$H$7/100))*'Settings'!$B$3) | L7: =IF($H$7="","",ROUND(MIN($K$7,'Settings'!$B$5)*'Settings'!$B$2,2)) | M7: =IF($J$7="","",IF($J$7<0,"Pass",IF($J$7<'Settings'!$B$4,"Thin",IF($J$7<0.06,"✅ Sharp band",IF($J$7<0.08,"Strong","⚠ Verify (stale?)"))))) | N7: Model 52.8% (fair -112). Your call. | P7: =IF(OR($H$7="",$O$7=""),"",(1+IF($H$7<0,-100/$H$7,$H$7/100))/(1+IF($O$7<0,-100/$O$7,$O$7/100))-1)
A8: 2026-06-28 | B8: Washington Nationals @ Baltimore Orioles | C8: 17:35 | D8: Total | E8: Under 10 | F8: 0.4724 | G8: 112 | H8: -108 | I8: =IF($H$8="","",IF($H$8<0,-$H$8/(-$H$8+100),100/($H$8+100))) | J8: =IF($H$8="","",$F$8*IF($H$8<0,-100/$H$8,$H$8/100)-(1-$F$8)) | K8: =IF($H$8="","",MAX(0,($F$8*IF($H$8<0,-100/$H$8,$H$8/100)-(1-$F$8))/IF($H$8<0,-100/$H$8,$H$8/100))*'Settings'!$B$3) | L8: =IF($H$8="","",ROUND(MIN($K$8,'Settings'!$B$5)*'Settings'!$B$2,2)) | M8: =IF($J$8="","",IF($J$8<0,"Pass",IF($J$8<'Settings'!$B$4,"Thin",IF($J$8<0.06,"✅ Sharp band",IF($J$8<0.08,"Strong","⚠ Verify (stale?)"))))) | N8: Model 47.2% (fair +112). Your call. | P8: =IF(OR($H$8="",$O$8=""),"",(1+IF($H$8<0,-100/$H$8,$H$8/100))/(1+IF($O$8<0,-100/$O$8,$O$8/100))-1)
A9: 2026-06-28 | B9: Washington Nationals @ Baltimore Orioles | C9: 17:35 | D9: Spread | E9: Baltimore Orioles -1.5 | F9: 0.50802885 | G9: -103 | H9: 108 | I9: =IF($H$9="","",IF($H$9<0,-$H$9/(-$H$9+100),100/($H$9+100))) | J9: =IF($H$9="","",$F$9*IF($H$9<0,-100/$H$9,$H$9/100)-(1-$F$9)) | K9: =IF($H$9="","",MAX(0,($F$9*IF($H$9<0,-100/$H$9,$H$9/100)-(1-$F$9))/IF($H$9<0,-100/$H$9,$H$9/100))*'Settings'!$B$3) | L9: =IF($H$9="","",ROUND(MIN($K$9,'Settings'!$B$5)*'Settings'!$B$2,2)) | M9: =IF($J$9="","",IF($J$9<0,"Pass",IF($J$9<'Settings'!$B$4,"Thin",IF($J$9<0.06,"✅ Sharp band",IF($J$9<0.08,"Strong","⚠ Verify (stale?)"))))) | N9: Model 50.8% (fair -103). Your call. | P9: =IF(OR($H$9="",$O$9=""),"",(1+IF($H$9<0,-100/$H$9,$H$9/100))/(1+IF($O$9<0,-100/$O$9,$O$9/100))-1)
A10: 2026-06-28 | B10: Washington Nationals @ Baltimore Orioles | C10: 17:35 | D10: Spread | E10: Washington Nationals +1.5 | F10: 0.4919619 | G10: 103 | H10: -110 | I10: =IF($H$10="","",IF($H$10<0,-$H$10/(-$H$10+100),100/($H$10+100))) | J10: =IF($H$10="","",$F$10*IF($H$10<0,-100/$H$10,$H$10/100)-(1-$F$10)) | K10: =IF($H$10="","",MAX(0,($F$10*IF($H$10<0,-100/$H$10,$H$10/100)-(1-$F$10))/IF($H$10<0,-100/$H$10,$H$10/100))*'Settings'!$B$3) | L10: =IF($H$10="","",ROUND(MIN($K$10,'Settings'!$B$5)*'Settings'!$B$2,2)) | M10: =IF($J$10="","",IF($J$10<0,"Pass",IF($J$10<'Settings'!$B$4,"Thin",IF($J$10<0.06,"✅ Sharp band",IF($J$10<0.08,"Strong","⚠ Verify (stale?)"))))) | N10: Model 49.2% (fair +103). Your call. | P10: =IF(OR($H$10="",$O$10=""),"",(1+IF($H$10<0,-100/$H$10,$H$10/100))/(1+IF($O$10<0,-100/$O$10,$O$10/100))-1)
A11: 2026-06-28 | B11: Cincinnati Reds @ Pittsburgh Pirates | C11: 17:35 | D11: Moneyline | E11: Cincinnati Reds | F11: 0.36740088 | G11: 172 | H11: 127 | I11: =IF($H$11="","",IF($H$11<0,-$H$11/(-$H$11+100),100/($H$11+100))) | J11: =IF($H$11="","",$F$11*IF($H$11<0,-100/$H$11,$H$11/100)-(1-$F$11)) | K11: =IF($H$11="","",MAX(0,($F$11*IF($H$11<0,-100/$H$11,$H$11/100)-(1-$F$11))/IF($H$11<0,-100/$H$11,$H$11/100))*'Settings'!$B$3) | L11: =IF($H$11="","",ROUND(MIN($K$11,'Settings'!$B$5)*'Settings'!$B$2,2)) | M11: =IF($J$11="","",IF($J$11<0,"Pass",IF($J$11<'Settings'!$B$4,"Thin",IF($J$11<0.06,"✅ Sharp band",IF($J$11<0.08,"Strong","⚠ Verify (stale?)"))))) | N11: Model 36.7% (fair +172). Your call. | P11: =IF(OR($H$11="",$O$11=""),"",(1+IF($H$11<0,-100/$H$11,$H$11/100))/(1+IF($O$11<0,-100/$O$11,$O$11/100))-1)
A12: 2026-06-28 | B12: Cincinnati Reds @ Pittsburgh Pirates | C12: 17:35 | D12: Moneyline | E12: Pittsburgh Pirates | F12: 0.63259427 | G12: -172 | H12: -127 | I12: =IF($H$12="","",IF($H$12<0,-$H$12/(-$H$12+100),100/($H$12+100))) | J12: =IF($H$12="","",$F$12*IF($H$12<0,-100/$H$12,$H$12/100)-(1-$F$12)) | K12: =IF($H$12="","",MAX(0,($F$12*IF($H$12<0,-100/$H$12,$H$12/100)-(1-$F$12))/IF($H$12<0,-100/$H$12,$H$12/100))*'Settings'!$B$3) | L12: =IF($H$12="","",ROUND(MIN($K$12,'Settings'!$B$5)*'Settings'!$B$2,2)) | M12: =IF($J$12="","",IF($J$12<0,"Pass",IF($J$12<'Settings'!$B$4,"Thin",IF($J$12<0.06,"✅ Sharp band",IF($J$12<0.08,"Strong","⚠ Verify (stale?)"))))) | N12: Model 63.3% (fair -172). Your call. | P12: =IF(OR($H$12="",$O$12=""),"",(1+IF($H$12<0,-100/$H$12,$H$12/100))/(1+IF($O$12<0,-100/$O$12,$O$12/100))-1)
A13: 2026-06-28 | B13: Cincinnati Reds @ Pittsburgh Pirates | C13: 17:35 | D13: Total | E13: Over 9.5 | F13: 0.5379 | G13: -116 | H13: 117 | I13: =IF($H$13="","",IF($H$13<0,-$H$13/(-$H$13+100),100/($H$13+100))) | J13: =IF($H$13="","",$F$13*IF($H$13<0,-100/$H$13,$H$13/100)-(1-$F$13)) | K13: =IF($H$13="","",MAX(0,($F$13*IF($H$13<0,-100/$H$13,$H$13/100)-(1-$F$13))/IF($H$13<0,-100/$H$13,$H$13/100))*'Settings'!$B$3) | L13: =IF($H$13="","",ROUND(MIN($K$13,'Settings'!$B$5)*'Settings'!$B$2,2)) | M13: =IF($J$13="","",IF($J$13<0,"Pass",IF($J$13<'Settings'!$B$4,"Thin",IF($J$13<0.06,"✅ Sharp band",IF($J$13<0.08,"Strong","⚠ Verify (stale?)"))))) | N13: Model 53.8% (fair -116). Your call. | P13: =IF(OR($H$13="",$O$13=""),"",(1+IF($H$13<0,-100/$H$13,$H$13/100))/(1+IF($O$13<0,-100/$O$13,$O$13/100))-1)
A14: 2026-06-28 | B14: Cincinnati Reds @ Pittsburgh Pirates | C14: 17:35 | D14: Total | E14: Under 9.5 | F14: 0.4621 | G14: 116 | H14: 128 | I14: =IF($H$14="","",IF($H$14<0,-$H$14/(-$H$14+100),100/($H$14+100))) | J14: =IF($H$14="","",$F$14*IF($H$14<0,-100/$H$14,$H$14/100)-(1-$F$14)) | K14: =IF($H$14="","",MAX(0,($F$14*IF($H$14<0,-100/$H$14,$H$14/100)-(1-$F$14))/IF($H$14<0,-100/$H$14,$H$14/100))*'Settings'!$B$3) | L14: =IF($H$14="","",ROUND(MIN($K$14,'Settings'!$B$5)*'Settings'!$B$2,2)) | M14: =IF($J$14="","",IF($J$14<0,"Pass",IF($J$14<'Settings'!$B$4,"Thin",IF($J$14<0.06,"✅ Sharp band",IF($J$14<0.08,"Strong","⚠ Verify (stale?)"))))) | N14: Model 46.2% (fair +116). Your call. | P14: =IF(OR($H$14="",$O$14=""),"",(1+IF($H$14<0,-100/$H$14,$H$14/100))/(1+IF($O$14<0,-100/$O$14,$O$14/100))-1)
A15: 2026-06-28 | B15: Cincinnati Reds @ Pittsburgh Pirates | C15: 17:35 | D15: Spread | E15: Pittsburgh Pirates -1.5 | F15: 0.577 | G15: -136 | H15: 160 | I15: =IF($H$15="","",IF($H$15<0,-$H$15/(-$H$15+100),100/($H$15+100))) | J15: =IF($H$15="","",$F$15*IF($H$15<0,-100/$H$15,$H$15/100)-(1-$F$15)) | K15: =IF($H$15="","",MAX(0,($F$15*IF($H$15<0,-100/$H$15,$H$15/100)-(1-$F$15))/IF($H$15<0,-100/$H$15,$H$15/100))*'Settings'!$B$3) | L15: =IF($H$15="","",ROUND(MIN($K$15,'Settings'!$B$5)*'Settings'!$B$2,2)) | M15: =IF($J$15="","",IF($J$15<0,"Pass",IF($J$15<'Settings'!$B$4,"Thin",IF($J$15<0.06,"✅ Sharp band",IF($J$15<0.08,"Strong","⚠ Verify (stale?)"))))) | N15: Model 57.7% (fair -136). Your call. | P15: =IF(OR($H$15="",$O$15=""),"",(1+IF($H$15<0,-100/$H$15,$H$15/100))/(1+IF($O$15<0,-100/$O$15,$O$15/100))-1)
A16: 2026-06-28 | B16: Cincinnati Reds @ Pittsburgh Pirates | C16: 17:35 | D16: Spread | E16: Cincinnati Reds +1.5 | F16: 0.423 | G16: 136 | H16: -117 | I16: =IF($H$16="","",IF($H$16<0,-$H$16/(-$H$16+100),100/($H$16+100))) | J16: =IF($H$16="","",$F$16*IF($H$16<0,-100/$H$16,$H$16/100)-(1-$F$16)) | K16: =IF($H$16="","",MAX(0,($F$16*IF($H$16<0,-100/$H$16,$H$16/100)-(1-$F$16))/IF($H$16<0,-100/$H$16,$H$16/100))*'Settings'!$B$3) | L16: =IF($H$16="","",ROUND(MIN($K$16,'Settings'!$B$5)*'Settings'!$B$2,2)) | M16: =IF($J$16="","",IF($J$16<0,"Pass",IF($J$16<'Settings'!$B$4,"Thin",IF($J$16<0.06,"✅ Sharp band",IF($J$16<0.08,"Strong","⚠ Verify (stale?)"))))) | N16: Model 42.3% (fair +136). Your call. | P16: =IF(OR($H$16="",$O$16=""),"",(1+IF($H$16<0,-100/$H$16,$H$16/100))/(1+IF($O$16<0,-100/$O$16,$O$16/100))-1)
A17: 2026-06-28 | B17: Texas Rangers @ Toronto Blue Jays | C17: 17:37 | D17: Moneyline | E17: Texas Rangers | F17: 0.48738532 | G17: 105 | H17: 118 | I17: =IF($H$17="","",IF($H$17<0,-$H$17/(-$H$17+100),100/($H$17+100))) | J17: =IF($H$17="","",$F$17*IF($H$17<0,-100/$H$17,$H$17/100)-(1-$F$17)) | K17: =IF($H$17="","",MAX(0,($F$17*IF($H$17<0,-100/$H$17,$H$17/100)-(1-$F$17))/IF($H$17<0,-100/$H$17,$H$17/100))*'Settings'!$B$3) | L17: =IF($H$17="","",ROUND(MIN($K$17,'Settings'!$B$5)*'Settings'!$B$2,2)) | M17: =IF($J$17="","",IF($J$17<0,"Pass",IF($J$17<'Settings'!$B$4,"Thin",IF($J$17<0.06,"✅ Sharp band",IF($J$17<0.08,"Strong","⚠ Verify (stale?)"))))) | N17: Model 48.7% (fair +105). Your call. | P17: =IF(OR($H$17="",$O$17=""),"",(1+IF($H$17<0,-100/$H$17,$H$17/100))/(1+IF($O$17<0,-100/$O$17,$O$17/100))-1)
A18: 2026-06-28 | B18: Texas Rangers @ Toronto Blue Jays | C18: 17:37 | D18: Moneyline | E18: Toronto Blue Jays | F18: 0.51261818 | G18: -105 | H18: -120 | I18: =IF($H$18="","",IF($H$18<0,-$H$18/(-$H$18+100),100/($H$18+100))) | J18: =IF($H$18="","",$F$18*IF($H$18<0,-100/$H$18,$H$18/100)-(1-$F$18)) | K18: =IF($H$18="","",MAX(0,($F$18*IF($H$18<0,-100/$H$18,$H$18/100)-(1-$F$18))/IF($H$18<0,-100/$H$18,$H$18/100))*'Settings'!$B$3) | L18: =IF($H$18="","",ROUND(MIN($K$18,'Settings'!$B$5)*'Settings'!$B$2,2)) | M18: =IF($J$18="","",IF($J$18<0,"Pass",IF($J$18<'Settings'!$B$4,"Thin",IF($J$18<0.06,"✅ Sharp band",IF($J$18<0.08,"Strong","⚠ Verify (stale?)"))))) | N18: Model 51.3% (fair -105). Your call. | P18: =IF(OR($H$18="",$O$18=""),"",(1+IF($H$18<0,-100/$H$18,$H$18/100))/(1+IF($O$18<0,-100/$O$18,$O$18/100))-1)
A19: 2026-06-28 | B19: Texas Rangers @ Toronto Blue Jays | C19: 17:37 | D19: Total | E19: Over 9 | F19: 0.4591 | G19: 118 | H19: 104 | I19: =IF($H$19="","",IF($H$19<0,-$H$19/(-$H$19+100),100/($H$19+100))) | J19: =IF($H$19="","",$F$19*IF($H$19<0,-100/$H$19,$H$19/100)-(1-$F$19)) | K19: =IF($H$19="","",MAX(0,($F$19*IF($H$19<0,-100/$H$19,$H$19/100)-(1-$F$19))/IF($H$19<0,-100/$H$19,$H$19/100))*'Settings'!$B$3) | L19: =IF($H$19="","",ROUND(MIN($K$19,'Settings'!$B$5)*'Settings'!$B$2,2)) | M19: =IF($J$19="","",IF($J$19<0,"Pass",IF($J$19<'Settings'!$B$4,"Thin",IF($J$19<0.06,"✅ Sharp band",IF($J$19<0.08,"Strong","⚠ Verify (stale?)"))))) | N19: Model 45.9% (fair +118). Your call. | P19: =IF(OR($H$19="",$O$19=""),"",(1+IF($H$19<0,-100/$H$19,$H$19/100))/(1+IF($O$19<0,-100/$O$19,$O$19/100))-1)
A20: 2026-06-28 | B20: Texas Rangers @ Toronto Blue Jays | C20: 17:37 | D20: Total | E20: Under 9 | F20: 0.5409 | G20: -118 | H20: 117 | I20: =IF($H$20="","",IF($H$20<0,-$H$20/(-$H$20+100),100/($H$20+100))) | J20: =IF($H$20="","",$F$20*IF($H$20<0,-100/$H$20,$H$20/100)-(1-$F$20)) | K20: =IF($H$20="","",MAX(0,($F$20*IF($H$20<0,-100/$H$20,$H$20/100)-(1-$F$20))/IF($H$20<0,-100/$H$20,$H$20/100))*'Settings'!$B$3) | L20: =IF($H$20="","",ROUND(MIN($K$20,'Settings'!$B$5)*'Settings'!$B$2,2)) | M20: =IF($J$20="","",IF($J$20<0,"Pass",IF($J$20<'Settings'!$B$4,"Thin",IF($J$20<0.06,"✅ Sharp band",IF($J$20<0.08,"Strong","⚠ Verify (stale?)"))))) | N20: Model 54.1% (fair -118). Your call. | P20: =IF(OR($H$20="",$O$20=""),"",(1+IF($H$20<0,-100/$H$20,$H$20/100))/(1+IF($O$20<0,-100/$O$20,$O$20/100))-1)
A21: 2026-06-28 | B21: Texas Rangers @ Toronto Blue Jays | C21: 17:37 | D21: Spread | E21: Toronto Blue Jays -1.5 | F21: 0.3575 | G21: 180 | H21: 174 | I21: =IF($H$21="","",IF($H$21<0,-$H$21/(-$H$21+100),100/($H$21+100))) | J21: =IF($H$21="","",$F$21*IF($H$21<0,-100/$H$21,$H$21/100)-(1-$F$21)) | K21: =IF($H$21="","",MAX(0,($F$21*IF($H$21<0,-100/$H$21,$H$21/100)-(1-$F$21))/IF($H$21<0,-100/$H$21,$H$21/100))*'Settings'!$B$3) | L21: =IF($H$21="","",ROUND(MIN($K$21,'Settings'!$B$5)*'Settings'!$B$2,2)) | M21: =IF($J$21="","",IF($J$21<0,"Pass",IF($J$21<'Settings'!$B$4,"Thin",IF($J$21<0.06,"✅ Sharp band",IF($J$21<0.08,"Strong","⚠ Verify (stale?)"))))) | N21: Model 35.8% (fair +180). Your call. | P21: =IF(OR($H$21="",$O$21=""),"",(1+IF($H$21<0,-100/$H$21,$H$21/100))/(1+IF($O$21<0,-100/$O$21,$O$21/100))-1)
A22: 2026-06-28 | B22: Texas Rangers @ Toronto Blue Jays | C22: 17:37 | D22: Spread | E22: Texas Rangers +1.5 | F22: 0.6425 | G22: -180 | H22: 163 | I22: =IF($H$22="","",IF($H$22<0,-$H$22/(-$H$22+100),100/($H$22+100))) | J22: =IF($H$22="","",$F$22*IF($H$22<0,-100/$H$22,$H$22/100)-(1-$F$22)) | K22: =IF($H$22="","",MAX(0,($F$22*IF($H$22<0,-100/$H$22,$H$22/100)-(1-$F$22))/IF($H$22<0,-100/$H$22,$H$22/100))*'Settings'!$B$3) | L22: =IF($H$22="","",ROUND(MIN($K$22,'Settings'!$B$5)*'Settings'!$B$2,2)) | M22: =IF($J$22="","",IF($J$22<0,"Pass",IF($J$22<'Settings'!$B$4,"Thin",IF($J$22<0.06,"✅ Sharp band",IF($J$22<0.08,"Strong","⚠ Verify (stale?)"))))) | N22: Model 64.2% (fair -180). Your call. | P22: =IF(OR($H$22="",$O$22=""),"",(1+IF($H$22<0,-100/$H$22,$H$22/100))/(1+IF($O$22<0,-100/$O$22,$O$22/100))-1)
A23: 2026-06-28 | B23: Houston Astros @ Detroit Tigers | C23: 17:40 | D23: Moneyline | E23: Houston Astros | F23: 0.51095 | G23: -104 | H23: 100 | I23: =IF($H$23="","",IF($H$23<0,-$H$23/(-$H$23+100),100/($H$23+100))) | J23: =IF($H$23="","",$F$23*IF($H$23<0,-100/$H$23,$H$23/100)-(1-$F$23)) | K23: =IF($H$23="","",MAX(0,($F$23*IF($H$23<0,-100/$H$23,$H$23/100)-(1-$F$23))/IF($H$23<0,-100/$H$23,$H$23/100))*'Settings'!$B$3) | L23: =IF($H$23="","",ROUND(MIN($K$23,'Settings'!$B$5)*'Settings'!$B$2,2)) | M23: =IF($J$23="","",IF($J$23<0,"Pass",IF($J$23<'Settings'!$B$4,"Thin",IF($J$23<0.06,"✅ Sharp band",IF($J$23<0.08,"Strong","⚠ Verify (stale?)"))))) | N23: Model 51.1% (fair -104). Your call. | P23: =IF(OR($H$23="",$O$23=""),"",(1+IF($H$23<0,-100/$H$23,$H$23/100))/(1+IF($O$23<0,-100/$O$23,$O$23/100))-1)
A24: 2026-06-28 | B24: Houston Astros @ Detroit Tigers | C24: 17:40 | D24: Moneyline | E24: Detroit Tigers | F24: 0.48903846 | G24: 104 | H24: 108 | I24: =IF($H$24="","",IF($H$24<0,-$H$24/(-$H$24+100),100/($H$24+100))) | J24: =IF($H$24="","",$F$24*IF($H$24<0,-100/$H$24,$H$24/100)-(1-$F$24)) | K24: =IF($H$24="","",MAX(0,($F$24*IF($H$24<0,-100/$H$24,$H$24/100)-(1-$F$24))/IF($H$24<0,-100/$H$24,$H$24/100))*'Settings'!$B$3) | L24: =IF($H$24="","",ROUND(MIN($K$24,'Settings'!$B$5)*'Settings'!$B$2,2)) | M24: =IF($J$24="","",IF($J$24<0,"Pass",IF($J$24<'Settings'!$B$4,"Thin",IF($J$24<0.06,"✅ Sharp band",IF($J$24<0.08,"Strong","⚠ Verify (stale?)"))))) | N24: Model 48.9% (fair +104). Your call. | P24: =IF(OR($H$24="",$O$24=""),"",(1+IF($H$24<0,-100/$H$24,$H$24/100))/(1+IF($O$24<0,-100/$O$24,$O$24/100))-1)
A25: 2026-06-28 | B25: Houston Astros @ Detroit Tigers | C25: 17:40 | D25: Total | E25: Over 8.5 | F25: 0.551 | G25: -123 | H25: 113 | I25: =IF($H$25="","",IF($H$25<0,-$H$25/(-$H$25+100),100/($H$25+100))) | J25: =IF($H$25="","",$F$25*IF($H$25<0,-100/$H$25,$H$25/100)-(1-$F$25)) | K25: =IF($H$25="","",MAX(0,($F$25*IF($H$25<0,-100/$H$25,$H$25/100)-(1-$F$25))/IF($H$25<0,-100/$H$25,$H$25/100))*'Settings'!$B$3) | L25: =IF($H$25="","",ROUND(MIN($K$25,'Settings'!$B$5)*'Settings'!$B$2,2)) | M25: =IF($J$25="","",IF($J$25<0,"Pass",IF($J$25<'Settings'!$B$4,"Thin",IF($J$25<0.06,"✅ Sharp band",IF($J$25<0.08,"Strong","⚠ Verify (stale?)"))))) | N25: Model 55.1% (fair -123). Your call. | P25: =IF(OR($H$25="",$O$25=""),"",(1+IF($H$25<0,-100/$H$25,$H$25/100))/(1+IF($O$25<0,-100/$O$25,$O$25/100))-1)
A26: 2026-06-28 | B26: Houston Astros @ Detroit Tigers | C26: 17:40 | D26: Total | E26: Under 8.5 | F26: 0.449 | G26: 123 | H26: 107 | I26: =IF($H$26="","",IF($H$26<0,-$H$26/(-$H$26+100),100/($H$26+100))) | J26: =IF($H$26="","",$F$26*IF($H$26<0,-100/$H$26,$H$26/100)-(1-$F$26)) | K26: =IF($H$26="","",MAX(0,($F$26*IF($H$26<0,-100/$H$26,$H$26/100)-(1-$F$26))/IF($H$26<0,-100/$H$26,$H$26/100))*'Settings'!$B$3) | L26: =IF($H$26="","",ROUND(MIN($K$26,'Settings'!$B$5)*'Settings'!$B$2,2)) | M26: =IF($J$26="","",IF($J$26<0,"Pass",IF($J$26<'Settings'!$B$4,"Thin",IF($J$26<0.06,"✅ Sharp band",IF($J$26<0.08,"Strong","⚠ Verify (stale?)"))))) | N26: Model 44.9% (fair +123). Your call. | P26: =IF(OR($H$26="",$O$26=""),"",(1+IF($H$26<0,-100/$H$26,$H$26/100))/(1+IF($O$26<0,-100/$O$26,$O$26/100))-1)
A27: 2026-06-28 | B27: Houston Astros @ Detroit Tigers | C27: 17:40 | D27: Spread | E27: Detroit Tigers -1.5 | F27: 0.3589 | G27: 179 | H27: 150 | I27: =IF($H$27="","",IF($H$27<0,-$H$27/(-$H$27+100),100/($H$27+100))) | J27: =IF($H$27="","",$F$27*IF($H$27<0,-100/$H$27,$H$27/100)-(1-$F$27)) | K27: =IF($H$27="","",MAX(0,($F$27*IF($H$27<0,-100/$H$27,$H$27/100)-(1-$F$27))/IF($H$27<0,-100/$H$27,$H$27/100))*'Settings'!$B$3) | L27: =IF($H$27="","",ROUND(MIN($K$27,'Settings'!$B$5)*'Settings'!$B$2,2)) | M27: =IF($J$27="","",IF($J$27<0,"Pass",IF($J$27<'Settings'!$B$4,"Thin",IF($J$27<0.06,"✅ Sharp band",IF($J$27<0.08,"Strong","⚠ Verify (stale?)"))))) | N27: Model 35.9% (fair +179). Your call. | P27: =IF(OR($H$27="",$O$27=""),"",(1+IF($H$27<0,-100/$H$27,$H$27/100))/(1+IF($O$27<0,-100/$O$27,$O$27/100))-1)
A28: 2026-06-28 | B28: Houston Astros @ Detroit Tigers | C28: 17:40 | D28: Spread | E28: Houston Astros +1.5 | F28: 0.6411 | G28: -179 | H28: 163 | I28: =IF($H$28="","",IF($H$28<0,-$H$28/(-$H$28+100),100/($H$28+100))) | J28: =IF($H$28="","",$F$28*IF($H$28<0,-100/$H$28,$H$28/100)-(1-$F$28)) | K28: =IF($H$28="","",MAX(0,($F$28*IF($H$28<0,-100/$H$28,$H$28/100)-(1-$F$28))/IF($H$28<0,-100/$H$28,$H$28/100))*'Settings'!$B$3) | L28: =IF($H$28="","",ROUND(MIN($K$28,'Settings'!$B$5)*'Settings'!$B$2,2)) | M28: =IF($J$28="","",IF($J$28<0,"Pass",IF($J$28<'Settings'!$B$4,"Thin",IF($J$28<0.06,"✅ Sharp band",IF($J$28<0.08,"Strong","⚠ Verify (stale?)"))))) | N28: Model 64.1% (fair -179). Your call. | P28: =IF(OR($H$28="",$O$28=""),"",(1+IF($H$28<0,-100/$H$28,$H$28/100))/(1+IF($O$28<0,-100/$O$28,$O$28/100))-1)
A29: 2026-06-28 | B29: Seattle Mariners @ Cleveland Guardians | C29: 17:40 | D29: Moneyline | E29: Seattle Mariners | F29: 0.51488372 | G29: -106 | H29: 115 | I29: =IF($H$29="","",IF($H$29<0,-$H$29/(-$H$29+100),100/($H$29+100))) | J29: =IF($H$29="","",$F$29*IF($H$29<0,-100/$H$29,$H$29/100)-(1-$F$29)) | K29: =IF($H$29="","",MAX(0,($F$29*IF($H$29<0,-100/$H$29,$H$29/100)-(1-$F$29))/IF($H$29<0,-100/$H$29,$H$29/100))*'Settings'!$B$3) | L29: =IF($H$29="","",ROUND(MIN($K$29,'Settings'!$B$5)*'Settings'!$B$2,2)) | M29: =IF($J$29="","",IF($J$29<0,"Pass",IF($J$29<'Settings'!$B$4,"Thin",IF($J$29<0.06,"✅ Sharp band",IF($J$29<0.08,"Strong","⚠ Verify (stale?)"))))) | N29: Model 51.5% (fair -106). Your call. | P29: =IF(OR($H$29="",$O$29=""),"",(1+IF($H$29<0,-100/$H$29,$H$29/100))/(1+IF($O$29<0,-100/$O$29,$O$29/100))-1)
A30: 2026-06-28 | B30: Seattle Mariners @ Cleveland Guardians | C30: 17:40 | D30: Moneyline | E30: Cleveland Guardians | F30: 0.48510423 | G30: 106 | H30: -113 | I30: =IF($H$30="","",IF($H$30<0,-$H$30/(-$H$30+100),100/($H$30+100))) | J30: =IF($H$30="","",$F$30*IF($H$30<0,-100/$H$30,$H$30/100)-(1-$F$30)) | K30: =IF($H$30="","",MAX(0,($F$30*IF($H$30<0,-100/$H$30,$H$30/100)-(1-$F$30))/IF($H$30<0,-100/$H$30,$H$30/100))*'Settings'!$B$3) | L30: =IF($H$30="","",ROUND(MIN($K$30,'Settings'!$B$5)*'Settings'!$B$2,2)) | M30: =IF($J$30="","",IF($J$30<0,"Pass",IF($J$30<'Settings'!$B$4,"Thin",IF($J$30<0.06,"✅ Sharp band",IF($J$30<0.08,"Strong","⚠ Verify (stale?)"))))) | N30: Model 48.5% (fair +106). Your call. | P30: =IF(OR($H$30="",$O$30=""),"",(1+IF($H$30<0,-100/$H$30,$H$30/100))/(1+IF($O$30<0,-100/$O$30,$O$30/100))-1)
A31: 2026-06-28 | B31: Seattle Mariners @ Cleveland Guardians | C31: 17:40 | D31: Total | E31: Over 7.5 | F31: 0.4395 | G31: 128 | H31: 104 | I31: =IF($H$31="","",IF($H$31<0,-$H$31/(-$H$31+100),100/($H$31+100))) | J31: =IF($H$31="","",$F$31*IF($H$31<0,-100/$H$31,$H$31/100)-(1-$F$31)) | K31: =IF($H$31="","",MAX(0,($F$31*IF($H$31<0,-100/$H$31,$H$31/100)-(1-$F$31))/IF($H$31<0,-100/$H$31,$H$31/100))*'Settings'!$B$3) | L31: =IF($H$31="","",ROUND(MIN($K$31,'Settings'!$B$5)*'Settings'!$B$2,2)) | M31: =IF($J$31="","",IF($J$31<0,"Pass",IF($J$31<'Settings'!$B$4,"Thin",IF($J$31<0.06,"✅ Sharp band",IF($J$31<0.08,"Strong","⚠ Verify (stale?)"))))) | N31: Model 44.0% (fair +128). Your call. | P31: =IF(OR($H$31="",$O$31=""),"",(1+IF($H$31<0,-100/$H$31,$H$31/100))/(1+IF($O$31<0,-100/$O$31,$O$31/100))-1)
A32: 2026-06-28 | B32: Seattle Mariners @ Cleveland Guardians | C32: 17:40 | D32: Total | E32: Under 7.5 | F32: 0.5605 | G32: -128 | H32: 121 | I32: =IF($H$32="","",IF($H$32<0,-$H$32/(-$H$32+100),100/($H$32+100))) | J32: =IF($H$32="","",$F$32*IF($H$32<0,-100/$H$32,$H$32/100)-(1-$F$32)) | K32: =IF($H$32="","",MAX(0,($F$32*IF($H$32<0,-100/$H$32,$H$32/100)-(1-$F$32))/IF($H$32<0,-100/$H$32,$H$32/100))*'Settings'!$B$3) | L32: =IF($H$32="","",ROUND(MIN($K$32,'Settings'!$B$5)*'Settings'!$B$2,2)) | M32: =IF($J$32="","",IF($J$32<0,"Pass",IF($J$32<'Settings'!$B$4,"Thin",IF($J$32<0.06,"✅ Sharp band",IF($J$32<0.08,"Strong","⚠ Verify (stale?)"))))) | N32: Model 56.0% (fair -128). Your call. | P32: =IF(OR($H$32="",$O$32=""),"",(1+IF($H$32<0,-100/$H$32,$H$32/100))/(1+IF($O$32<0,-100/$O$32,$O$32/100))-1)
A33: 2026-06-28 | B33: Seattle Mariners @ Cleveland Guardians | C33: 17:40 | D33: Spread | E33: Cleveland Guardians -1.5 | F33: 0.2906 | G33: 244 | H33: 186 | I33: =IF($H$33="","",IF($H$33<0,-$H$33/(-$H$33+100),100/($H$33+100))) | J33: =IF($H$33="","",$F$33*IF($H$33<0,-100/$H$33,$H$33/100)-(1-$F$33)) | K33: =IF($H$33="","",MAX(0,($F$33*IF($H$33<0,-100/$H$33,$H$33/100)-(1-$F$33))/IF($H$33<0,-100/$H$33,$H$33/100))*'Settings'!$B$3) | L33: =IF($H$33="","",ROUND(MIN($K$33,'Settings'!$B$5)*'Settings'!$B$2,2)) | M33: =IF($J$33="","",IF($J$33<0,"Pass",IF($J$33<'Settings'!$B$4,"Thin",IF($J$33<0.06,"✅ Sharp band",IF($J$33<0.08,"Strong","⚠ Verify (stale?)"))))) | N33: Model 29.1% (fair +244). Your call. | P33: =IF(OR($H$33="",$O$33=""),"",(1+IF($H$33<0,-100/$H$33,$H$33/100))/(1+IF($O$33<0,-100/$O$33,$O$33/100))-1)
A34: 2026-06-28 | B34: Seattle Mariners @ Cleveland Guardians | C34: 17:40 | D34: Spread | E34: Seattle Mariners +1.5 | F34: 0.7094 | G34: -244 | H34: 186 | I34: =IF($H$34="","",IF($H$34<0,-$H$34/(-$H$34+100),100/($H$34+100))) | J34: =IF($H$34="","",$F$34*IF($H$34<0,-100/$H$34,$H$34/100)-(1-$F$34)) | K34: =IF($H$34="","",MAX(0,($F$34*IF($H$34<0,-100/$H$34,$H$34/100)-(1-$F$34))/IF($H$34<0,-100/$H$34,$H$34/100))*'Settings'!$B$3) | L34: =IF($H$34="","",ROUND(MIN($K$34,'Settings'!$B$5)*'Settings'!$B$2,2)) | M34: =IF($J$34="","",IF($J$34<0,"Pass",IF($J$34<'Settings'!$B$4,"Thin",IF($J$34<0.06,"✅ Sharp band",IF($J$34<0.08,"Strong","⚠ Verify (stale?)"))))) | N34: Model 70.9% (fair -244). Your call. | P34: =IF(OR($H$34="",$O$34=""),"",(1+IF($H$34<0,-100/$H$34,$H$34/100))/(1+IF($O$34<0,-100/$O$34,$O$34/100))-1)
A35: 2026-06-28 | B35: Arizona Diamondbacks @ Tampa Bay Rays | C35: 17:40 | D35: Moneyline | E35: Arizona Diamondbacks | F35: 0.37761404 | G35: 165 | H35: 185 | I35: =IF($H$35="","",IF($H$35<0,-$H$35/(-$H$35+100),100/($H$35+100))) | J35: =IF($H$35="","",$F$35*IF($H$35<0,-100/$H$35,$H$35/100)-(1-$F$35)) | K35: =IF($H$35="","",MAX(0,($F$35*IF($H$35<0,-100/$H$35,$H$35/100)-(1-$F$35))/IF($H$35<0,-100/$H$35,$H$35/100))*'Settings'!$B$3) | L35: =IF($H$35="","",ROUND(MIN($K$35,'Settings'!$B$5)*'Settings'!$B$2,2)) | M35: =IF($J$35="","",IF($J$35<0,"Pass",IF($J$35<'Settings'!$B$4,"Thin",IF($J$35<0.06,"✅ Sharp band",IF($J$35<0.08,"Strong","⚠ Verify (stale?)"))))) | N35: Model 37.8% (fair +165). Your call. | P35: =IF(OR($H$35="",$O$35=""),"",(1+IF($H$35<0,-100/$H$35,$H$35/100))/(1+IF($O$35<0,-100/$O$35,$O$35/100))-1)
A36: 2026-06-28 | B36: Arizona Diamondbacks @ Tampa Bay Rays | C36: 17:40 | D36: Moneyline | E36: Tampa Bay Rays | F36: 0.62242374 | G36: -165 | H36: -178 | I36: =IF($H$36="","",IF($H$36<0,-$H$36/(-$H$36+100),100/($H$36+100))) | J36: =IF($H$36="","",$F$36*IF($H$36<0,-100/$H$36,$H$36/100)-(1-$F$36)) | K36: =IF($H$36="","",MAX(0,($F$36*IF($H$36<0,-100/$H$36,$H$36/100)-(1-$F$36))/IF($H$36<0,-100/$H$36,$H$36/100))*'Settings'!$B$3) | L36: =IF($H$36="","",ROUND(MIN($K$36,'Settings'!$B$5)*'Settings'!$B$2,2)) | M36: =IF($J$36="","",IF($J$36<0,"Pass",IF($J$36<'Settings'!$B$4,"Thin",IF($J$36<0.06,"✅ Sharp band",IF($J$36<0.08,"Strong","⚠ Verify (stale?)"))))) | N36: Model 62.2% (fair -165). Your call. | P36: =IF(OR($H$36="",$O$36=""),"",(1+IF($H$36<0,-100/$H$36,$H$36/100))/(1+IF($O$36<0,-100/$O$36,$O$36/100))-1)
A37: 2026-06-28 | B37: Arizona Diamondbacks @ Tampa Bay Rays | C37: 17:40 | D37: Total | E37: Over 8 | F37: 0.4802 | G37: 108 | H37: -102 | I37: =IF($H$37="","",IF($H$37<0,-$H$37/(-$H$37+100),100/($H$37+100))) | J37: =IF($H$37="","",$F$37*IF($H$37<0,-100/$H$37,$H$37/100)-(1-$F$37)) | K37: =IF($H$37="","",MAX(0,($F$37*IF($H$37<0,-100/$H$37,$H$37/100)-(1-$F$37))/IF($H$37<0,-100/$H$37,$H$37/100))*'Settings'!$B$3) | L37: =IF($H$37="","",ROUND(MIN($K$37,'Settings'!$B$5)*'Settings'!$B$2,2)) | M37: =IF($J$37="","",IF($J$37<0,"Pass",IF($J$37<'Settings'!$B$4,"Thin",IF($J$37<0.06,"✅ Sharp band",IF($J$37<0.08,"Strong","⚠ Verify (stale?)"))))) | N37: Model 48.0% (fair +108). Your call. | P37: =IF(OR($H$37="",$O$37=""),"",(1+IF($H$37<0,-100/$H$37,$H$37/100))/(1+IF($O$37<0,-100/$O$37,$O$37/100))-1)
A38: 2026-06-28 | B38: Arizona Diamondbacks @ Tampa Bay Rays | C38: 17:40 | D38: Total | E38: Under 8 | F38: 0.5198 | G38: -108 | H38: 115 | I38: =IF($H$38="","",IF($H$38<0,-$H$38/(-$H$38+100),100/($H$38+100))) | J38: =IF($H$38="","",$F$38*IF($H$38<0,-100/$H$38,$H$38/100)-(1-$F$38)) | K38: =IF($H$38="","",MAX(0,($F$38*IF($H$38<0,-100/$H$38,$H$38/100)-(1-$F$38))/IF($H$38<0,-100/$H$38,$H$38/100))*'Settings'!$B$3) | L38: =IF($H$38="","",ROUND(MIN($K$38,'Settings'!$B$5)*'Settings'!$B$2,2)) | M38: =IF($J$38="","",IF($J$38<0,"Pass",IF($J$38<'Settings'!$B$4,"Thin",IF($J$38<0.06,"✅ Sharp band",IF($J$38<0.08,"Strong","⚠ Verify (stale?)"))))) | N38: Model 52.0% (fair -108). Your call. | P38: =IF(OR($H$38="",$O$38=""),"",(1+IF($H$38<0,-100/$H$38,$H$38/100))/(1+IF($O$38<0,-100/$O$38,$O$38/100))-1)
A39: 2026-06-28 | B39: Arizona Diamondbacks @ Tampa Bay Rays | C39: 17:40 | D39: Spread | E39: Tampa Bay Rays -1.5 | F39: 0.45525346 | G39: 120 | H39: 117 | I39: =IF($H$39="","",IF($H$39<0,-$H$39/(-$H$39+100),100/($H$39+100))) | J39: =IF($H$39="","",$F$39*IF($H$39<0,-100/$H$39,$H$39/100)-(1-$F$39)) | K39: =IF($H$39="","",MAX(0,($F$39*IF($H$39<0,-100/$H$39,$H$39/100)-(1-$F$39))/IF($H$39<0,-100/$H$39,$H$39/100))*'Settings'!$B$3) | L39: =IF($H$39="","",ROUND(MIN($K$39,'Settings'!$B$5)*'Settings'!$B$2,2)) | M39: =IF($J$39="","",IF($J$39<0,"Pass",IF($J$39<'Settings'!$B$4,"Thin",IF($J$39<0.06,"✅ Sharp band",IF($J$39<0.08,"Strong","⚠ Verify (stale?)"))))) | N39: Model 45.5% (fair +120). Your call. | P39: =IF(OR($H$39="",$O$39=""),"",(1+IF($H$39<0,-100/$H$39,$H$39/100))/(1+IF($O$39<0,-100/$O$39,$O$39/100))-1)
A40: 2026-06-28 | B40: Arizona Diamondbacks @ Tampa Bay Rays | C40: 17:40 | D40: Spread | E40: Arizona Diamondbacks +1.5 | F40: 0.54474545 | G40: -120 | H40: -120 | I40: =IF($H$40="","",IF($H$40<0,-$H$40/(-$H$40+100),100/($H$40+100))) | J40: =IF($H$40="","",$F$40*IF($H$40<0,-100/$H$40,$H$40/100)-(1-$F$40)) | K40: =IF($H$40="","",MAX(0,($F$40*IF($H$40<0,-100/$H$40,$H$40/100)-(1-$F$40))/IF($H$40<0,-100/$H$40,$H$40/100))*'Settings'!$B$3) | L40: =IF($H$40="","",ROUND(MIN($K$40,'Settings'!$B$5)*'Settings'!$B$2,2)) | M40: =IF($J$40="","",IF($J$40<0,"Pass",IF($J$40<'Settings'!$B$4,"Thin",IF($J$40<0.06,"✅ Sharp band",IF($J$40<0.08,"Strong","⚠ Verify (stale?)"))))) | N40: Model 54.5% (fair -120). Your call. | P40: =IF(OR($H$40="",$O$40=""),"",(1+IF($H$40<0,-100/$H$40,$H$40/100))/(1+IF($O$40<0,-100/$O$40,$O$40/100))-1)
A41: 2026-06-28 | B41: Philadelphia Phillies @ New York Mets | C41: 17:40 | D41: Moneyline | E41: Philadelphia Phillies | F41: 0.591 | G41: -144 | H41: -150 | I41: =IF($H$41="","",IF($H$41<0,-$H$41/(-$H$41+100),100/($H$41+100))) | J41: =IF($H$41="","",$F$41*IF($H$41<0,-100/$H$41,$H$41/100)-(1-$F$41)) | K41: =IF($H$41="","",MAX(0,($F$41*IF($H$41<0,-100/$H$41,$H$41/100)-(1-$F$41))/IF($H$41<0,-100/$H$41,$H$41/100))*'Settings'!$B$3) | L41: =IF($H$41="","",ROUND(MIN($K$41,'Settings'!$B$5)*'Settings'!$B$2,2)) | M41: =IF($J$41="","",IF($J$41<0,"Pass",IF($J$41<'Settings'!$B$4,"Thin",IF($J$41<0.06,"✅ Sharp band",IF($J$41<0.08,"Strong","⚠ Verify (stale?)"))))) | N41: Model 59.1% (fair -144). Your call. | P41: =IF(OR($H$41="",$O$41=""),"",(1+IF($H$41<0,-100/$H$41,$H$41/100))/(1+IF($O$41<0,-100/$O$41,$O$41/100))-1)
...

Sheet WNBA Games
A1: WNBA — game markets
A2: Moneyline · Total · Spread. Yellow = your price.
A4: Date | B4: Matchup | C4: Start | D4: Market | E4: Selection | F4: Model Win% | G4: Model Fair | H4: ✏ Your Odds | I4: Implied% | J4: Your Edge (EV) | K4: ¼-Kelly % | L4: Stake $ | M4: Verdict | N4: Model read | O4: ✏ Closing | P4: CLV %
A5: 2026-06-28 | B5: Minnesota Lynx @ Dallas Wings | C5: 18:00 | D5: Moneyline | E5: Minnesota Lynx | F5: 0.61465574 | G5: -160 | H5: -144 | I5: =IF($H$5="","",IF($H$5<0,-$H$5/(-$H$5+100),100/($H$5+100))) | J5: =IF($H$5="","",$F$5*IF($H$5<0,-100/$H$5,$H$5/100)-(1-$F$5)) | K5: =IF($H$5="","",MAX(0,($F$5*IF($H$5<0,-100/$H$5,$H$5/100)-(1-$F$5))/IF($H$5<0,-100/$H$5,$H$5/100))*'Settings'!$B$3) | L5: =IF($H$5="","",ROUND(MIN($K$5,'Settings'!$B$5)*'Settings'!$B$2,2)) | M5: =IF($J$5="","",IF($J$5<0,"Pass",IF($J$5<'Settings'!$B$4,"Thin",IF($J$5<0.06,"✅ Sharp band",IF($J$5<0.08,"Strong","⚠ Verify (stale?)"))))) | N5: Model 61.5% (fair -160). Your call. | P5: =IF(OR($H$5="",$O$5=""),"",(1+IF($H$5<0,-100/$H$5,$H$5/100))/(1+IF($O$5<0,-100/$O$5,$O$5/100))-1)
A6: 2026-06-28 | B6: Minnesota Lynx @ Dallas Wings | C6: 18:00 | D6: Moneyline | E6: Dallas Wings | F6: 0.38532787 | G6: 160 | H6: 144 | I6: =IF($H$6="","",IF($H$6<0,-$H$6/(-$H$6+100),100/($H$6+100))) | J6: =IF($H$6="","",$F$6*IF($H$6<0,-100/$H$6,$H$6/100)-(1-$F$6)) | K6: =IF($H$6="","",MAX(0,($F$6*IF($H$6<0,-100/$H$6,$H$6/100)-(1-$F$6))/IF($H$6<0,-100/$H$6,$H$6/100))*'Settings'!$B$3) | L6: =IF($H$6="","",ROUND(MIN($K$6,'Settings'!$B$5)*'Settings'!$B$2,2)) | M6: =IF($J$6="","",IF($J$6<0,"Pass",IF($J$6<'Settings'!$B$4,"Thin",IF($J$6<0.06,"✅ Sharp band",IF($J$6<0.08,"Strong","⚠ Verify (stale?)"))))) | N6: Model 38.5% (fair +160). Your call. | P6: =IF(OR($H$6="",$O$6=""),"",(1+IF($H$6<0,-100/$H$6,$H$6/100))/(1+IF($O$6<0,-100/$O$6,$O$6/100))-1)
A7: 2026-06-28 | B7: Minnesota Lynx @ Dallas Wings | C7: 18:00 | D7: Total | E7: Over 178.5 | F7: 0.38439216 | G7: 160 | H7: -104 | I7: =IF($H$7="","",IF($H$7<0,-$H$7/(-$H$7+100),100/($H$7+100))) | J7: =IF($H$7="","",$F$7*IF($H$7<0,-100/$H$7,$H$7/100)-(1-$F$7)) | K7: =IF($H$7="","",MAX(0,($F$7*IF($H$7<0,-100/$H$7,$H$7/100)-(1-$F$7))/IF($H$7<0,-100/$H$7,$H$7/100))*'Settings'!$B$3) | L7: =IF($H$7="","",ROUND(MIN($K$7,'Settings'!$B$5)*'Settings'!$B$2,2)) | M7: =IF($J$7="","",IF($J$7<0,"Pass",IF($J$7<'Settings'!$B$4,"Thin",IF($J$7<0.06,"✅ Sharp band",IF($J$7<0.08,"Strong","⚠ Verify (stale?)"))))) | N7: Model 38.4% (fair +160). Your call. | P7: =IF(OR($H$7="",$O$7=""),"",(1+IF($H$7<0,-100/$H$7,$H$7/100))/(1+IF($O$7<0,-100/$O$7,$O$7/100))-1)
A8: 2026-06-28 | B8: Minnesota Lynx @ Dallas Wings | C8: 18:00 | D8: Total | E8: Under 178.5 | F8: 0.6156 | G8: -160 | H8: -104 | I8: =IF($H$8="","",IF($H$8<0,-$H$8/(-$H$8+100),100/($H$8+100))) | J8: =IF($H$8="","",$F$8*IF($H$8<0,-100/$H$8,$H$8/100)-(1-$F$8)) | K8: =IF($H$8="","",MAX(0,($F$8*IF($H$8<0,-100/$H$8,$H$8/100)-(1-$F$8))/IF($H$8<0,-100/$H$8,$H$8/100))*'Settings'!$B$3) | L8: =IF($H$8="","",ROUND(MIN($K$8,'Settings'!$B$5)*'Settings'!$B$2,2)) | M8: =IF($J$8="","",IF($J$8<0,"Pass",IF($J$8<'Settings'!$B$4,"Thin",IF($J$8<0.06,"✅ Sharp band",IF($J$8<0.08,"Strong","⚠ Verify (stale?)"))))) | N8: Model 61.6% (fair -160). Your call. | P8: =IF(OR($H$8="",$O$8=""),"",(1+IF($H$8<0,-100/$H$8,$H$8/100))/(1+IF($O$8<0,-100/$O$8,$O$8/100))-1)
A9: 2026-06-28 | B9: Minnesota Lynx @ Dallas Wings | C9: 18:00 | D9: Spread | E9: Dallas Wings +2.5 | F9: 0.4447 | G9: 125 | H9: 106 | I9: =IF($H$9="","",IF($H$9<0,-$H$9/(-$H$9+100),100/($H$9+100))) | J9: =IF($H$9="","",$F$9*IF($H$9<0,-100/$H$9,$H$9/100)-(1-$F$9)) | K9: =IF($H$9="","",MAX(0,($F$9*IF($H$9<0,-100/$H$9,$H$9/100)-(1-$F$9))/IF($H$9<0,-100/$H$9,$H$9/100))*'Settings'!$B$3) | L9: =IF($H$9="","",ROUND(MIN($K$9,'Settings'!$B$5)*'Settings'!$B$2,2)) | M9: =IF($J$9="","",IF($J$9<0,"Pass",IF($J$9<'Settings'!$B$4,"Thin",IF($J$9<0.06,"✅ Sharp band",IF($J$9<0.08,"Strong","⚠ Verify (stale?)"))))) | N9: Model 44.5% (fair +125). Your call. | P9: =IF(OR($H$9="",$O$9=""),"",(1+IF($H$9<0,-100/$H$9,$H$9/100))/(1+IF($O$9<0,-100/$O$9,$O$9/100))-1)
A10: 2026-06-28 | B10: Minnesota Lynx @ Dallas Wings | C10: 18:00 | D10: Spread | E10: Minnesota Lynx -2.5 | F10: 0.5553 | G10: -125 | H10: 122 | I10: =IF($H$10="","",IF($H$10<0,-$H$10/(-$H$10+100),100/($H$10+100))) | J10: =IF($H$10="","",$F$10*IF($H$10<0,-100/$H$10,$H$10/100)-(1-$F$10)) | K10: =IF($H$10="","",MAX(0,($F$10*IF($H$10<0,-100/$H$10,$H$10/100)-(1-$F$10))/IF($H$10<0,-100/$H$10,$H$10/100))*'Settings'!$B$3) | L10: =IF($H$10="","",ROUND(MIN($K$10,'Settings'!$B$5)*'Settings'!$B$2,2)) | M10: =IF($J$10="","",IF($J$10<0,"Pass",IF($J$10<'Settings'!$B$4,"Thin",IF($J$10<0.06,"✅ Sharp band",IF($J$10<0.08,"Strong","⚠ Verify (stale?)"))))) | N10: Model 55.5% (fair -125). Your call. | P10: =IF(OR($H$10="",$O$10=""),"",(1+IF($H$10<0,-100/$H$10,$H$10/100))/(1+IF($O$10<0,-100/$O$10,$O$10/100))-1)
A11: 2026-06-28 | B11: Portland Fire @ Washington Mystics | C11: 19:00 | D11: Moneyline | E11: Portland Fire | F11: 0.29921739 | G11: 234 | H11: 245 | I11: =IF($H$11="","",IF($H$11<0,-$H$11/(-$H$11+100),100/($H$11+100))) | J11: =IF($H$11="","",$F$11*IF($H$11<0,-100/$H$11,$H$11/100)-(1-$F$11)) | K11: =IF($H$11="","",MAX(0,($F$11*IF($H$11<0,-100/$H$11,$H$11/100)-(1-$F$11))/IF($H$11<0,-100/$H$11,$H$11/100))*'Settings'!$B$3) | L11: =IF($H$11="","",ROUND(MIN($K$11,'Settings'!$B$5)*'Settings'!$B$2,2)) | M11: =IF($J$11="","",IF($J$11<0,"Pass",IF($J$11<'Settings'!$B$4,"Thin",IF($J$11<0.06,"✅ Sharp band",IF($J$11<0.08,"Strong","⚠ Verify (stale?)"))))) | N11: Model 29.9% (fair +234). Your call. | P11: =IF(OR($H$11="",$O$11=""),"",(1+IF($H$11<0,-100/$H$11,$H$11/100))/(1+IF($O$11<0,-100/$O$11,$O$11/100))-1)
A12: 2026-06-28 | B12: Portland Fire @ Washington Mystics | C12: 19:00 | D12: Moneyline | E12: Washington Mystics | F12: 0.70077101 | G12: -234 | H12: -245 | I12: =IF($H$12="","",IF($H$12<0,-$H$12/(-$H$12+100),100/($H$12+100))) | J12: =IF($H$12="","",$F$12*IF($H$12<0,-100/$H$12,$H$12/100)-(1-$F$12)) | K12: =IF($H$12="","",MAX(0,($F$12*IF($H$12<0,-100/$H$12,$H$12/100)-(1-$F$12))/IF($H$12<0,-100/$H$12,$H$12/100))*'Settings'!$B$3) | L12: =IF($H$12="","",ROUND(MIN($K$12,'Settings'!$B$5)*'Settings'!$B$2,2)) | M12: =IF($J$12="","",IF($J$12<0,"Pass",IF($J$12<'Settings'!$B$4,"Thin",IF($J$12<0.06,"✅ Sharp band",IF($J$12<0.08,"Strong","⚠ Verify (stale?)"))))) | N12: Model 70.1% (fair -234). Your call. | P12: =IF(OR($H$12="",$O$12=""),"",(1+IF($H$12<0,-100/$H$12,$H$12/100))/(1+IF($O$12<0,-100/$O$12,$O$12/100))-1)
A13: 2026-06-28 | B13: Portland Fire @ Washington Mystics | C13: 19:00 | D13: Total | E13: Over 167.5 | F13: 0.5512 | G13: -123 | H13: -106 | I13: =IF($H$13="","",IF($H$13<0,-$H$13/(-$H$13+100),100/($H$13+100))) | J13: =IF($H$13="","",$F$13*IF($H$13<0,-100/$H$13,$H$13/100)-(1-$F$13)) | K13: =IF($H$13="","",MAX(0,($F$13*IF($H$13<0,-100/$H$13,$H$13/100)-(1-$F$13))/IF($H$13<0,-100/$H$13,$H$13/100))*'Settings'!$B$3) | L13: =IF($H$13="","",ROUND(MIN($K$13,'Settings'!$B$5)*'Settings'!$B$2,2)) | M13: =IF($J$13="","",IF($J$13<0,"Pass",IF($J$13<'Settings'!$B$4,"Thin",IF($J$13<0.06,"✅ Sharp band",IF($J$13<0.08,"Strong","⚠ Verify (stale?)"))))) | N13: Model 55.1% (fair -123). Your call. | P13: =IF(OR($H$13="",$O$13=""),"",(1+IF($H$13<0,-100/$H$13,$H$13/100))/(1+IF($O$13<0,-100/$O$13,$O$13/100))-1)
