Workbook

Sheet Read Me
A1: 🎯 Project 54.7 — Daily Wager Workbook
A2: 52.4% pays the house. 54.7% pays you.
A5: Built | B5: 2026-06-29 18:56
A7: HOW IT WORKS
A8: 1. | B8: The model's win probability for every market is locked. It does not change when odds move.
A9: 2. | B9: Type the price YOUR sportsbook is showing into the yellow “✏ Your Odds” cells (American odds, e.g. -110 or +135).
A10: 3. | B10: Implied %, Your Edge (EV), the ¼-Kelly stake and the Verdict recompute instantly — in Excel or Google Sheets, offline.
A11: 4. | B11: Set your Bankroll and Kelly fraction once on the Settings tab; every stake on every tab follows it.
A12: 5. | B12: After a game, type the closing line into the ✏ Closing column on the Games tab — CLV % shows whether you beat the close (the earliest honest sign an edge is real).
A14: READING THE VERDICT
A15: Pass | B15: Model says there's no edge at your price — skip it.
A16: Thin | B16: Positive but below your min-edge threshold.
A17: ✅ Sharp band | B17: 2–6% EV — where the model's edge has actually held up (good closing-line value). The sweet spot.
A18: Strong | B18: 6–8% EV — bigger, rarer.
A19: ⚠ Verify | B19: 8%+ EV usually means a stale or oddball price, not free money. Double-check the line before trusting it.
A21: WHY EDIT YOUR OWN ODDS?
B22: Every other tool de-vigs a sharp book for you and locks the math in an app whose lines go stale. Here the number is yours, so nothing can be out of date — and the math is in front of you.
A24: THE DEAL | B24: Personal research. Not financial advice. No bankroll promises. If gambling stops being fun, stop — call 1-800-GAMBLER.
B25: We publish our losses too — see the Track Record tab. We tell you when to pass. The trigger is always yours.

Sheet Settings
A1: ⚙ Settings
A2: Bankroll ($) | B2: 1000
A3: Kelly fraction | B3: 0.25
A4: Min edge to flag (EV) | B4: 0.02
A5: Max stake (% of bankroll) | B5: 0.05
A7: Default ¼-Kelly is deliberate: full Kelly is mathematically optimal but brutal on variance, and edges are always overestimated. Quarter-Kelly keeps ~most of the growth at a fraction of the risk.

Sheet Top Plays
A1: ⭐ Top Plays — biggest model edges today
A2: Ranked at the posted price. Swap in your book's number and watch the edge update. Nothing here is a lock.
A4: Date | B4: Matchup | C4: Start | D4: Market | E4: Selection | F4: Model Win% | G4: Model Fair | H4: ✏ Your Odds | I4: Implied% | J4: Your Edge (EV) | K4: ¼-Kelly % | L4: Stake $ | M4: Verdict | N4: Model read | O4: ✏ Closing | P4: CLV %
A5: 2026-06-30 | B5: San Diego Padres @ Chicago Cubs | C5: 00:05 | D5: Total | E5: Under 11.5 | F5: 0.68977746 | G5: -222 | H5: -113 | I5: =IF($H$5="","",IF($H$5<0,-$H$5/(-$H$5+100),100/($H$5+100))) | J5: =IF($H$5="","",$F$5*IF($H$5<0,-100/$H$5,$H$5/100)-(1-$F$5)) | K5: =IF($H$5="","",MAX(0,($F$5*IF($H$5<0,-100/$H$5,$H$5/100)-(1-$F$5))/IF($H$5<0,-100/$H$5,$H$5/100))*'Settings'!$B$3) | L5: =IF($H$5="","",ROUND(MIN($K$5,'Settings'!$B$5)*'Settings'!$B$2,2)) | M5: =IF($J$5="","",IF($J$5<0,"Pass",IF($J$5<'Settings'!$B$4,"Thin",IF($J$5<0.06,"✅ Sharp band",IF($J$5<0.08,"Strong","⚠ Verify (stale?)"))))) | N5: Model 69.0% (fair -222). Your call. | P5: =IF(OR($H$5="",$O$5=""),"",(1+IF($H$5<0,-100/$H$5,$H$5/100))/(1+IF($O$5<0,-100/$O$5,$O$5/100))-1)
A6: 2026-06-29 | B6: San Diego Padres @ Chicago Cubs | C6: 00:05 | D6: Total | E6: Under 11.5 | F6: 0.63455 | G6: -174 | H6: 100 | I6: =IF($H$6="","",IF($H$6<0,-$H$6/(-$H$6+100),100/($H$6+100))) | J6: =IF($H$6="","",$F$6*IF($H$6<0,-100/$H$6,$H$6/100)-(1-$F$6)) | K6: =IF($H$6="","",MAX(0,($F$6*IF($H$6<0,-100/$H$6,$H$6/100)-(1-$F$6))/IF($H$6<0,-100/$H$6,$H$6/100))*'Settings'!$B$3) | L6: =IF($H$6="","",ROUND(MIN($K$6,'Settings'!$B$5)*'Settings'!$B$2,2)) | M6: =IF($J$6="","",IF($J$6<0,"Pass",IF($J$6<'Settings'!$B$4,"Thin",IF($J$6<0.06,"✅ Sharp band",IF($J$6<0.08,"Strong","⚠ Verify (stale?)"))))) | N6: Model 63.5% (fair -174). Your call. | P6: =IF(OR($H$6="",$O$6=""),"",(1+IF($H$6<0,-100/$H$6,$H$6/100))/(1+IF($O$6<0,-100/$O$6,$O$6/100))-1)
A7: 2026-06-29 | B7: Miami Marlins @ Colorado Rockies | C7: 00:40 | D7: Total | E7: Under 12 | F7: 0.58322115 | G7: -140 | H7: 108 | I7: =IF($H$7="","",IF($H$7<0,-$H$7/(-$H$7+100),100/($H$7+100))) | J7: =IF($H$7="","",$F$7*IF($H$7<0,-100/$H$7,$H$7/100)-(1-$F$7)) | K7: =IF($H$7="","",MAX(0,($F$7*IF($H$7<0,-100/$H$7,$H$7/100)-(1-$F$7))/IF($H$7<0,-100/$H$7,$H$7/100))*'Settings'!$B$3) | L7: =IF($H$7="","",ROUND(MIN($K$7,'Settings'!$B$5)*'Settings'!$B$2,2)) | M7: =IF($J$7="","",IF($J$7<0,"Pass",IF($J$7<'Settings'!$B$4,"Thin",IF($J$7<0.06,"✅ Sharp band",IF($J$7<0.08,"Strong","⚠ Verify (stale?)"))))) | N7: Model 58.3% (fair -140). Your call. | P7: =IF(OR($H$7="",$O$7=""),"",(1+IF($H$7<0,-100/$H$7,$H$7/100))/(1+IF($O$7<0,-100/$O$7,$O$7/100))-1)
A8: 2026-06-30 | B8: Detroit Tigers @ New York Yankees | C8: 23:05 | D8: Spread | E8: New York Yankees -1.5 | F8: 0.40867857 | G8: 145 | H8: 180 | I8: =IF($H$8="","",IF($H$8<0,-$H$8/(-$H$8+100),100/($H$8+100))) | J8: =IF($H$8="","",$F$8*IF($H$8<0,-100/$H$8,$H$8/100)-(1-$F$8)) | K8: =IF($H$8="","",MAX(0,($F$8*IF($H$8<0,-100/$H$8,$H$8/100)-(1-$F$8))/IF($H$8<0,-100/$H$8,$H$8/100))*'Settings'!$B$3) | L8: =IF($H$8="","",ROUND(MIN($K$8,'Settings'!$B$5)*'Settings'!$B$2,2)) | M8: =IF($J$8="","",IF($J$8<0,"Pass",IF($J$8<'Settings'!$B$4,"Thin",IF($J$8<0.06,"✅ Sharp band",IF($J$8<0.08,"Strong","⚠ Verify (stale?)"))))) | N8: Model 40.9% (fair +145). Your call. | P8: =IF(OR($H$8="",$O$8=""),"",(1+IF($H$8<0,-100/$H$8,$H$8/100))/(1+IF($O$8<0,-100/$O$8,$O$8/100))-1)
A9: 2026-06-29 | B9: Pittsburgh Pirates @ Philadelphia Phillies | C9: 22:40 | D9: Moneyline | E9: Pittsburgh Pirates | F9: 0.54663462 | G9: -121 | H9: 108 | I9: =IF($H$9="","",IF($H$9<0,-$H$9/(-$H$9+100),100/($H$9+100))) | J9: =IF($H$9="","",$F$9*IF($H$9<0,-100/$H$9,$H$9/100)-(1-$F$9)) | K9: =IF($H$9="","",MAX(0,($F$9*IF($H$9<0,-100/$H$9,$H$9/100)-(1-$F$9))/IF($H$9<0,-100/$H$9,$H$9/100))*'Settings'!$B$3) | L9: =IF($H$9="","",ROUND(MIN($K$9,'Settings'!$B$5)*'Settings'!$B$2,2)) | M9: =IF($J$9="","",IF($J$9<0,"Pass",IF($J$9<'Settings'!$B$4,"Thin",IF($J$9<0.06,"✅ Sharp band",IF($J$9<0.08,"Strong","⚠ Verify (stale?)"))))) | N9: Model 54.7% (fair -121). Your call. | P9: =IF(OR($H$9="",$O$9=""),"",(1+IF($H$9<0,-100/$H$9,$H$9/100))/(1+IF($O$9<0,-100/$O$9,$O$9/100))-1)
A10: 2026-06-29 | B10: Cincinnati Reds @ Milwaukee Brewers | C10: 23:40 | D10: Moneyline | E10: Milwaukee Brewers | F10: 0.62844444 | G10: -169 | H10: -125 | I10: =IF($H$10="","",IF($H$10<0,-$H$10/(-$H$10+100),100/($H$10+100))) | J10: =IF($H$10="","",$F$10*IF($H$10<0,-100/$H$10,$H$10/100)-(1-$F$10)) | K10: =IF($H$10="","",MAX(0,($F$10*IF($H$10<0,-100/$H$10,$H$10/100)-(1-$F$10))/IF($H$10<0,-100/$H$10,$H$10/100))*'Settings'!$B$3) | L10: =IF($H$10="","",ROUND(MIN($K$10,'Settings'!$B$5)*'Settings'!$B$2,2)) | M10: =IF($J$10="","",IF($J$10<0,"Pass",IF($J$10<'Settings'!$B$4,"Thin",IF($J$10<0.06,"✅ Sharp band",IF($J$10<0.08,"Strong","⚠ Verify (stale?)"))))) | N10: Model 62.8% (fair -169). Your call. | P10: =IF(OR($H$10="",$O$10=""),"",(1+IF($H$10<0,-100/$H$10,$H$10/100))/(1+IF($O$10<0,-100/$O$10,$O$10/100))-1)
A11: 2026-06-30 | B11: Tampa Bay Rays @ Kansas City Royals | C11: 23:40 | D11: Total | E11: Under 10.5 | F11: 0.57189804 | G11: -134 | H11: -104 | I11: =IF($H$11="","",IF($H$11<0,-$H$11/(-$H$11+100),100/($H$11+100))) | J11: =IF($H$11="","",$F$11*IF($H$11<0,-100/$H$11,$H$11/100)-(1-$F$11)) | K11: =IF($H$11="","",MAX(0,($F$11*IF($H$11<0,-100/$H$11,$H$11/100)-(1-$F$11))/IF($H$11<0,-100/$H$11,$H$11/100))*'Settings'!$B$3) | L11: =IF($H$11="","",ROUND(MIN($K$11,'Settings'!$B$5)*'Settings'!$B$2,2)) | M11: =IF($J$11="","",IF($J$11<0,"Pass",IF($J$11<'Settings'!$B$4,"Thin",IF($J$11<0.06,"✅ Sharp band",IF($J$11<0.08,"Strong","⚠ Verify (stale?)"))))) | N11: Model 57.2% (fair -134). Your call. | P11: =IF(OR($H$11="",$O$11=""),"",(1+IF($H$11<0,-100/$H$11,$H$11/100))/(1+IF($O$11<0,-100/$O$11,$O$11/100))-1)
A12: 2026-06-30 | B12: Cincinnati Reds @ Milwaukee Brewers | C12: 23:40 | D12: Spread | E12: Milwaukee Brewers -1.5 | F12: 0.47029412 | G12: 113 | H12: 138 | I12: =IF($H$12="","",IF($H$12<0,-$H$12/(-$H$12+100),100/($H$12+100))) | J12: =IF($H$12="","",$F$12*IF($H$12<0,-100/$H$12,$H$12/100)-(1-$F$12)) | K12: =IF($H$12="","",MAX(0,($F$12*IF($H$12<0,-100/$H$12,$H$12/100)-(1-$F$12))/IF($H$12<0,-100/$H$12,$H$12/100))*'Settings'!$B$3) | L12: =IF($H$12="","",ROUND(MIN($K$12,'Settings'!$B$5)*'Settings'!$B$2,2)) | M12: =IF($J$12="","",IF($J$12<0,"Pass",IF($J$12<'Settings'!$B$4,"Thin",IF($J$12<0.06,"✅ Sharp band",IF($J$12<0.08,"Strong","⚠ Verify (stale?)"))))) | N12: Model 47.0% (fair +113). Your call. | P12: =IF(OR($H$12="",$O$12=""),"",(1+IF($H$12<0,-100/$H$12,$H$12/100))/(1+IF($O$12<0,-100/$O$12,$O$12/100))-1)
A13: 2026-06-30 | B13: Pittsburgh Pirates @ Philadelphia Phillies | C13: 22:40 | D13: Moneyline | E13: Pittsburgh Pirates | F13: 0.37157191 | G13: 169 | H13: 199 | I13: =IF($H$13="","",IF($H$13<0,-$H$13/(-$H$13+100),100/($H$13+100))) | J13: =IF($H$13="","",$F$13*IF($H$13<0,-100/$H$13,$H$13/100)-(1-$F$13)) | K13: =IF($H$13="","",MAX(0,($F$13*IF($H$13<0,-100/$H$13,$H$13/100)-(1-$F$13))/IF($H$13<0,-100/$H$13,$H$13/100))*'Settings'!$B$3) | L13: =IF($H$13="","",ROUND(MIN($K$13,'Settings'!$B$5)*'Settings'!$B$2,2)) | M13: =IF($J$13="","",IF($J$13<0,"Pass",IF($J$13<'Settings'!$B$4,"Thin",IF($J$13<0.06,"✅ Sharp band",IF($J$13<0.08,"Strong","⚠ Verify (stale?)"))))) | N13: Model 37.2% (fair +169). Your call. | P13: =IF(OR($H$13="",$O$13=""),"",(1+IF($H$13<0,-100/$H$13,$H$13/100))/(1+IF($O$13<0,-100/$O$13,$O$13/100))-1)
A14: 2026-06-30 | B14: St. Louis Cardinals @ Atlanta Braves | C14: 23:15 | D14: Total | E14: Under 9.5 | F14: 0.56440392 | G14: -130 | H14: -104 | I14: =IF($H$14="","",IF($H$14<0,-$H$14/(-$H$14+100),100/($H$14+100))) | J14: =IF($H$14="","",$F$14*IF($H$14<0,-100/$H$14,$H$14/100)-(1-$F$14)) | K14: =IF($H$14="","",MAX(0,($F$14*IF($H$14<0,-100/$H$14,$H$14/100)-(1-$F$14))/IF($H$14<0,-100/$H$14,$H$14/100))*'Settings'!$B$3) | L14: =IF($H$14="","",ROUND(MIN($K$14,'Settings'!$B$5)*'Settings'!$B$2,2)) | M14: =IF($J$14="","",IF($J$14<0,"Pass",IF($J$14<'Settings'!$B$4,"Thin",IF($J$14<0.06,"✅ Sharp band",IF($J$14<0.08,"Strong","⚠ Verify (stale?)"))))) | N14: Model 56.4% (fair -130). Your call. | P14: =IF(OR($H$14="",$O$14=""),"",(1+IF($H$14<0,-100/$H$14,$H$14/100))/(1+IF($O$14<0,-100/$O$14,$O$14/100))-1)
A15: 2026-06-29 | B15: Texas Rangers @ Cleveland Guardians | C15: 23:10 | D15: Moneyline | E15: Texas Rangers | F15: 0.45213115 | G15: 121 | H15: 144 | I15: =IF($H$15="","",IF($H$15<0,-$H$15/(-$H$15+100),100/($H$15+100))) | J15: =IF($H$15="","",$F$15*IF($H$15<0,-100/$H$15,$H$15/100)-(1-$F$15)) | K15: =IF($H$15="","",MAX(0,($F$15*IF($H$15<0,-100/$H$15,$H$15/100)-(1-$F$15))/IF($H$15<0,-100/$H$15,$H$15/100))*'Settings'!$B$3) | L15: =IF($H$15="","",ROUND(MIN($K$15,'Settings'!$B$5)*'Settings'!$B$2,2)) | M15: =IF($J$15="","",IF($J$15<0,"Pass",IF($J$15<'Settings'!$B$4,"Thin",IF($J$15<0.06,"✅ Sharp band",IF($J$15<0.08,"Strong","⚠ Verify (stale?)"))))) | N15: Model 45.2% (fair +121). Your call. | P15: =IF(OR($H$15="",$O$15=""),"",(1+IF($H$15<0,-100/$H$15,$H$15/100))/(1+IF($O$15<0,-100/$O$15,$O$15/100))-1)
A16: 2026-06-30 | B16: Washington Nationals @ Boston Red Sox | C16: 23:10 | D16: Total | E16: Under 10.5 | F16: 0.57120577 | G16: -133 | H16: -108 | I16: =IF($H$16="","",IF($H$16<0,-$H$16/(-$H$16+100),100/($H$16+100))) | J16: =IF($H$16="","",$F$16*IF($H$16<0,-100/$H$16,$H$16/100)-(1-$F$16)) | K16: =IF($H$16="","",MAX(0,($F$16*IF($H$16<0,-100/$H$16,$H$16/100)-(1-$F$16))/IF($H$16<0,-100/$H$16,$H$16/100))*'Settings'!$B$3) | L16: =IF($H$16="","",ROUND(MIN($K$16,'Settings'!$B$5)*'Settings'!$B$2,2)) | M16: =IF($J$16="","",IF($J$16<0,"Pass",IF($J$16<'Settings'!$B$4,"Thin",IF($J$16<0.06,"✅ Sharp band",IF($J$16<0.08,"Strong","⚠ Verify (stale?)"))))) | N16: Model 57.1% (fair -133). Your call. | P16: =IF(OR($H$16="",$O$16=""),"",(1+IF($H$16<0,-100/$H$16,$H$16/100))/(1+IF($O$16<0,-100/$O$16,$O$16/100))-1)
A17: 2026-06-29 | B17: Miami Marlins @ Colorado Rockies | C17: 00:40 | D17: Moneyline | E17: Colorado Rockies | F17: 0.45995798 | G17: 117 | H17: 138 | I17: =IF($H$17="","",IF($H$17<0,-$H$17/(-$H$17+100),100/($H$17+100))) | J17: =IF($H$17="","",$F$17*IF($H$17<0,-100/$H$17,$H$17/100)-(1-$F$17)) | K17: =IF($H$17="","",MAX(0,($F$17*IF($H$17<0,-100/$H$17,$H$17/100)-(1-$F$17))/IF($H$17<0,-100/$H$17,$H$17/100))*'Settings'!$B$3) | L17: =IF($H$17="","",ROUND(MIN($K$17,'Settings'!$B$5)*'Settings'!$B$2,2)) | M17: =IF($J$17="","",IF($J$17<0,"Pass",IF($J$17<'Settings'!$B$4,"Thin",IF($J$17<0.06,"✅ Sharp band",IF($J$17<0.08,"Strong","⚠ Verify (stale?)"))))) | N17: Model 46.0% (fair +117). Your call. | P17: =IF(OR($H$17="",$O$17=""),"",(1+IF($H$17<0,-100/$H$17,$H$17/100))/(1+IF($O$17<0,-100/$O$17,$O$17/100))-1)
A18: 2026-06-30 | B18: Texas Rangers @ Cleveland Guardians | C18: 22:40 | D18: Moneyline | E18: Texas Rangers | F18: 0.53553922 | G18: -115 | H18: 104 | I18: =IF($H$18="","",IF($H$18<0,-$H$18/(-$H$18+100),100/($H$18+100))) | J18: =IF($H$18="","",$F$18*IF($H$18<0,-100/$H$18,$H$18/100)-(1-$F$18)) | K18: =IF($H$18="","",MAX(0,($F$18*IF($H$18<0,-100/$H$18,$H$18/100)-(1-$F$18))/IF($H$18<0,-100/$H$18,$H$18/100))*'Settings'!$B$3) | L18: =IF($H$18="","",ROUND(MIN($K$18,'Settings'!$B$5)*'Settings'!$B$2,2)) | M18: =IF($J$18="","",IF($J$18<0,"Pass",IF($J$18<'Settings'!$B$4,"Thin",IF($J$18<0.06,"✅ Sharp band",IF($J$18<0.08,"Strong","⚠ Verify (stale?)"))))) | N18: Model 53.6% (fair -115). Your call. | P18: =IF(OR($H$18="",$O$18=""),"",(1+IF($H$18<0,-100/$H$18,$H$18/100))/(1+IF($O$18<0,-100/$O$18,$O$18/100))-1)
A19: 2026-06-29 | B19: Minnesota Twins @ Houston Astros | C19: 00:10 | D19: Moneyline | E19: Minnesota Twins | F19: 0.48039648 | G19: 108 | H19: 127 | I19: =IF($H$19="","",IF($H$19<0,-$H$19/(-$H$19+100),100/($H$19+100))) | J19: =IF($H$19="","",$F$19*IF($H$19<0,-100/$H$19,$H$19/100)-(1-$F$19)) | K19: =IF($H$19="","",MAX(0,($F$19*IF($H$19<0,-100/$H$19,$H$19/100)-(1-$F$19))/IF($H$19<0,-100/$H$19,$H$19/100))*'Settings'!$B$3) | L19: =IF($H$19="","",ROUND(MIN($K$19,'Settings'!$B$5)*'Settings'!$B$2,2)) | M19: =IF($J$19="","",IF($J$19<0,"Pass",IF($J$19<'Settings'!$B$4,"Thin",IF($J$19<0.06,"✅ Sharp band",IF($J$19<0.08,"Strong","⚠ Verify (stale?)"))))) | N19: Model 48.0% (fair +108). Your call. | P19: =IF(OR($H$19="",$O$19=""),"",(1+IF($H$19<0,-100/$H$19,$H$19/100))/(1+IF($O$19<0,-100/$O$19,$O$19/100))-1)
A20: 2026-06-30 | B20: Pittsburgh Pirates @ Philadelphia Phillies | C20: 22:40 | D20: Total | E20: Over 8.5 | F20: 0.52384615 | G20: -110 | H20: 108 | I20: =IF($H$20="","",IF($H$20<0,-$H$20/(-$H$20+100),100/($H$20+100))) | J20: =IF($H$20="","",$F$20*IF($H$20<0,-100/$H$20,$H$20/100)-(1-$F$20)) | K20: =IF($H$20="","",MAX(0,($F$20*IF($H$20<0,-100/$H$20,$H$20/100)-(1-$F$20))/IF($H$20<0,-100/$H$20,$H$20/100))*'Settings'!$B$3) | L20: =IF($H$20="","",ROUND(MIN($K$20,'Settings'!$B$5)*'Settings'!$B$2,2)) | M20: =IF($J$20="","",IF($J$20<0,"Pass",IF($J$20<'Settings'!$B$4,"Thin",IF($J$20<0.06,"✅ Sharp band",IF($J$20<0.08,"Strong","⚠ Verify (stale?)"))))) | N20: Model 52.4% (fair -110). Your call. | P20: =IF(OR($H$20="",$O$20=""),"",(1+IF($H$20<0,-100/$H$20,$H$20/100))/(1+IF($O$20<0,-100/$O$20,$O$20/100))-1)
A21: 2026-06-30 | B21: St. Louis Cardinals @ Atlanta Braves | C21: 23:15 | D21: Moneyline | E21: St. Louis Cardinals | F21: 0.43954918 | G21: 128 | H21: 144 | I21: =IF($H$21="","",IF($H$21<0,-$H$21/(-$H$21+100),100/($H$21+100))) | J21: =IF($H$21="","",$F$21*IF($H$21<0,-100/$H$21,$H$21/100)-(1-$F$21)) | K21: =IF($H$21="","",MAX(0,($F$21*IF($H$21<0,-100/$H$21,$H$21/100)-(1-$F$21))/IF($H$21<0,-100/$H$21,$H$21/100))*'Settings'!$B$3) | L21: =IF($H$21="","",ROUND(MIN($K$21,'Settings'!$B$5)*'Settings'!$B$2,2)) | M21: =IF($J$21="","",IF($J$21<0,"Pass",IF($J$21<'Settings'!$B$4,"Thin",IF($J$21<0.06,"✅ Sharp band",IF($J$21<0.08,"Strong","⚠ Verify (stale?)"))))) | N21: Model 44.0% (fair +128). Your call. | P21: =IF(OR($H$21="",$O$21=""),"",(1+IF($H$21<0,-100/$H$21,$H$21/100))/(1+IF($O$21<0,-100/$O$21,$O$21/100))-1)
A22: 2026-06-29 | B22: New York Mets @ Toronto Blue Jays | C22: 23:07 | D22: Total | E22: Under 8.5 | F22: 0.53515 | G22: -115 | H22: 100 | I22: =IF($H$22="","",IF($H$22<0,-$H$22/(-$H$22+100),100/($H$22+100))) | J22: =IF($H$22="","",$F$22*IF($H$22<0,-100/$H$22,$H$22/100)-(1-$F$22)) | K22: =IF($H$22="","",MAX(0,($F$22*IF($H$22<0,-100/$H$22,$H$22/100)-(1-$F$22))/IF($H$22<0,-100/$H$22,$H$22/100))*'Settings'!$B$3) | L22: =IF($H$22="","",ROUND(MIN($K$22,'Settings'!$B$5)*'Settings'!$B$2,2)) | M22: =IF($J$22="","",IF($J$22<0,"Pass",IF($J$22<'Settings'!$B$4,"Thin",IF($J$22<0.06,"✅ Sharp band",IF($J$22<0.08,"Strong","⚠ Verify (stale?)"))))) | N22: Model 53.5% (fair -115). Your call. | P22: =IF(OR($H$22="",$O$22=""),"",(1+IF($H$22<0,-100/$H$22,$H$22/100))/(1+IF($O$22<0,-100/$O$22,$O$22/100))-1)
A23: 2026-06-30 | B23: Tampa Bay Rays @ Kansas City Royals | C23: 23:40 | D23: Moneyline | E23: Kansas City Royals | F23: 0.51293269 | G23: -105 | H23: 108 | I23: =IF($H$23="","",IF($H$23<0,-$H$23/(-$H$23+100),100/($H$23+100))) | J23: =IF($H$23="","",$F$23*IF($H$23<0,-100/$H$23,$H$23/100)-(1-$F$23)) | K23: =IF($H$23="","",MAX(0,($F$23*IF($H$23<0,-100/$H$23,$H$23/100)-(1-$F$23))/IF($H$23<0,-100/$H$23,$H$23/100))*'Settings'!$B$3) | L23: =IF($H$23="","",ROUND(MIN($K$23,'Settings'!$B$5)*'Settings'!$B$2,2)) | M23: =IF($J$23="","",IF($J$23<0,"Pass",IF($J$23<'Settings'!$B$4,"Thin",IF($J$23<0.06,"✅ Sharp band",IF($J$23<0.08,"Strong","⚠ Verify (stale?)"))))) | N23: Model 51.3% (fair -105). Your call. | P23: =IF(OR($H$23="",$O$23=""),"",(1+IF($H$23<0,-100/$H$23,$H$23/100))/(1+IF($O$23<0,-100/$O$23,$O$23/100))-1)
A24: 2026-06-30 | B24: Chicago White Sox @ Baltimore Orioles | C24: 22:35 | D24: Total | E24: Over 10.5 | F24: 0.51206731 | G24: -105 | H24: 108 | I24: =IF($H$24="","",IF($H$24<0,-$H$24/(-$H$24+100),100/($H$24+100))) | J24: =IF($H$24="","",$F$24*IF($H$24<0,-100/$H$24,$H$24/100)-(1-$F$24)) | K24: =IF($H$24="","",MAX(0,($F$24*IF($H$24<0,-100/$H$24,$H$24/100)-(1-$F$24))/IF($H$24<0,-100/$H$24,$H$24/100))*'Settings'!$B$3) | L24: =IF($H$24="","",ROUND(MIN($K$24,'Settings'!$B$5)*'Settings'!$B$2,2)) | M24: =IF($J$24="","",IF($J$24<0,"Pass",IF($J$24<'Settings'!$B$4,"Thin",IF($J$24<0.06,"✅ Sharp band",IF($J$24<0.08,"Strong","⚠ Verify (stale?)"))))) | N24: Model 51.2% (fair -105). Your call. | P24: =IF(OR($H$24="",$O$24=""),"",(1+IF($H$24<0,-100/$H$24,$H$24/100))/(1+IF($O$24<0,-100/$O$24,$O$24/100))-1)
A25: 2026-06-30 | B25: Chicago White Sox @ Baltimore Orioles | C25: 22:35 | D25: Moneyline | E25: Chicago White Sox | F25: 0.44613445 | G25: 124 | H25: 138 | I25: =IF($H$25="","",IF($H$25<0,-$H$25/(-$H$25+100),100/($H$25+100))) | J25: =IF($H$25="","",$F$25*IF($H$25<0,-100/$H$25,$H$25/100)-(1-$F$25)) | K25: =IF($H$25="","",MAX(0,($F$25*IF($H$25<0,-100/$H$25,$H$25/100)-(1-$F$25))/IF($H$25<0,-100/$H$25,$H$25/100))*'Settings'!$B$3) | L25: =IF($H$25="","",ROUND(MIN($K$25,'Settings'!$B$5)*'Settings'!$B$2,2)) | M25: =IF($J$25="","",IF($J$25<0,"Pass",IF($J$25<'Settings'!$B$4,"Thin",IF($J$25<0.06,"✅ Sharp band",IF($J$25<0.08,"Strong","⚠ Verify (stale?)"))))) | N25: Model 44.6% (fair +124). Your call. | P25: =IF(OR($H$25="",$O$25=""),"",(1+IF($H$25<0,-100/$H$25,$H$25/100))/(1+IF($O$25<0,-100/$O$25,$O$25/100))-1)
A26: 2026-06-30 | B26: Tampa Bay Rays @ Kansas City Royals | C26: 23:40 | D26: Spread | E26: Kansas City Royals +1.5 | F26: 0.62693265 | G26: -168 | H26: -145 | I26: =IF($H$26="","",IF($H$26<0,-$H$26/(-$H$26+100),100/($H$26+100))) | J26: =IF($H$26="","",$F$26*IF($H$26<0,-100/$H$26,$H$26/100)-(1-$F$26)) | K26: =IF($H$26="","",MAX(0,($F$26*IF($H$26<0,-100/$H$26,$H$26/100)-(1-$F$26))/IF($H$26<0,-100/$H$26,$H$26/100))*'Settings'!$B$3) | L26: =IF($H$26="","",ROUND(MIN($K$26,'Settings'!$B$5)*'Settings'!$B$2,2)) | M26: =IF($J$26="","",IF($J$26<0,"Pass",IF($J$26<'Settings'!$B$4,"Thin",IF($J$26<0.06,"✅ Sharp band",IF($J$26<0.08,"Strong","⚠ Verify (stale?)"))))) | N26: Model 62.7% (fair -168). Your call. | P26: =IF(OR($H$26="",$O$26=""),"",(1+IF($H$26<0,-100/$H$26,$H$26/100))/(1+IF($O$26<0,-100/$O$26,$O$26/100))-1)
A27: 2026-06-29 | B27: New York Mets @ Toronto Blue Jays | C27: 23:07 | D27: Moneyline | E27: New York Mets | F27: 0.48640553 | G27: 106 | H27: 117 | I27: =IF($H$27="","",IF($H$27<0,-$H$27/(-$H$27+100),100/($H$27+100))) | J27: =IF($H$27="","",$F$27*IF($H$27<0,-100/$H$27,$H$27/100)-(1-$F$27)) | K27: =IF($H$27="","",MAX(0,($F$27*IF($H$27<0,-100/$H$27,$H$27/100)-(1-$F$27))/IF($H$27<0,-100/$H$27,$H$27/100))*'Settings'!$B$3) | L27: =IF($H$27="","",ROUND(MIN($K$27,'Settings'!$B$5)*'Settings'!$B$2,2)) | M27: =IF($J$27="","",IF($J$27<0,"Pass",IF($J$27<'Settings'!$B$4,"Thin",IF($J$27<0.06,"✅ Sharp band",IF($J$27<0.08,"Strong","⚠ Verify (stale?)"))))) | N27: Model 48.6% (fair +106). Your call. | P27: =IF(OR($H$27="",$O$27=""),"",(1+IF($H$27<0,-100/$H$27,$H$27/100))/(1+IF($O$27<0,-100/$O$27,$O$27/100))-1)
A28: 2026-06-30 | B28: Detroit Tigers @ New York Yankees | C28: 23:05 | D28: Moneyline | E28: New York Yankees | F28: 0.58744493 | G28: -142 | H28: -127 | I28: =IF($H$28="","",IF($H$28<0,-$H$28/(-$H$28+100),100/($H$28+100))) | J28: =IF($H$28="","",$F$28*IF($H$28<0,-100/$H$28,$H$28/100)-(1-$F$28)) | K28: =IF($H$28="","",MAX(0,($F$28*IF($H$28<0,-100/$H$28,$H$28/100)-(1-$F$28))/IF($H$28<0,-100/$H$28,$H$28/100))*'Settings'!$B$3) | L28: =IF($H$28="","",ROUND(MIN($K$28,'Settings'!$B$5)*'Settings'!$B$2,2)) | M28: =IF($J$28="","",IF($J$28<0,"Pass",IF($J$28<'Settings'!$B$4,"Thin",IF($J$28<0.06,"✅ Sharp band",IF($J$28<0.08,"Strong","⚠ Verify (stale?)"))))) | N28: Model 58.7% (fair -142). Your call. | P28: =IF(OR($H$28="",$O$28=""),"",(1+IF($H$28<0,-100/$H$28,$H$28/100))/(1+IF($O$28<0,-100/$O$28,$O$28/100))-1)
A29: 2026-06-30 | B29: Cincinnati Reds @ Milwaukee Brewers | C29: 23:40 | D29: Total | E29: Over 8.5 | F29: 0.55232066 | G29: -123 | H29: -113 | I29: =IF($H$29="","",IF($H$29<0,-$H$29/(-$H$29+100),100/($H$29+100))) | J29: =IF($H$29="","",$F$29*IF($H$29<0,-100/$H$29,$H$29/100)-(1-$F$29)) | K29: =IF($H$29="","",MAX(0,($F$29*IF($H$29<0,-100/$H$29,$H$29/100)-(1-$F$29))/IF($H$29<0,-100/$H$29,$H$29/100))*'Settings'!$B$3) | L29: =IF($H$29="","",ROUND(MIN($K$29,'Settings'!$B$5)*'Settings'!$B$2,2)) | M29: =IF($J$29="","",IF($J$29<0,"Pass",IF($J$29<'Settings'!$B$4,"Thin",IF($J$29<0.06,"✅ Sharp band",IF($J$29<0.08,"Strong","⚠ Verify (stale?)"))))) | N29: Model 55.2% (fair -123). Your call. | P29: =IF(OR($H$29="",$O$29=""),"",(1+IF($H$29<0,-100/$H$29,$H$29/100))/(1+IF($O$29<0,-100/$O$29,$O$29/100))-1)

Sheet MLB Games
A1: MLB — game markets
A2: Moneyline · Total · Spread. Yellow = your price.
A4: Date | B4: Matchup | C4: Start | D4: Market | E4: Selection | F4: Model Win% | G4: Model Fair | H4: ✏ Your Odds | I4: Implied% | J4: Your Edge (EV) | K4: ¼-Kelly % | L4: Stake $ | M4: Verdict | N4: Model read | O4: ✏ Closing | P4: CLV %
A5: 2026-06-29 | B5: Chicago White Sox @ Baltimore Orioles | C5: 22:35 | D5: Moneyline | E5: Chicago White Sox | F5: 0.46509009 | G5: 115 | H5: 122 | I5: =IF($H$5="","",IF($H$5<0,-$H$5/(-$H$5+100),100/($H$5+100))) | J5: =IF($H$5="","",$F$5*IF($H$5<0,-100/$H$5,$H$5/100)-(1-$F$5)) | K5: =IF($H$5="","",MAX(0,($F$5*IF($H$5<0,-100/$H$5,$H$5/100)-(1-$F$5))/IF($H$5<0,-100/$H$5,$H$5/100))*'Settings'!$B$3) | L5: =IF($H$5="","",ROUND(MIN($K$5,'Settings'!$B$5)*'Settings'!$B$2,2)) | M5: =IF($J$5="","",IF($J$5<0,"Pass",IF($J$5<'Settings'!$B$4,"Thin",IF($J$5<0.06,"✅ Sharp band",IF($J$5<0.08,"Strong","⚠ Verify (stale?)"))))) | N5: Model 46.5% (fair +115). Your call. | P5: =IF(OR($H$5="",$O$5=""),"",(1+IF($H$5<0,-100/$H$5,$H$5/100))/(1+IF($O$5<0,-100/$O$5,$O$5/100))-1)
A6: 2026-06-29 | B6: Chicago White Sox @ Baltimore Orioles | C6: 22:35 | D6: Moneyline | E6: Baltimore Orioles | F6: 0.53487273 | G6: -115 | H6: -120 | I6: =IF($H$6="","",IF($H$6<0,-$H$6/(-$H$6+100),100/($H$6+100))) | J6: =IF($H$6="","",$F$6*IF($H$6<0,-100/$H$6,$H$6/100)-(1-$F$6)) | K6: =IF($H$6="","",MAX(0,($F$6*IF($H$6<0,-100/$H$6,$H$6/100)-(1-$F$6))/IF($H$6<0,-100/$H$6,$H$6/100))*'Settings'!$B$3) | L6: =IF($H$6="","",ROUND(MIN($K$6,'Settings'!$B$5)*'Settings'!$B$2,2)) | M6: =IF($J$6="","",IF($J$6<0,"Pass",IF($J$6<'Settings'!$B$4,"Thin",IF($J$6<0.06,"✅ Sharp band",IF($J$6<0.08,"Strong","⚠ Verify (stale?)"))))) | N6: Model 53.5% (fair -115). Your call. | P6: =IF(OR($H$6="",$O$6=""),"",(1+IF($H$6<0,-100/$H$6,$H$6/100))/(1+IF($O$6<0,-100/$O$6,$O$6/100))-1)
A7: 2026-06-29 | B7: Chicago White Sox @ Baltimore Orioles | C7: 22:35 | D7: Total | E7: Over 9.5 | F7: 0.4763 | G7: 110 | H7: 113 | I7: =IF($H$7="","",IF($H$7<0,-$H$7/(-$H$7+100),100/($H$7+100))) | J7: =IF($H$7="","",$F$7*IF($H$7<0,-100/$H$7,$H$7/100)-(1-$F$7)) | K7: =IF($H$7="","",MAX(0,($F$7*IF($H$7<0,-100/$H$7,$H$7/100)-(1-$F$7))/IF($H$7<0,-100/$H$7,$H$7/100))*'Settings'!$B$3) | L7: =IF($H$7="","",ROUND(MIN($K$7,'Settings'!$B$5)*'Settings'!$B$2,2)) | M7: =IF($J$7="","",IF($J$7<0,"Pass",IF($J$7<'Settings'!$B$4,"Thin",IF($J$7<0.06,"✅ Sharp band",IF($J$7<0.08,"Strong","⚠ Verify (stale?)"))))) | N7: Model 47.6% (fair +110). Your call. | P7: =IF(OR($H$7="",$O$7=""),"",(1+IF($H$7<0,-100/$H$7,$H$7/100))/(1+IF($O$7<0,-100/$O$7,$O$7/100))-1)
A8: 2026-06-29 | B8: Chicago White Sox @ Baltimore Orioles | C8: 22:35 | D8: Total | E8: Under 9.5 | F8: 0.5237 | G8: -110 | H8: 128 | I8: =IF($H$8="","",IF($H$8<0,-$H$8/(-$H$8+100),100/($H$8+100))) | J8: =IF($H$8="","",$F$8*IF($H$8<0,-100/$H$8,$H$8/100)-(1-$F$8)) | K8: =IF($H$8="","",MAX(0,($F$8*IF($H$8<0,-100/$H$8,$H$8/100)-(1-$F$8))/IF($H$8<0,-100/$H$8,$H$8/100))*'Settings'!$B$3) | L8: =IF($H$8="","",ROUND(MIN($K$8,'Settings'!$B$5)*'Settings'!$B$2,2)) | M8: =IF($J$8="","",IF($J$8<0,"Pass",IF($J$8<'Settings'!$B$4,"Thin",IF($J$8<0.06,"✅ Sharp band",IF($J$8<0.08,"Strong","⚠ Verify (stale?)"))))) | N8: Model 52.4% (fair -110). Your call. | P8: =IF(OR($H$8="",$O$8=""),"",(1+IF($H$8<0,-100/$H$8,$H$8/100))/(1+IF($O$8<0,-100/$O$8,$O$8/100))-1)
A9: 2026-06-29 | B9: Chicago White Sox @ Baltimore Orioles | C9: 22:35 | D9: Spread | E9: Baltimore Orioles -1.5 | F9: 0.3914 | G9: 155 | H9: 163 | I9: =IF($H$9="","",IF($H$9<0,-$H$9/(-$H$9+100),100/($H$9+100))) | J9: =IF($H$9="","",$F$9*IF($H$9<0,-100/$H$9,$H$9/100)-(1-$F$9)) | K9: =IF($H$9="","",MAX(0,($F$9*IF($H$9<0,-100/$H$9,$H$9/100)-(1-$F$9))/IF($H$9<0,-100/$H$9,$H$9/100))*'Settings'!$B$3) | L9: =IF($H$9="","",ROUND(MIN($K$9,'Settings'!$B$5)*'Settings'!$B$2,2)) | M9: =IF($J$9="","",IF($J$9<0,"Pass",IF($J$9<'Settings'!$B$4,"Thin",IF($J$9<0.06,"✅ Sharp band",IF($J$9<0.08,"Strong","⚠ Verify (stale?)"))))) | N9: Model 39.1% (fair +155). Your call. | P9: =IF(OR($H$9="",$O$9=""),"",(1+IF($H$9<0,-100/$H$9,$H$9/100))/(1+IF($O$9<0,-100/$O$9,$O$9/100))-1)
A10: 2026-06-29 | B10: Chicago White Sox @ Baltimore Orioles | C10: 22:35 | D10: Spread | E10: Chicago White Sox +1.5 | F10: 0.6086 | G10: -155 | H10: 163 | I10: =IF($H$10="","",IF($H$10<0,-$H$10/(-$H$10+100),100/($H$10+100))) | J10: =IF($H$10="","",$F$10*IF($H$10<0,-100/$H$10,$H$10/100)-(1-$F$10)) | K10: =IF($H$10="","",MAX(0,($F$10*IF($H$10<0,-100/$H$10,$H$10/100)-(1-$F$10))/IF($H$10<0,-100/$H$10,$H$10/100))*'Settings'!$B$3) | L10: =IF($H$10="","",ROUND(MIN($K$10,'Settings'!$B$5)*'Settings'!$B$2,2)) | M10: =IF($J$10="","",IF($J$10<0,"Pass",IF($J$10<'Settings'!$B$4,"Thin",IF($J$10<0.06,"✅ Sharp band",IF($J$10<0.08,"Strong","⚠ Verify (stale?)"))))) | N10: Model 60.9% (fair -155). Your call. | P10: =IF(OR($H$10="",$O$10=""),"",(1+IF($H$10<0,-100/$H$10,$H$10/100))/(1+IF($O$10<0,-100/$O$10,$O$10/100))-1)
A11: 2026-06-29 | B11: Pittsburgh Pirates @ Philadelphia Phillies | C11: 22:40 | D11: Moneyline | E11: Pittsburgh Pirates | F11: 0.54663462 | G11: -121 | H11: 108 | I11: =IF($H$11="","",IF($H$11<0,-$H$11/(-$H$11+100),100/($H$11+100))) | J11: =IF($H$11="","",$F$11*IF($H$11<0,-100/$H$11,$H$11/100)-(1-$F$11)) | K11: =IF($H$11="","",MAX(0,($F$11*IF($H$11<0,-100/$H$11,$H$11/100)-(1-$F$11))/IF($H$11<0,-100/$H$11,$H$11/100))*'Settings'!$B$3) | L11: =IF($H$11="","",ROUND(MIN($K$11,'Settings'!$B$5)*'Settings'!$B$2,2)) | M11: =IF($J$11="","",IF($J$11<0,"Pass",IF($J$11<'Settings'!$B$4,"Thin",IF($J$11<0.06,"✅ Sharp band",IF($J$11<0.08,"Strong","⚠ Verify (stale?)"))))) | N11: Model 54.7% (fair -121). Your call. | P11: =IF(OR($H$11="",$O$11=""),"",(1+IF($H$11<0,-100/$H$11,$H$11/100))/(1+IF($O$11<0,-100/$O$11,$O$11/100))-1)
A12: 2026-06-29 | B12: Pittsburgh Pirates @ Philadelphia Phillies | C12: 22:40 | D12: Moneyline | E12: Philadelphia Phillies | F12: 0.45339505 | G12: 121 | H12: -102 | I12: =IF($H$12="","",IF($H$12<0,-$H$12/(-$H$12+100),100/($H$12+100))) | J12: =IF($H$12="","",$F$12*IF($H$12<0,-100/$H$12,$H$12/100)-(1-$F$12)) | K12: =IF($H$12="","",MAX(0,($F$12*IF($H$12<0,-100/$H$12,$H$12/100)-(1-$F$12))/IF($H$12<0,-100/$H$12,$H$12/100))*'Settings'!$B$3) | L12: =IF($H$12="","",ROUND(MIN($K$12,'Settings'!$B$5)*'Settings'!$B$2,2)) | M12: =IF($J$12="","",IF($J$12<0,"Pass",IF($J$12<'Settings'!$B$4,"Thin",IF($J$12<0.06,"✅ Sharp band",IF($J$12<0.08,"Strong","⚠ Verify (stale?)"))))) | N12: Model 45.3% (fair +121). Your call. | P12: =IF(OR($H$12="",$O$12=""),"",(1+IF($H$12<0,-100/$H$12,$H$12/100))/(1+IF($O$12<0,-100/$O$12,$O$12/100))-1)
A13: 2026-06-29 | B13: Pittsburgh Pirates @ Philadelphia Phillies | C13: 22:40 | D13: Total | E13: Over 9 | F13: 0.4931 | G13: 103 | H13: 104 | I13: =IF($H$13="","",IF($H$13<0,-$H$13/(-$H$13+100),100/($H$13+100))) | J13: =IF($H$13="","",$F$13*IF($H$13<0,-100/$H$13,$H$13/100)-(1-$F$13)) | K13: =IF($H$13="","",MAX(0,($F$13*IF($H$13<0,-100/$H$13,$H$13/100)-(1-$F$13))/IF($H$13<0,-100/$H$13,$H$13/100))*'Settings'!$B$3) | L13: =IF($H$13="","",ROUND(MIN($K$13,'Settings'!$B$5)*'Settings'!$B$2,2)) | M13: =IF($J$13="","",IF($J$13<0,"Pass",IF($J$13<'Settings'!$B$4,"Thin",IF($J$13<0.06,"✅ Sharp band",IF($J$13<0.08,"Strong","⚠ Verify (stale?)"))))) | N13: Model 49.3% (fair +103). Your call. | P13: =IF(OR($H$13="",$O$13=""),"",(1+IF($H$13<0,-100/$H$13,$H$13/100))/(1+IF($O$13<0,-100/$O$13,$O$13/100))-1)
A14: 2026-06-29 | B14: Pittsburgh Pirates @ Philadelphia Phillies | C14: 22:40 | D14: Total | E14: Under 9 | F14: 0.5069 | G14: -103 | H14: 122 | I14: =IF($H$14="","",IF($H$14<0,-$H$14/(-$H$14+100),100/($H$14+100))) | J14: =IF($H$14="","",$F$14*IF($H$14<0,-100/$H$14,$H$14/100)-(1-$F$14)) | K14: =IF($H$14="","",MAX(0,($F$14*IF($H$14<0,-100/$H$14,$H$14/100)-(1-$F$14))/IF($H$14<0,-100/$H$14,$H$14/100))*'Settings'!$B$3) | L14: =IF($H$14="","",ROUND(MIN($K$14,'Settings'!$B$5)*'Settings'!$B$2,2)) | M14: =IF($J$14="","",IF($J$14<0,"Pass",IF($J$14<'Settings'!$B$4,"Thin",IF($J$14<0.06,"✅ Sharp band",IF($J$14<0.08,"Strong","⚠ Verify (stale?)"))))) | N14: Model 50.7% (fair -103). Your call. | P14: =IF(OR($H$14="",$O$14=""),"",(1+IF($H$14<0,-100/$H$14,$H$14/100))/(1+IF($O$14<0,-100/$O$14,$O$14/100))-1)
A15: 2026-06-29 | B15: Pittsburgh Pirates @ Philadelphia Phillies | C15: 22:40 | D15: Spread | E15: Philadelphia Phillies -1.5 | F15: 0.2818 | G15: 255 | H15: 175 | I15: =IF($H$15="","",IF($H$15<0,-$H$15/(-$H$15+100),100/($H$15+100))) | J15: =IF($H$15="","",$F$15*IF($H$15<0,-100/$H$15,$H$15/100)-(1-$F$15)) | K15: =IF($H$15="","",MAX(0,($F$15*IF($H$15<0,-100/$H$15,$H$15/100)-(1-$F$15))/IF($H$15<0,-100/$H$15,$H$15/100))*'Settings'!$B$3) | L15: =IF($H$15="","",ROUND(MIN($K$15,'Settings'!$B$5)*'Settings'!$B$2,2)) | M15: =IF($J$15="","",IF($J$15<0,"Pass",IF($J$15<'Settings'!$B$4,"Thin",IF($J$15<0.06,"✅ Sharp band",IF($J$15<0.08,"Strong","⚠ Verify (stale?)"))))) | N15: Model 28.2% (fair +255). Your call. | P15: =IF(OR($H$15="",$O$15=""),"",(1+IF($H$15<0,-100/$H$15,$H$15/100))/(1+IF($O$15<0,-100/$O$15,$O$15/100))-1)
A16: 2026-06-29 | B16: Pittsburgh Pirates @ Philadelphia Phillies | C16: 22:40 | D16: Spread | E16: Pittsburgh Pirates +1.5 | F16: 0.7182 | G16: -255 | H16: 167 | I16: =IF($H$16="","",IF($H$16<0,-$H$16/(-$H$16+100),100/($H$16+100))) | J16: =IF($H$16="","",$F$16*IF($H$16<0,-100/$H$16,$H$16/100)-(1-$F$16)) | K16: =IF($H$16="","",MAX(0,($F$16*IF($H$16<0,-100/$H$16,$H$16/100)-(1-$F$16))/IF($H$16<0,-100/$H$16,$H$16/100))*'Settings'!$B$3) | L16: =IF($H$16="","",ROUND(MIN($K$16,'Settings'!$B$5)*'Settings'!$B$2,2)) | M16: =IF($J$16="","",IF($J$16<0,"Pass",IF($J$16<'Settings'!$B$4,"Thin",IF($J$16<0.06,"✅ Sharp band",IF($J$16<0.08,"Strong","⚠ Verify (stale?)"))))) | N16: Model 71.8% (fair -255). Your call. | P16: =IF(OR($H$16="",$O$16=""),"",(1+IF($H$16<0,-100/$H$16,$H$16/100))/(1+IF($O$16<0,-100/$O$16,$O$16/100))-1)
A17: 2026-06-29 | B17: Detroit Tigers @ New York Yankees | C17: 23:05 | D17: Moneyline | E17: Detroit Tigers | F17: 0.45911504 | G17: 118 | H17: 126 | I17: =IF($H$17="","",IF($H$17<0,-$H$17/(-$H$17+100),100/($H$17+100))) | J17: =IF($H$17="","",$F$17*IF($H$17<0,-100/$H$17,$H$17/100)-(1-$F$17)) | K17: =IF($H$17="","",MAX(0,($F$17*IF($H$17<0,-100/$H$17,$H$17/100)-(1-$F$17))/IF($H$17<0,-100/$H$17,$H$17/100))*'Settings'!$B$3) | L17: =IF($H$17="","",ROUND(MIN($K$17,'Settings'!$B$5)*'Settings'!$B$2,2)) | M17: =IF($J$17="","",IF($J$17<0,"Pass",IF($J$17<'Settings'!$B$4,"Thin",IF($J$17<0.06,"✅ Sharp band",IF($J$17<0.08,"Strong","⚠ Verify (stale?)"))))) | N17: Model 45.9% (fair +118). Your call. | P17: =IF(OR($H$17="",$O$17=""),"",(1+IF($H$17<0,-100/$H$17,$H$17/100))/(1+IF($O$17<0,-100/$O$17,$O$17/100))-1)
A18: 2026-06-29 | B18: Detroit Tigers @ New York Yankees | C18: 23:05 | D18: Moneyline | E18: New York Yankees | F18: 0.54089692 | G18: -118 | H18: -127 | I18: =IF($H$18="","",IF($H$18<0,-$H$18/(-$H$18+100),100/($H$18+100))) | J18: =IF($H$18="","",$F$18*IF($H$18<0,-100/$H$18,$H$18/100)-(1-$F$18)) | K18: =IF($H$18="","",MAX(0,($F$18*IF($H$18<0,-100/$H$18,$H$18/100)-(1-$F$18))/IF($H$18<0,-100/$H$18,$H$18/100))*'Settings'!$B$3) | L18: =IF($H$18="","",ROUND(MIN($K$18,'Settings'!$B$5)*'Settings'!$B$2,2)) | M18: =IF($J$18="","",IF($J$18<0,"Pass",IF($J$18<'Settings'!$B$4,"Thin",IF($J$18<0.06,"✅ Sharp band",IF($J$18<0.08,"Strong","⚠ Verify (stale?)"))))) | N18: Model 54.1% (fair -118). Your call. | P18: =IF(OR($H$18="",$O$18=""),"",(1+IF($H$18<0,-100/$H$18,$H$18/100))/(1+IF($O$18<0,-100/$O$18,$O$18/100))-1)
A19: 2026-06-29 | B19: Detroit Tigers @ New York Yankees | C19: 23:05 | D19: Total | E19: Over 8 | F19: 0.486 | G19: 106 | H19: 100 | I19: =IF($H$19="","",IF($H$19<0,-$H$19/(-$H$19+100),100/($H$19+100))) | J19: =IF($H$19="","",$F$19*IF($H$19<0,-100/$H$19,$H$19/100)-(1-$F$19)) | K19: =IF($H$19="","",MAX(0,($F$19*IF($H$19<0,-100/$H$19,$H$19/100)-(1-$F$19))/IF($H$19<0,-100/$H$19,$H$19/100))*'Settings'!$B$3) | L19: =IF($H$19="","",ROUND(MIN($K$19,'Settings'!$B$5)*'Settings'!$B$2,2)) | M19: =IF($J$19="","",IF($J$19<0,"Pass",IF($J$19<'Settings'!$B$4,"Thin",IF($J$19<0.06,"✅ Sharp band",IF($J$19<0.08,"Strong","⚠ Verify (stale?)"))))) | N19: Model 48.6% (fair +106). Your call. | P19: =IF(OR($H$19="",$O$19=""),"",(1+IF($H$19<0,-100/$H$19,$H$19/100))/(1+IF($O$19<0,-100/$O$19,$O$19/100))-1)
A20: 2026-06-29 | B20: Detroit Tigers @ New York Yankees | C20: 23:05 | D20: Total | E20: Under 8 | F20: 0.514 | G20: -106 | H20: 117 | I20: =IF($H$20="","",IF($H$20<0,-$H$20/(-$H$20+100),100/($H$20+100))) | J20: =IF($H$20="","",$F$20*IF($H$20<0,-100/$H$20,$H$20/100)-(1-$F$20)) | K20: =IF($H$20="","",MAX(0,($F$20*IF($H$20<0,-100/$H$20,$H$20/100)-(1-$F$20))/IF($H$20<0,-100/$H$20,$H$20/100))*'Settings'!$B$3) | L20: =IF($H$20="","",ROUND(MIN($K$20,'Settings'!$B$5)*'Settings'!$B$2,2)) | M20: =IF($J$20="","",IF($J$20<0,"Pass",IF($J$20<'Settings'!$B$4,"Thin",IF($J$20<0.06,"✅ Sharp band",IF($J$20<0.08,"Strong","⚠ Verify (stale?)"))))) | N20: Model 51.4% (fair -106). Your call. | P20: =IF(OR($H$20="",$O$20=""),"",(1+IF($H$20<0,-100/$H$20,$H$20/100))/(1+IF($O$20<0,-100/$O$20,$O$20/100))-1)
A21: 2026-06-29 | B21: Detroit Tigers @ New York Yankees | C21: 23:05 | D21: Spread | E21: New York Yankees -1.5 | F21: 0.3815 | G21: 162 | H21: 163 | I21: =IF($H$21="","",IF($H$21<0,-$H$21/(-$H$21+100),100/($H$21+100))) | J21: =IF($H$21="","",$F$21*IF($H$21<0,-100/$H$21,$H$21/100)-(1-$F$21)) | K21: =IF($H$21="","",MAX(0,($F$21*IF($H$21<0,-100/$H$21,$H$21/100)-(1-$F$21))/IF($H$21<0,-100/$H$21,$H$21/100))*'Settings'!$B$3) | L21: =IF($H$21="","",ROUND(MIN($K$21,'Settings'!$B$5)*'Settings'!$B$2,2)) | M21: =IF($J$21="","",IF($J$21<0,"Pass",IF($J$21<'Settings'!$B$4,"Thin",IF($J$21<0.06,"✅ Sharp band",IF($J$21<0.08,"Strong","⚠ Verify (stale?)"))))) | N21: Model 38.1% (fair +162). Your call. | P21: =IF(OR($H$21="",$O$21=""),"",(1+IF($H$21<0,-100/$H$21,$H$21/100))/(1+IF($O$21<0,-100/$O$21,$O$21/100))-1)
A22: 2026-06-29 | B22: Detroit Tigers @ New York Yankees | C22: 23:05 | D22: Spread | E22: Detroit Tigers +1.5 | F22: 0.6185 | G22: -162 | H22: -116 | I22: =IF($H$22="","",IF($H$22<0,-$H$22/(-$H$22+100),100/($H$22+100))) | J22: =IF($H$22="","",$F$22*IF($H$22<0,-100/$H$22,$H$22/100)-(1-$F$22)) | K22: =IF($H$22="","",MAX(0,($F$22*IF($H$22<0,-100/$H$22,$H$22/100)-(1-$F$22))/IF($H$22<0,-100/$H$22,$H$22/100))*'Settings'!$B$3) | L22: =IF($H$22="","",ROUND(MIN($K$22,'Settings'!$B$5)*'Settings'!$B$2,2)) | M22: =IF($J$22="","",IF($J$22<0,"Pass",IF($J$22<'Settings'!$B$4,"Thin",IF($J$22<0.06,"✅ Sharp band",IF($J$22<0.08,"Strong","⚠ Verify (stale?)"))))) | N22: Model 61.9% (fair -162). Your call. | P22: =IF(OR($H$22="",$O$22=""),"",(1+IF($H$22<0,-100/$H$22,$H$22/100))/(1+IF($O$22<0,-100/$O$22,$O$22/100))-1)
A23: 2026-06-29 | B23: New York Mets @ Toronto Blue Jays | C23: 23:07 | D23: Moneyline | E23: New York Mets | F23: 0.48640553 | G23: 106 | H23: 117 | I23: =IF($H$23="","",IF($H$23<0,-$H$23/(-$H$23+100),100/($H$23+100))) | J23: =IF($H$23="","",$F$23*IF($H$23<0,-100/$H$23,$H$23/100)-(1-$F$23)) | K23: =IF($H$23="","",MAX(0,($F$23*IF($H$23<0,-100/$H$23,$H$23/100)-(1-$F$23))/IF($H$23<0,-100/$H$23,$H$23/100))*'Settings'!$B$3) | L23: =IF($H$23="","",ROUND(MIN($K$23,'Settings'!$B$5)*'Settings'!$B$2,2)) | M23: =IF($J$23="","",IF($J$23<0,"Pass",IF($J$23<'Settings'!$B$4,"Thin",IF($J$23<0.06,"✅ Sharp band",IF($J$23<0.08,"Strong","⚠ Verify (stale?)"))))) | N23: Model 48.6% (fair +106). Your call. | P23: =IF(OR($H$23="",$O$23=""),"",(1+IF($H$23<0,-100/$H$23,$H$23/100))/(1+IF($O$23<0,-100/$O$23,$O$23/100))-1)
A24: 2026-06-29 | B24: New York Mets @ Toronto Blue Jays | C24: 23:07 | D24: Moneyline | E24: Toronto Blue Jays | F24: 0.51355991 | G24: -106 | H24: -117 | I24: =IF($H$24="","",IF($H$24<0,-$H$24/(-$H$24+100),100/($H$24+100))) | J24: =IF($H$24="","",$F$24*IF($H$24<0,-100/$H$24,$H$24/100)-(1-$F$24)) | K24: =IF($H$24="","",MAX(0,($F$24*IF($H$24<0,-100/$H$24,$H$24/100)-(1-$F$24))/IF($H$24<0,-100/$H$24,$H$24/100))*'Settings'!$B$3) | L24: =IF($H$24="","",ROUND(MIN($K$24,'Settings'!$B$5)*'Settings'!$B$2,2)) | M24: =IF($J$24="","",IF($J$24<0,"Pass",IF($J$24<'Settings'!$B$4,"Thin",IF($J$24<0.06,"✅ Sharp band",IF($J$24<0.08,"Strong","⚠ Verify (stale?)"))))) | N24: Model 51.4% (fair -106). Your call. | P24: =IF(OR($H$24="",$O$24=""),"",(1+IF($H$24<0,-100/$H$24,$H$24/100))/(1+IF($O$24<0,-100/$O$24,$O$24/100))-1)
A25: 2026-06-29 | B25: New York Mets @ Toronto Blue Jays | C25: 23:07 | D25: Total | E25: Over 8.5 | F25: 0.46485 | G25: 115 | H25: 100 | I25: =IF($H$25="","",IF($H$25<0,-$H$25/(-$H$25+100),100/($H$25+100))) | J25: =IF($H$25="","",$F$25*IF($H$25<0,-100/$H$25,$H$25/100)-(1-$F$25)) | K25: =IF($H$25="","",MAX(0,($F$25*IF($H$25<0,-100/$H$25,$H$25/100)-(1-$F$25))/IF($H$25<0,-100/$H$25,$H$25/100))*'Settings'!$B$3) | L25: =IF($H$25="","",ROUND(MIN($K$25,'Settings'!$B$5)*'Settings'!$B$2,2)) | M25: =IF($J$25="","",IF($J$25<0,"Pass",IF($J$25<'Settings'!$B$4,"Thin",IF($J$25<0.06,"✅ Sharp band",IF($J$25<0.08,"Strong","⚠ Verify (stale?)"))))) | N25: Model 46.5% (fair +115). Your call. | P25: =IF(OR($H$25="",$O$25=""),"",(1+IF($H$25<0,-100/$H$25,$H$25/100))/(1+IF($O$25<0,-100/$O$25,$O$25/100))-1)
A26: 2026-06-29 | B26: New York Mets @ Toronto Blue Jays | C26: 23:07 | D26: Total | E26: Under 8.5 | F26: 0.53515 | G26: -115 | H26: 100 | I26: =IF($H$26="","",IF($H$26<0,-$H$26/(-$H$26+100),100/($H$26+100))) | J26: =IF($H$26="","",$F$26*IF($H$26<0,-100/$H$26,$H$26/100)-(1-$F$26)) | K26: =IF($H$26="","",MAX(0,($F$26*IF($H$26<0,-100/$H$26,$H$26/100)-(1-$F$26))/IF($H$26<0,-100/$H$26,$H$26/100))*'Settings'!$B$3) | L26: =IF($H$26="","",ROUND(MIN($K$26,'Settings'!$B$5)*'Settings'!$B$2,2)) | M26: =IF($J$26="","",IF($J$26<0,"Pass",IF($J$26<'Settings'!$B$4,"Thin",IF($J$26<0.06,"✅ Sharp band",IF($J$26<0.08,"Strong","⚠ Verify (stale?)"))))) | N26: Model 53.5% (fair -115). Your call. | P26: =IF(OR($H$26="",$O$26=""),"",(1+IF($H$26<0,-100/$H$26,$H$26/100))/(1+IF($O$26<0,-100/$O$26,$O$26/100))-1)
A27: 2026-06-29 | B27: New York Mets @ Toronto Blue Jays | C27: 23:07 | D27: Spread | E27: Toronto Blue Jays -1.5 | F27: 0.3483 | G27: 187 | H27: 174 | I27: =IF($H$27="","",IF($H$27<0,-$H$27/(-$H$27+100),100/($H$27+100))) | J27: =IF($H$27="","",$F$27*IF($H$27<0,-100/$H$27,$H$27/100)-(1-$F$27)) | K27: =IF($H$27="","",MAX(0,($F$27*IF($H$27<0,-100/$H$27,$H$27/100)-(1-$F$27))/IF($H$27<0,-100/$H$27,$H$27/100))*'Settings'!$B$3) | L27: =IF($H$27="","",ROUND(MIN($K$27,'Settings'!$B$5)*'Settings'!$B$2,2)) | M27: =IF($J$27="","",IF($J$27<0,"Pass",IF($J$27<'Settings'!$B$4,"Thin",IF($J$27<0.06,"✅ Sharp band",IF($J$27<0.08,"Strong","⚠ Verify (stale?)"))))) | N27: Model 34.8% (fair +187). Your call. | P27: =IF(OR($H$27="",$O$27=""),"",(1+IF($H$27<0,-100/$H$27,$H$27/100))/(1+IF($O$27<0,-100/$O$27,$O$27/100))-1)
A28: 2026-06-29 | B28: New York Mets @ Toronto Blue Jays | C28: 23:07 | D28: Spread | E28: New York Mets +1.5 | F28: 0.6517 | G28: -187 | H28: 178 | I28: =IF($H$28="","",IF($H$28<0,-$H$28/(-$H$28+100),100/($H$28+100))) | J28: =IF($H$28="","",$F$28*IF($H$28<0,-100/$H$28,$H$28/100)-(1-$F$28)) | K28: =IF($H$28="","",MAX(0,($F$28*IF($H$28<0,-100/$H$28,$H$28/100)-(1-$F$28))/IF($H$28<0,-100/$H$28,$H$28/100))*'Settings'!$B$3) | L28: =IF($H$28="","",ROUND(MIN($K$28,'Settings'!$B$5)*'Settings'!$B$2,2)) | M28: =IF($J$28="","",IF($J$28<0,"Pass",IF($J$28<'Settings'!$B$4,"Thin",IF($J$28<0.06,"✅ Sharp band",IF($J$28<0.08,"Strong","⚠ Verify (stale?)"))))) | N28: Model 65.2% (fair -187). Your call. | P28: =IF(OR($H$28="",$O$28=""),"",(1+IF($H$28<0,-100/$H$28,$H$28/100))/(1+IF($O$28<0,-100/$O$28,$O$28/100))-1)
A29: 2026-06-29 | B29: Washington Nationals @ Boston Red Sox | C29: 23:10 | D29: Moneyline | E29: Washington Nationals | F29: 0.3892 | G29: 157 | H29: 163 | I29: =IF($H$29="","",IF($H$29<0,-$H$29/(-$H$29+100),100/($H$29+100))) | J29: =IF($H$29="","",$F$29*IF($H$29<0,-100/$H$29,$H$29/100)-(1-$F$29)) | K29: =IF($H$29="","",MAX(0,($F$29*IF($H$29<0,-100/$H$29,$H$29/100)-(1-$F$29))/IF($H$29<0,-100/$H$29,$H$29/100))*'Settings'!$B$3) | L29: =IF($H$29="","",ROUND(MIN($K$29,'Settings'!$B$5)*'Settings'!$B$2,2)) | M29: =IF($J$29="","",IF($J$29<0,"Pass",IF($J$29<'Settings'!$B$4,"Thin",IF($J$29<0.06,"✅ Sharp band",IF($J$29<0.08,"Strong","⚠ Verify (stale?)"))))) | N29: Model 38.9% (fair +157). Your call. | P29: =IF(OR($H$29="",$O$29=""),"",(1+IF($H$29<0,-100/$H$29,$H$29/100))/(1+IF($O$29<0,-100/$O$29,$O$29/100))-1)
A30: 2026-06-29 | B30: Washington Nationals @ Boston Red Sox | C30: 23:10 | D30: Moneyline | E30: Boston Red Sox | F30: 0.6108 | G30: -157 | H30: 122 | I30: =IF($H$30="","",IF($H$30<0,-$H$30/(-$H$30+100),100/($H$30+100))) | J30: =IF($H$30="","",$F$30*IF($H$30<0,-100/$H$30,$H$30/100)-(1-$F$30)) | K30: =IF($H$30="","",MAX(0,($F$30*IF($H$30<0,-100/$H$30,$H$30/100)-(1-$F$30))/IF($H$30<0,-100/$H$30,$H$30/100))*'Settings'!$B$3) | L30: =IF($H$30="","",ROUND(MIN($K$30,'Settings'!$B$5)*'Settings'!$B$2,2)) | M30: =IF($J$30="","",IF($J$30<0,"Pass",IF($J$30<'Settings'!$B$4,"Thin",IF($J$30<0.06,"✅ Sharp band",IF($J$30<0.08,"Strong","⚠ Verify (stale?)"))))) | N30: Model 61.1% (fair -157). Your call. | P30: =IF(OR($H$30="",$O$30=""),"",(1+IF($H$30<0,-100/$H$30,$H$30/100))/(1+IF($O$30<0,-100/$O$30,$O$30/100))-1)
A31: 2026-06-29 | B31: Washington Nationals @ Boston Red Sox | C31: 23:10 | D31: Total | E31: Over 9.5 | F31: 0.4783 | G31: 109 | H31: 113 | I31: =IF($H$31="","",IF($H$31<0,-$H$31/(-$H$31+100),100/($H$31+100))) | J31: =IF($H$31="","",$F$31*IF($H$31<0,-100/$H$31,$H$31/100)-(1-$F$31)) | K31: =IF($H$31="","",MAX(0,($F$31*IF($H$31<0,-100/$H$31,$H$31/100)-(1-$F$31))/IF($H$31<0,-100/$H$31,$H$31/100))*'Settings'!$B$3) | L31: =IF($H$31="","",ROUND(MIN($K$31,'Settings'!$B$5)*'Settings'!$B$2,2)) | M31: =IF($J$31="","",IF($J$31<0,"Pass",IF($J$31<'Settings'!$B$4,"Thin",IF($J$31<0.06,"✅ Sharp band",IF($J$31<0.08,"Strong","⚠ Verify (stale?)"))))) | N31: Model 47.8% (fair +109). Your call. | P31: =IF(OR($H$31="",$O$31=""),"",(1+IF($H$31<0,-100/$H$31,$H$31/100))/(1+IF($O$31<0,-100/$O$31,$O$31/100))-1)
A32: 2026-06-29 | B32: Washington Nationals @ Boston Red Sox | C32: 23:10 | D32: Total | E32: Under 9.5 | F32: 0.5217 | G32: -109 | H32: 128 | I32: =IF($H$32="","",IF($H$32<0,-$H$32/(-$H$32+100),100/($H$32+100))) | J32: =IF($H$32="","",$F$32*IF($H$32<0,-100/$H$32,$H$32/100)-(1-$F$32)) | K32: =IF($H$32="","",MAX(0,($F$32*IF($H$32<0,-100/$H$32,$H$32/100)-(1-$F$32))/IF($H$32<0,-100/$H$32,$H$32/100))*'Settings'!$B$3) | L32: =IF($H$32="","",ROUND(MIN($K$32,'Settings'!$B$5)*'Settings'!$B$2,2)) | M32: =IF($J$32="","",IF($J$32<0,"Pass",IF($J$32<'Settings'!$B$4,"Thin",IF($J$32<0.06,"✅ Sharp band",IF($J$32<0.08,"Strong","⚠ Verify (stale?)"))))) | N32: Model 52.2% (fair -109). Your call. | P32: =IF(OR($H$32="",$O$32=""),"",(1+IF($H$32<0,-100/$H$32,$H$32/100))/(1+IF($O$32<0,-100/$O$32,$O$32/100))-1)
A33: 2026-06-29 | B33: Washington Nationals @ Boston Red Sox | C33: 23:10 | D33: Spread | E33: Boston Red Sox -1.5 | F33: 0.4737 | G33: 111 | H33: 163 | I33: =IF($H$33="","",IF($H$33<0,-$H$33/(-$H$33+100),100/($H$33+100))) | J33: =IF($H$33="","",$F$33*IF($H$33<0,-100/$H$33,$H$33/100)-(1-$F$33)) | K33: =IF($H$33="","",MAX(0,($F$33*IF($H$33<0,-100/$H$33,$H$33/100)-(1-$F$33))/IF($H$33<0,-100/$H$33,$H$33/100))*'Settings'!$B$3) | L33: =IF($H$33="","",ROUND(MIN($K$33,'Settings'!$B$5)*'Settings'!$B$2,2)) | M33: =IF($J$33="","",IF($J$33<0,"Pass",IF($J$33<'Settings'!$B$4,"Thin",IF($J$33<0.06,"✅ Sharp band",IF($J$33<0.08,"Strong","⚠ Verify (stale?)"))))) | N33: Model 47.4% (fair +111). Your call. | P33: =IF(OR($H$33="",$O$33=""),"",(1+IF($H$33<0,-100/$H$33,$H$33/100))/(1+IF($O$33<0,-100/$O$33,$O$33/100))-1)
A34: 2026-06-29 | B34: Washington Nationals @ Boston Red Sox | C34: 23:10 | D34: Spread | E34: Washington Nationals +1.5 | F34: 0.5263 | G34: -111 | H34: -130 | I34: =IF($H$34="","",IF($H$34<0,-$H$34/(-$H$34+100),100/($H$34+100))) | J34: =IF($H$34="","",$F$34*IF($H$34<0,-100/$H$34,$H$34/100)-(1-$F$34)) | K34: =IF($H$34="","",MAX(0,($F$34*IF($H$34<0,-100/$H$34,$H$34/100)-(1-$F$34))/IF($H$34<0,-100/$H$34,$H$34/100))*'Settings'!$B$3) | L34: =IF($H$34="","",ROUND(MIN($K$34,'Settings'!$B$5)*'Settings'!$B$2,2)) | M34: =IF($J$34="","",IF($J$34<0,"Pass",IF($J$34<'Settings'!$B$4,"Thin",IF($J$34<0.06,"✅ Sharp band",IF($J$34<0.08,"Strong","⚠ Verify (stale?)"))))) | N34: Model 52.6% (fair -111). Your call. | P34: =IF(OR($H$34="",$O$34=""),"",(1+IF($H$34<0,-100/$H$34,$H$34/100))/(1+IF($O$34<0,-100/$O$34,$O$34/100))-1)
A35: 2026-06-29 | B35: Texas Rangers @ Cleveland Guardians | C35: 23:10 | D35: Moneyline | E35: Texas Rangers | F35: 0.45213115 | G35: 121 | H35: 144 | I35: =IF($H$35="","",IF($H$35<0,-$H$35/(-$H$35+100),100/($H$35+100))) | J35: =IF($H$35="","",$F$35*IF($H$35<0,-100/$H$35,$H$35/100)-(1-$F$35)) | K35: =IF($H$35="","",MAX(0,($F$35*IF($H$35<0,-100/$H$35,$H$35/100)-(1-$F$35))/IF($H$35<0,-100/$H$35,$H$35/100))*'Settings'!$B$3) | L35: =IF($H$35="","",ROUND(MIN($K$35,'Settings'!$B$5)*'Settings'!$B$2,2)) | M35: =IF($J$35="","",IF($J$35<0,"Pass",IF($J$35<'Settings'!$B$4,"Thin",IF($J$35<0.06,"✅ Sharp band",IF($J$35<0.08,"Strong","⚠ Verify (stale?)"))))) | N35: Model 45.2% (fair +121). Your call. | P35: =IF(OR($H$35="",$O$35=""),"",(1+IF($H$35<0,-100/$H$35,$H$35/100))/(1+IF($O$35<0,-100/$O$35,$O$35/100))-1)
A36: 2026-06-29 | B36: Texas Rangers @ Cleveland Guardians | C36: 23:10 | D36: Moneyline | E36: Cleveland Guardians | F36: 0.5479082 | G36: -121 | H36: -144 | I36: =IF($H$36="","",IF($H$36<0,-$H$36/(-$H$36+100),100/($H$36+100))) | J36: =IF($H$36="","",$F$36*IF($H$36<0,-100/$H$36,$H$36/100)-(1-$F$36)) | K36: =IF($H$36="","",MAX(0,($F$36*IF($H$36<0,-100/$H$36,$H$36/100)-(1-$F$36))/IF($H$36<0,-100/$H$36,$H$36/100))*'Settings'!$B$3) | L36: =IF($H$36="","",ROUND(MIN($K$36,'Settings'!$B$5)*'Settings'!$B$2,2)) | M36: =IF($J$36="","",IF($J$36<0,"Pass",IF($J$36<'Settings'!$B$4,"Thin",IF($J$36<0.06,"✅ Sharp band",IF($J$36<0.08,"Strong","⚠ Verify (stale?)"))))) | N36: Model 54.8% (fair -121). Your call. | P36: =IF(OR($H$36="",$O$36=""),"",(1+IF($H$36<0,-100/$H$36,$H$36/100))/(1+IF($O$36<0,-100/$O$36,$O$36/100))-1)
A37: 2026-06-29 | B37: Texas Rangers @ Cleveland Guardians | C37: 23:10 | D37: Total | E37: Over 8 | F37: 0.3837 | G37: 161 | H37: 112 | I37: =IF($H$37="","",IF($H$37<0,-$H$37/(-$H$37+100),100/($H$37+100))) | J37: =IF($H$37="","",$F$37*IF($H$37<0,-100/$H$37,$H$37/100)-(1-$F$37)) | K37: =IF($H$37="","",MAX(0,($F$37*IF($H$37<0,-100/$H$37,$H$37/100)-(1-$F$37))/IF($H$37<0,-100/$H$37,$H$37/100))*'Settings'!$B$3) | L37: =IF($H$37="","",ROUND(MIN($K$37,'Settings'!$B$5)*'Settings'!$B$2,2)) | M37: =IF($J$37="","",IF($J$37<0,"Pass",IF($J$37<'Settings'!$B$4,"Thin",IF($J$37<0.06,"✅ Sharp band",IF($J$37<0.08,"Strong","⚠ Verify (stale?)"))))) | N37: Model 38.4% (fair +161). Your call. | P37: =IF(OR($H$37="",$O$37=""),"",(1+IF($H$37<0,-100/$H$37,$H$37/100))/(1+IF($O$37<0,-100/$O$37,$O$37/100))-1)
A38: 2026-06-29 | B38: Texas Rangers @ Cleveland Guardians | C38: 23:10 | D38: Total | E38: Under 8 | F38: 0.6163 | G38: -161 | H38: 104 | I38: =IF($H$38="","",IF($H$38<0,-$H$38/(-$H$38+100),100/($H$38+100))) | J38: =IF($H$38="","",$F$38*IF($H$38<0,-100/$H$38,$H$38/100)-(1-$F$38)) | K38: =IF($H$38="","",MAX(0,($F$38*IF($H$38<0,-100/$H$38,$H$38/100)-(1-$F$38))/IF($H$38<0,-100/$H$38,$H$38/100))*'Settings'!$B$3) | L38: =IF($H$38="","",ROUND(MIN($K$38,'Settings'!$B$5)*'Settings'!$B$2,2)) | M38: =IF($J$38="","",IF($J$38<0,"Pass",IF($J$38<'Settings'!$B$4,"Thin",IF($J$38<0.06,"✅ Sharp band",IF($J$38<0.08,"Strong","⚠ Verify (stale?)"))))) | N38: Model 61.6% (fair -161). Your call. | P38: =IF(OR($H$38="",$O$38=""),"",(1+IF($H$38<0,-100/$H$38,$H$38/100))/(1+IF($O$38<0,-100/$O$38,$O$38/100))-1)
A39: 2026-06-29 | B39: Texas Rangers @ Cleveland Guardians | C39: 23:10 | D39: Spread | E39: Cleveland Guardians -1.5 | F39: 0.3579 | G39: 179 | H39: 150 | I39: =IF($H$39="","",IF($H$39<0,-$H$39/(-$H$39+100),100/($H$39+100))) | J39: =IF($H$39="","",$F$39*IF($H$39<0,-100/$H$39,$H$39/100)-(1-$F$39)) | K39: =IF($H$39="","",MAX(0,($F$39*IF($H$39<0,-100/$H$39,$H$39/100)-(1-$F$39))/IF($H$39<0,-100/$H$39,$H$39/100))*'Settings'!$B$3) | L39: =IF($H$39="","",ROUND(MIN($K$39,'Settings'!$B$5)*'Settings'!$B$2,2)) | M39: =IF($J$39="","",IF($J$39<0,"Pass",IF($J$39<'Settings'!$B$4,"Thin",IF($J$39<0.06,"✅ Sharp band",IF($J$39<0.08,"Strong","⚠ Verify (stale?)"))))) | N39: Model 35.8% (fair +179). Your call. | P39: =IF(OR($H$39="",$O$39=""),"",(1+IF($H$39<0,-100/$H$39,$H$39/100))/(1+IF($O$39<0,-100/$O$39,$O$39/100))-1)
A40: 2026-06-29 | B40: Texas Rangers @ Cleveland Guardians | C40: 23:10 | D40: Spread | E40: Texas Rangers +1.5 | F40: 0.6421 | G40: -179 | H40: 150 | I40: =IF($H$40="","",IF($H$40<0,-$H$40/(-$H$40+100),100/($H$40+100))) | J40: =IF($H$40="","",$F$40*IF($H$40<0,-100/$H$40,$H$40/100)-(1-$F$40)) | K40: =IF($H$40="","",MAX(0,($F$40*IF($H$40<0,-100/$H$40,$H$40/100)-(1-$F$40))/IF($H$40<0,-100/$H$40,$H$40/100))*'Settings'!$B$3) | L40: =IF($H$40="","",ROUND(MIN($K$40,'Settings'!$B$5)*'Settings'!$B$2,2)) | M40: =IF($J$40="","",IF($J$40<0,"Pass",IF($J$40<'Settings'!$B$4,"Thin",IF($J$40<0.06,"✅ Sharp band",IF($J$40<0.08,"Strong","⚠ Verify (stale?)"))))) | N40: Model 64.2% (fair -179). Your call. | P40: =IF(OR($H$40="",$O$40=""),"",(1+IF($H$40<0,-100/$H$40,$H$40/100))/(1+IF($O$40<0,-100/$O$40,$O$40/100))-1)
A41: 2026-06-29 | B41: Cincinnati Reds @ Milwaukee Brewers | C41: 23:40 | D41: Moneyline | E41: Cincinnati Reds | F41: 0.37157658 | G41: 169 | H41: 122 | I41: =IF($H$41="","",IF($H$41<0,-$H$41/(-$H$41+100),100/($H$41+100))) | J41: =IF($H$41="","",$F$41*IF($H$41<0,-100/$H$41,$H$41/100)-(1-$F$41)) | K41: =IF($H$41="","",MAX(0,($F$41*IF($H$41<0,-100/$H$41,$H$41/100)-(1-$F$41))/IF($H$41<0,-100/$H$41,$H$41/100))*'Settings'!$B$3) | L41: =IF($H$41="","",ROUND(MIN($K$41,'Settings'!$B$5)*'Settings'!$B$2,2)) | M41: =IF($J$41="","",IF($J$41<0,"Pass",IF($J$41<'Settings'!$B$4,"Thin",IF($J$41<0.06,"✅ Sharp band",IF($J$41<0.08,"Strong","⚠ Verify (stale?)"))))) | N41: Model 37.2% (fair +169). Your call. | P41: =IF(OR($H$41="",$O$41=""),"",(1+IF($H$41<0,-100/$H$41,$H$41/100))/(1+IF($O$41<0,-100/$O$41,$O$41/100))-1)
...

Sheet WNBA Games
A1: WNBA — game markets
A2: Moneyline · Total · Spread. Yellow = your price.
A4: Date | B4: Matchup | C4: Start | D4: Market | E4: Selection | F4: Model Win% | G4: Model Fair | H4: ✏ Your Odds | I4: Implied% | J4: Your Edge (EV) | K4: ¼-Kelly % | L4: Stake $ | M4: Verdict | N4: Model read | O4: ✏ Closing | P4: CLV %
A5: 2026-06-30 | B5: Las Vegas Aces @ New York Liberty | C5: 23:00 | D5: Moneyline | E5: Las Vegas Aces | F5: 0.5591 | G5: -127 | I5: =IF($H$5="","",IF($H$5<0,-$H$5/(-$H$5+100),100/($H$5+100))) | J5: =IF($H$5="","",$F$5*IF($H$5<0,-100/$H$5,$H$5/100)-(1-$F$5)) | K5: =IF($H$5="","",MAX(0,($F$5*IF($H$5<0,-100/$H$5,$H$5/100)-(1-$F$5))/IF($H$5<0,-100/$H$5,$H$5/100))*'Settings'!$B$3) | L5: =IF($H$5="","",ROUND(MIN($K$5,'Settings'!$B$5)*'Settings'!$B$2,2)) | M5: =IF($J$5="","",IF($J$5<0,"Pass",IF($J$5<'Settings'!$B$4,"Thin",IF($J$5<0.06,"✅ Sharp band",IF($J$5<0.08,"Strong","⚠ Verify (stale?)"))))) | N5: Model 55.9% (fair -127). Your call. | P5: =IF(OR($H$5="",$O$5=""),"",(1+IF($H$5<0,-100/$H$5,$H$5/100))/(1+IF($O$5<0,-100/$O$5,$O$5/100))-1)
A6: 2026-06-30 | B6: Las Vegas Aces @ New York Liberty | C6: 23:00 | D6: Moneyline | E6: New York Liberty | F6: 0.4409 | G6: 127 | I6: =IF($H$6="","",IF($H$6<0,-$H$6/(-$H$6+100),100/($H$6+100))) | J6: =IF($H$6="","",$F$6*IF($H$6<0,-100/$H$6,$H$6/100)-(1-$F$6)) | K6: =IF($H$6="","",MAX(0,($F$6*IF($H$6<0,-100/$H$6,$H$6/100)-(1-$F$6))/IF($H$6<0,-100/$H$6,$H$6/100))*'Settings'!$B$3) | L6: =IF($H$6="","",ROUND(MIN($K$6,'Settings'!$B$5)*'Settings'!$B$2,2)) | M6: =IF($J$6="","",IF($J$6<0,"Pass",IF($J$6<'Settings'!$B$4,"Thin",IF($J$6<0.06,"✅ Sharp band",IF($J$6<0.08,"Strong","⚠ Verify (stale?)"))))) | N6: Model 44.1% (fair +127). Your call. | P6: =IF(OR($H$6="",$O$6=""),"",(1+IF($H$6<0,-100/$H$6,$H$6/100))/(1+IF($O$6<0,-100/$O$6,$O$6/100))-1)

Sheet Track Record
A1: 📒 Track Record — receipts, losses included
A2: Graded in the open. A process you can audit beats a hot streak you can't.
A4: Scope | B4: Graded games | C4: Model Brier | D4: Bets | E4: Win % | F4: Units | G4: ROI % | H4: Avg CLV % | I4: CLV beat %
A5: Overall | B5: 260 | C5: 0.2507 | D5: 187 | E5: 0.4492 | F5: -5.62 | G5: -3.01 | H5: 2.88 | I5: 0.503
A6: MLB | B6: 230 | C6: 0.2526 | D6: 148 | E6: 0.4662 | F6: -2.97 | G6: -2.01 | H6: 3.99 | I6: 0.5259
A7: WNBA | B7: 29 | C7: 0.2371 | D7: 37 | E7: 0.3784 | F7: -3.45 | G7: -9.33 | H7: -2.61 | I7: 0.3929
A8: NBA | B8: 1 | C8: 0.1979 | D8: 2 | E8: 0.5 | F8: 0.8 | G8: 40 | H8: 4.92 | I8: 0.5
A10: Brier: lower is better (0.25 = a coin flip). CLV beat %: how often we beat the closing line — the earliest honest sign an edge is real, before win/loss catches up.
A13: Calibration — honesty check
A14: When the model said X%, how often it actually happened (n=221, ECE 0.064 — lower is better; a calibrated model's bars sit on the diagonal).
A16: Model said | B16: Games | C16: We predicted | D16: Actually won | E16: Gap
A17: 10–20% | B17: 1 | C17: 0.1885 | D17: 0 | E17: -0.1885
A18: 20–30% | B18: 7 | C18: 0.2599 | D18: 0.4286 | E18: 0.1687
A19: 30–40% | B19: 20 | C19: 0.3715 | D19: 0.6 | E19: 0.2285
A20: 40–50% | B20: 70 | C20: 0.4561 | D20: 0.4714 | E20: 0.0153
A21: 50–60% | B21: 81 | C21: 0.5447 | D21: 0.5556 | E21: 0.0109
A22: 60–70% | B22: 33 | C22: 0.6435 | D22: 0.5152 | E22: -0.1284
A23: 70–80% | B23: 7 | C23: 0.7484 | D23: 0.5714 | E23: -0.1769
A24: 80–90% | B24: 2 | C24: 0.8538 | D24: 0.5 | E24: -0.3538

Sheet Research Hub
A1: 🔬 Research Hub
A2: Premium matchup breakdowns · 2026-06-29 · L5 window. Each game has its own tab.
A4: MLB: Chicago White Sox @ Baltimore Orioles
A5: MLB: Pittsburgh Pirates @ Philadelphia Phillies
A6: MLB: Detroit Tigers @ New York Yankees
A7: MLB: New York Mets @ Toronto Blue Jays
A8: MLB: Washington Nationals @ Boston Red Sox
A9: MLB: Texas Rangers @ Cleveland Guardians
A10: MLB: Cincinnati Reds @ Milwaukee Brewers
A11: MLB: San Diego Padres @ Chicago Cubs
A12: MLB: Minnesota Twins @ Houston Astros
A13: MLB: Miami Marlins @ Colorado Rockies
A15: Tip: the website's research view lets you flip the L5/L10/L15/L20/L30/Season window live; here every window is in the table so you can read any of them.

Sheet MLB Sox @ Orioles
A1: Chicago White Sox @ Baltimore Orioles
A2: MLB · 2026-06-29 · L5 window
A62: Chicago White Sox offense vs Baltimore Orioles defense
A63: Stat | B63: A Season | C63: A L30 | D63: A L20 | E63: A L15 | F63: A L10 | G63: A L5 | H63: A Rk | I63: Adv | J63: H Rk | K63: H L5 | L63: H L10 | M63: H L15 | N63: H L20 | O63: H L30 | P63: H Season | Q63: Opp stat
A64: Runs/G | B64: 4.605 | C64: 4.667 | D64: 5.6 | E64: 5.6 | F64: 5.4 | G64: 5.2 | H64: 4th | I64: ★★★ | J64: 29th | K64: 5.8 | L64: 5.9 | M64: 6.4 | N64: 6.2 | O64: 5.4 | P64: 5.243 | Q64: Opp Runs/G
A65: Hits/G | B65: 7.444 | C65: 7.586 | D65: 8.684 | E65: 8.5 | F65: 7.667 | G65: 7.6 | H65: 17th | J65: 18th | K65: 7.8 | L65: 7.889 | M65: 9.429 | N65: 8.947 | O65: 8.759 | P65: 8.667 | Q65: Opp Hits/G
A66: HR/G | B66: 1.306 | C66: 1.345 | D66: 1.737 | E66: 1.643 | F66: 1.556 | G66: 1.2 | H66: 8th | J66: — | K66: — | L66: — | M66: — | N66: — | O66: — | P66: — | Q66: Opp HR/G
A67: Batter K/G | B67: 9.389 | C67: 8.724 | D67: 9.053 | E67: 9.286 | F67: 9.667 | G67: 10.4 | H67: 27th | J67: 21st | K67: 7.6 | L67: 7.778 | M67: 7.714 | N67: 8.053 | O67: 8.138 | P67: 8.444 | Q67: Opp Batter K/G
A68: 1st Inn R/G | B68: 0.611 | C68: 0.552 | D68: 0.737 | E68: 0.857 | F68: 0.667 | G68: 0.6 | H68: 14th | J68: 16th | K68: 0.4 | L68: 0.556 | M68: 0.429 | N68: 0.421 | O68: 0.379 | P68: 0.333 | Q68: Opp 1st Inn R/G
A70: Baltimore Orioles offense vs Chicago White Sox defense
A71: Stat | B71: A Season | C71: A L30 | D71: A L20 | E71: A L15 | F71: A L10 | G71: A L5 | H71: A Rk | I71: Adv | J71: H Rk | K71: H L5 | L71: H L10 | M71: H L15 | N71: H L20 | O71: H L30 | P71: H Season | Q71: Opp stat
A72: Runs/G | B72: 4.162 | C72: 4.133 | D72: 4.1 | E72: 4.2 | F72: 3.2 | G72: 3.2 | H72: 18th | I72: ★ | J72: 21st | K72: 4.6 | L72: 5 | M72: 5.133 | N72: 5.15 | O72: 4.467 | P72: 5.105 | Q72: Opp Runs/G
A73: Hits/G | B73: 8 | C73: 7.897 | D73: 7.895 | E73: 8.714 | F73: 7.889 | G73: 8.6 | H73: 7th | I73: ★ | J73: 11th | K73: 7.4 | L73: 7.889 | M73: 8.214 | N73: 8 | O73: 7.586 | P73: 8.111 | Q73: Opp Hits/G
A74: HR/G | B74: 1.194 | C74: 1.276 | D74: 1.421 | E74: 1.571 | F74: 1.222 | G74: 1.4 | H74: 5th | J74: — | K74: — | L74: — | M74: — | N74: — | O74: — | P74: — | Q74: Opp HR/G
A75: Batter K/G | B75: 9.306 | C75: 9.241 | D75: 9.526 | E75: 8.929 | F75: 9.444 | G75: 10 | H75: 24th | J75: 10th | K75: 9.4 | L75: 8.556 | M75: 8.643 | N75: 8.316 | O75: 8 | P75: 8.056 | Q75: Opp Batter K/G
A76: 1st Inn R/G | B76: 0.278 | C76: 0.31 | D76: 0.368 | E76: 0.5 | F76: 0.111 | G76: 0.2 | H76: 22nd | J76: 10th | K76: 0.2 | L76: 0.222 | M76: 0.214 | N76: 0.158 | O76: 0.241 | P76: 0.444 | Q76: Opp 1st Inn R/G

Sheet MLB Pirates @ Phillies
A1: Pittsburgh Pirates @ Philadelphia Phillies
A2: MLB · 2026-06-29 · L5 window
A61: Pittsburgh Pirates offense vs Philadelphia Phillies defense
A62: Stat | B62: A Season | C62: A L30 | D62: A L20 | E62: A L15 | F62: A L10 | G62: A L5 | H62: A Rk | I62: Adv | J62: H Rk | K62: H L5 | L62: H L10 | M62: H L15 | N62: H L20 | O62: H L30 | P62: H Season | Q62: Opp stat
A63: Runs/G | B63: 4.767 | C63: 5.033 | D63: 4.6 | E63: 4.867 | F63: 5.1 | G63: 4.6 | H63: 12th | J63: 8th | K63: 2.8 | L63: 4.7 | M63: 5.067 | N63: 5.1 | O63: 5.633 | P63: 5.375 | Q63: Opp Runs/G
