Workbook

Sheet Read Me
A1: 🎯 Project 54.7 — Daily Wager Workbook
A2: 52.4% pays the house. 54.7% pays you.
A5: Built | B5: 2026-07-09 15:58
A7: HOW IT WORKS
A8: 1. | B8: The model's win probability for every market is locked. It does not change when odds move.
A9: 2. | B9: Type the price YOUR sportsbook is showing into the yellow “✏ Your Odds” cells (American odds, e.g. -110 or +135).
A10: 3. | B10: Implied %, Your Edge (EV), the ¼-Kelly stake and the Verdict recompute instantly — in Excel or Google Sheets, offline.
A11: 4. | B11: Set your Bankroll and Kelly fraction once on the Settings tab; every stake on every tab follows it.
A12: 5. | B12: After a game, type the closing line into the ✏ Closing column on the Games tab — CLV % shows whether you beat the close (the earliest honest sign an edge is real).
A14: READING THE VERDICT
A15: Pass | B15: Model says there's no edge at your price — skip it.
A16: Thin | B16: Positive but below your min-edge threshold.
A17: ✅ Sharp band | B17: 2–6% EV — where the model's edge has actually held up (good closing-line value). The sweet spot.
A18: Strong | B18: 6–8% EV — bigger, rarer.
A19: ⚠ Verify | B19: 8%+ EV usually means a stale or oddball price, not free money. Double-check the line before trusting it.
A21: WHY EDIT YOUR OWN ODDS?
B22: Every other tool de-vigs a sharp book for you and locks the math in an app whose lines go stale. Here the number is yours, so nothing can be out of date — and the math is in front of you.
A24: THE DEAL | B24: Personal research. Not financial advice. No bankroll promises. If gambling stops being fun, stop — call 1-800-GAMBLER.
B25: We publish our losses too — see the Track Record tab. We tell you when to pass. The trigger is always yours.

Sheet Settings
A1: ⚙ Settings
A2: Bankroll ($) | B2: 1000
A3: Kelly fraction | B3: 0.25
A4: Min edge to flag (EV) | B4: 0.02
A5: Max stake (% of bankroll) | B5: 0.05
A7: Default ¼-Kelly is deliberate: full Kelly is mathematically optimal but brutal on variance, and edges are always overestimated. Quarter-Kelly keeps ~most of the growth at a fraction of the risk.

Sheet Top Plays
A1: ⭐ Top Plays — biggest model edges today
A2: Ranked at the posted price. Swap in your book's number and watch the edge update. Nothing here is a lock.
A4: Date | B4: Matchup | C4: Start | D4: Market | E4: Selection | F4: Model Win% | G4: Model Fair | H4: ✏ Your Odds | I4: Implied% | J4: Your Edge (EV) | K4: ¼-Kelly % | L4: Stake $ | M4: Verdict | N4: Model read | O4: ✏ Closing | P4: CLV %
A5: 2026-07-09 | B5: Boston Red Sox @ Chicago White Sox | C5: 18:10 | D5: Spread | E5: Boston Red Sox +1.5 | F5: 0.6376 | G5: -176 | H5: 170 | I5: =IF($H$5="","",IF($H$5<0,-$H$5/(-$H$5+100),100/($H$5+100))) | J5: =IF($H$5="","",$F$5*IF($H$5<0,-100/$H$5,$H$5/100)-(1-$F$5)) | K5: =IF($H$5="","",MAX(0,($F$5*IF($H$5<0,-100/$H$5,$H$5/100)-(1-$F$5))/IF($H$5<0,-100/$H$5,$H$5/100))*'Settings'!$B$3) | L5: =IF($H$5="","",ROUND(MIN($K$5,'Settings'!$B$5)*'Settings'!$B$2,2)) | M5: =IF($J$5="","",IF($J$5<0,"Pass",IF($J$5<'Settings'!$B$4,"Thin",IF($J$5<0.06,"✅ Sharp band",IF($J$5<0.08,"Strong","⚠ Verify (stale?)"))))) | N5: Model 63.8% (fair -176). Your call. | P5: =IF(OR($H$5="",$O$5=""),"",(1+IF($H$5<0,-100/$H$5,$H$5/100))/(1+IF($O$5<0,-100/$O$5,$O$5/100))-1)
A6: 2026-07-09 | B6: Atlanta Braves @ Pittsburgh Pirates | C6: 16:35 | D6: Total | E6: Under 10.5 | F6: 0.5914 | G6: -145 | H6: 115 | I6: =IF($H$6="","",IF($H$6<0,-$H$6/(-$H$6+100),100/($H$6+100))) | J6: =IF($H$6="","",$F$6*IF($H$6<0,-100/$H$6,$H$6/100)-(1-$F$6)) | K6: =IF($H$6="","",MAX(0,($F$6*IF($H$6<0,-100/$H$6,$H$6/100)-(1-$F$6))/IF($H$6<0,-100/$H$6,$H$6/100))*'Settings'!$B$3) | L6: =IF($H$6="","",ROUND(MIN($K$6,'Settings'!$B$5)*'Settings'!$B$2,2)) | M6: =IF($J$6="","",IF($J$6<0,"Pass",IF($J$6<'Settings'!$B$4,"Thin",IF($J$6<0.06,"✅ Sharp band",IF($J$6<0.08,"Strong","⚠ Verify (stale?)"))))) | N6: Model 59.1% (fair -145). Your call. | P6: =IF(OR($H$6="",$O$6=""),"",(1+IF($H$6<0,-100/$H$6,$H$6/100))/(1+IF($O$6<0,-100/$O$6,$O$6/100))-1)
A7: 2026-07-09 | B7: Boston Red Sox @ Chicago White Sox | C7: 18:10 | D7: Total | E7: Under 9.5 | F7: 0.5644 | G7: -130 | H7: 120 | I7: =IF($H$7="","",IF($H$7<0,-$H$7/(-$H$7+100),100/($H$7+100))) | J7: =IF($H$7="","",$F$7*IF($H$7<0,-100/$H$7,$H$7/100)-(1-$F$7)) | K7: =IF($H$7="","",MAX(0,($F$7*IF($H$7<0,-100/$H$7,$H$7/100)-(1-$F$7))/IF($H$7<0,-100/$H$7,$H$7/100))*'Settings'!$B$3) | L7: =IF($H$7="","",ROUND(MIN($K$7,'Settings'!$B$5)*'Settings'!$B$2,2)) | M7: =IF($J$7="","",IF($J$7<0,"Pass",IF($J$7<'Settings'!$B$4,"Thin",IF($J$7<0.06,"✅ Sharp band",IF($J$7<0.08,"Strong","⚠ Verify (stale?)"))))) | N7: Model 56.4% (fair -130). Your call. | P7: =IF(OR($H$7="",$O$7=""),"",(1+IF($H$7<0,-100/$H$7,$H$7/100))/(1+IF($O$7<0,-100/$O$7,$O$7/100))-1)
A8: 2026-07-09 | B8: Seattle Storm @ Atlanta Dream | C8: 00:00 | D8: Moneyline | E8: Seattle Storm | F8: 0.2065 | G8: 384 | H8: 495 | I8: =IF($H$8="","",IF($H$8<0,-$H$8/(-$H$8+100),100/($H$8+100))) | J8: =IF($H$8="","",$F$8*IF($H$8<0,-100/$H$8,$H$8/100)-(1-$F$8)) | K8: =IF($H$8="","",MAX(0,($F$8*IF($H$8<0,-100/$H$8,$H$8/100)-(1-$F$8))/IF($H$8<0,-100/$H$8,$H$8/100))*'Settings'!$B$3) | L8: =IF($H$8="","",ROUND(MIN($K$8,'Settings'!$B$5)*'Settings'!$B$2,2)) | M8: =IF($J$8="","",IF($J$8<0,"Pass",IF($J$8<'Settings'!$B$4,"Thin",IF($J$8<0.06,"✅ Sharp band",IF($J$8<0.08,"Strong","⚠ Verify (stale?)"))))) | N8: Model 20.7% (fair +384). Your call. | P8: =IF(OR($H$8="",$O$8=""),"",(1+IF($H$8<0,-100/$H$8,$H$8/100))/(1+IF($O$8<0,-100/$O$8,$O$8/100))-1)
A9: 2026-07-09 | B9: Philadelphia Phillies @ Cincinnati Reds | C9: 23:10 | D9: Moneyline | E9: Philadelphia Phillies | F9: 0.7412 | G9: -286 | H9: -153 | I9: =IF($H$9="","",IF($H$9<0,-$H$9/(-$H$9+100),100/($H$9+100))) | J9: =IF($H$9="","",$F$9*IF($H$9<0,-100/$H$9,$H$9/100)-(1-$F$9)) | K9: =IF($H$9="","",MAX(0,($F$9*IF($H$9<0,-100/$H$9,$H$9/100)-(1-$F$9))/IF($H$9<0,-100/$H$9,$H$9/100))*'Settings'!$B$3) | L9: =IF($H$9="","",ROUND(MIN($K$9,'Settings'!$B$5)*'Settings'!$B$2,2)) | M9: =IF($J$9="","",IF($J$9<0,"Pass",IF($J$9<'Settings'!$B$4,"Thin",IF($J$9<0.06,"✅ Sharp band",IF($J$9<0.08,"Strong","⚠ Verify (stale?)"))))) | N9: Model 74.1% (fair -286). Your call. | P9: =IF(OR($H$9="",$O$9=""),"",(1+IF($H$9<0,-100/$H$9,$H$9/100))/(1+IF($O$9<0,-100/$O$9,$O$9/100))-1)
A10: 2026-07-09 | B10: Indiana Fever @ Phoenix Mercury | C10: 02:00 | D10: Total | E10: Over 171.5 | F10: 0.5771 | G10: -136 | H10: 104 | I10: =IF($H$10="","",IF($H$10<0,-$H$10/(-$H$10+100),100/($H$10+100))) | J10: =IF($H$10="","",$F$10*IF($H$10<0,-100/$H$10,$H$10/100)-(1-$F$10)) | K10: =IF($H$10="","",MAX(0,($F$10*IF($H$10<0,-100/$H$10,$H$10/100)-(1-$F$10))/IF($H$10<0,-100/$H$10,$H$10/100))*'Settings'!$B$3) | L10: =IF($H$10="","",ROUND(MIN($K$10,'Settings'!$B$5)*'Settings'!$B$2,2)) | M10: =IF($J$10="","",IF($J$10<0,"Pass",IF($J$10<'Settings'!$B$4,"Thin",IF($J$10<0.06,"✅ Sharp band",IF($J$10<0.08,"Strong","⚠ Verify (stale?)"))))) | N10: Model 57.7% (fair -136). Your call. | P10: =IF(OR($H$10="",$O$10=""),"",(1+IF($H$10<0,-100/$H$10,$H$10/100))/(1+IF($O$10<0,-100/$O$10,$O$10/100))-1)
A11: 2026-07-09 | B11: Indiana Fever @ Phoenix Mercury | C11: 02:00 | D11: Moneyline | E11: Indiana Fever | F11: 0.5663 | G11: -131 | H11: 104 | I11: =IF($H$11="","",IF($H$11<0,-$H$11/(-$H$11+100),100/($H$11+100))) | J11: =IF($H$11="","",$F$11*IF($H$11<0,-100/$H$11,$H$11/100)-(1-$F$11)) | K11: =IF($H$11="","",MAX(0,($F$11*IF($H$11<0,-100/$H$11,$H$11/100)-(1-$F$11))/IF($H$11<0,-100/$H$11,$H$11/100))*'Settings'!$B$3) | L11: =IF($H$11="","",ROUND(MIN($K$11,'Settings'!$B$5)*'Settings'!$B$2,2)) | M11: =IF($J$11="","",IF($J$11<0,"Pass",IF($J$11<'Settings'!$B$4,"Thin",IF($J$11<0.06,"✅ Sharp band",IF($J$11<0.08,"Strong","⚠ Verify (stale?)"))))) | N11: Model 56.6% (fair -131). Your call. | P11: =IF(OR($H$11="",$O$11=""),"",(1+IF($H$11<0,-100/$H$11,$H$11/100))/(1+IF($O$11<0,-100/$O$11,$O$11/100))-1)
A12: 2026-07-10 | B12: Golden State Valkyries @ Connecticut Sun | C12: 23:30 | D12: Total | E12: Over 154.5 | F12: 0.5767 | G12: -136 | H12: 100 | I12: =IF($H$12="","",IF($H$12<0,-$H$12/(-$H$12+100),100/($H$12+100))) | J12: =IF($H$12="","",$F$12*IF($H$12<0,-100/$H$12,$H$12/100)-(1-$F$12)) | K12: =IF($H$12="","",MAX(0,($F$12*IF($H$12<0,-100/$H$12,$H$12/100)-(1-$F$12))/IF($H$12<0,-100/$H$12,$H$12/100))*'Settings'!$B$3) | L12: =IF($H$12="","",ROUND(MIN($K$12,'Settings'!$B$5)*'Settings'!$B$2,2)) | M12: =IF($J$12="","",IF($J$12<0,"Pass",IF($J$12<'Settings'!$B$4,"Thin",IF($J$12<0.06,"✅ Sharp band",IF($J$12<0.08,"Strong","⚠ Verify (stale?)"))))) | N12: Model 57.7% (fair -136). Your call. | P12: =IF(OR($H$12="",$O$12=""),"",(1+IF($H$12<0,-100/$H$12,$H$12/100))/(1+IF($O$12<0,-100/$O$12,$O$12/100))-1)
A13: 2026-07-10 | B13: Atlanta Braves @ St. Louis Cardinals | C13: 00:15 | D13: Total | E13: Under 8.5 | F13: 0.5575 | G13: -126 | H13: 105 | I13: =IF($H$13="","",IF($H$13<0,-$H$13/(-$H$13+100),100/($H$13+100))) | J13: =IF($H$13="","",$F$13*IF($H$13<0,-100/$H$13,$H$13/100)-(1-$F$13)) | K13: =IF($H$13="","",MAX(0,($F$13*IF($H$13<0,-100/$H$13,$H$13/100)-(1-$F$13))/IF($H$13<0,-100/$H$13,$H$13/100))*'Settings'!$B$3) | L13: =IF($H$13="","",ROUND(MIN($K$13,'Settings'!$B$5)*'Settings'!$B$2,2)) | M13: =IF($J$13="","",IF($J$13<0,"Pass",IF($J$13<'Settings'!$B$4,"Thin",IF($J$13<0.06,"✅ Sharp band",IF($J$13<0.08,"Strong","⚠ Verify (stale?)"))))) | N13: Model 55.8% (fair -126). Your call. | P13: =IF(OR($H$13="",$O$13=""),"",(1+IF($H$13<0,-100/$H$13,$H$13/100))/(1+IF($O$13<0,-100/$O$13,$O$13/100))-1)
A14: 2026-07-09 | B14: Seattle Mariners @ Miami Marlins | C14: 22:40 | D14: Total | E14: Over 8.5 | F14: 0.5288 | G14: -112 | H14: 115 | I14: =IF($H$14="","",IF($H$14<0,-$H$14/(-$H$14+100),100/($H$14+100))) | J14: =IF($H$14="","",$F$14*IF($H$14<0,-100/$H$14,$H$14/100)-(1-$F$14)) | K14: =IF($H$14="","",MAX(0,($F$14*IF($H$14<0,-100/$H$14,$H$14/100)-(1-$F$14))/IF($H$14<0,-100/$H$14,$H$14/100))*'Settings'!$B$3) | L14: =IF($H$14="","",ROUND(MIN($K$14,'Settings'!$B$5)*'Settings'!$B$2,2)) | M14: =IF($J$14="","",IF($J$14<0,"Pass",IF($J$14<'Settings'!$B$4,"Thin",IF($J$14<0.06,"✅ Sharp band",IF($J$14<0.08,"Strong","⚠ Verify (stale?)"))))) | N14: Model 52.9% (fair -112). Your call. | P14: =IF(OR($H$14="",$O$14=""),"",(1+IF($H$14<0,-100/$H$14,$H$14/100))/(1+IF($O$14<0,-100/$O$14,$O$14/100))-1)
A15: 2026-07-10 | B15: New York Yankees @ Washington Nationals | C15: 22:45 | D15: Moneyline | E15: Washington Nationals | F15: 0.4771 | G15: 110 | H15: 136 | I15: =IF($H$15="","",IF($H$15<0,-$H$15/(-$H$15+100),100/($H$15+100))) | J15: =IF($H$15="","",$F$15*IF($H$15<0,-100/$H$15,$H$15/100)-(1-$F$15)) | K15: =IF($H$15="","",MAX(0,($F$15*IF($H$15<0,-100/$H$15,$H$15/100)-(1-$F$15))/IF($H$15<0,-100/$H$15,$H$15/100))*'Settings'!$B$3) | L15: =IF($H$15="","",ROUND(MIN($K$15,'Settings'!$B$5)*'Settings'!$B$2,2)) | M15: =IF($J$15="","",IF($J$15<0,"Pass",IF($J$15<'Settings'!$B$4,"Thin",IF($J$15<0.06,"✅ Sharp band",IF($J$15<0.08,"Strong","⚠ Verify (stale?)"))))) | N15: Model 47.7% (fair +110). Your call. | P15: =IF(OR($H$15="",$O$15=""),"",(1+IF($H$15<0,-100/$H$15,$H$15/100))/(1+IF($O$15<0,-100/$O$15,$O$15/100))-1)
A16: 2026-07-10 | B16: Kansas City Royals @ Baltimore Orioles | C16: 23:05 | D16: Total | E16: Under 10.5 | F16: 0.5616 | G16: -128 | H16: 100 | I16: =IF($H$16="","",IF($H$16<0,-$H$16/(-$H$16+100),100/($H$16+100))) | J16: =IF($H$16="","",$F$16*IF($H$16<0,-100/$H$16,$H$16/100)-(1-$F$16)) | K16: =IF($H$16="","",MAX(0,($F$16*IF($H$16<0,-100/$H$16,$H$16/100)-(1-$F$16))/IF($H$16<0,-100/$H$16,$H$16/100))*'Settings'!$B$3) | L16: =IF($H$16="","",ROUND(MIN($K$16,'Settings'!$B$5)*'Settings'!$B$2,2)) | M16: =IF($J$16="","",IF($J$16<0,"Pass",IF($J$16<'Settings'!$B$4,"Thin",IF($J$16<0.06,"✅ Sharp band",IF($J$16<0.08,"Strong","⚠ Verify (stale?)"))))) | N16: Model 56.2% (fair -128). Your call. | P16: =IF(OR($H$16="",$O$16=""),"",(1+IF($H$16<0,-100/$H$16,$H$16/100))/(1+IF($O$16<0,-100/$O$16,$O$16/100))-1)
A17: 2026-07-09 | B17: Indiana Fever @ Phoenix Mercury | C17: 02:00 | D17: Spread | E17: Indiana Fever +1.5 | F17: 0.5604 | G17: -127 | H17: 100 | I17: =IF($H$17="","",IF($H$17<0,-$H$17/(-$H$17+100),100/($H$17+100))) | J17: =IF($H$17="","",$F$17*IF($H$17<0,-100/$H$17,$H$17/100)-(1-$F$17)) | K17: =IF($H$17="","",MAX(0,($F$17*IF($H$17<0,-100/$H$17,$H$17/100)-(1-$F$17))/IF($H$17<0,-100/$H$17,$H$17/100))*'Settings'!$B$3) | L17: =IF($H$17="","",ROUND(MIN($K$17,'Settings'!$B$5)*'Settings'!$B$2,2)) | M17: =IF($J$17="","",IF($J$17<0,"Pass",IF($J$17<'Settings'!$B$4,"Thin",IF($J$17<0.06,"✅ Sharp band",IF($J$17<0.08,"Strong","⚠ Verify (stale?)"))))) | N17: Model 56.0% (fair -127). Your call. | P17: =IF(OR($H$17="",$O$17=""),"",(1+IF($H$17<0,-100/$H$17,$H$17/100))/(1+IF($O$17<0,-100/$O$17,$O$17/100))-1)
A18: 2026-07-09 | B18: Las Vegas Aces @ Portland Fire | C18: 02:00 | D18: Total | E18: Over 174.5 | F18: 0.5476 | G18: -121 | H18: 104 | I18: =IF($H$18="","",IF($H$18<0,-$H$18/(-$H$18+100),100/($H$18+100))) | J18: =IF($H$18="","",$F$18*IF($H$18<0,-100/$H$18,$H$18/100)-(1-$F$18)) | K18: =IF($H$18="","",MAX(0,($F$18*IF($H$18<0,-100/$H$18,$H$18/100)-(1-$F$18))/IF($H$18<0,-100/$H$18,$H$18/100))*'Settings'!$B$3) | L18: =IF($H$18="","",ROUND(MIN($K$18,'Settings'!$B$5)*'Settings'!$B$2,2)) | M18: =IF($J$18="","",IF($J$18<0,"Pass",IF($J$18<'Settings'!$B$4,"Thin",IF($J$18<0.06,"✅ Sharp band",IF($J$18<0.08,"Strong","⚠ Verify (stale?)"))))) | N18: Model 54.8% (fair -121). Your call. | P18: =IF(OR($H$18="",$O$18=""),"",(1+IF($H$18<0,-100/$H$18,$H$18/100))/(1+IF($O$18<0,-100/$O$18,$O$18/100))-1)
A19: 2026-07-09 | B19: Kansas City Royals @ New York Mets | C19: 17:10 | D19: Total | E19: Under 9.5 | F19: 0.542 | G19: -118 | H19: 106 | I19: =IF($H$19="","",IF($H$19<0,-$H$19/(-$H$19+100),100/($H$19+100))) | J19: =IF($H$19="","",$F$19*IF($H$19<0,-100/$H$19,$H$19/100)-(1-$F$19)) | K19: =IF($H$19="","",MAX(0,($F$19*IF($H$19<0,-100/$H$19,$H$19/100)-(1-$F$19))/IF($H$19<0,-100/$H$19,$H$19/100))*'Settings'!$B$3) | L19: =IF($H$19="","",ROUND(MIN($K$19,'Settings'!$B$5)*'Settings'!$B$2,2)) | M19: =IF($J$19="","",IF($J$19<0,"Pass",IF($J$19<'Settings'!$B$4,"Thin",IF($J$19<0.06,"✅ Sharp band",IF($J$19<0.08,"Strong","⚠ Verify (stale?)"))))) | N19: Model 54.2% (fair -118). Your call. | P19: =IF(OR($H$19="",$O$19=""),"",(1+IF($H$19<0,-100/$H$19,$H$19/100))/(1+IF($O$19<0,-100/$O$19,$O$19/100))-1)
A20: 2026-07-09 | B20: Athletics @ Detroit Tigers | C20: 22:40 | D20: Total | E20: Under 9.5 | F20: 0.5182 | G20: -108 | H20: 113 | I20: =IF($H$20="","",IF($H$20<0,-$H$20/(-$H$20+100),100/($H$20+100))) | J20: =IF($H$20="","",$F$20*IF($H$20<0,-100/$H$20,$H$20/100)-(1-$F$20)) | K20: =IF($H$20="","",MAX(0,($F$20*IF($H$20<0,-100/$H$20,$H$20/100)-(1-$F$20))/IF($H$20<0,-100/$H$20,$H$20/100))*'Settings'!$B$3) | L20: =IF($H$20="","",ROUND(MIN($K$20,'Settings'!$B$5)*'Settings'!$B$2,2)) | M20: =IF($J$20="","",IF($J$20<0,"Pass",IF($J$20<'Settings'!$B$4,"Thin",IF($J$20<0.06,"✅ Sharp band",IF($J$20<0.08,"Strong","⚠ Verify (stale?)"))))) | N20: Model 51.8% (fair -108). Your call. | P20: =IF(OR($H$20="",$O$20=""),"",(1+IF($H$20<0,-100/$H$20,$H$20/100))/(1+IF($O$20<0,-100/$O$20,$O$20/100))-1)
A21: 2026-07-10 | B21: Dallas Wings @ Toronto Tempo | C21: 23:30 | D21: Moneyline | E21: Toronto Tempo | F21: 0.2999 | G21: 233 | H21: 264 | I21: =IF($H$21="","",IF($H$21<0,-$H$21/(-$H$21+100),100/($H$21+100))) | J21: =IF($H$21="","",$F$21*IF($H$21<0,-100/$H$21,$H$21/100)-(1-$F$21)) | K21: =IF($H$21="","",MAX(0,($F$21*IF($H$21<0,-100/$H$21,$H$21/100)-(1-$F$21))/IF($H$21<0,-100/$H$21,$H$21/100))*'Settings'!$B$3) | L21: =IF($H$21="","",ROUND(MIN($K$21,'Settings'!$B$5)*'Settings'!$B$2,2)) | M21: =IF($J$21="","",IF($J$21<0,"Pass",IF($J$21<'Settings'!$B$4,"Thin",IF($J$21<0.06,"✅ Sharp band",IF($J$21<0.08,"Strong","⚠ Verify (stale?)"))))) | N21: Model 30.0% (fair +233). Your call. | P21: =IF(OR($H$21="",$O$21=""),"",(1+IF($H$21<0,-100/$H$21,$H$21/100))/(1+IF($O$21<0,-100/$O$21,$O$21/100))-1)
A22: 2026-07-10 | B22: Houston Astros @ Texas Rangers | C22: 00:05 | D22: Moneyline | E22: Texas Rangers | F22: 0.4894 | G22: 104 | H22: 122 | I22: =IF($H$22="","",IF($H$22<0,-$H$22/(-$H$22+100),100/($H$22+100))) | J22: =IF($H$22="","",$F$22*IF($H$22<0,-100/$H$22,$H$22/100)-(1-$F$22)) | K22: =IF($H$22="","",MAX(0,($F$22*IF($H$22<0,-100/$H$22,$H$22/100)-(1-$F$22))/IF($H$22<0,-100/$H$22,$H$22/100))*'Settings'!$B$3) | L22: =IF($H$22="","",ROUND(MIN($K$22,'Settings'!$B$5)*'Settings'!$B$2,2)) | M22: =IF($J$22="","",IF($J$22<0,"Pass",IF($J$22<'Settings'!$B$4,"Thin",IF($J$22<0.06,"✅ Sharp band",IF($J$22<0.08,"Strong","⚠ Verify (stale?)"))))) | N22: Model 48.9% (fair +104). Your call. | P22: =IF(OR($H$22="",$O$22=""),"",(1+IF($H$22<0,-100/$H$22,$H$22/100))/(1+IF($O$22<0,-100/$O$22,$O$22/100))-1)
A23: 2026-07-10 | B23: Chicago Sky @ Los Angeles Sparks | C23: 02:00 | D23: Moneyline | E23: Los Angeles Sparks | F23: 0.5529 | G23: -124 | H23: -104 | I23: =IF($H$23="","",IF($H$23<0,-$H$23/(-$H$23+100),100/($H$23+100))) | J23: =IF($H$23="","",$F$23*IF($H$23<0,-100/$H$23,$H$23/100)-(1-$F$23)) | K23: =IF($H$23="","",MAX(0,($F$23*IF($H$23<0,-100/$H$23,$H$23/100)-(1-$F$23))/IF($H$23<0,-100/$H$23,$H$23/100))*'Settings'!$B$3) | L23: =IF($H$23="","",ROUND(MIN($K$23,'Settings'!$B$5)*'Settings'!$B$2,2)) | M23: =IF($J$23="","",IF($J$23<0,"Pass",IF($J$23<'Settings'!$B$4,"Thin",IF($J$23<0.06,"✅ Sharp band",IF($J$23<0.08,"Strong","⚠ Verify (stale?)"))))) | N23: Model 55.3% (fair -124). Your call. | P23: =IF(OR($H$23="",$O$23=""),"",(1+IF($H$23<0,-100/$H$23,$H$23/100))/(1+IF($O$23<0,-100/$O$23,$O$23/100))-1)
A24: 2026-07-10 | B24: Dallas Wings @ Toronto Tempo | C24: 23:30 | D24: Spread | E24: Toronto Tempo +6.5 | F24: 0.5522 | G24: -123 | H24: -104 | I24: =IF($H$24="","",IF($H$24<0,-$H$24/(-$H$24+100),100/($H$24+100))) | J24: =IF($H$24="","",$F$24*IF($H$24<0,-100/$H$24,$H$24/100)-(1-$F$24)) | K24: =IF($H$24="","",MAX(0,($F$24*IF($H$24<0,-100/$H$24,$H$24/100)-(1-$F$24))/IF($H$24<0,-100/$H$24,$H$24/100))*'Settings'!$B$3) | L24: =IF($H$24="","",ROUND(MIN($K$24,'Settings'!$B$5)*'Settings'!$B$2,2)) | M24: =IF($J$24="","",IF($J$24<0,"Pass",IF($J$24<'Settings'!$B$4,"Thin",IF($J$24<0.06,"✅ Sharp band",IF($J$24<0.08,"Strong","⚠ Verify (stale?)"))))) | N24: Model 55.2% (fair -123). Your call. | P24: =IF(OR($H$24="",$O$24=""),"",(1+IF($H$24<0,-100/$H$24,$H$24/100))/(1+IF($O$24<0,-100/$O$24,$O$24/100))-1)
A25: 2026-07-09 | B25: Cleveland Guardians @ Minnesota Twins | C25: 17:40 | D25: Moneyline | E25: Minnesota Twins | F25: 0.5009 | G25: -100 | H25: 115 | I25: =IF($H$25="","",IF($H$25<0,-$H$25/(-$H$25+100),100/($H$25+100))) | J25: =IF($H$25="","",$F$25*IF($H$25<0,-100/$H$25,$H$25/100)-(1-$F$25)) | K25: =IF($H$25="","",MAX(0,($F$25*IF($H$25<0,-100/$H$25,$H$25/100)-(1-$F$25))/IF($H$25<0,-100/$H$25,$H$25/100))*'Settings'!$B$3) | L25: =IF($H$25="","",ROUND(MIN($K$25,'Settings'!$B$5)*'Settings'!$B$2,2)) | M25: =IF($J$25="","",IF($J$25<0,"Pass",IF($J$25<'Settings'!$B$4,"Thin",IF($J$25<0.06,"✅ Sharp band",IF($J$25<0.08,"Strong","⚠ Verify (stale?)"))))) | N25: Model 50.1% (fair -100). Your call. | P25: =IF(OR($H$25="",$O$25=""),"",(1+IF($H$25<0,-100/$H$25,$H$25/100))/(1+IF($O$25<0,-100/$O$25,$O$25/100))-1)
A26: 2026-07-09 | B26: Milwaukee Brewers @ St. Louis Cardinals | C26: 23:45 | D26: Moneyline | E26: St. Louis Cardinals | F26: 0.4764 | G26: 110 | H26: 125 | I26: =IF($H$26="","",IF($H$26<0,-$H$26/(-$H$26+100),100/($H$26+100))) | J26: =IF($H$26="","",$F$26*IF($H$26<0,-100/$H$26,$H$26/100)-(1-$F$26)) | K26: =IF($H$26="","",MAX(0,($F$26*IF($H$26<0,-100/$H$26,$H$26/100)-(1-$F$26))/IF($H$26<0,-100/$H$26,$H$26/100))*'Settings'!$B$3) | L26: =IF($H$26="","",ROUND(MIN($K$26,'Settings'!$B$5)*'Settings'!$B$2,2)) | M26: =IF($J$26="","",IF($J$26<0,"Pass",IF($J$26<'Settings'!$B$4,"Thin",IF($J$26<0.06,"✅ Sharp band",IF($J$26<0.08,"Strong","⚠ Verify (stale?)"))))) | N26: Model 47.6% (fair +110). Your call. | P26: =IF(OR($H$26="",$O$26=""),"",(1+IF($H$26<0,-100/$H$26,$H$26/100))/(1+IF($O$26<0,-100/$O$26,$O$26/100))-1)
A27: 2026-07-10 | B27: Chicago Cubs @ Cincinnati Reds | C27: 23:10 | D27: Total | E27: Over 9.5 | F27: 0.5151 | G27: -106 | H27: 108 | I27: =IF($H$27="","",IF($H$27<0,-$H$27/(-$H$27+100),100/($H$27+100))) | J27: =IF($H$27="","",$F$27*IF($H$27<0,-100/$H$27,$H$27/100)-(1-$F$27)) | K27: =IF($H$27="","",MAX(0,($F$27*IF($H$27<0,-100/$H$27,$H$27/100)-(1-$F$27))/IF($H$27<0,-100/$H$27,$H$27/100))*'Settings'!$B$3) | L27: =IF($H$27="","",ROUND(MIN($K$27,'Settings'!$B$5)*'Settings'!$B$2,2)) | M27: =IF($J$27="","",IF($J$27<0,"Pass",IF($J$27<'Settings'!$B$4,"Thin",IF($J$27<0.06,"✅ Sharp band",IF($J$27<0.08,"Strong","⚠ Verify (stale?)"))))) | N27: Model 51.5% (fair -106). Your call. | P27: =IF(OR($H$27="",$O$27=""),"",(1+IF($H$27<0,-100/$H$27,$H$27/100))/(1+IF($O$27<0,-100/$O$27,$O$27/100))-1)
A28: 2026-07-09 | B28: Athletics @ Detroit Tigers | C28: 22:40 | D28: Total | E28: Over 9.5 | F28: 0.4818 | G28: 108 | H28: 122 | I28: =IF($H$28="","",IF($H$28<0,-$H$28/(-$H$28+100),100/($H$28+100))) | J28: =IF($H$28="","",$F$28*IF($H$28<0,-100/$H$28,$H$28/100)-(1-$F$28)) | K28: =IF($H$28="","",MAX(0,($F$28*IF($H$28<0,-100/$H$28,$H$28/100)-(1-$F$28))/IF($H$28<0,-100/$H$28,$H$28/100))*'Settings'!$B$3) | L28: =IF($H$28="","",ROUND(MIN($K$28,'Settings'!$B$5)*'Settings'!$B$2,2)) | M28: =IF($J$28="","",IF($J$28<0,"Pass",IF($J$28<'Settings'!$B$4,"Thin",IF($J$28<0.06,"✅ Sharp band",IF($J$28<0.08,"Strong","⚠ Verify (stale?)"))))) | N28: Model 48.2% (fair +108). Your call. | P28: =IF(OR($H$28="",$O$28=""),"",(1+IF($H$28<0,-100/$H$28,$H$28/100))/(1+IF($O$28<0,-100/$O$28,$O$28/100))-1)
A29: 2026-07-09 | B29: Seattle Storm @ Atlanta Dream | C29: 00:00 | D29: Total | E29: Over 168.5 | F29: 0.5395 | G29: -117 | H29: -102 | I29: =IF($H$29="","",IF($H$29<0,-$H$29/(-$H$29+100),100/($H$29+100))) | J29: =IF($H$29="","",$F$29*IF($H$29<0,-100/$H$29,$H$29/100)-(1-$F$29)) | K29: =IF($H$29="","",MAX(0,($F$29*IF($H$29<0,-100/$H$29,$H$29/100)-(1-$F$29))/IF($H$29<0,-100/$H$29,$H$29/100))*'Settings'!$B$3) | L29: =IF($H$29="","",ROUND(MIN($K$29,'Settings'!$B$5)*'Settings'!$B$2,2)) | M29: =IF($J$29="","",IF($J$29<0,"Pass",IF($J$29<'Settings'!$B$4,"Thin",IF($J$29<0.06,"✅ Sharp band",IF($J$29<0.08,"Strong","⚠ Verify (stale?)"))))) | N29: Model 53.9% (fair -117). Your call. | P29: =IF(OR($H$29="",$O$29=""),"",(1+IF($H$29<0,-100/$H$29,$H$29/100))/(1+IF($O$29<0,-100/$O$29,$O$29/100))-1)

Sheet MLB Games
A1: MLB — game markets
A2: Moneyline · Total · Spread. Yellow = your price.
A4: Date | B4: Matchup | C4: Start | D4: Market | E4: Selection | F4: Model Win% | G4: Model Fair | H4: ✏ Your Odds | I4: Implied% | J4: Your Edge (EV) | K4: ¼-Kelly % | L4: Stake $ | M4: Verdict | N4: Model read | O4: ✏ Closing | P4: CLV %
A5: 2026-07-09 | B5: Atlanta Braves @ Pittsburgh Pirates | C5: 16:35 | D5: Moneyline | E5: Atlanta Braves | F5: 0.4735 | G5: 111 | H5: -102 | I5: =IF($H$5="","",IF($H$5<0,-$H$5/(-$H$5+100),100/($H$5+100))) | J5: =IF($H$5="","",$F$5*IF($H$5<0,-100/$H$5,$H$5/100)-(1-$F$5)) | K5: =IF($H$5="","",MAX(0,($F$5*IF($H$5<0,-100/$H$5,$H$5/100)-(1-$F$5))/IF($H$5<0,-100/$H$5,$H$5/100))*'Settings'!$B$3) | L5: =IF($H$5="","",ROUND(MIN($K$5,'Settings'!$B$5)*'Settings'!$B$2,2)) | M5: =IF($J$5="","",IF($J$5<0,"Pass",IF($J$5<'Settings'!$B$4,"Thin",IF($J$5<0.06,"✅ Sharp band",IF($J$5<0.08,"Strong","⚠ Verify (stale?)"))))) | N5: Model 47.4% (fair +111). Your call. | P5: =IF(OR($H$5="",$O$5=""),"",(1+IF($H$5<0,-100/$H$5,$H$5/100))/(1+IF($O$5<0,-100/$O$5,$O$5/100))-1)
A6: 2026-07-09 | B6: Atlanta Braves @ Pittsburgh Pirates | C6: 16:35 | D6: Moneyline | E6: Pittsburgh Pirates | F6: 0.5265 | G6: -111 | H6: 100 | I6: =IF($H$6="","",IF($H$6<0,-$H$6/(-$H$6+100),100/($H$6+100))) | J6: =IF($H$6="","",$F$6*IF($H$6<0,-100/$H$6,$H$6/100)-(1-$F$6)) | K6: =IF($H$6="","",MAX(0,($F$6*IF($H$6<0,-100/$H$6,$H$6/100)-(1-$F$6))/IF($H$6<0,-100/$H$6,$H$6/100))*'Settings'!$B$3) | L6: =IF($H$6="","",ROUND(MIN($K$6,'Settings'!$B$5)*'Settings'!$B$2,2)) | M6: =IF($J$6="","",IF($J$6<0,"Pass",IF($J$6<'Settings'!$B$4,"Thin",IF($J$6<0.06,"✅ Sharp band",IF($J$6<0.08,"Strong","⚠ Verify (stale?)"))))) | N6: Model 52.6% (fair -111). Your call. | P6: =IF(OR($H$6="",$O$6=""),"",(1+IF($H$6<0,-100/$H$6,$H$6/100))/(1+IF($O$6<0,-100/$O$6,$O$6/100))-1)
A7: 2026-07-09 | B7: Atlanta Braves @ Pittsburgh Pirates | C7: 16:35 | D7: Total | E7: Over 10.5 | F7: 0.4086 | G7: 145 | H7: 113 | I7: =IF($H$7="","",IF($H$7<0,-$H$7/(-$H$7+100),100/($H$7+100))) | J7: =IF($H$7="","",$F$7*IF($H$7<0,-100/$H$7,$H$7/100)-(1-$F$7)) | K7: =IF($H$7="","",MAX(0,($F$7*IF($H$7<0,-100/$H$7,$H$7/100)-(1-$F$7))/IF($H$7<0,-100/$H$7,$H$7/100))*'Settings'!$B$3) | L7: =IF($H$7="","",ROUND(MIN($K$7,'Settings'!$B$5)*'Settings'!$B$2,2)) | M7: =IF($J$7="","",IF($J$7<0,"Pass",IF($J$7<'Settings'!$B$4,"Thin",IF($J$7<0.06,"✅ Sharp band",IF($J$7<0.08,"Strong","⚠ Verify (stale?)"))))) | N7: Model 40.9% (fair +145). Your call. | P7: =IF(OR($H$7="",$O$7=""),"",(1+IF($H$7<0,-100/$H$7,$H$7/100))/(1+IF($O$7<0,-100/$O$7,$O$7/100))-1)
A8: 2026-07-09 | B8: Atlanta Braves @ Pittsburgh Pirates | C8: 16:35 | D8: Total | E8: Under 10.5 | F8: 0.5914 | G8: -145 | H8: 115 | I8: =IF($H$8="","",IF($H$8<0,-$H$8/(-$H$8+100),100/($H$8+100))) | J8: =IF($H$8="","",$F$8*IF($H$8<0,-100/$H$8,$H$8/100)-(1-$F$8)) | K8: =IF($H$8="","",MAX(0,($F$8*IF($H$8<0,-100/$H$8,$H$8/100)-(1-$F$8))/IF($H$8<0,-100/$H$8,$H$8/100))*'Settings'!$B$3) | L8: =IF($H$8="","",ROUND(MIN($K$8,'Settings'!$B$5)*'Settings'!$B$2,2)) | M8: =IF($J$8="","",IF($J$8<0,"Pass",IF($J$8<'Settings'!$B$4,"Thin",IF($J$8<0.06,"✅ Sharp band",IF($J$8<0.08,"Strong","⚠ Verify (stale?)"))))) | N8: Model 59.1% (fair -145). Your call. | P8: =IF(OR($H$8="",$O$8=""),"",(1+IF($H$8<0,-100/$H$8,$H$8/100))/(1+IF($O$8<0,-100/$O$8,$O$8/100))-1)
A9: 2026-07-09 | B9: Atlanta Braves @ Pittsburgh Pirates | C9: 16:35 | D9: Spread | E9: Pittsburgh Pirates +1.5 | F9: 0.6147 | G9: -160 | H9: -144 | I9: =IF($H$9="","",IF($H$9<0,-$H$9/(-$H$9+100),100/($H$9+100))) | J9: =IF($H$9="","",$F$9*IF($H$9<0,-100/$H$9,$H$9/100)-(1-$F$9)) | K9: =IF($H$9="","",MAX(0,($F$9*IF($H$9<0,-100/$H$9,$H$9/100)-(1-$F$9))/IF($H$9<0,-100/$H$9,$H$9/100))*'Settings'!$B$3) | L9: =IF($H$9="","",ROUND(MIN($K$9,'Settings'!$B$5)*'Settings'!$B$2,2)) | M9: =IF($J$9="","",IF($J$9<0,"Pass",IF($J$9<'Settings'!$B$4,"Thin",IF($J$9<0.06,"✅ Sharp band",IF($J$9<0.08,"Strong","⚠ Verify (stale?)"))))) | N9: Model 61.5% (fair -160). Your call. | P9: =IF(OR($H$9="",$O$9=""),"",(1+IF($H$9<0,-100/$H$9,$H$9/100))/(1+IF($O$9<0,-100/$O$9,$O$9/100))-1)
A10: 2026-07-09 | B10: Atlanta Braves @ Pittsburgh Pirates | C10: 16:35 | D10: Spread | E10: Atlanta Braves -1.5 | F10: 0.3853 | G10: 160 | H10: 144 | I10: =IF($H$10="","",IF($H$10<0,-$H$10/(-$H$10+100),100/($H$10+100))) | J10: =IF($H$10="","",$F$10*IF($H$10<0,-100/$H$10,$H$10/100)-(1-$F$10)) | K10: =IF($H$10="","",MAX(0,($F$10*IF($H$10<0,-100/$H$10,$H$10/100)-(1-$F$10))/IF($H$10<0,-100/$H$10,$H$10/100))*'Settings'!$B$3) | L10: =IF($H$10="","",ROUND(MIN($K$10,'Settings'!$B$5)*'Settings'!$B$2,2)) | M10: =IF($J$10="","",IF($J$10<0,"Pass",IF($J$10<'Settings'!$B$4,"Thin",IF($J$10<0.06,"✅ Sharp band",IF($J$10<0.08,"Strong","⚠ Verify (stale?)"))))) | N10: Model 38.5% (fair +160). Your call. | P10: =IF(OR($H$10="",$O$10=""),"",(1+IF($H$10<0,-100/$H$10,$H$10/100))/(1+IF($O$10<0,-100/$O$10,$O$10/100))-1)
A11: 2026-07-09 | B11: Kansas City Royals @ New York Mets | C11: 17:10 | D11: Moneyline | E11: Kansas City Royals | F11: 0.4343 | G11: 130 | H11: 127 | I11: =IF($H$11="","",IF($H$11<0,-$H$11/(-$H$11+100),100/($H$11+100))) | J11: =IF($H$11="","",$F$11*IF($H$11<0,-100/$H$11,$H$11/100)-(1-$F$11)) | K11: =IF($H$11="","",MAX(0,($F$11*IF($H$11<0,-100/$H$11,$H$11/100)-(1-$F$11))/IF($H$11<0,-100/$H$11,$H$11/100))*'Settings'!$B$3) | L11: =IF($H$11="","",ROUND(MIN($K$11,'Settings'!$B$5)*'Settings'!$B$2,2)) | M11: =IF($J$11="","",IF($J$11<0,"Pass",IF($J$11<'Settings'!$B$4,"Thin",IF($J$11<0.06,"✅ Sharp band",IF($J$11<0.08,"Strong","⚠ Verify (stale?)"))))) | N11: Model 43.4% (fair +130). Your call. | P11: =IF(OR($H$11="",$O$11=""),"",(1+IF($H$11<0,-100/$H$11,$H$11/100))/(1+IF($O$11<0,-100/$O$11,$O$11/100))-1)
A12: 2026-07-09 | B12: Kansas City Royals @ New York Mets | C12: 17:10 | D12: Moneyline | E12: New York Mets | F12: 0.5657 | G12: -130 | H12: -127 | I12: =IF($H$12="","",IF($H$12<0,-$H$12/(-$H$12+100),100/($H$12+100))) | J12: =IF($H$12="","",$F$12*IF($H$12<0,-100/$H$12,$H$12/100)-(1-$F$12)) | K12: =IF($H$12="","",MAX(0,($F$12*IF($H$12<0,-100/$H$12,$H$12/100)-(1-$F$12))/IF($H$12<0,-100/$H$12,$H$12/100))*'Settings'!$B$3) | L12: =IF($H$12="","",ROUND(MIN($K$12,'Settings'!$B$5)*'Settings'!$B$2,2)) | M12: =IF($J$12="","",IF($J$12<0,"Pass",IF($J$12<'Settings'!$B$4,"Thin",IF($J$12<0.06,"✅ Sharp band",IF($J$12<0.08,"Strong","⚠ Verify (stale?)"))))) | N12: Model 56.6% (fair -130). Your call. | P12: =IF(OR($H$12="",$O$12=""),"",(1+IF($H$12<0,-100/$H$12,$H$12/100))/(1+IF($O$12<0,-100/$O$12,$O$12/100))-1)
A13: 2026-07-09 | B13: Kansas City Royals @ New York Mets | C13: 17:10 | D13: Total | E13: Over 9.5 | F13: 0.458 | G13: 118 | H13: 113 | I13: =IF($H$13="","",IF($H$13<0,-$H$13/(-$H$13+100),100/($H$13+100))) | J13: =IF($H$13="","",$F$13*IF($H$13<0,-100/$H$13,$H$13/100)-(1-$F$13)) | K13: =IF($H$13="","",MAX(0,($F$13*IF($H$13<0,-100/$H$13,$H$13/100)-(1-$F$13))/IF($H$13<0,-100/$H$13,$H$13/100))*'Settings'!$B$3) | L13: =IF($H$13="","",ROUND(MIN($K$13,'Settings'!$B$5)*'Settings'!$B$2,2)) | M13: =IF($J$13="","",IF($J$13<0,"Pass",IF($J$13<'Settings'!$B$4,"Thin",IF($J$13<0.06,"✅ Sharp band",IF($J$13<0.08,"Strong","⚠ Verify (stale?)"))))) | N13: Model 45.8% (fair +118). Your call. | P13: =IF(OR($H$13="",$O$13=""),"",(1+IF($H$13<0,-100/$H$13,$H$13/100))/(1+IF($O$13<0,-100/$O$13,$O$13/100))-1)
A14: 2026-07-09 | B14: Kansas City Royals @ New York Mets | C14: 17:10 | D14: Total | E14: Under 9.5 | F14: 0.542 | G14: -118 | H14: 106 | I14: =IF($H$14="","",IF($H$14<0,-$H$14/(-$H$14+100),100/($H$14+100))) | J14: =IF($H$14="","",$F$14*IF($H$14<0,-100/$H$14,$H$14/100)-(1-$F$14)) | K14: =IF($H$14="","",MAX(0,($F$14*IF($H$14<0,-100/$H$14,$H$14/100)-(1-$F$14))/IF($H$14<0,-100/$H$14,$H$14/100))*'Settings'!$B$3) | L14: =IF($H$14="","",ROUND(MIN($K$14,'Settings'!$B$5)*'Settings'!$B$2,2)) | M14: =IF($J$14="","",IF($J$14<0,"Pass",IF($J$14<'Settings'!$B$4,"Thin",IF($J$14<0.06,"✅ Sharp band",IF($J$14<0.08,"Strong","⚠ Verify (stale?)"))))) | N14: Model 54.2% (fair -118). Your call. | P14: =IF(OR($H$14="",$O$14=""),"",(1+IF($H$14<0,-100/$H$14,$H$14/100))/(1+IF($O$14<0,-100/$O$14,$O$14/100))-1)
A15: 2026-07-09 | B15: Kansas City Royals @ New York Mets | C15: 17:10 | D15: Spread | E15: New York Mets -1.5 | F15: 0.3921 | G15: 155 | H15: 153 | I15: =IF($H$15="","",IF($H$15<0,-$H$15/(-$H$15+100),100/($H$15+100))) | J15: =IF($H$15="","",$F$15*IF($H$15<0,-100/$H$15,$H$15/100)-(1-$F$15)) | K15: =IF($H$15="","",MAX(0,($F$15*IF($H$15<0,-100/$H$15,$H$15/100)-(1-$F$15))/IF($H$15<0,-100/$H$15,$H$15/100))*'Settings'!$B$3) | L15: =IF($H$15="","",ROUND(MIN($K$15,'Settings'!$B$5)*'Settings'!$B$2,2)) | M15: =IF($J$15="","",IF($J$15<0,"Pass",IF($J$15<'Settings'!$B$4,"Thin",IF($J$15<0.06,"✅ Sharp band",IF($J$15<0.08,"Strong","⚠ Verify (stale?)"))))) | N15: Model 39.2% (fair +155). Your call. | P15: =IF(OR($H$15="",$O$15=""),"",(1+IF($H$15<0,-100/$H$15,$H$15/100))/(1+IF($O$15<0,-100/$O$15,$O$15/100))-1)
A16: 2026-07-09 | B16: Kansas City Royals @ New York Mets | C16: 17:10 | D16: Spread | E16: Kansas City Royals +1.5 | F16: 0.6079 | G16: -155 | H16: -156 | I16: =IF($H$16="","",IF($H$16<0,-$H$16/(-$H$16+100),100/($H$16+100))) | J16: =IF($H$16="","",$F$16*IF($H$16<0,-100/$H$16,$H$16/100)-(1-$F$16)) | K16: =IF($H$16="","",MAX(0,($F$16*IF($H$16<0,-100/$H$16,$H$16/100)-(1-$F$16))/IF($H$16<0,-100/$H$16,$H$16/100))*'Settings'!$B$3) | L16: =IF($H$16="","",ROUND(MIN($K$16,'Settings'!$B$5)*'Settings'!$B$2,2)) | M16: =IF($J$16="","",IF($J$16<0,"Pass",IF($J$16<'Settings'!$B$4,"Thin",IF($J$16<0.06,"✅ Sharp band",IF($J$16<0.08,"Strong","⚠ Verify (stale?)"))))) | N16: Model 60.8% (fair -155). Your call. | P16: =IF(OR($H$16="",$O$16=""),"",(1+IF($H$16<0,-100/$H$16,$H$16/100))/(1+IF($O$16<0,-100/$O$16,$O$16/100))-1)
A17: 2026-07-09 | B17: New York Yankees @ Tampa Bay Rays | C17: 17:10 | D17: Moneyline | E17: New York Yankees | F17: 0.4257 | G17: 135 | H17: 136 | I17: =IF($H$17="","",IF($H$17<0,-$H$17/(-$H$17+100),100/($H$17+100))) | J17: =IF($H$17="","",$F$17*IF($H$17<0,-100/$H$17,$H$17/100)-(1-$F$17)) | K17: =IF($H$17="","",MAX(0,($F$17*IF($H$17<0,-100/$H$17,$H$17/100)-(1-$F$17))/IF($H$17<0,-100/$H$17,$H$17/100))*'Settings'!$B$3) | L17: =IF($H$17="","",ROUND(MIN($K$17,'Settings'!$B$5)*'Settings'!$B$2,2)) | M17: =IF($J$17="","",IF($J$17<0,"Pass",IF($J$17<'Settings'!$B$4,"Thin",IF($J$17<0.06,"✅ Sharp band",IF($J$17<0.08,"Strong","⚠ Verify (stale?)"))))) | N17: Model 42.6% (fair +135). Your call. | P17: =IF(OR($H$17="",$O$17=""),"",(1+IF($H$17<0,-100/$H$17,$H$17/100))/(1+IF($O$17<0,-100/$O$17,$O$17/100))-1)
A18: 2026-07-09 | B18: New York Yankees @ Tampa Bay Rays | C18: 17:10 | D18: Moneyline | E18: Tampa Bay Rays | F18: 0.5743 | G18: -135 | H18: -135 | I18: =IF($H$18="","",IF($H$18<0,-$H$18/(-$H$18+100),100/($H$18+100))) | J18: =IF($H$18="","",$F$18*IF($H$18<0,-100/$H$18,$H$18/100)-(1-$F$18)) | K18: =IF($H$18="","",MAX(0,($F$18*IF($H$18<0,-100/$H$18,$H$18/100)-(1-$F$18))/IF($H$18<0,-100/$H$18,$H$18/100))*'Settings'!$B$3) | L18: =IF($H$18="","",ROUND(MIN($K$18,'Settings'!$B$5)*'Settings'!$B$2,2)) | M18: =IF($J$18="","",IF($J$18<0,"Pass",IF($J$18<'Settings'!$B$4,"Thin",IF($J$18<0.06,"✅ Sharp band",IF($J$18<0.08,"Strong","⚠ Verify (stale?)"))))) | N18: Model 57.4% (fair -135). Your call. | P18: =IF(OR($H$18="",$O$18=""),"",(1+IF($H$18<0,-100/$H$18,$H$18/100))/(1+IF($O$18<0,-100/$O$18,$O$18/100))-1)
A19: 2026-07-09 | B19: New York Yankees @ Tampa Bay Rays | C19: 17:10 | D19: Total | E19: Over 7.5 | F19: 0.5201 | G19: -108 | H19: 104 | I19: =IF($H$19="","",IF($H$19<0,-$H$19/(-$H$19+100),100/($H$19+100))) | J19: =IF($H$19="","",$F$19*IF($H$19<0,-100/$H$19,$H$19/100)-(1-$F$19)) | K19: =IF($H$19="","",MAX(0,($F$19*IF($H$19<0,-100/$H$19,$H$19/100)-(1-$F$19))/IF($H$19<0,-100/$H$19,$H$19/100))*'Settings'!$B$3) | L19: =IF($H$19="","",ROUND(MIN($K$19,'Settings'!$B$5)*'Settings'!$B$2,2)) | M19: =IF($J$19="","",IF($J$19<0,"Pass",IF($J$19<'Settings'!$B$4,"Thin",IF($J$19<0.06,"✅ Sharp band",IF($J$19<0.08,"Strong","⚠ Verify (stale?)"))))) | N19: Model 52.0% (fair -108). Your call. | P19: =IF(OR($H$19="",$O$19=""),"",(1+IF($H$19<0,-100/$H$19,$H$19/100))/(1+IF($O$19<0,-100/$O$19,$O$19/100))-1)
A20: 2026-07-09 | B20: New York Yankees @ Tampa Bay Rays | C20: 17:10 | D20: Total | E20: Under 7.5 | F20: 0.4799 | G20: 108 | H20: -104 | I20: =IF($H$20="","",IF($H$20<0,-$H$20/(-$H$20+100),100/($H$20+100))) | J20: =IF($H$20="","",$F$20*IF($H$20<0,-100/$H$20,$H$20/100)-(1-$F$20)) | K20: =IF($H$20="","",MAX(0,($F$20*IF($H$20<0,-100/$H$20,$H$20/100)-(1-$F$20))/IF($H$20<0,-100/$H$20,$H$20/100))*'Settings'!$B$3) | L20: =IF($H$20="","",ROUND(MIN($K$20,'Settings'!$B$5)*'Settings'!$B$2,2)) | M20: =IF($J$20="","",IF($J$20<0,"Pass",IF($J$20<'Settings'!$B$4,"Thin",IF($J$20<0.06,"✅ Sharp band",IF($J$20<0.08,"Strong","⚠ Verify (stale?)"))))) | N20: Model 48.0% (fair +108). Your call. | P20: =IF(OR($H$20="",$O$20=""),"",(1+IF($H$20<0,-100/$H$20,$H$20/100))/(1+IF($O$20<0,-100/$O$20,$O$20/100))-1)
A21: 2026-07-09 | B21: New York Yankees @ Tampa Bay Rays | C21: 17:10 | D21: Spread | E21: Tampa Bay Rays -1.5 | F21: 0.3893 | G21: 157 | H21: 153 | I21: =IF($H$21="","",IF($H$21<0,-$H$21/(-$H$21+100),100/($H$21+100))) | J21: =IF($H$21="","",$F$21*IF($H$21<0,-100/$H$21,$H$21/100)-(1-$F$21)) | K21: =IF($H$21="","",MAX(0,($F$21*IF($H$21<0,-100/$H$21,$H$21/100)-(1-$F$21))/IF($H$21<0,-100/$H$21,$H$21/100))*'Settings'!$B$3) | L21: =IF($H$21="","",ROUND(MIN($K$21,'Settings'!$B$5)*'Settings'!$B$2,2)) | M21: =IF($J$21="","",IF($J$21<0,"Pass",IF($J$21<'Settings'!$B$4,"Thin",IF($J$21<0.06,"✅ Sharp band",IF($J$21<0.08,"Strong","⚠ Verify (stale?)"))))) | N21: Model 38.9% (fair +157). Your call. | P21: =IF(OR($H$21="",$O$21=""),"",(1+IF($H$21<0,-100/$H$21,$H$21/100))/(1+IF($O$21<0,-100/$O$21,$O$21/100))-1)
A22: 2026-07-09 | B22: New York Yankees @ Tampa Bay Rays | C22: 17:10 | D22: Spread | E22: New York Yankees +1.5 | F22: 0.6107 | G22: -157 | H22: -156 | I22: =IF($H$22="","",IF($H$22<0,-$H$22/(-$H$22+100),100/($H$22+100))) | J22: =IF($H$22="","",$F$22*IF($H$22<0,-100/$H$22,$H$22/100)-(1-$F$22)) | K22: =IF($H$22="","",MAX(0,($F$22*IF($H$22<0,-100/$H$22,$H$22/100)-(1-$F$22))/IF($H$22<0,-100/$H$22,$H$22/100))*'Settings'!$B$3) | L22: =IF($H$22="","",ROUND(MIN($K$22,'Settings'!$B$5)*'Settings'!$B$2,2)) | M22: =IF($J$22="","",IF($J$22<0,"Pass",IF($J$22<'Settings'!$B$4,"Thin",IF($J$22<0.06,"✅ Sharp band",IF($J$22<0.08,"Strong","⚠ Verify (stale?)"))))) | N22: Model 61.1% (fair -157). Your call. | P22: =IF(OR($H$22="",$O$22=""),"",(1+IF($H$22<0,-100/$H$22,$H$22/100))/(1+IF($O$22<0,-100/$O$22,$O$22/100))-1)
A23: 2026-07-09 | B23: Chicago Cubs @ Baltimore Orioles | C23: 17:35 | D23: Moneyline | E23: Chicago Cubs | F23: 0.4566 | G23: 119 | H23: 120 | I23: =IF($H$23="","",IF($H$23<0,-$H$23/(-$H$23+100),100/($H$23+100))) | J23: =IF($H$23="","",$F$23*IF($H$23<0,-100/$H$23,$H$23/100)-(1-$F$23)) | K23: =IF($H$23="","",MAX(0,($F$23*IF($H$23<0,-100/$H$23,$H$23/100)-(1-$F$23))/IF($H$23<0,-100/$H$23,$H$23/100))*'Settings'!$B$3) | L23: =IF($H$23="","",ROUND(MIN($K$23,'Settings'!$B$5)*'Settings'!$B$2,2)) | M23: =IF($J$23="","",IF($J$23<0,"Pass",IF($J$23<'Settings'!$B$4,"Thin",IF($J$23<0.06,"✅ Sharp band",IF($J$23<0.08,"Strong","⚠ Verify (stale?)"))))) | N23: Model 45.7% (fair +119). Your call. | P23: =IF(OR($H$23="",$O$23=""),"",(1+IF($H$23<0,-100/$H$23,$H$23/100))/(1+IF($O$23<0,-100/$O$23,$O$23/100))-1)
A24: 2026-07-09 | B24: Chicago Cubs @ Baltimore Orioles | C24: 17:35 | D24: Moneyline | E24: Baltimore Orioles | F24: 0.5434 | G24: -119 | H24: -117 | I24: =IF($H$24="","",IF($H$24<0,-$H$24/(-$H$24+100),100/($H$24+100))) | J24: =IF($H$24="","",$F$24*IF($H$24<0,-100/$H$24,$H$24/100)-(1-$F$24)) | K24: =IF($H$24="","",MAX(0,($F$24*IF($H$24<0,-100/$H$24,$H$24/100)-(1-$F$24))/IF($H$24<0,-100/$H$24,$H$24/100))*'Settings'!$B$3) | L24: =IF($H$24="","",ROUND(MIN($K$24,'Settings'!$B$5)*'Settings'!$B$2,2)) | M24: =IF($J$24="","",IF($J$24<0,"Pass",IF($J$24<'Settings'!$B$4,"Thin",IF($J$24<0.06,"✅ Sharp band",IF($J$24<0.08,"Strong","⚠ Verify (stale?)"))))) | N24: Model 54.3% (fair -119). Your call. | P24: =IF(OR($H$24="",$O$24=""),"",(1+IF($H$24<0,-100/$H$24,$H$24/100))/(1+IF($O$24<0,-100/$O$24,$O$24/100))-1)
A25: 2026-07-09 | B25: Chicago Cubs @ Baltimore Orioles | C25: 17:35 | D25: Total | E25: Over 10 | F25: 0.4512 | G25: 122 | H25: 102 | I25: =IF($H$25="","",IF($H$25<0,-$H$25/(-$H$25+100),100/($H$25+100))) | J25: =IF($H$25="","",$F$25*IF($H$25<0,-100/$H$25,$H$25/100)-(1-$F$25)) | K25: =IF($H$25="","",MAX(0,($F$25*IF($H$25<0,-100/$H$25,$H$25/100)-(1-$F$25))/IF($H$25<0,-100/$H$25,$H$25/100))*'Settings'!$B$3) | L25: =IF($H$25="","",ROUND(MIN($K$25,'Settings'!$B$5)*'Settings'!$B$2,2)) | M25: =IF($J$25="","",IF($J$25<0,"Pass",IF($J$25<'Settings'!$B$4,"Thin",IF($J$25<0.06,"✅ Sharp band",IF($J$25<0.08,"Strong","⚠ Verify (stale?)"))))) | N25: Model 45.1% (fair +122). Your call. | P25: =IF(OR($H$25="",$O$25=""),"",(1+IF($H$25<0,-100/$H$25,$H$25/100))/(1+IF($O$25<0,-100/$O$25,$O$25/100))-1)
A26: 2026-07-09 | B26: Chicago Cubs @ Baltimore Orioles | C26: 17:35 | D26: Total | E26: Under 10 | F26: 0.4668 | G26: 114 | H26: 106 | I26: =IF($H$26="","",IF($H$26<0,-$H$26/(-$H$26+100),100/($H$26+100))) | J26: =IF($H$26="","",$F$26*IF($H$26<0,-100/$H$26,$H$26/100)-(1-$F$26)) | K26: =IF($H$26="","",MAX(0,($F$26*IF($H$26<0,-100/$H$26,$H$26/100)-(1-$F$26))/IF($H$26<0,-100/$H$26,$H$26/100))*'Settings'!$B$3) | L26: =IF($H$26="","",ROUND(MIN($K$26,'Settings'!$B$5)*'Settings'!$B$2,2)) | M26: =IF($J$26="","",IF($J$26<0,"Pass",IF($J$26<'Settings'!$B$4,"Thin",IF($J$26<0.06,"✅ Sharp band",IF($J$26<0.08,"Strong","⚠ Verify (stale?)"))))) | N26: Model 46.7% (fair +114). Your call. | P26: =IF(OR($H$26="",$O$26=""),"",(1+IF($H$26<0,-100/$H$26,$H$26/100))/(1+IF($O$26<0,-100/$O$26,$O$26/100))-1)
A27: 2026-07-09 | B27: Chicago Cubs @ Baltimore Orioles | C27: 17:35 | D27: Spread | E27: Baltimore Orioles -1.5 | F27: 0.3653 | G27: 174 | H27: 163 | I27: =IF($H$27="","",IF($H$27<0,-$H$27/(-$H$27+100),100/($H$27+100))) | J27: =IF($H$27="","",$F$27*IF($H$27<0,-100/$H$27,$H$27/100)-(1-$F$27)) | K27: =IF($H$27="","",MAX(0,($F$27*IF($H$27<0,-100/$H$27,$H$27/100)-(1-$F$27))/IF($H$27<0,-100/$H$27,$H$27/100))*'Settings'!$B$3) | L27: =IF($H$27="","",ROUND(MIN($K$27,'Settings'!$B$5)*'Settings'!$B$2,2)) | M27: =IF($J$27="","",IF($J$27<0,"Pass",IF($J$27<'Settings'!$B$4,"Thin",IF($J$27<0.06,"✅ Sharp band",IF($J$27<0.08,"Strong","⚠ Verify (stale?)"))))) | N27: Model 36.5% (fair +174). Your call. | P27: =IF(OR($H$27="",$O$27=""),"",(1+IF($H$27<0,-100/$H$27,$H$27/100))/(1+IF($O$27<0,-100/$O$27,$O$27/100))-1)
A28: 2026-07-09 | B28: Chicago Cubs @ Baltimore Orioles | C28: 17:35 | D28: Spread | E28: Chicago Cubs +1.5 | F28: 0.6347 | G28: -174 | H28: -170 | I28: =IF($H$28="","",IF($H$28<0,-$H$28/(-$H$28+100),100/($H$28+100))) | J28: =IF($H$28="","",$F$28*IF($H$28<0,-100/$H$28,$H$28/100)-(1-$F$28)) | K28: =IF($H$28="","",MAX(0,($F$28*IF($H$28<0,-100/$H$28,$H$28/100)-(1-$F$28))/IF($H$28<0,-100/$H$28,$H$28/100))*'Settings'!$B$3) | L28: =IF($H$28="","",ROUND(MIN($K$28,'Settings'!$B$5)*'Settings'!$B$2,2)) | M28: =IF($J$28="","",IF($J$28<0,"Pass",IF($J$28<'Settings'!$B$4,"Thin",IF($J$28<0.06,"✅ Sharp band",IF($J$28<0.08,"Strong","⚠ Verify (stale?)"))))) | N28: Model 63.5% (fair -174). Your call. | P28: =IF(OR($H$28="",$O$28=""),"",(1+IF($H$28<0,-100/$H$28,$H$28/100))/(1+IF($O$28<0,-100/$O$28,$O$28/100))-1)
A29: 2026-07-09 | B29: Cleveland Guardians @ Minnesota Twins | C29: 17:40 | D29: Moneyline | E29: Cleveland Guardians | F29: 0.4991 | G29: 100 | H29: -115 | I29: =IF($H$29="","",IF($H$29<0,-$H$29/(-$H$29+100),100/($H$29+100))) | J29: =IF($H$29="","",$F$29*IF($H$29<0,-100/$H$29,$H$29/100)-(1-$F$29)) | K29: =IF($H$29="","",MAX(0,($F$29*IF($H$29<0,-100/$H$29,$H$29/100)-(1-$F$29))/IF($H$29<0,-100/$H$29,$H$29/100))*'Settings'!$B$3) | L29: =IF($H$29="","",ROUND(MIN($K$29,'Settings'!$B$5)*'Settings'!$B$2,2)) | M29: =IF($J$29="","",IF($J$29<0,"Pass",IF($J$29<'Settings'!$B$4,"Thin",IF($J$29<0.06,"✅ Sharp band",IF($J$29<0.08,"Strong","⚠ Verify (stale?)"))))) | N29: Model 49.9% (fair +100). Your call. | P29: =IF(OR($H$29="",$O$29=""),"",(1+IF($H$29<0,-100/$H$29,$H$29/100))/(1+IF($O$29<0,-100/$O$29,$O$29/100))-1)
A30: 2026-07-09 | B30: Cleveland Guardians @ Minnesota Twins | C30: 17:40 | D30: Moneyline | E30: Minnesota Twins | F30: 0.5009 | G30: -100 | H30: 115 | I30: =IF($H$30="","",IF($H$30<0,-$H$30/(-$H$30+100),100/($H$30+100))) | J30: =IF($H$30="","",$F$30*IF($H$30<0,-100/$H$30,$H$30/100)-(1-$F$30)) | K30: =IF($H$30="","",MAX(0,($F$30*IF($H$30<0,-100/$H$30,$H$30/100)-(1-$F$30))/IF($H$30<0,-100/$H$30,$H$30/100))*'Settings'!$B$3) | L30: =IF($H$30="","",ROUND(MIN($K$30,'Settings'!$B$5)*'Settings'!$B$2,2)) | M30: =IF($J$30="","",IF($J$30<0,"Pass",IF($J$30<'Settings'!$B$4,"Thin",IF($J$30<0.06,"✅ Sharp band",IF($J$30<0.08,"Strong","⚠ Verify (stale?)"))))) | N30: Model 50.1% (fair -100). Your call. | P30: =IF(OR($H$30="",$O$30=""),"",(1+IF($H$30<0,-100/$H$30,$H$30/100))/(1+IF($O$30<0,-100/$O$30,$O$30/100))-1)
A31: 2026-07-09 | B31: Cleveland Guardians @ Minnesota Twins | C31: 17:40 | D31: Total | E31: Over 8.5 | F31: 0.5151 | G31: -106 | H31: -104 | I31: =IF($H$31="","",IF($H$31<0,-$H$31/(-$H$31+100),100/($H$31+100))) | J31: =IF($H$31="","",$F$31*IF($H$31<0,-100/$H$31,$H$31/100)-(1-$F$31)) | K31: =IF($H$31="","",MAX(0,($F$31*IF($H$31<0,-100/$H$31,$H$31/100)-(1-$F$31))/IF($H$31<0,-100/$H$31,$H$31/100))*'Settings'!$B$3) | L31: =IF($H$31="","",ROUND(MIN($K$31,'Settings'!$B$5)*'Settings'!$B$2,2)) | M31: =IF($J$31="","",IF($J$31<0,"Pass",IF($J$31<'Settings'!$B$4,"Thin",IF($J$31<0.06,"✅ Sharp band",IF($J$31<0.08,"Strong","⚠ Verify (stale?)"))))) | N31: Model 51.5% (fair -106). Your call. | P31: =IF(OR($H$31="",$O$31=""),"",(1+IF($H$31<0,-100/$H$31,$H$31/100))/(1+IF($O$31<0,-100/$O$31,$O$31/100))-1)
A32: 2026-07-09 | B32: Cleveland Guardians @ Minnesota Twins | C32: 17:40 | D32: Total | E32: Under 8.5 | F32: 0.4849 | G32: 106 | H32: 104 | I32: =IF($H$32="","",IF($H$32<0,-$H$32/(-$H$32+100),100/($H$32+100))) | J32: =IF($H$32="","",$F$32*IF($H$32<0,-100/$H$32,$H$32/100)-(1-$F$32)) | K32: =IF($H$32="","",MAX(0,($F$32*IF($H$32<0,-100/$H$32,$H$32/100)-(1-$F$32))/IF($H$32<0,-100/$H$32,$H$32/100))*'Settings'!$B$3) | L32: =IF($H$32="","",ROUND(MIN($K$32,'Settings'!$B$5)*'Settings'!$B$2,2)) | M32: =IF($J$32="","",IF($J$32<0,"Pass",IF($J$32<'Settings'!$B$4,"Thin",IF($J$32<0.06,"✅ Sharp band",IF($J$32<0.08,"Strong","⚠ Verify (stale?)"))))) | N32: Model 48.5% (fair +106). Your call. | P32: =IF(OR($H$32="",$O$32=""),"",(1+IF($H$32<0,-100/$H$32,$H$32/100))/(1+IF($O$32<0,-100/$O$32,$O$32/100))-1)
A33: 2026-07-09 | B33: Cleveland Guardians @ Minnesota Twins | C33: 17:40 | D33: Spread | E33: Minnesota Twins +1.5 | F33: 0.6111 | G33: -157 | H33: -144 | I33: =IF($H$33="","",IF($H$33<0,-$H$33/(-$H$33+100),100/($H$33+100))) | J33: =IF($H$33="","",$F$33*IF($H$33<0,-100/$H$33,$H$33/100)-(1-$F$33)) | K33: =IF($H$33="","",MAX(0,($F$33*IF($H$33<0,-100/$H$33,$H$33/100)-(1-$F$33))/IF($H$33<0,-100/$H$33,$H$33/100))*'Settings'!$B$3) | L33: =IF($H$33="","",ROUND(MIN($K$33,'Settings'!$B$5)*'Settings'!$B$2,2)) | M33: =IF($J$33="","",IF($J$33<0,"Pass",IF($J$33<'Settings'!$B$4,"Thin",IF($J$33<0.06,"✅ Sharp band",IF($J$33<0.08,"Strong","⚠ Verify (stale?)"))))) | N33: Model 61.1% (fair -157). Your call. | P33: =IF(OR($H$33="",$O$33=""),"",(1+IF($H$33<0,-100/$H$33,$H$33/100))/(1+IF($O$33<0,-100/$O$33,$O$33/100))-1)
A34: 2026-07-09 | B34: Cleveland Guardians @ Minnesota Twins | C34: 17:40 | D34: Spread | E34: Cleveland Guardians -1.5 | F34: 0.3889 | G34: 157 | H34: 147 | I34: =IF($H$34="","",IF($H$34<0,-$H$34/(-$H$34+100),100/($H$34+100))) | J34: =IF($H$34="","",$F$34*IF($H$34<0,-100/$H$34,$H$34/100)-(1-$F$34)) | K34: =IF($H$34="","",MAX(0,($F$34*IF($H$34<0,-100/$H$34,$H$34/100)-(1-$F$34))/IF($H$34<0,-100/$H$34,$H$34/100))*'Settings'!$B$3) | L34: =IF($H$34="","",ROUND(MIN($K$34,'Settings'!$B$5)*'Settings'!$B$2,2)) | M34: =IF($J$34="","",IF($J$34<0,"Pass",IF($J$34<'Settings'!$B$4,"Thin",IF($J$34<0.06,"✅ Sharp band",IF($J$34<0.08,"Strong","⚠ Verify (stale?)"))))) | N34: Model 38.9% (fair +157). Your call. | P34: =IF(OR($H$34="",$O$34=""),"",(1+IF($H$34<0,-100/$H$34,$H$34/100))/(1+IF($O$34<0,-100/$O$34,$O$34/100))-1)
A35: 2026-07-09 | B35: Boston Red Sox @ Chicago White Sox | C35: 18:10 | D35: Moneyline | E35: Boston Red Sox | F35: 0.4832 | G35: 107 | H35: 104 | I35: =IF($H$35="","",IF($H$35<0,-$H$35/(-$H$35+100),100/($H$35+100))) | J35: =IF($H$35="","",$F$35*IF($H$35<0,-100/$H$35,$H$35/100)-(1-$F$35)) | K35: =IF($H$35="","",MAX(0,($F$35*IF($H$35<0,-100/$H$35,$H$35/100)-(1-$F$35))/IF($H$35<0,-100/$H$35,$H$35/100))*'Settings'!$B$3) | L35: =IF($H$35="","",ROUND(MIN($K$35,'Settings'!$B$5)*'Settings'!$B$2,2)) | M35: =IF($J$35="","",IF($J$35<0,"Pass",IF($J$35<'Settings'!$B$4,"Thin",IF($J$35<0.06,"✅ Sharp band",IF($J$35<0.08,"Strong","⚠ Verify (stale?)"))))) | N35: Model 48.3% (fair +107). Your call. | P35: =IF(OR($H$35="",$O$35=""),"",(1+IF($H$35<0,-100/$H$35,$H$35/100))/(1+IF($O$35<0,-100/$O$35,$O$35/100))-1)
A36: 2026-07-09 | B36: Boston Red Sox @ Chicago White Sox | C36: 18:10 | D36: Moneyline | E36: Chicago White Sox | F36: 0.5168 | G36: -107 | H36: 104 | I36: =IF($H$36="","",IF($H$36<0,-$H$36/(-$H$36+100),100/($H$36+100))) | J36: =IF($H$36="","",$F$36*IF($H$36<0,-100/$H$36,$H$36/100)-(1-$F$36)) | K36: =IF($H$36="","",MAX(0,($F$36*IF($H$36<0,-100/$H$36,$H$36/100)-(1-$F$36))/IF($H$36<0,-100/$H$36,$H$36/100))*'Settings'!$B$3) | L36: =IF($H$36="","",ROUND(MIN($K$36,'Settings'!$B$5)*'Settings'!$B$2,2)) | M36: =IF($J$36="","",IF($J$36<0,"Pass",IF($J$36<'Settings'!$B$4,"Thin",IF($J$36<0.06,"✅ Sharp band",IF($J$36<0.08,"Strong","⚠ Verify (stale?)"))))) | N36: Model 51.7% (fair -107). Your call. | P36: =IF(OR($H$36="",$O$36=""),"",(1+IF($H$36<0,-100/$H$36,$H$36/100))/(1+IF($O$36<0,-100/$O$36,$O$36/100))-1)
A37: 2026-07-09 | B37: Boston Red Sox @ Chicago White Sox | C37: 18:10 | D37: Total | E37: Over 9.5 | F37: 0.4356 | G37: 130 | H37: 117 | I37: =IF($H$37="","",IF($H$37<0,-$H$37/(-$H$37+100),100/($H$37+100))) | J37: =IF($H$37="","",$F$37*IF($H$37<0,-100/$H$37,$H$37/100)-(1-$F$37)) | K37: =IF($H$37="","",MAX(0,($F$37*IF($H$37<0,-100/$H$37,$H$37/100)-(1-$F$37))/IF($H$37<0,-100/$H$37,$H$37/100))*'Settings'!$B$3) | L37: =IF($H$37="","",ROUND(MIN($K$37,'Settings'!$B$5)*'Settings'!$B$2,2)) | M37: =IF($J$37="","",IF($J$37<0,"Pass",IF($J$37<'Settings'!$B$4,"Thin",IF($J$37<0.06,"✅ Sharp band",IF($J$37<0.08,"Strong","⚠ Verify (stale?)"))))) | N37: Model 43.6% (fair +130). Your call. | P37: =IF(OR($H$37="",$O$37=""),"",(1+IF($H$37<0,-100/$H$37,$H$37/100))/(1+IF($O$37<0,-100/$O$37,$O$37/100))-1)
A38: 2026-07-09 | B38: Boston Red Sox @ Chicago White Sox | C38: 18:10 | D38: Total | E38: Under 9.5 | F38: 0.5644 | G38: -130 | H38: 120 | I38: =IF($H$38="","",IF($H$38<0,-$H$38/(-$H$38+100),100/($H$38+100))) | J38: =IF($H$38="","",$F$38*IF($H$38<0,-100/$H$38,$H$38/100)-(1-$F$38)) | K38: =IF($H$38="","",MAX(0,($F$38*IF($H$38<0,-100/$H$38,$H$38/100)-(1-$F$38))/IF($H$38<0,-100/$H$38,$H$38/100))*'Settings'!$B$3) | L38: =IF($H$38="","",ROUND(MIN($K$38,'Settings'!$B$5)*'Settings'!$B$2,2)) | M38: =IF($J$38="","",IF($J$38<0,"Pass",IF($J$38<'Settings'!$B$4,"Thin",IF($J$38<0.06,"✅ Sharp band",IF($J$38<0.08,"Strong","⚠ Verify (stale?)"))))) | N38: Model 56.4% (fair -130). Your call. | P38: =IF(OR($H$38="",$O$38=""),"",(1+IF($H$38<0,-100/$H$38,$H$38/100))/(1+IF($O$38<0,-100/$O$38,$O$38/100))-1)
A39: 2026-07-09 | B39: Boston Red Sox @ Chicago White Sox | C39: 18:10 | D39: Spread | E39: Chicago White Sox -1.5 | F39: 0.3624 | G39: 176 | H39: 170 | I39: =IF($H$39="","",IF($H$39<0,-$H$39/(-$H$39+100),100/($H$39+100))) | J39: =IF($H$39="","",$F$39*IF($H$39<0,-100/$H$39,$H$39/100)-(1-$F$39)) | K39: =IF($H$39="","",MAX(0,($F$39*IF($H$39<0,-100/$H$39,$H$39/100)-(1-$F$39))/IF($H$39<0,-100/$H$39,$H$39/100))*'Settings'!$B$3) | L39: =IF($H$39="","",ROUND(MIN($K$39,'Settings'!$B$5)*'Settings'!$B$2,2)) | M39: =IF($J$39="","",IF($J$39<0,"Pass",IF($J$39<'Settings'!$B$4,"Thin",IF($J$39<0.06,"✅ Sharp band",IF($J$39<0.08,"Strong","⚠ Verify (stale?)"))))) | N39: Model 36.2% (fair +176). Your call. | P39: =IF(OR($H$39="",$O$39=""),"",(1+IF($H$39<0,-100/$H$39,$H$39/100))/(1+IF($O$39<0,-100/$O$39,$O$39/100))-1)
A40: 2026-07-09 | B40: Boston Red Sox @ Chicago White Sox | C40: 18:10 | D40: Spread | E40: Boston Red Sox +1.5 | F40: 0.6376 | G40: -176 | H40: 170 | I40: =IF($H$40="","",IF($H$40<0,-$H$40/(-$H$40+100),100/($H$40+100))) | J40: =IF($H$40="","",$F$40*IF($H$40<0,-100/$H$40,$H$40/100)-(1-$F$40)) | K40: =IF($H$40="","",MAX(0,($F$40*IF($H$40<0,-100/$H$40,$H$40/100)-(1-$F$40))/IF($H$40<0,-100/$H$40,$H$40/100))*'Settings'!$B$3) | L40: =IF($H$40="","",ROUND(MIN($K$40,'Settings'!$B$5)*'Settings'!$B$2,2)) | M40: =IF($J$40="","",IF($J$40<0,"Pass",IF($J$40<'Settings'!$B$4,"Thin",IF($J$40<0.06,"✅ Sharp band",IF($J$40<0.08,"Strong","⚠ Verify (stale?)"))))) | N40: Model 63.8% (fair -176). Your call. | P40: =IF(OR($H$40="",$O$40=""),"",(1+IF($H$40<0,-100/$H$40,$H$40/100))/(1+IF($O$40<0,-100/$O$40,$O$40/100))-1)
A41: 2026-07-09 | B41: Athletics @ Detroit Tigers | C41: 22:40 | D41: Moneyline | E41: Athletics | F41: 0.4586 | G41: 118 | H41: 117 | I41: =IF($H$41="","",IF($H$41<0,-$H$41/(-$H$41+100),100/($H$41+100))) | J41: =IF($H$41="","",$F$41*IF($H$41<0,-100/$H$41,$H$41/100)-(1-$F$41)) | K41: =IF($H$41="","",MAX(0,($F$41*IF($H$41<0,-100/$H$41,$H$41/100)-(1-$F$41))/IF($H$41<0,-100/$H$41,$H$41/100))*'Settings'!$B$3) | L41: =IF($H$41="","",ROUND(MIN($K$41,'Settings'!$B$5)*'Settings'!$B$2,2)) | M41: =IF($J$41="","",IF($J$41<0,"Pass",IF($J$41<'Settings'!$B$4,"Thin",IF($J$41<0.06,"✅ Sharp band",IF($J$41<0.08,"Strong","⚠ Verify (stale?)"))))) | N41: Model 45.9% (fair +118). Your call. | P41: =IF(OR($H$41="",$O$41=""),"",(1+IF($H$41<0,-100/$H$41,$H$41/100))/(1+IF($O$41<0,-100/$O$41,$O$41/100))-1)
...

Sheet WNBA Games
A1: WNBA — game markets
A2: Moneyline · Total · Spread. Yellow = your price.
A4: Date | B4: Matchup | C4: Start | D4: Market | E4: Selection | F4: Model Win% | G4: Model Fair | H4: ✏ Your Odds | I4: Implied% | J4: Your Edge (EV) | K4: ¼-Kelly % | L4: Stake $ | M4: Verdict | N4: Model read | O4: ✏ Closing | P4: CLV %
A5: 2026-07-09 | B5: Seattle Storm @ Atlanta Dream | C5: 00:00 | D5: Moneyline | E5: Seattle Storm | F5: 0.2065 | G5: 384 | H5: 495 | I5: =IF($H$5="","",IF($H$5<0,-$H$5/(-$H$5+100),100/($H$5+100))) | J5: =IF($H$5="","",$F$5*IF($H$5<0,-100/$H$5,$H$5/100)-(1-$F$5)) | K5: =IF($H$5="","",MAX(0,($F$5*IF($H$5<0,-100/$H$5,$H$5/100)-(1-$F$5))/IF($H$5<0,-100/$H$5,$H$5/100))*'Settings'!$B$3) | L5: =IF($H$5="","",ROUND(MIN($K$5,'Settings'!$B$5)*'Settings'!$B$2,2)) | M5: =IF($J$5="","",IF($J$5<0,"Pass",IF($J$5<'Settings'!$B$4,"Thin",IF($J$5<0.06,"✅ Sharp band",IF($J$5<0.08,"Strong","⚠ Verify (stale?)"))))) | N5: Model 20.7% (fair +384). Your call. | P5: =IF(OR($H$5="",$O$5=""),"",(1+IF($H$5<0,-100/$H$5,$H$5/100))/(1+IF($O$5<0,-100/$O$5,$O$5/100))-1)
A6: 2026-07-09 | B6: Seattle Storm @ Atlanta Dream | C6: 00:00 | D6: Moneyline | E6: Atlanta Dream | F6: 0.7935 | G6: -384 | H6: -456 | I6: =IF($H$6="","",IF($H$6<0,-$H$6/(-$H$6+100),100/($H$6+100))) | J6: =IF($H$6="","",$F$6*IF($H$6<0,-100/$H$6,$H$6/100)-(1-$F$6)) | K6: =IF($H$6="","",MAX(0,($F$6*IF($H$6<0,-100/$H$6,$H$6/100)-(1-$F$6))/IF($H$6<0,-100/$H$6,$H$6/100))*'Settings'!$B$3) | L6: =IF($H$6="","",ROUND(MIN($K$6,'Settings'!$B$5)*'Settings'!$B$2,2)) | M6: =IF($J$6="","",IF($J$6<0,"Pass",IF($J$6<'Settings'!$B$4,"Thin",IF($J$6<0.06,"✅ Sharp band",IF($J$6<0.08,"Strong","⚠ Verify (stale?)"))))) | N6: Model 79.3% (fair -384). Your call. | P6: =IF(OR($H$6="",$O$6=""),"",(1+IF($H$6<0,-100/$H$6,$H$6/100))/(1+IF($O$6<0,-100/$O$6,$O$6/100))-1)
A7: 2026-07-09 | B7: Seattle Storm @ Atlanta Dream | C7: 00:00 | D7: Total | E7: Over 168.5 | F7: 0.5395 | G7: -117 | H7: -102 | I7: =IF($H$7="","",IF($H$7<0,-$H$7/(-$H$7+100),100/($H$7+100))) | J7: =IF($H$7="","",$F$7*IF($H$7<0,-100/$H$7,$H$7/100)-(1-$F$7)) | K7: =IF($H$7="","",MAX(0,($F$7*IF($H$7<0,-100/$H$7,$H$7/100)-(1-$F$7))/IF($H$7<0,-100/$H$7,$H$7/100))*'Settings'!$B$3) | L7: =IF($H$7="","",ROUND(MIN($K$7,'Settings'!$B$5)*'Settings'!$B$2,2)) | M7: =IF($J$7="","",IF($J$7<0,"Pass",IF($J$7<'Settings'!$B$4,"Thin",IF($J$7<0.06,"✅ Sharp band",IF($J$7<0.08,"Strong","⚠ Verify (stale?)"))))) | N7: Model 53.9% (fair -117). Your call. | P7: =IF(OR($H$7="",$O$7=""),"",(1+IF($H$7<0,-100/$H$7,$H$7/100))/(1+IF($O$7<0,-100/$O$7,$O$7/100))-1)
A8: 2026-07-09 | B8: Seattle Storm @ Atlanta Dream | C8: 00:00 | D8: Total | E8: Under 168.5 | F8: 0.4605 | G8: 117 | H8: 100 | I8: =IF($H$8="","",IF($H$8<0,-$H$8/(-$H$8+100),100/($H$8+100))) | J8: =IF($H$8="","",$F$8*IF($H$8<0,-100/$H$8,$H$8/100)-(1-$F$8)) | K8: =IF($H$8="","",MAX(0,($F$8*IF($H$8<0,-100/$H$8,$H$8/100)-(1-$F$8))/IF($H$8<0,-100/$H$8,$H$8/100))*'Settings'!$B$3) | L8: =IF($H$8="","",ROUND(MIN($K$8,'Settings'!$B$5)*'Settings'!$B$2,2)) | M8: =IF($J$8="","",IF($J$8<0,"Pass",IF($J$8<'Settings'!$B$4,"Thin",IF($J$8<0.06,"✅ Sharp band",IF($J$8<0.08,"Strong","⚠ Verify (stale?)"))))) | N8: Model 46.1% (fair +117). Your call. | P8: =IF(OR($H$8="",$O$8=""),"",(1+IF($H$8<0,-100/$H$8,$H$8/100))/(1+IF($O$8<0,-100/$O$8,$O$8/100))-1)
A9: 2026-07-09 | B9: Seattle Storm @ Atlanta Dream | C9: 00:00 | D9: Spread | E9: Atlanta Dream -12.5 | F9: 0.38178831 | G9: 162 | H9: 102 | I9: =IF($H$9="","",IF($H$9<0,-$H$9/(-$H$9+100),100/($H$9+100))) | J9: =IF($H$9="","",$F$9*IF($H$9<0,-100/$H$9,$H$9/100)-(1-$F$9)) | K9: =IF($H$9="","",MAX(0,($F$9*IF($H$9<0,-100/$H$9,$H$9/100)-(1-$F$9))/IF($H$9<0,-100/$H$9,$H$9/100))*'Settings'!$B$3) | L9: =IF($H$9="","",ROUND(MIN($K$9,'Settings'!$B$5)*'Settings'!$B$2,2)) | M9: =IF($J$9="","",IF($J$9<0,"Pass",IF($J$9<'Settings'!$B$4,"Thin",IF($J$9<0.06,"✅ Sharp band",IF($J$9<0.08,"Strong","⚠ Verify (stale?)"))))) | N9: Model 38.2% (fair +162). Your call. | P9: =IF(OR($H$9="",$O$9=""),"",(1+IF($H$9<0,-100/$H$9,$H$9/100))/(1+IF($O$9<0,-100/$O$9,$O$9/100))-1)
A10: 2026-07-09 | B10: Seattle Storm @ Atlanta Dream | C10: 00:00 | D10: Spread | E10: Seattle Storm +12.5 | F10: 0.61821169 | G10: -162 | H10: 376 | I10: =IF($H$10="","",IF($H$10<0,-$H$10/(-$H$10+100),100/($H$10+100))) | J10: =IF($H$10="","",$F$10*IF($H$10<0,-100/$H$10,$H$10/100)-(1-$F$10)) | K10: =IF($H$10="","",MAX(0,($F$10*IF($H$10<0,-100/$H$10,$H$10/100)-(1-$F$10))/IF($H$10<0,-100/$H$10,$H$10/100))*'Settings'!$B$3) | L10: =IF($H$10="","",ROUND(MIN($K$10,'Settings'!$B$5)*'Settings'!$B$2,2)) | M10: =IF($J$10="","",IF($J$10<0,"Pass",IF($J$10<'Settings'!$B$4,"Thin",IF($J$10<0.06,"✅ Sharp band",IF($J$10<0.08,"Strong","⚠ Verify (stale?)"))))) | N10: Model 61.8% (fair -162). Your call. | P10: =IF(OR($H$10="",$O$10=""),"",(1+IF($H$10<0,-100/$H$10,$H$10/100))/(1+IF($O$10<0,-100/$O$10,$O$10/100))-1)
A11: 2026-07-09 | B11: Indiana Fever @ Phoenix Mercury | C11: 02:00 | D11: Moneyline | E11: Indiana Fever | F11: 0.5663 | G11: -131 | H11: 104 | I11: =IF($H$11="","",IF($H$11<0,-$H$11/(-$H$11+100),100/($H$11+100))) | J11: =IF($H$11="","",$F$11*IF($H$11<0,-100/$H$11,$H$11/100)-(1-$F$11)) | K11: =IF($H$11="","",MAX(0,($F$11*IF($H$11<0,-100/$H$11,$H$11/100)-(1-$F$11))/IF($H$11<0,-100/$H$11,$H$11/100))*'Settings'!$B$3) | L11: =IF($H$11="","",ROUND(MIN($K$11,'Settings'!$B$5)*'Settings'!$B$2,2)) | M11: =IF($J$11="","",IF($J$11<0,"Pass",IF($J$11<'Settings'!$B$4,"Thin",IF($J$11<0.06,"✅ Sharp band",IF($J$11<0.08,"Strong","⚠ Verify (stale?)"))))) | N11: Model 56.6% (fair -131). Your call. | P11: =IF(OR($H$11="",$O$11=""),"",(1+IF($H$11<0,-100/$H$11,$H$11/100))/(1+IF($O$11<0,-100/$O$11,$O$11/100))-1)
A12: 2026-07-09 | B12: Indiana Fever @ Phoenix Mercury | C12: 02:00 | D12: Moneyline | E12: Phoenix Mercury | F12: 0.4337 | G12: 131 | H12: -104 | I12: =IF($H$12="","",IF($H$12<0,-$H$12/(-$H$12+100),100/($H$12+100))) | J12: =IF($H$12="","",$F$12*IF($H$12<0,-100/$H$12,$H$12/100)-(1-$F$12)) | K12: =IF($H$12="","",MAX(0,($F$12*IF($H$12<0,-100/$H$12,$H$12/100)-(1-$F$12))/IF($H$12<0,-100/$H$12,$H$12/100))*'Settings'!$B$3) | L12: =IF($H$12="","",ROUND(MIN($K$12,'Settings'!$B$5)*'Settings'!$B$2,2)) | M12: =IF($J$12="","",IF($J$12<0,"Pass",IF($J$12<'Settings'!$B$4,"Thin",IF($J$12<0.06,"✅ Sharp band",IF($J$12<0.08,"Strong","⚠ Verify (stale?)"))))) | N12: Model 43.4% (fair +131). Your call. | P12: =IF(OR($H$12="",$O$12=""),"",(1+IF($H$12<0,-100/$H$12,$H$12/100))/(1+IF($O$12<0,-100/$O$12,$O$12/100))-1)
A13: 2026-07-09 | B13: Indiana Fever @ Phoenix Mercury | C13: 02:00 | D13: Total | E13: Over 171.5 | F13: 0.5771 | G13: -136 | H13: 104 | I13: =IF($H$13="","",IF($H$13<0,-$H$13/(-$H$13+100),100/($H$13+100))) | J13: =IF($H$13="","",$F$13*IF($H$13<0,-100/$H$13,$H$13/100)-(1-$F$13)) | K13: =IF($H$13="","",MAX(0,($F$13*IF($H$13<0,-100/$H$13,$H$13/100)-(1-$F$13))/IF($H$13<0,-100/$H$13,$H$13/100))*'Settings'!$B$3) | L13: =IF($H$13="","",ROUND(MIN($K$13,'Settings'!$B$5)*'Settings'!$B$2,2)) | M13: =IF($J$13="","",IF($J$13<0,"Pass",IF($J$13<'Settings'!$B$4,"Thin",IF($J$13<0.06,"✅ Sharp band",IF($J$13<0.08,"Strong","⚠ Verify (stale?)"))))) | N13: Model 57.7% (fair -136). Your call. | P13: =IF(OR($H$13="",$O$13=""),"",(1+IF($H$13<0,-100/$H$13,$H$13/100))/(1+IF($O$13<0,-100/$O$13,$O$13/100))-1)
