Workbook

Sheet Read Me
A1: 🎯 Project 54.7 — Daily Wager Workbook
A2: 52.4% pays the house. 54.7% pays you.
A5: Built | B5: 2026-07-04 18:03
A7: HOW IT WORKS
A8: 1. | B8: The model's win probability for every market is locked. It does not change when odds move.
A9: 2. | B9: Type the price YOUR sportsbook is showing into the yellow “✏ Your Odds” cells (American odds, e.g. -110 or +135).
A10: 3. | B10: Implied %, Your Edge (EV), the ¼-Kelly stake and the Verdict recompute instantly — in Excel or Google Sheets, offline.
A11: 4. | B11: Set your Bankroll and Kelly fraction once on the Settings tab; every stake on every tab follows it.
A12: 5. | B12: After a game, type the closing line into the ✏ Closing column on the Games tab — CLV % shows whether you beat the close (the earliest honest sign an edge is real).
A14: READING THE VERDICT
A15: Pass | B15: Model says there's no edge at your price — skip it.
A16: Thin | B16: Positive but below your min-edge threshold.
A17: ✅ Sharp band | B17: 2–6% EV — where the model's edge has actually held up (good closing-line value). The sweet spot.
A18: Strong | B18: 6–8% EV — bigger, rarer.
A19: ⚠ Verify | B19: 8%+ EV usually means a stale or oddball price, not free money. Double-check the line before trusting it.
A21: WHY EDIT YOUR OWN ODDS?
B22: Every other tool de-vigs a sharp book for you and locks the math in an app whose lines go stale. Here the number is yours, so nothing can be out of date — and the math is in front of you.
A24: THE DEAL | B24: Personal research. Not financial advice. No bankroll promises. If gambling stops being fun, stop — call 1-800-GAMBLER.
B25: We publish our losses too — see the Track Record tab. We tell you when to pass. The trigger is always yours.

Sheet Settings
A1: ⚙ Settings
A2: Bankroll ($) | B2: 1000
A3: Kelly fraction | B3: 0.25
A4: Min edge to flag (EV) | B4: 0.02
A5: Max stake (% of bankroll) | B5: 0.05
A7: Default ¼-Kelly is deliberate: full Kelly is mathematically optimal but brutal on variance, and edges are always overestimated. Quarter-Kelly keeps ~most of the growth at a fraction of the risk.

Sheet Top Plays
A1: ⭐ Top Plays — biggest model edges today
A2: Ranked at the posted price. Swap in your book's number and watch the edge update. Nothing here is a lock.
A4: Date | B4: Matchup | C4: Start | D4: Market | E4: Selection | F4: Model Win% | G4: Model Fair | H4: ✏ Your Odds | I4: Implied% | J4: Your Edge (EV) | K4: ¼-Kelly % | L4: Stake $ | M4: Verdict | N4: Model read | O4: ✏ Closing | P4: CLV %
A5: 2026-07-04 | B5: Baltimore Orioles @ Cincinnati Reds | C5: 23:10 | D5: Spread | E5: Baltimore Orioles +1.5 | F5: 0.69600719 | G5: -229 | H5: 178 | I5: =IF($H$5="","",IF($H$5<0,-$H$5/(-$H$5+100),100/($H$5+100))) | J5: =IF($H$5="","",$F$5*IF($H$5<0,-100/$H$5,$H$5/100)-(1-$F$5)) | K5: =IF($H$5="","",MAX(0,($F$5*IF($H$5<0,-100/$H$5,$H$5/100)-(1-$F$5))/IF($H$5<0,-100/$H$5,$H$5/100))*'Settings'!$B$3) | L5: =IF($H$5="","",ROUND(MIN($K$5,'Settings'!$B$5)*'Settings'!$B$2,2)) | M5: =IF($J$5="","",IF($J$5<0,"Pass",IF($J$5<'Settings'!$B$4,"Thin",IF($J$5<0.06,"✅ Sharp band",IF($J$5<0.08,"Strong","⚠ Verify (stale?)"))))) | N5: Model 69.6% (fair -229). Your call. | P5: =IF(OR($H$5="",$O$5=""),"",(1+IF($H$5<0,-100/$H$5,$H$5/100))/(1+IF($O$5<0,-100/$O$5,$O$5/100))-1)
A6: 2026-07-05 | B6: New York Mets @ Atlanta Braves | C6: 16:30 | D6: Spread | E6: New York Mets +1.5 | F6: 0.67311111 | G6: -206 | H6: 170 | I6: =IF($H$6="","",IF($H$6<0,-$H$6/(-$H$6+100),100/($H$6+100))) | J6: =IF($H$6="","",$F$6*IF($H$6<0,-100/$H$6,$H$6/100)-(1-$F$6)) | K6: =IF($H$6="","",MAX(0,($F$6*IF($H$6<0,-100/$H$6,$H$6/100)-(1-$F$6))/IF($H$6<0,-100/$H$6,$H$6/100))*'Settings'!$B$3) | L6: =IF($H$6="","",ROUND(MIN($K$6,'Settings'!$B$5)*'Settings'!$B$2,2)) | M6: =IF($J$6="","",IF($J$6<0,"Pass",IF($J$6<'Settings'!$B$4,"Thin",IF($J$6<0.06,"✅ Sharp band",IF($J$6<0.08,"Strong","⚠ Verify (stale?)"))))) | N6: Model 67.3% (fair -206). Your call. | P6: =IF(OR($H$6="",$O$6=""),"",(1+IF($H$6<0,-100/$H$6,$H$6/100))/(1+IF($O$6<0,-100/$O$6,$O$6/100))-1)
A7: 2026-07-05 | B7: Boston Red Sox @ Los Angeles Angels | C7: 01:30 | D7: Moneyline | E7: Boston Red Sox | F7: 0.57351931 | G7: -134 | H7: 133 | I7: =IF($H$7="","",IF($H$7<0,-$H$7/(-$H$7+100),100/($H$7+100))) | J7: =IF($H$7="","",$F$7*IF($H$7<0,-100/$H$7,$H$7/100)-(1-$F$7)) | K7: =IF($H$7="","",MAX(0,($F$7*IF($H$7<0,-100/$H$7,$H$7/100)-(1-$F$7))/IF($H$7<0,-100/$H$7,$H$7/100))*'Settings'!$B$3) | L7: =IF($H$7="","",ROUND(MIN($K$7,'Settings'!$B$5)*'Settings'!$B$2,2)) | M7: =IF($J$7="","",IF($J$7<0,"Pass",IF($J$7<'Settings'!$B$4,"Thin",IF($J$7<0.06,"✅ Sharp band",IF($J$7<0.08,"Strong","⚠ Verify (stale?)"))))) | N7: Model 57.4% (fair -134). Your call. | P7: =IF(OR($H$7="",$O$7=""),"",(1+IF($H$7<0,-100/$H$7,$H$7/100))/(1+IF($O$7<0,-100/$O$7,$O$7/100))-1)
A8: 2026-07-04 | B8: New York Mets @ Atlanta Braves | C8: 00:08 | D8: Spread | E8: New York Mets +1.5 | F8: 0.62197183 | G8: -165 | H8: 113 | I8: =IF($H$8="","",IF($H$8<0,-$H$8/(-$H$8+100),100/($H$8+100))) | J8: =IF($H$8="","",$F$8*IF($H$8<0,-100/$H$8,$H$8/100)-(1-$F$8)) | K8: =IF($H$8="","",MAX(0,($F$8*IF($H$8<0,-100/$H$8,$H$8/100)-(1-$F$8))/IF($H$8<0,-100/$H$8,$H$8/100))*'Settings'!$B$3) | L8: =IF($H$8="","",ROUND(MIN($K$8,'Settings'!$B$5)*'Settings'!$B$2,2)) | M8: =IF($J$8="","",IF($J$8<0,"Pass",IF($J$8<'Settings'!$B$4,"Thin",IF($J$8<0.06,"✅ Sharp band",IF($J$8<0.08,"Strong","⚠ Verify (stale?)"))))) | N8: Model 62.2% (fair -165). Your call. | P8: =IF(OR($H$8="",$O$8=""),"",(1+IF($H$8<0,-100/$H$8,$H$8/100))/(1+IF($O$8<0,-100/$O$8,$O$8/100))-1)
A9: 2026-07-04 | B9: Boston Red Sox @ Los Angeles Angels | C9: 01:38 | D9: Moneyline | E9: Boston Red Sox | F9: 0.55251101 | G9: -123 | H9: 127 | I9: =IF($H$9="","",IF($H$9<0,-$H$9/(-$H$9+100),100/($H$9+100))) | J9: =IF($H$9="","",$F$9*IF($H$9<0,-100/$H$9,$H$9/100)-(1-$F$9)) | K9: =IF($H$9="","",MAX(0,($F$9*IF($H$9<0,-100/$H$9,$H$9/100)-(1-$F$9))/IF($H$9<0,-100/$H$9,$H$9/100))*'Settings'!$B$3) | L9: =IF($H$9="","",ROUND(MIN($K$9,'Settings'!$B$5)*'Settings'!$B$2,2)) | M9: =IF($J$9="","",IF($J$9<0,"Pass",IF($J$9<'Settings'!$B$4,"Thin",IF($J$9<0.06,"✅ Sharp band",IF($J$9<0.08,"Strong","⚠ Verify (stale?)"))))) | N9: Model 55.3% (fair -123). Your call. | P9: =IF(OR($H$9="",$O$9=""),"",(1+IF($H$9<0,-100/$H$9,$H$9/100))/(1+IF($O$9<0,-100/$O$9,$O$9/100))-1)
A10: 2026-07-04 | B10: Minnesota Twins @ New York Yankees | C10: 17:35 | D10: Spread | E10: Minnesota Twins +1.5 | F10: 0.62890887 | G10: -169 | H10: -103 | I10: =IF($H$10="","",IF($H$10<0,-$H$10/(-$H$10+100),100/($H$10+100))) | J10: =IF($H$10="","",$F$10*IF($H$10<0,-100/$H$10,$H$10/100)-(1-$F$10)) | K10: =IF($H$10="","",MAX(0,($F$10*IF($H$10<0,-100/$H$10,$H$10/100)-(1-$F$10))/IF($H$10<0,-100/$H$10,$H$10/100))*'Settings'!$B$3) | L10: =IF($H$10="","",ROUND(MIN($K$10,'Settings'!$B$5)*'Settings'!$B$2,2)) | M10: =IF($J$10="","",IF($J$10<0,"Pass",IF($J$10<'Settings'!$B$4,"Thin",IF($J$10<0.06,"✅ Sharp band",IF($J$10<0.08,"Strong","⚠ Verify (stale?)"))))) | N10: Model 62.9% (fair -169). Your call. | P10: =IF(OR($H$10="",$O$10=""),"",(1+IF($H$10<0,-100/$H$10,$H$10/100))/(1+IF($O$10<0,-100/$O$10,$O$10/100))-1)
A11: 2026-07-04 | B11: St. Louis Cardinals @ Chicago Cubs | C11: 00:08 | D11: Spread | E11: St. Louis Cardinals +1.5 | F11: 0.60836634 | G11: -155 | H11: 102 | I11: =IF($H$11="","",IF($H$11<0,-$H$11/(-$H$11+100),100/($H$11+100))) | J11: =IF($H$11="","",$F$11*IF($H$11<0,-100/$H$11,$H$11/100)-(1-$F$11)) | K11: =IF($H$11="","",MAX(0,($F$11*IF($H$11<0,-100/$H$11,$H$11/100)-(1-$F$11))/IF($H$11<0,-100/$H$11,$H$11/100))*'Settings'!$B$3) | L11: =IF($H$11="","",ROUND(MIN($K$11,'Settings'!$B$5)*'Settings'!$B$2,2)) | M11: =IF($J$11="","",IF($J$11<0,"Pass",IF($J$11<'Settings'!$B$4,"Thin",IF($J$11<0.06,"✅ Sharp band",IF($J$11<0.08,"Strong","⚠ Verify (stale?)"))))) | N11: Model 60.8% (fair -155). Your call. | P11: =IF(OR($H$11="",$O$11=""),"",(1+IF($H$11<0,-100/$H$11,$H$11/100))/(1+IF($O$11<0,-100/$O$11,$O$11/100))-1)
A12: 2026-07-04 | B12: Toronto Blue Jays @ Seattle Mariners | C12: 20:10 | D12: Spread | E12: Toronto Blue Jays +1.5 | F12: 0.5806 | G12: -138 | H12: 100 | I12: =IF($H$12="","",IF($H$12<0,-$H$12/(-$H$12+100),100/($H$12+100))) | J12: =IF($H$12="","",$F$12*IF($H$12<0,-100/$H$12,$H$12/100)-(1-$F$12)) | K12: =IF($H$12="","",MAX(0,($F$12*IF($H$12<0,-100/$H$12,$H$12/100)-(1-$F$12))/IF($H$12<0,-100/$H$12,$H$12/100))*'Settings'!$B$3) | L12: =IF($H$12="","",ROUND(MIN($K$12,'Settings'!$B$5)*'Settings'!$B$2,2)) | M12: =IF($J$12="","",IF($J$12<0,"Pass",IF($J$12<'Settings'!$B$4,"Thin",IF($J$12<0.06,"✅ Sharp band",IF($J$12<0.08,"Strong","⚠ Verify (stale?)"))))) | N12: Model 58.1% (fair -138). Your call. | P12: =IF(OR($H$12="",$O$12=""),"",(1+IF($H$12<0,-100/$H$12,$H$12/100))/(1+IF($O$12<0,-100/$O$12,$O$12/100))-1)
A13: 2026-07-04 | B13: Chicago White Sox @ Cleveland Guardians | C13: 23:10 | D13: Spread | E13: Chicago White Sox +1.5 | F13: 0.61786652 | G13: -162 | H13: -121 | I13: =IF($H$13="","",IF($H$13<0,-$H$13/(-$H$13+100),100/($H$13+100))) | J13: =IF($H$13="","",$F$13*IF($H$13<0,-100/$H$13,$H$13/100)-(1-$F$13)) | K13: =IF($H$13="","",MAX(0,($F$13*IF($H$13<0,-100/$H$13,$H$13/100)-(1-$F$13))/IF($H$13<0,-100/$H$13,$H$13/100))*'Settings'!$B$3) | L13: =IF($H$13="","",ROUND(MIN($K$13,'Settings'!$B$5)*'Settings'!$B$2,2)) | M13: =IF($J$13="","",IF($J$13<0,"Pass",IF($J$13<'Settings'!$B$4,"Thin",IF($J$13<0.06,"✅ Sharp band",IF($J$13<0.08,"Strong","⚠ Verify (stale?)"))))) | N13: Model 61.8% (fair -162). Your call. | P13: =IF(OR($H$13="",$O$13=""),"",(1+IF($H$13<0,-100/$H$13,$H$13/100))/(1+IF($O$13<0,-100/$O$13,$O$13/100))-1)
A14: 2026-07-05 | B14: New York Mets @ Atlanta Braves | C14: 16:30 | D14: Total | E14: Under 9.5 | F14: 0.57445825 | G14: -135 | H14: -106 | I14: =IF($H$14="","",IF($H$14<0,-$H$14/(-$H$14+100),100/($H$14+100))) | J14: =IF($H$14="","",$F$14*IF($H$14<0,-100/$H$14,$H$14/100)-(1-$F$14)) | K14: =IF($H$14="","",MAX(0,($F$14*IF($H$14<0,-100/$H$14,$H$14/100)-(1-$F$14))/IF($H$14<0,-100/$H$14,$H$14/100))*'Settings'!$B$3) | L14: =IF($H$14="","",ROUND(MIN($K$14,'Settings'!$B$5)*'Settings'!$B$2,2)) | M14: =IF($J$14="","",IF($J$14<0,"Pass",IF($J$14<'Settings'!$B$4,"Thin",IF($J$14<0.06,"✅ Sharp band",IF($J$14<0.08,"Strong","⚠ Verify (stale?)"))))) | N14: Model 57.4% (fair -135). Your call. | P14: =IF(OR($H$14="",$O$14=""),"",(1+IF($H$14<0,-100/$H$14,$H$14/100))/(1+IF($O$14<0,-100/$O$14,$O$14/100))-1)
A15: 2026-07-05 | B15: Baltimore Orioles @ Cincinnati Reds | C15: 17:05 | D15: Moneyline | E15: Baltimore Orioles | F15: 0.54318627 | G15: -119 | H15: 104 | I15: =IF($H$15="","",IF($H$15<0,-$H$15/(-$H$15+100),100/($H$15+100))) | J15: =IF($H$15="","",$F$15*IF($H$15<0,-100/$H$15,$H$15/100)-(1-$F$15)) | K15: =IF($H$15="","",MAX(0,($F$15*IF($H$15<0,-100/$H$15,$H$15/100)-(1-$F$15))/IF($H$15<0,-100/$H$15,$H$15/100))*'Settings'!$B$3) | L15: =IF($H$15="","",ROUND(MIN($K$15,'Settings'!$B$5)*'Settings'!$B$2,2)) | M15: =IF($J$15="","",IF($J$15<0,"Pass",IF($J$15<'Settings'!$B$4,"Thin",IF($J$15<0.06,"✅ Sharp band",IF($J$15<0.08,"Strong","⚠ Verify (stale?)"))))) | N15: Model 54.3% (fair -119). Your call. | P15: =IF(OR($H$15="",$O$15=""),"",(1+IF($H$15<0,-100/$H$15,$H$15/100))/(1+IF($O$15<0,-100/$O$15,$O$15/100))-1)
A16: 2026-07-05 | B16: Minnesota Twins @ New York Yankees | C16: 17:35 | D16: Moneyline | E16: Minnesota Twins | F16: 0.47227468 | G16: 112 | H16: 133 | I16: =IF($H$16="","",IF($H$16<0,-$H$16/(-$H$16+100),100/($H$16+100))) | J16: =IF($H$16="","",$F$16*IF($H$16<0,-100/$H$16,$H$16/100)-(1-$F$16)) | K16: =IF($H$16="","",MAX(0,($F$16*IF($H$16<0,-100/$H$16,$H$16/100)-(1-$F$16))/IF($H$16<0,-100/$H$16,$H$16/100))*'Settings'!$B$3) | L16: =IF($H$16="","",ROUND(MIN($K$16,'Settings'!$B$5)*'Settings'!$B$2,2)) | M16: =IF($J$16="","",IF($J$16<0,"Pass",IF($J$16<'Settings'!$B$4,"Thin",IF($J$16<0.06,"✅ Sharp band",IF($J$16<0.08,"Strong","⚠ Verify (stale?)"))))) | N16: Model 47.2% (fair +112). Your call. | P16: =IF(OR($H$16="",$O$16=""),"",(1+IF($H$16<0,-100/$H$16,$H$16/100))/(1+IF($O$16<0,-100/$O$16,$O$16/100))-1)
A17: 2026-07-04 | B17: Baltimore Orioles @ Cincinnati Reds | C17: 23:10 | D17: Moneyline | E17: Baltimore Orioles | F17: 0.49926267 | G17: 100 | H17: 117 | I17: =IF($H$17="","",IF($H$17<0,-$H$17/(-$H$17+100),100/($H$17+100))) | J17: =IF($H$17="","",$F$17*IF($H$17<0,-100/$H$17,$H$17/100)-(1-$F$17)) | K17: =IF($H$17="","",MAX(0,($F$17*IF($H$17<0,-100/$H$17,$H$17/100)-(1-$F$17))/IF($H$17<0,-100/$H$17,$H$17/100))*'Settings'!$B$3) | L17: =IF($H$17="","",ROUND(MIN($K$17,'Settings'!$B$5)*'Settings'!$B$2,2)) | M17: =IF($J$17="","",IF($J$17<0,"Pass",IF($J$17<'Settings'!$B$4,"Thin",IF($J$17<0.06,"✅ Sharp band",IF($J$17<0.08,"Strong","⚠ Verify (stale?)"))))) | N17: Model 49.9% (fair +100). Your call. | P17: =IF(OR($H$17="",$O$17=""),"",(1+IF($H$17<0,-100/$H$17,$H$17/100))/(1+IF($O$17<0,-100/$O$17,$O$17/100))-1)
A18: 2026-07-05 | B18: Baltimore Orioles @ Cincinnati Reds | C18: 17:05 | D18: Spread | E18: Baltimore Orioles -1.5 | F18: 0.42167969 | G18: 137 | H18: 156 | I18: =IF($H$18="","",IF($H$18<0,-$H$18/(-$H$18+100),100/($H$18+100))) | J18: =IF($H$18="","",$F$18*IF($H$18<0,-100/$H$18,$H$18/100)-(1-$F$18)) | K18: =IF($H$18="","",MAX(0,($F$18*IF($H$18<0,-100/$H$18,$H$18/100)-(1-$F$18))/IF($H$18<0,-100/$H$18,$H$18/100))*'Settings'!$B$3) | L18: =IF($H$18="","",ROUND(MIN($K$18,'Settings'!$B$5)*'Settings'!$B$2,2)) | M18: =IF($J$18="","",IF($J$18<0,"Pass",IF($J$18<'Settings'!$B$4,"Thin",IF($J$18<0.06,"✅ Sharp band",IF($J$18<0.08,"Strong","⚠ Verify (stale?)"))))) | N18: Model 42.2% (fair +137). Your call. | P18: =IF(OR($H$18="",$O$18=""),"",(1+IF($H$18<0,-100/$H$18,$H$18/100))/(1+IF($O$18<0,-100/$O$18,$O$18/100))-1)
A19: 2026-07-04 | B19: St. Louis Cardinals @ Chicago Cubs | C19: 00:08 | D19: Moneyline | E19: St. Louis Cardinals | F19: 0.42844 | G19: 133 | H19: 150 | I19: =IF($H$19="","",IF($H$19<0,-$H$19/(-$H$19+100),100/($H$19+100))) | J19: =IF($H$19="","",$F$19*IF($H$19<0,-100/$H$19,$H$19/100)-(1-$F$19)) | K19: =IF($H$19="","",MAX(0,($F$19*IF($H$19<0,-100/$H$19,$H$19/100)-(1-$F$19))/IF($H$19<0,-100/$H$19,$H$19/100))*'Settings'!$B$3) | L19: =IF($H$19="","",ROUND(MIN($K$19,'Settings'!$B$5)*'Settings'!$B$2,2)) | M19: =IF($J$19="","",IF($J$19<0,"Pass",IF($J$19<'Settings'!$B$4,"Thin",IF($J$19<0.06,"✅ Sharp band",IF($J$19<0.08,"Strong","⚠ Verify (stale?)"))))) | N19: Model 42.8% (fair +133). Your call. | P19: =IF(OR($H$19="",$O$19=""),"",(1+IF($H$19<0,-100/$H$19,$H$19/100))/(1+IF($O$19<0,-100/$O$19,$O$19/100))-1)
A20: 2026-07-04 | B20: Minnesota Twins @ New York Yankees | C20: 17:35 | D20: Moneyline | E20: Minnesota Twins | F20: 0.446 | G20: 124 | H20: 140 | I20: =IF($H$20="","",IF($H$20<0,-$H$20/(-$H$20+100),100/($H$20+100))) | J20: =IF($H$20="","",$F$20*IF($H$20<0,-100/$H$20,$H$20/100)-(1-$F$20)) | K20: =IF($H$20="","",MAX(0,($F$20*IF($H$20<0,-100/$H$20,$H$20/100)-(1-$F$20))/IF($H$20<0,-100/$H$20,$H$20/100))*'Settings'!$B$3) | L20: =IF($H$20="","",ROUND(MIN($K$20,'Settings'!$B$5)*'Settings'!$B$2,2)) | M20: =IF($J$20="","",IF($J$20<0,"Pass",IF($J$20<'Settings'!$B$4,"Thin",IF($J$20<0.06,"✅ Sharp band",IF($J$20<0.08,"Strong","⚠ Verify (stale?)"))))) | N20: Model 44.6% (fair +124). Your call. | P20: =IF(OR($H$20="",$O$20=""),"",(1+IF($H$20<0,-100/$H$20,$H$20/100))/(1+IF($O$20<0,-100/$O$20,$O$20/100))-1)
A21: 2026-07-04 | B21: New York Mets @ Atlanta Braves | C21: 00:08 | D21: Moneyline | E21: New York Mets | F21: 0.41621094 | G21: 140 | H21: 156 | I21: =IF($H$21="","",IF($H$21<0,-$H$21/(-$H$21+100),100/($H$21+100))) | J21: =IF($H$21="","",$F$21*IF($H$21<0,-100/$H$21,$H$21/100)-(1-$F$21)) | K21: =IF($H$21="","",MAX(0,($F$21*IF($H$21<0,-100/$H$21,$H$21/100)-(1-$F$21))/IF($H$21<0,-100/$H$21,$H$21/100))*'Settings'!$B$3) | L21: =IF($H$21="","",ROUND(MIN($K$21,'Settings'!$B$5)*'Settings'!$B$2,2)) | M21: =IF($J$21="","",IF($J$21<0,"Pass",IF($J$21<'Settings'!$B$4,"Thin",IF($J$21<0.06,"✅ Sharp band",IF($J$21<0.08,"Strong","⚠ Verify (stale?)"))))) | N21: Model 41.6% (fair +140). Your call. | P21: =IF(OR($H$21="",$O$21=""),"",(1+IF($H$21<0,-100/$H$21,$H$21/100))/(1+IF($O$21<0,-100/$O$21,$O$21/100))-1)
A22: 2026-07-05 | B22: Chicago White Sox @ Cleveland Guardians | C22: 18:00 | D22: Moneyline | E22: Chicago White Sox | F22: 0.45300429 | G22: 121 | H22: 133 | I22: =IF($H$22="","",IF($H$22<0,-$H$22/(-$H$22+100),100/($H$22+100))) | J22: =IF($H$22="","",$F$22*IF($H$22<0,-100/$H$22,$H$22/100)-(1-$F$22)) | K22: =IF($H$22="","",MAX(0,($F$22*IF($H$22<0,-100/$H$22,$H$22/100)-(1-$F$22))/IF($H$22<0,-100/$H$22,$H$22/100))*'Settings'!$B$3) | L22: =IF($H$22="","",ROUND(MIN($K$22,'Settings'!$B$5)*'Settings'!$B$2,2)) | M22: =IF($J$22="","",IF($J$22<0,"Pass",IF($J$22<'Settings'!$B$4,"Thin",IF($J$22<0.06,"✅ Sharp band",IF($J$22<0.08,"Strong","⚠ Verify (stale?)"))))) | N22: Model 45.3% (fair +121). Your call. | P22: =IF(OR($H$22="",$O$22=""),"",(1+IF($H$22<0,-100/$H$22,$H$22/100))/(1+IF($O$22<0,-100/$O$22,$O$22/100))-1)
A23: 2026-07-05 | B23: Detroit Tigers @ Texas Rangers | C23: 19:30 | D23: Moneyline | E23: Detroit Tigers | F23: 0.52615 | G23: -111 | H23: 100 | I23: =IF($H$23="","",IF($H$23<0,-$H$23/(-$H$23+100),100/($H$23+100))) | J23: =IF($H$23="","",$F$23*IF($H$23<0,-100/$H$23,$H$23/100)-(1-$F$23)) | K23: =IF($H$23="","",MAX(0,($F$23*IF($H$23<0,-100/$H$23,$H$23/100)-(1-$F$23))/IF($H$23<0,-100/$H$23,$H$23/100))*'Settings'!$B$3) | L23: =IF($H$23="","",ROUND(MIN($K$23,'Settings'!$B$5)*'Settings'!$B$2,2)) | M23: =IF($J$23="","",IF($J$23<0,"Pass",IF($J$23<'Settings'!$B$4,"Thin",IF($J$23<0.06,"✅ Sharp band",IF($J$23<0.08,"Strong","⚠ Verify (stale?)"))))) | N23: Model 52.6% (fair -111). Your call. | P23: =IF(OR($H$23="",$O$23=""),"",(1+IF($H$23<0,-100/$H$23,$H$23/100))/(1+IF($O$23<0,-100/$O$23,$O$23/100))-1)
A24: 2026-07-05 | B24: Tampa Bay Rays @ Houston Astros | C24: 19:30 | D24: Moneyline | E24: Houston Astros | F24: 0.47328829 | G24: 111 | H24: 122 | I24: =IF($H$24="","",IF($H$24<0,-$H$24/(-$H$24+100),100/($H$24+100))) | J24: =IF($H$24="","",$F$24*IF($H$24<0,-100/$H$24,$H$24/100)-(1-$F$24)) | K24: =IF($H$24="","",MAX(0,($F$24*IF($H$24<0,-100/$H$24,$H$24/100)-(1-$F$24))/IF($H$24<0,-100/$H$24,$H$24/100))*'Settings'!$B$3) | L24: =IF($H$24="","",ROUND(MIN($K$24,'Settings'!$B$5)*'Settings'!$B$2,2)) | M24: =IF($J$24="","",IF($J$24<0,"Pass",IF($J$24<'Settings'!$B$4,"Thin",IF($J$24<0.06,"✅ Sharp band",IF($J$24<0.08,"Strong","⚠ Verify (stale?)"))))) | N24: Model 47.3% (fair +111). Your call. | P24: =IF(OR($H$24="",$O$24=""),"",(1+IF($H$24<0,-100/$H$24,$H$24/100))/(1+IF($O$24<0,-100/$O$24,$O$24/100))-1)
A25: 2026-07-05 | B25: New York Mets @ Atlanta Braves | C25: 16:30 | D25: Moneyline | E25: New York Mets | F25: 0.49 | G25: 104 | H25: 113 | I25: =IF($H$25="","",IF($H$25<0,-$H$25/(-$H$25+100),100/($H$25+100))) | J25: =IF($H$25="","",$F$25*IF($H$25<0,-100/$H$25,$H$25/100)-(1-$F$25)) | K25: =IF($H$25="","",MAX(0,($F$25*IF($H$25<0,-100/$H$25,$H$25/100)-(1-$F$25))/IF($H$25<0,-100/$H$25,$H$25/100))*'Settings'!$B$3) | L25: =IF($H$25="","",ROUND(MIN($K$25,'Settings'!$B$5)*'Settings'!$B$2,2)) | M25: =IF($J$25="","",IF($J$25<0,"Pass",IF($J$25<'Settings'!$B$4,"Thin",IF($J$25<0.06,"✅ Sharp band",IF($J$25<0.08,"Strong","⚠ Verify (stale?)"))))) | N25: Model 49.0% (fair +104). Your call. | P25: =IF(OR($H$25="",$O$25=""),"",(1+IF($H$25<0,-100/$H$25,$H$25/100))/(1+IF($O$25<0,-100/$O$25,$O$25/100))-1)
A26: 2026-07-05 | B26: San Francisco Giants @ Colorado Rockies | C26: 20:00 | D26: Total | E26: Under 13.5 | F26: 0.54638571 | G26: -120 | H26: -110 | I26: =IF($H$26="","",IF($H$26<0,-$H$26/(-$H$26+100),100/($H$26+100))) | J26: =IF($H$26="","",$F$26*IF($H$26<0,-100/$H$26,$H$26/100)-(1-$F$26)) | K26: =IF($H$26="","",MAX(0,($F$26*IF($H$26<0,-100/$H$26,$H$26/100)-(1-$F$26))/IF($H$26<0,-100/$H$26,$H$26/100))*'Settings'!$B$3) | L26: =IF($H$26="","",ROUND(MIN($K$26,'Settings'!$B$5)*'Settings'!$B$2,2)) | M26: =IF($J$26="","",IF($J$26<0,"Pass",IF($J$26<'Settings'!$B$4,"Thin",IF($J$26<0.06,"✅ Sharp band",IF($J$26<0.08,"Strong","⚠ Verify (stale?)"))))) | N26: Model 54.6% (fair -120). Your call. | P26: =IF(OR($H$26="",$O$26=""),"",(1+IF($H$26<0,-100/$H$26,$H$26/100))/(1+IF($O$26<0,-100/$O$26,$O$26/100))-1)
A27: 2026-07-05 | B27: Pittsburgh Pirates @ Washington Nationals | C27: 17:00 | D27: Moneyline | E27: Washington Nationals | F27: 0.51117647 | G27: -105 | H27: 104 | I27: =IF($H$27="","",IF($H$27<0,-$H$27/(-$H$27+100),100/($H$27+100))) | J27: =IF($H$27="","",$F$27*IF($H$27<0,-100/$H$27,$H$27/100)-(1-$F$27)) | K27: =IF($H$27="","",MAX(0,($F$27*IF($H$27<0,-100/$H$27,$H$27/100)-(1-$F$27))/IF($H$27<0,-100/$H$27,$H$27/100))*'Settings'!$B$3) | L27: =IF($H$27="","",ROUND(MIN($K$27,'Settings'!$B$5)*'Settings'!$B$2,2)) | M27: =IF($J$27="","",IF($J$27<0,"Pass",IF($J$27<'Settings'!$B$4,"Thin",IF($J$27<0.06,"✅ Sharp band",IF($J$27<0.08,"Strong","⚠ Verify (stale?)"))))) | N27: Model 51.1% (fair -105). Your call. | P27: =IF(OR($H$27="",$O$27=""),"",(1+IF($H$27<0,-100/$H$27,$H$27/100))/(1+IF($O$27<0,-100/$O$27,$O$27/100))-1)
A28: 2026-07-05 | B28: Minnesota Twins @ New York Yankees | C28: 17:35 | D28: Spread | E28: Minnesota Twins +1.5 | F28: 0.63636923 | G28: -175 | H28: -160 | I28: =IF($H$28="","",IF($H$28<0,-$H$28/(-$H$28+100),100/($H$28+100))) | J28: =IF($H$28="","",$F$28*IF($H$28<0,-100/$H$28,$H$28/100)-(1-$F$28)) | K28: =IF($H$28="","",MAX(0,($F$28*IF($H$28<0,-100/$H$28,$H$28/100)-(1-$F$28))/IF($H$28<0,-100/$H$28,$H$28/100))*'Settings'!$B$3) | L28: =IF($H$28="","",ROUND(MIN($K$28,'Settings'!$B$5)*'Settings'!$B$2,2)) | M28: =IF($J$28="","",IF($J$28<0,"Pass",IF($J$28<'Settings'!$B$4,"Thin",IF($J$28<0.06,"✅ Sharp band",IF($J$28<0.08,"Strong","⚠ Verify (stale?)"))))) | N28: Model 63.6% (fair -175). Your call. | P28: =IF(OR($H$28="",$O$28=""),"",(1+IF($H$28<0,-100/$H$28,$H$28/100))/(1+IF($O$28<0,-100/$O$28,$O$28/100))-1)
A29: 2026-07-05 | B29: Chicago White Sox @ Cleveland Guardians | C29: 18:00 | D29: Total | E29: Over 8.5 | F29: 0.52627059 | G29: -111 | H29: -104 | I29: =IF($H$29="","",IF($H$29<0,-$H$29/(-$H$29+100),100/($H$29+100))) | J29: =IF($H$29="","",$F$29*IF($H$29<0,-100/$H$29,$H$29/100)-(1-$F$29)) | K29: =IF($H$29="","",MAX(0,($F$29*IF($H$29<0,-100/$H$29,$H$29/100)-(1-$F$29))/IF($H$29<0,-100/$H$29,$H$29/100))*'Settings'!$B$3) | L29: =IF($H$29="","",ROUND(MIN($K$29,'Settings'!$B$5)*'Settings'!$B$2,2)) | M29: =IF($J$29="","",IF($J$29<0,"Pass",IF($J$29<'Settings'!$B$4,"Thin",IF($J$29<0.06,"✅ Sharp band",IF($J$29<0.08,"Strong","⚠ Verify (stale?)"))))) | N29: Model 52.6% (fair -111). Your call. | P29: =IF(OR($H$29="",$O$29=""),"",(1+IF($H$29<0,-100/$H$29,$H$29/100))/(1+IF($O$29<0,-100/$O$29,$O$29/100))-1)

Sheet MLB Games
A1: MLB — game markets
A2: Moneyline · Total · Spread. Yellow = your price.
A4: Date | B4: Matchup | C4: Start | D4: Market | E4: Selection | F4: Model Win% | G4: Model Fair | H4: ✏ Your Odds | I4: Implied% | J4: Your Edge (EV) | K4: ¼-Kelly % | L4: Stake $ | M4: Verdict | N4: Model read | O4: ✏ Closing | P4: CLV %
A5: 2026-07-04 | B5: Pittsburgh Pirates @ Washington Nationals | C5: 15:05 | D5: Moneyline | E5: Pittsburgh Pirates | F5: 0.57729836 | G5: -137 | H5: -144 | I5: =IF($H$5="","",IF($H$5<0,-$H$5/(-$H$5+100),100/($H$5+100))) | J5: =IF($H$5="","",$F$5*IF($H$5<0,-100/$H$5,$H$5/100)-(1-$F$5)) | K5: =IF($H$5="","",MAX(0,($F$5*IF($H$5<0,-100/$H$5,$H$5/100)-(1-$F$5))/IF($H$5<0,-100/$H$5,$H$5/100))*'Settings'!$B$3) | L5: =IF($H$5="","",ROUND(MIN($K$5,'Settings'!$B$5)*'Settings'!$B$2,2)) | M5: =IF($J$5="","",IF($J$5<0,"Pass",IF($J$5<'Settings'!$B$4,"Thin",IF($J$5<0.06,"✅ Sharp band",IF($J$5<0.08,"Strong","⚠ Verify (stale?)"))))) | N5: Model 57.7% (fair -137). Your call. | P5: =IF(OR($H$5="",$O$5=""),"",(1+IF($H$5<0,-100/$H$5,$H$5/100))/(1+IF($O$5<0,-100/$O$5,$O$5/100))-1)
A6: 2026-07-04 | B6: Pittsburgh Pirates @ Washington Nationals | C6: 15:05 | D6: Moneyline | E6: Washington Nationals | F6: 0.42270492 | G6: 137 | H6: 144 | I6: =IF($H$6="","",IF($H$6<0,-$H$6/(-$H$6+100),100/($H$6+100))) | J6: =IF($H$6="","",$F$6*IF($H$6<0,-100/$H$6,$H$6/100)-(1-$F$6)) | K6: =IF($H$6="","",MAX(0,($F$6*IF($H$6<0,-100/$H$6,$H$6/100)-(1-$F$6))/IF($H$6<0,-100/$H$6,$H$6/100))*'Settings'!$B$3) | L6: =IF($H$6="","",ROUND(MIN($K$6,'Settings'!$B$5)*'Settings'!$B$2,2)) | M6: =IF($J$6="","",IF($J$6<0,"Pass",IF($J$6<'Settings'!$B$4,"Thin",IF($J$6<0.06,"✅ Sharp band",IF($J$6<0.08,"Strong","⚠ Verify (stale?)"))))) | N6: Model 42.3% (fair +137). Your call. | P6: =IF(OR($H$6="",$O$6=""),"",(1+IF($H$6<0,-100/$H$6,$H$6/100))/(1+IF($O$6<0,-100/$O$6,$O$6/100))-1)
A7: 2026-07-04 | B7: Pittsburgh Pirates @ Washington Nationals | C7: 15:05 | D7: Total | E7: Over 10.5 | F7: 0.443 | G7: 126 | H7: 113 | I7: =IF($H$7="","",IF($H$7<0,-$H$7/(-$H$7+100),100/($H$7+100))) | J7: =IF($H$7="","",$F$7*IF($H$7<0,-100/$H$7,$H$7/100)-(1-$F$7)) | K7: =IF($H$7="","",MAX(0,($F$7*IF($H$7<0,-100/$H$7,$H$7/100)-(1-$F$7))/IF($H$7<0,-100/$H$7,$H$7/100))*'Settings'!$B$3) | L7: =IF($H$7="","",ROUND(MIN($K$7,'Settings'!$B$5)*'Settings'!$B$2,2)) | M7: =IF($J$7="","",IF($J$7<0,"Pass",IF($J$7<'Settings'!$B$4,"Thin",IF($J$7<0.06,"✅ Sharp band",IF($J$7<0.08,"Strong","⚠ Verify (stale?)"))))) | N7: Model 44.3% (fair +126). Your call. | P7: =IF(OR($H$7="",$O$7=""),"",(1+IF($H$7<0,-100/$H$7,$H$7/100))/(1+IF($O$7<0,-100/$O$7,$O$7/100))-1)
A8: 2026-07-04 | B8: Pittsburgh Pirates @ Washington Nationals | C8: 15:05 | D8: Total | E8: Under 10.5 | F8: 0.557 | G8: -126 | H8: 125 | I8: =IF($H$8="","",IF($H$8<0,-$H$8/(-$H$8+100),100/($H$8+100))) | J8: =IF($H$8="","",$F$8*IF($H$8<0,-100/$H$8,$H$8/100)-(1-$F$8)) | K8: =IF($H$8="","",MAX(0,($F$8*IF($H$8<0,-100/$H$8,$H$8/100)-(1-$F$8))/IF($H$8<0,-100/$H$8,$H$8/100))*'Settings'!$B$3) | L8: =IF($H$8="","",ROUND(MIN($K$8,'Settings'!$B$5)*'Settings'!$B$2,2)) | M8: =IF($J$8="","",IF($J$8<0,"Pass",IF($J$8<'Settings'!$B$4,"Thin",IF($J$8<0.06,"✅ Sharp band",IF($J$8<0.08,"Strong","⚠ Verify (stale?)"))))) | N8: Model 55.7% (fair -126). Your call. | P8: =IF(OR($H$8="",$O$8=""),"",(1+IF($H$8<0,-100/$H$8,$H$8/100))/(1+IF($O$8<0,-100/$O$8,$O$8/100))-1)
A9: 2026-07-04 | B9: Minnesota Twins @ New York Yankees | C9: 17:35 | D9: Moneyline | E9: Minnesota Twins | F9: 0.446 | G9: 124 | H9: 140 | I9: =IF($H$9="","",IF($H$9<0,-$H$9/(-$H$9+100),100/($H$9+100))) | J9: =IF($H$9="","",$F$9*IF($H$9<0,-100/$H$9,$H$9/100)-(1-$F$9)) | K9: =IF($H$9="","",MAX(0,($F$9*IF($H$9<0,-100/$H$9,$H$9/100)-(1-$F$9))/IF($H$9<0,-100/$H$9,$H$9/100))*'Settings'!$B$3) | L9: =IF($H$9="","",ROUND(MIN($K$9,'Settings'!$B$5)*'Settings'!$B$2,2)) | M9: =IF($J$9="","",IF($J$9<0,"Pass",IF($J$9<'Settings'!$B$4,"Thin",IF($J$9<0.06,"✅ Sharp band",IF($J$9<0.08,"Strong","⚠ Verify (stale?)"))))) | N9: Model 44.6% (fair +124). Your call. | P9: =IF(OR($H$9="",$O$9=""),"",(1+IF($H$9<0,-100/$H$9,$H$9/100))/(1+IF($O$9<0,-100/$O$9,$O$9/100))-1)
A10: 2026-07-04 | B10: Minnesota Twins @ New York Yankees | C10: 17:35 | D10: Moneyline | E10: New York Yankees | F10: 0.55399544 | G10: -124 | H10: -141 | I10: =IF($H$10="","",IF($H$10<0,-$H$10/(-$H$10+100),100/($H$10+100))) | J10: =IF($H$10="","",$F$10*IF($H$10<0,-100/$H$10,$H$10/100)-(1-$F$10)) | K10: =IF($H$10="","",MAX(0,($F$10*IF($H$10<0,-100/$H$10,$H$10/100)-(1-$F$10))/IF($H$10<0,-100/$H$10,$H$10/100))*'Settings'!$B$3) | L10: =IF($H$10="","",ROUND(MIN($K$10,'Settings'!$B$5)*'Settings'!$B$2,2)) | M10: =IF($J$10="","",IF($J$10<0,"Pass",IF($J$10<'Settings'!$B$4,"Thin",IF($J$10<0.06,"✅ Sharp band",IF($J$10<0.08,"Strong","⚠ Verify (stale?)"))))) | N10: Model 55.4% (fair -124). Your call. | P10: =IF(OR($H$10="",$O$10=""),"",(1+IF($H$10<0,-100/$H$10,$H$10/100))/(1+IF($O$10<0,-100/$O$10,$O$10/100))-1)
A11: 2026-07-04 | B11: Minnesota Twins @ New York Yankees | C11: 17:35 | D11: Total | E11: Over 11 | F11: 0.3454 | G11: 190 | H11: 125 | I11: =IF($H$11="","",IF($H$11<0,-$H$11/(-$H$11+100),100/($H$11+100))) | J11: =IF($H$11="","",$F$11*IF($H$11<0,-100/$H$11,$H$11/100)-(1-$F$11)) | K11: =IF($H$11="","",MAX(0,($F$11*IF($H$11<0,-100/$H$11,$H$11/100)-(1-$F$11))/IF($H$11<0,-100/$H$11,$H$11/100))*'Settings'!$B$3) | L11: =IF($H$11="","",ROUND(MIN($K$11,'Settings'!$B$5)*'Settings'!$B$2,2)) | M11: =IF($J$11="","",IF($J$11<0,"Pass",IF($J$11<'Settings'!$B$4,"Thin",IF($J$11<0.06,"✅ Sharp band",IF($J$11<0.08,"Strong","⚠ Verify (stale?)"))))) | N11: Model 34.5% (fair +190). Your call. | P11: =IF(OR($H$11="",$O$11=""),"",(1+IF($H$11<0,-100/$H$11,$H$11/100))/(1+IF($O$11<0,-100/$O$11,$O$11/100))-1)
A12: 2026-07-04 | B12: Minnesota Twins @ New York Yankees | C12: 17:35 | D12: Total | E12: Under 11 | F12: 0.6546 | G12: -190 | H12: -102 | I12: =IF($H$12="","",IF($H$12<0,-$H$12/(-$H$12+100),100/($H$12+100))) | J12: =IF($H$12="","",$F$12*IF($H$12<0,-100/$H$12,$H$12/100)-(1-$F$12)) | K12: =IF($H$12="","",MAX(0,($F$12*IF($H$12<0,-100/$H$12,$H$12/100)-(1-$F$12))/IF($H$12<0,-100/$H$12,$H$12/100))*'Settings'!$B$3) | L12: =IF($H$12="","",ROUND(MIN($K$12,'Settings'!$B$5)*'Settings'!$B$2,2)) | M12: =IF($J$12="","",IF($J$12<0,"Pass",IF($J$12<'Settings'!$B$4,"Thin",IF($J$12<0.06,"✅ Sharp band",IF($J$12<0.08,"Strong","⚠ Verify (stale?)"))))) | N12: Model 65.5% (fair -190). Your call. | P12: =IF(OR($H$12="",$O$12=""),"",(1+IF($H$12<0,-100/$H$12,$H$12/100))/(1+IF($O$12<0,-100/$O$12,$O$12/100))-1)
A13: 2026-07-04 | B13: Minnesota Twins @ New York Yankees | C13: 17:35 | D13: Spread | E13: New York Yankees -1.5 | F13: 0.37110638 | G13: 169 | H13: 135 | I13: =IF($H$13="","",IF($H$13<0,-$H$13/(-$H$13+100),100/($H$13+100))) | J13: =IF($H$13="","",$F$13*IF($H$13<0,-100/$H$13,$H$13/100)-(1-$F$13)) | K13: =IF($H$13="","",MAX(0,($F$13*IF($H$13<0,-100/$H$13,$H$13/100)-(1-$F$13))/IF($H$13<0,-100/$H$13,$H$13/100))*'Settings'!$B$3) | L13: =IF($H$13="","",ROUND(MIN($K$13,'Settings'!$B$5)*'Settings'!$B$2,2)) | M13: =IF($J$13="","",IF($J$13<0,"Pass",IF($J$13<'Settings'!$B$4,"Thin",IF($J$13<0.06,"✅ Sharp band",IF($J$13<0.08,"Strong","⚠ Verify (stale?)"))))) | N13: Model 37.1% (fair +169). Your call. | P13: =IF(OR($H$13="",$O$13=""),"",(1+IF($H$13<0,-100/$H$13,$H$13/100))/(1+IF($O$13<0,-100/$O$13,$O$13/100))-1)
A14: 2026-07-04 | B14: Minnesota Twins @ New York Yankees | C14: 17:35 | D14: Spread | E14: Minnesota Twins +1.5 | F14: 0.62890887 | G14: -169 | H14: -103 | I14: =IF($H$14="","",IF($H$14<0,-$H$14/(-$H$14+100),100/($H$14+100))) | J14: =IF($H$14="","",$F$14*IF($H$14<0,-100/$H$14,$H$14/100)-(1-$F$14)) | K14: =IF($H$14="","",MAX(0,($F$14*IF($H$14<0,-100/$H$14,$H$14/100)-(1-$F$14))/IF($H$14<0,-100/$H$14,$H$14/100))*'Settings'!$B$3) | L14: =IF($H$14="","",ROUND(MIN($K$14,'Settings'!$B$5)*'Settings'!$B$2,2)) | M14: =IF($J$14="","",IF($J$14<0,"Pass",IF($J$14<'Settings'!$B$4,"Thin",IF($J$14<0.06,"✅ Sharp band",IF($J$14<0.08,"Strong","⚠ Verify (stale?)"))))) | N14: Model 62.9% (fair -169). Your call. | P14: =IF(OR($H$14="",$O$14=""),"",(1+IF($H$14<0,-100/$H$14,$H$14/100))/(1+IF($O$14<0,-100/$O$14,$O$14/100))-1)
A15: 2026-07-04 | B15: Detroit Tigers @ Texas Rangers | C15: 20:05 | D15: Moneyline | E15: Detroit Tigers | F15: 0.52167209 | G15: -109 | H15: -115 | I15: =IF($H$15="","",IF($H$15<0,-$H$15/(-$H$15+100),100/($H$15+100))) | J15: =IF($H$15="","",$F$15*IF($H$15<0,-100/$H$15,$H$15/100)-(1-$F$15)) | K15: =IF($H$15="","",MAX(0,($F$15*IF($H$15<0,-100/$H$15,$H$15/100)-(1-$F$15))/IF($H$15<0,-100/$H$15,$H$15/100))*'Settings'!$B$3) | L15: =IF($H$15="","",ROUND(MIN($K$15,'Settings'!$B$5)*'Settings'!$B$2,2)) | M15: =IF($J$15="","",IF($J$15<0,"Pass",IF($J$15<'Settings'!$B$4,"Thin",IF($J$15<0.06,"✅ Sharp band",IF($J$15<0.08,"Strong","⚠ Verify (stale?)"))))) | N15: Model 52.2% (fair -109). Your call. | P15: =IF(OR($H$15="",$O$15=""),"",(1+IF($H$15<0,-100/$H$15,$H$15/100))/(1+IF($O$15<0,-100/$O$15,$O$15/100))-1)
A16: 2026-07-04 | B16: Detroit Tigers @ Texas Rangers | C16: 20:05 | D16: Moneyline | E16: Texas Rangers | F16: 0.47830986 | G16: 109 | H16: 113 | I16: =IF($H$16="","",IF($H$16<0,-$H$16/(-$H$16+100),100/($H$16+100))) | J16: =IF($H$16="","",$F$16*IF($H$16<0,-100/$H$16,$H$16/100)-(1-$F$16)) | K16: =IF($H$16="","",MAX(0,($F$16*IF($H$16<0,-100/$H$16,$H$16/100)-(1-$F$16))/IF($H$16<0,-100/$H$16,$H$16/100))*'Settings'!$B$3) | L16: =IF($H$16="","",ROUND(MIN($K$16,'Settings'!$B$5)*'Settings'!$B$2,2)) | M16: =IF($J$16="","",IF($J$16<0,"Pass",IF($J$16<'Settings'!$B$4,"Thin",IF($J$16<0.06,"✅ Sharp band",IF($J$16<0.08,"Strong","⚠ Verify (stale?)"))))) | N16: Model 47.8% (fair +109). Your call. | P16: =IF(OR($H$16="",$O$16=""),"",(1+IF($H$16<0,-100/$H$16,$H$16/100))/(1+IF($O$16<0,-100/$O$16,$O$16/100))-1)
A17: 2026-07-04 | B17: Detroit Tigers @ Texas Rangers | C17: 20:05 | D17: Total | E17: Over 8.5 | F17: 0.5843 | G17: -141 | H17: 100 | I17: =IF($H$17="","",IF($H$17<0,-$H$17/(-$H$17+100),100/($H$17+100))) | J17: =IF($H$17="","",$F$17*IF($H$17<0,-100/$H$17,$H$17/100)-(1-$F$17)) | K17: =IF($H$17="","",MAX(0,($F$17*IF($H$17<0,-100/$H$17,$H$17/100)-(1-$F$17))/IF($H$17<0,-100/$H$17,$H$17/100))*'Settings'!$B$3) | L17: =IF($H$17="","",ROUND(MIN($K$17,'Settings'!$B$5)*'Settings'!$B$2,2)) | M17: =IF($J$17="","",IF($J$17<0,"Pass",IF($J$17<'Settings'!$B$4,"Thin",IF($J$17<0.06,"✅ Sharp band",IF($J$17<0.08,"Strong","⚠ Verify (stale?)"))))) | N17: Model 58.4% (fair -141). Your call. | P17: =IF(OR($H$17="",$O$17=""),"",(1+IF($H$17<0,-100/$H$17,$H$17/100))/(1+IF($O$17<0,-100/$O$17,$O$17/100))-1)
A18: 2026-07-04 | B18: Detroit Tigers @ Texas Rangers | C18: 20:05 | D18: Total | E18: Under 8.5 | F18: 0.4157 | G18: 141 | H18: 114 | I18: =IF($H$18="","",IF($H$18<0,-$H$18/(-$H$18+100),100/($H$18+100))) | J18: =IF($H$18="","",$F$18*IF($H$18<0,-100/$H$18,$H$18/100)-(1-$F$18)) | K18: =IF($H$18="","",MAX(0,($F$18*IF($H$18<0,-100/$H$18,$H$18/100)-(1-$F$18))/IF($H$18<0,-100/$H$18,$H$18/100))*'Settings'!$B$3) | L18: =IF($H$18="","",ROUND(MIN($K$18,'Settings'!$B$5)*'Settings'!$B$2,2)) | M18: =IF($J$18="","",IF($J$18<0,"Pass",IF($J$18<'Settings'!$B$4,"Thin",IF($J$18<0.06,"✅ Sharp band",IF($J$18<0.08,"Strong","⚠ Verify (stale?)"))))) | N18: Model 41.6% (fair +141). Your call. | P18: =IF(OR($H$18="",$O$18=""),"",(1+IF($H$18<0,-100/$H$18,$H$18/100))/(1+IF($O$18<0,-100/$O$18,$O$18/100))-1)
A19: 2026-07-04 | B19: Toronto Blue Jays @ Seattle Mariners | C19: 20:10 | D19: Moneyline | E19: Toronto Blue Jays | F19: 0.40728 | G19: 146 | H19: 150 | I19: =IF($H$19="","",IF($H$19<0,-$H$19/(-$H$19+100),100/($H$19+100))) | J19: =IF($H$19="","",$F$19*IF($H$19<0,-100/$H$19,$H$19/100)-(1-$F$19)) | K19: =IF($H$19="","",MAX(0,($F$19*IF($H$19<0,-100/$H$19,$H$19/100)-(1-$F$19))/IF($H$19<0,-100/$H$19,$H$19/100))*'Settings'!$B$3) | L19: =IF($H$19="","",ROUND(MIN($K$19,'Settings'!$B$5)*'Settings'!$B$2,2)) | M19: =IF($J$19="","",IF($J$19<0,"Pass",IF($J$19<'Settings'!$B$4,"Thin",IF($J$19<0.06,"✅ Sharp band",IF($J$19<0.08,"Strong","⚠ Verify (stale?)"))))) | N19: Model 40.7% (fair +146). Your call. | P19: =IF(OR($H$19="",$O$19=""),"",(1+IF($H$19<0,-100/$H$19,$H$19/100))/(1+IF($O$19<0,-100/$O$19,$O$19/100))-1)
A20: 2026-07-04 | B20: Toronto Blue Jays @ Seattle Mariners | C20: 20:10 | D20: Moneyline | E20: Seattle Mariners | F20: 0.59274 | G20: -146 | H20: -150 | I20: =IF($H$20="","",IF($H$20<0,-$H$20/(-$H$20+100),100/($H$20+100))) | J20: =IF($H$20="","",$F$20*IF($H$20<0,-100/$H$20,$H$20/100)-(1-$F$20)) | K20: =IF($H$20="","",MAX(0,($F$20*IF($H$20<0,-100/$H$20,$H$20/100)-(1-$F$20))/IF($H$20<0,-100/$H$20,$H$20/100))*'Settings'!$B$3) | L20: =IF($H$20="","",ROUND(MIN($K$20,'Settings'!$B$5)*'Settings'!$B$2,2)) | M20: =IF($J$20="","",IF($J$20<0,"Pass",IF($J$20<'Settings'!$B$4,"Thin",IF($J$20<0.06,"✅ Sharp band",IF($J$20<0.08,"Strong","⚠ Verify (stale?)"))))) | N20: Model 59.3% (fair -146). Your call. | P20: =IF(OR($H$20="",$O$20=""),"",(1+IF($H$20<0,-100/$H$20,$H$20/100))/(1+IF($O$20<0,-100/$O$20,$O$20/100))-1)
A21: 2026-07-04 | B21: Toronto Blue Jays @ Seattle Mariners | C21: 20:10 | D21: Total | E21: Over 7.5 | F21: 0.457 | G21: 119 | H21: 100 | I21: =IF($H$21="","",IF($H$21<0,-$H$21/(-$H$21+100),100/($H$21+100))) | J21: =IF($H$21="","",$F$21*IF($H$21<0,-100/$H$21,$H$21/100)-(1-$F$21)) | K21: =IF($H$21="","",MAX(0,($F$21*IF($H$21<0,-100/$H$21,$H$21/100)-(1-$F$21))/IF($H$21<0,-100/$H$21,$H$21/100))*'Settings'!$B$3) | L21: =IF($H$21="","",ROUND(MIN($K$21,'Settings'!$B$5)*'Settings'!$B$2,2)) | M21: =IF($J$21="","",IF($J$21<0,"Pass",IF($J$21<'Settings'!$B$4,"Thin",IF($J$21<0.06,"✅ Sharp band",IF($J$21<0.08,"Strong","⚠ Verify (stale?)"))))) | N21: Model 45.7% (fair +119). Your call. | P21: =IF(OR($H$21="",$O$21=""),"",(1+IF($H$21<0,-100/$H$21,$H$21/100))/(1+IF($O$21<0,-100/$O$21,$O$21/100))-1)
A22: 2026-07-04 | B22: Toronto Blue Jays @ Seattle Mariners | C22: 20:10 | D22: Total | E22: Under 7.5 | F22: 0.543 | G22: -119 | H22: 127 | I22: =IF($H$22="","",IF($H$22<0,-$H$22/(-$H$22+100),100/($H$22+100))) | J22: =IF($H$22="","",$F$22*IF($H$22<0,-100/$H$22,$H$22/100)-(1-$F$22)) | K22: =IF($H$22="","",MAX(0,($F$22*IF($H$22<0,-100/$H$22,$H$22/100)-(1-$F$22))/IF($H$22<0,-100/$H$22,$H$22/100))*'Settings'!$B$3) | L22: =IF($H$22="","",ROUND(MIN($K$22,'Settings'!$B$5)*'Settings'!$B$2,2)) | M22: =IF($J$22="","",IF($J$22<0,"Pass",IF($J$22<'Settings'!$B$4,"Thin",IF($J$22<0.06,"✅ Sharp band",IF($J$22<0.08,"Strong","⚠ Verify (stale?)"))))) | N22: Model 54.3% (fair -119). Your call. | P22: =IF(OR($H$22="",$O$22=""),"",(1+IF($H$22<0,-100/$H$22,$H$22/100))/(1+IF($O$22<0,-100/$O$22,$O$22/100))-1)
A23: 2026-07-04 | B23: Toronto Blue Jays @ Seattle Mariners | C23: 20:10 | D23: Spread | E23: Seattle Mariners -1.5 | F23: 0.41941909 | G23: 138 | H23: 141 | I23: =IF($H$23="","",IF($H$23<0,-$H$23/(-$H$23+100),100/($H$23+100))) | J23: =IF($H$23="","",$F$23*IF($H$23<0,-100/$H$23,$H$23/100)-(1-$F$23)) | K23: =IF($H$23="","",MAX(0,($F$23*IF($H$23<0,-100/$H$23,$H$23/100)-(1-$F$23))/IF($H$23<0,-100/$H$23,$H$23/100))*'Settings'!$B$3) | L23: =IF($H$23="","",ROUND(MIN($K$23,'Settings'!$B$5)*'Settings'!$B$2,2)) | M23: =IF($J$23="","",IF($J$23<0,"Pass",IF($J$23<'Settings'!$B$4,"Thin",IF($J$23<0.06,"✅ Sharp band",IF($J$23<0.08,"Strong","⚠ Verify (stale?)"))))) | N23: Model 41.9% (fair +138). Your call. | P23: =IF(OR($H$23="",$O$23=""),"",(1+IF($H$23<0,-100/$H$23,$H$23/100))/(1+IF($O$23<0,-100/$O$23,$O$23/100))-1)
A24: 2026-07-04 | B24: Toronto Blue Jays @ Seattle Mariners | C24: 20:10 | D24: Spread | E24: Toronto Blue Jays +1.5 | F24: 0.5806 | G24: -138 | H24: 100 | I24: =IF($H$24="","",IF($H$24<0,-$H$24/(-$H$24+100),100/($H$24+100))) | J24: =IF($H$24="","",$F$24*IF($H$24<0,-100/$H$24,$H$24/100)-(1-$F$24)) | K24: =IF($H$24="","",MAX(0,($F$24*IF($H$24<0,-100/$H$24,$H$24/100)-(1-$F$24))/IF($H$24<0,-100/$H$24,$H$24/100))*'Settings'!$B$3) | L24: =IF($H$24="","",ROUND(MIN($K$24,'Settings'!$B$5)*'Settings'!$B$2,2)) | M24: =IF($J$24="","",IF($J$24<0,"Pass",IF($J$24<'Settings'!$B$4,"Thin",IF($J$24<0.06,"✅ Sharp band",IF($J$24<0.08,"Strong","⚠ Verify (stale?)"))))) | N24: Model 58.1% (fair -138). Your call. | P24: =IF(OR($H$24="",$O$24=""),"",(1+IF($H$24<0,-100/$H$24,$H$24/100))/(1+IF($O$24<0,-100/$O$24,$O$24/100))-1)
A25: 2026-07-04 | B25: Baltimore Orioles @ Cincinnati Reds | C25: 23:10 | D25: Moneyline | E25: Baltimore Orioles | F25: 0.49926267 | G25: 100 | H25: 117 | I25: =IF($H$25="","",IF($H$25<0,-$H$25/(-$H$25+100),100/($H$25+100))) | J25: =IF($H$25="","",$F$25*IF($H$25<0,-100/$H$25,$H$25/100)-(1-$F$25)) | K25: =IF($H$25="","",MAX(0,($F$25*IF($H$25<0,-100/$H$25,$H$25/100)-(1-$F$25))/IF($H$25<0,-100/$H$25,$H$25/100))*'Settings'!$B$3) | L25: =IF($H$25="","",ROUND(MIN($K$25,'Settings'!$B$5)*'Settings'!$B$2,2)) | M25: =IF($J$25="","",IF($J$25<0,"Pass",IF($J$25<'Settings'!$B$4,"Thin",IF($J$25<0.06,"✅ Sharp band",IF($J$25<0.08,"Strong","⚠ Verify (stale?)"))))) | N25: Model 49.9% (fair +100). Your call. | P25: =IF(OR($H$25="",$O$25=""),"",(1+IF($H$25<0,-100/$H$25,$H$25/100))/(1+IF($O$25<0,-100/$O$25,$O$25/100))-1)
A26: 2026-07-04 | B26: Baltimore Orioles @ Cincinnati Reds | C26: 23:10 | D26: Moneyline | E26: Cincinnati Reds | F26: 0.50072727 | G26: -100 | H26: -120 | I26: =IF($H$26="","",IF($H$26<0,-$H$26/(-$H$26+100),100/($H$26+100))) | J26: =IF($H$26="","",$F$26*IF($H$26<0,-100/$H$26,$H$26/100)-(1-$F$26)) | K26: =IF($H$26="","",MAX(0,($F$26*IF($H$26<0,-100/$H$26,$H$26/100)-(1-$F$26))/IF($H$26<0,-100/$H$26,$H$26/100))*'Settings'!$B$3) | L26: =IF($H$26="","",ROUND(MIN($K$26,'Settings'!$B$5)*'Settings'!$B$2,2)) | M26: =IF($J$26="","",IF($J$26<0,"Pass",IF($J$26<'Settings'!$B$4,"Thin",IF($J$26<0.06,"✅ Sharp band",IF($J$26<0.08,"Strong","⚠ Verify (stale?)"))))) | N26: Model 50.1% (fair -100). Your call. | P26: =IF(OR($H$26="",$O$26=""),"",(1+IF($H$26<0,-100/$H$26,$H$26/100))/(1+IF($O$26<0,-100/$O$26,$O$26/100))-1)
A27: 2026-07-04 | B27: Baltimore Orioles @ Cincinnati Reds | C27: 23:10 | D27: Total | E27: Over 10 | F27: 0.4376 | G27: 129 | H27: 129 | I27: =IF($H$27="","",IF($H$27<0,-$H$27/(-$H$27+100),100/($H$27+100))) | J27: =IF($H$27="","",$F$27*IF($H$27<0,-100/$H$27,$H$27/100)-(1-$F$27)) | K27: =IF($H$27="","",MAX(0,($F$27*IF($H$27<0,-100/$H$27,$H$27/100)-(1-$F$27))/IF($H$27<0,-100/$H$27,$H$27/100))*'Settings'!$B$3) | L27: =IF($H$27="","",ROUND(MIN($K$27,'Settings'!$B$5)*'Settings'!$B$2,2)) | M27: =IF($J$27="","",IF($J$27<0,"Pass",IF($J$27<'Settings'!$B$4,"Thin",IF($J$27<0.06,"✅ Sharp band",IF($J$27<0.08,"Strong","⚠ Verify (stale?)"))))) | N27: Model 43.8% (fair +129). Your call. | P27: =IF(OR($H$27="",$O$27=""),"",(1+IF($H$27<0,-100/$H$27,$H$27/100))/(1+IF($O$27<0,-100/$O$27,$O$27/100))-1)
A28: 2026-07-04 | B28: Baltimore Orioles @ Cincinnati Reds | C28: 23:10 | D28: Total | E28: Under 10 | F28: 0.5624 | G28: -129 | H28: 100 | I28: =IF($H$28="","",IF($H$28<0,-$H$28/(-$H$28+100),100/($H$28+100))) | J28: =IF($H$28="","",$F$28*IF($H$28<0,-100/$H$28,$H$28/100)-(1-$F$28)) | K28: =IF($H$28="","",MAX(0,($F$28*IF($H$28<0,-100/$H$28,$H$28/100)-(1-$F$28))/IF($H$28<0,-100/$H$28,$H$28/100))*'Settings'!$B$3) | L28: =IF($H$28="","",ROUND(MIN($K$28,'Settings'!$B$5)*'Settings'!$B$2,2)) | M28: =IF($J$28="","",IF($J$28<0,"Pass",IF($J$28<'Settings'!$B$4,"Thin",IF($J$28<0.06,"✅ Sharp band",IF($J$28<0.08,"Strong","⚠ Verify (stale?)"))))) | N28: Model 56.2% (fair -129). Your call. | P28: =IF(OR($H$28="",$O$28=""),"",(1+IF($H$28<0,-100/$H$28,$H$28/100))/(1+IF($O$28<0,-100/$O$28,$O$28/100))-1)
A29: 2026-07-04 | B29: Baltimore Orioles @ Cincinnati Reds | C29: 23:10 | D29: Spread | E29: Cincinnati Reds -1.5 | F29: 0.304 | G29: 229 | H29: 170 | I29: =IF($H$29="","",IF($H$29<0,-$H$29/(-$H$29+100),100/($H$29+100))) | J29: =IF($H$29="","",$F$29*IF($H$29<0,-100/$H$29,$H$29/100)-(1-$F$29)) | K29: =IF($H$29="","",MAX(0,($F$29*IF($H$29<0,-100/$H$29,$H$29/100)-(1-$F$29))/IF($H$29<0,-100/$H$29,$H$29/100))*'Settings'!$B$3) | L29: =IF($H$29="","",ROUND(MIN($K$29,'Settings'!$B$5)*'Settings'!$B$2,2)) | M29: =IF($J$29="","",IF($J$29<0,"Pass",IF($J$29<'Settings'!$B$4,"Thin",IF($J$29<0.06,"✅ Sharp band",IF($J$29<0.08,"Strong","⚠ Verify (stale?)"))))) | N29: Model 30.4% (fair +229). Your call. | P29: =IF(OR($H$29="",$O$29=""),"",(1+IF($H$29<0,-100/$H$29,$H$29/100))/(1+IF($O$29<0,-100/$O$29,$O$29/100))-1)
A30: 2026-07-04 | B30: Baltimore Orioles @ Cincinnati Reds | C30: 23:10 | D30: Spread | E30: Baltimore Orioles +1.5 | F30: 0.69600719 | G30: -229 | H30: 178 | I30: =IF($H$30="","",IF($H$30<0,-$H$30/(-$H$30+100),100/($H$30+100))) | J30: =IF($H$30="","",$F$30*IF($H$30<0,-100/$H$30,$H$30/100)-(1-$F$30)) | K30: =IF($H$30="","",MAX(0,($F$30*IF($H$30<0,-100/$H$30,$H$30/100)-(1-$F$30))/IF($H$30<0,-100/$H$30,$H$30/100))*'Settings'!$B$3) | L30: =IF($H$30="","",ROUND(MIN($K$30,'Settings'!$B$5)*'Settings'!$B$2,2)) | M30: =IF($J$30="","",IF($J$30<0,"Pass",IF($J$30<'Settings'!$B$4,"Thin",IF($J$30<0.06,"✅ Sharp band",IF($J$30<0.08,"Strong","⚠ Verify (stale?)"))))) | N30: Model 69.6% (fair -229). Your call. | P30: =IF(OR($H$30="",$O$30=""),"",(1+IF($H$30<0,-100/$H$30,$H$30/100))/(1+IF($O$30<0,-100/$O$30,$O$30/100))-1)
A31: 2026-07-04 | B31: Tampa Bay Rays @ Houston Astros | C31: 23:10 | D31: Moneyline | E31: Tampa Bay Rays | F31: 0.48961538 | G31: 104 | H31: 108 | I31: =IF($H$31="","",IF($H$31<0,-$H$31/(-$H$31+100),100/($H$31+100))) | J31: =IF($H$31="","",$F$31*IF($H$31<0,-100/$H$31,$H$31/100)-(1-$F$31)) | K31: =IF($H$31="","",MAX(0,($F$31*IF($H$31<0,-100/$H$31,$H$31/100)-(1-$F$31))/IF($H$31<0,-100/$H$31,$H$31/100))*'Settings'!$B$3) | L31: =IF($H$31="","",ROUND(MIN($K$31,'Settings'!$B$5)*'Settings'!$B$2,2)) | M31: =IF($J$31="","",IF($J$31<0,"Pass",IF($J$31<'Settings'!$B$4,"Thin",IF($J$31<0.06,"✅ Sharp band",IF($J$31<0.08,"Strong","⚠ Verify (stale?)"))))) | N31: Model 49.0% (fair +104). Your call. | P31: =IF(OR($H$31="",$O$31=""),"",(1+IF($H$31<0,-100/$H$31,$H$31/100))/(1+IF($O$31<0,-100/$O$31,$O$31/100))-1)
A32: 2026-07-04 | B32: Tampa Bay Rays @ Houston Astros | C32: 23:10 | D32: Moneyline | E32: Houston Astros | F32: 0.51035192 | G32: -104 | H32: -108 | I32: =IF($H$32="","",IF($H$32<0,-$H$32/(-$H$32+100),100/($H$32+100))) | J32: =IF($H$32="","",$F$32*IF($H$32<0,-100/$H$32,$H$32/100)-(1-$F$32)) | K32: =IF($H$32="","",MAX(0,($F$32*IF($H$32<0,-100/$H$32,$H$32/100)-(1-$F$32))/IF($H$32<0,-100/$H$32,$H$32/100))*'Settings'!$B$3) | L32: =IF($H$32="","",ROUND(MIN($K$32,'Settings'!$B$5)*'Settings'!$B$2,2)) | M32: =IF($J$32="","",IF($J$32<0,"Pass",IF($J$32<'Settings'!$B$4,"Thin",IF($J$32<0.06,"✅ Sharp band",IF($J$32<0.08,"Strong","⚠ Verify (stale?)"))))) | N32: Model 51.0% (fair -104). Your call. | P32: =IF(OR($H$32="",$O$32=""),"",(1+IF($H$32<0,-100/$H$32,$H$32/100))/(1+IF($O$32<0,-100/$O$32,$O$32/100))-1)
A33: 2026-07-04 | B33: Tampa Bay Rays @ Houston Astros | C33: 23:10 | D33: Total | E33: Over 7.5 | F33: 0.6294 | G33: -170 | H33: 122 | I33: =IF($H$33="","",IF($H$33<0,-$H$33/(-$H$33+100),100/($H$33+100))) | J33: =IF($H$33="","",$F$33*IF($H$33<0,-100/$H$33,$H$33/100)-(1-$F$33)) | K33: =IF($H$33="","",MAX(0,($F$33*IF($H$33<0,-100/$H$33,$H$33/100)-(1-$F$33))/IF($H$33<0,-100/$H$33,$H$33/100))*'Settings'!$B$3) | L33: =IF($H$33="","",ROUND(MIN($K$33,'Settings'!$B$5)*'Settings'!$B$2,2)) | M33: =IF($J$33="","",IF($J$33<0,"Pass",IF($J$33<'Settings'!$B$4,"Thin",IF($J$33<0.06,"✅ Sharp band",IF($J$33<0.08,"Strong","⚠ Verify (stale?)"))))) | N33: Model 62.9% (fair -170). Your call. | P33: =IF(OR($H$33="",$O$33=""),"",(1+IF($H$33<0,-100/$H$33,$H$33/100))/(1+IF($O$33<0,-100/$O$33,$O$33/100))-1)
A34: 2026-07-04 | B34: Tampa Bay Rays @ Houston Astros | C34: 23:10 | D34: Total | E34: Under 7.5 | F34: 0.3706 | G34: 170 | H34: 100 | I34: =IF($H$34="","",IF($H$34<0,-$H$34/(-$H$34+100),100/($H$34+100))) | J34: =IF($H$34="","",$F$34*IF($H$34<0,-100/$H$34,$H$34/100)-(1-$F$34)) | K34: =IF($H$34="","",MAX(0,($F$34*IF($H$34<0,-100/$H$34,$H$34/100)-(1-$F$34))/IF($H$34<0,-100/$H$34,$H$34/100))*'Settings'!$B$3) | L34: =IF($H$34="","",ROUND(MIN($K$34,'Settings'!$B$5)*'Settings'!$B$2,2)) | M34: =IF($J$34="","",IF($J$34<0,"Pass",IF($J$34<'Settings'!$B$4,"Thin",IF($J$34<0.06,"✅ Sharp band",IF($J$34<0.08,"Strong","⚠ Verify (stale?)"))))) | N34: Model 37.1% (fair +170). Your call. | P34: =IF(OR($H$34="",$O$34=""),"",(1+IF($H$34<0,-100/$H$34,$H$34/100))/(1+IF($O$34<0,-100/$O$34,$O$34/100))-1)
A35: 2026-07-04 | B35: Chicago White Sox @ Cleveland Guardians | C35: 23:10 | D35: Moneyline | E35: Chicago White Sox | F35: 0.45264317 | G35: 121 | H35: 127 | I35: =IF($H$35="","",IF($H$35<0,-$H$35/(-$H$35+100),100/($H$35+100))) | J35: =IF($H$35="","",$F$35*IF($H$35<0,-100/$H$35,$H$35/100)-(1-$F$35)) | K35: =IF($H$35="","",MAX(0,($F$35*IF($H$35<0,-100/$H$35,$H$35/100)-(1-$F$35))/IF($H$35<0,-100/$H$35,$H$35/100))*'Settings'!$B$3) | L35: =IF($H$35="","",ROUND(MIN($K$35,'Settings'!$B$5)*'Settings'!$B$2,2)) | M35: =IF($J$35="","",IF($J$35<0,"Pass",IF($J$35<'Settings'!$B$4,"Thin",IF($J$35<0.06,"✅ Sharp band",IF($J$35<0.08,"Strong","⚠ Verify (stale?)"))))) | N35: Model 45.3% (fair +121). Your call. | P35: =IF(OR($H$35="",$O$35=""),"",(1+IF($H$35<0,-100/$H$35,$H$35/100))/(1+IF($O$35<0,-100/$O$35,$O$35/100))-1)
A36: 2026-07-04 | B36: Chicago White Sox @ Cleveland Guardians | C36: 23:10 | D36: Moneyline | E36: Cleveland Guardians | F36: 0.54733084 | G36: -121 | H36: -127 | I36: =IF($H$36="","",IF($H$36<0,-$H$36/(-$H$36+100),100/($H$36+100))) | J36: =IF($H$36="","",$F$36*IF($H$36<0,-100/$H$36,$H$36/100)-(1-$F$36)) | K36: =IF($H$36="","",MAX(0,($F$36*IF($H$36<0,-100/$H$36,$H$36/100)-(1-$F$36))/IF($H$36<0,-100/$H$36,$H$36/100))*'Settings'!$B$3) | L36: =IF($H$36="","",ROUND(MIN($K$36,'Settings'!$B$5)*'Settings'!$B$2,2)) | M36: =IF($J$36="","",IF($J$36<0,"Pass",IF($J$36<'Settings'!$B$4,"Thin",IF($J$36<0.06,"✅ Sharp band",IF($J$36<0.08,"Strong","⚠ Verify (stale?)"))))) | N36: Model 54.7% (fair -121). Your call. | P36: =IF(OR($H$36="",$O$36=""),"",(1+IF($H$36<0,-100/$H$36,$H$36/100))/(1+IF($O$36<0,-100/$O$36,$O$36/100))-1)
A37: 2026-07-04 | B37: Chicago White Sox @ Cleveland Guardians | C37: 23:10 | D37: Total | E37: Over 8 | F37: 0.4379 | G37: 128 | H37: 127 | I37: =IF($H$37="","",IF($H$37<0,-$H$37/(-$H$37+100),100/($H$37+100))) | J37: =IF($H$37="","",$F$37*IF($H$37<0,-100/$H$37,$H$37/100)-(1-$F$37)) | K37: =IF($H$37="","",MAX(0,($F$37*IF($H$37<0,-100/$H$37,$H$37/100)-(1-$F$37))/IF($H$37<0,-100/$H$37,$H$37/100))*'Settings'!$B$3) | L37: =IF($H$37="","",ROUND(MIN($K$37,'Settings'!$B$5)*'Settings'!$B$2,2)) | M37: =IF($J$37="","",IF($J$37<0,"Pass",IF($J$37<'Settings'!$B$4,"Thin",IF($J$37<0.06,"✅ Sharp band",IF($J$37<0.08,"Strong","⚠ Verify (stale?)"))))) | N37: Model 43.8% (fair +128). Your call. | P37: =IF(OR($H$37="",$O$37=""),"",(1+IF($H$37<0,-100/$H$37,$H$37/100))/(1+IF($O$37<0,-100/$O$37,$O$37/100))-1)
A38: 2026-07-04 | B38: Chicago White Sox @ Cleveland Guardians | C38: 23:10 | D38: Total | E38: Under 8 | F38: 0.5621 | G38: -128 | H38: -113 | I38: =IF($H$38="","",IF($H$38<0,-$H$38/(-$H$38+100),100/($H$38+100))) | J38: =IF($H$38="","",$F$38*IF($H$38<0,-100/$H$38,$H$38/100)-(1-$F$38)) | K38: =IF($H$38="","",MAX(0,($F$38*IF($H$38<0,-100/$H$38,$H$38/100)-(1-$F$38))/IF($H$38<0,-100/$H$38,$H$38/100))*'Settings'!$B$3) | L38: =IF($H$38="","",ROUND(MIN($K$38,'Settings'!$B$5)*'Settings'!$B$2,2)) | M38: =IF($J$38="","",IF($J$38<0,"Pass",IF($J$38<'Settings'!$B$4,"Thin",IF($J$38<0.06,"✅ Sharp band",IF($J$38<0.08,"Strong","⚠ Verify (stale?)"))))) | N38: Model 56.2% (fair -128). Your call. | P38: =IF(OR($H$38="",$O$38=""),"",(1+IF($H$38<0,-100/$H$38,$H$38/100))/(1+IF($O$38<0,-100/$O$38,$O$38/100))-1)
A39: 2026-07-04 | B39: Chicago White Sox @ Cleveland Guardians | C39: 23:10 | D39: Spread | E39: Cleveland Guardians -1.5 | F39: 0.38213483 | G39: 162 | H39: 167 | I39: =IF($H$39="","",IF($H$39<0,-$H$39/(-$H$39+100),100/($H$39+100))) | J39: =IF($H$39="","",$F$39*IF($H$39<0,-100/$H$39,$H$39/100)-(1-$F$39)) | K39: =IF($H$39="","",MAX(0,($F$39*IF($H$39<0,-100/$H$39,$H$39/100)-(1-$F$39))/IF($H$39<0,-100/$H$39,$H$39/100))*'Settings'!$B$3) | L39: =IF($H$39="","",ROUND(MIN($K$39,'Settings'!$B$5)*'Settings'!$B$2,2)) | M39: =IF($J$39="","",IF($J$39<0,"Pass",IF($J$39<'Settings'!$B$4,"Thin",IF($J$39<0.06,"✅ Sharp band",IF($J$39<0.08,"Strong","⚠ Verify (stale?)"))))) | N39: Model 38.2% (fair +162). Your call. | P39: =IF(OR($H$39="",$O$39=""),"",(1+IF($H$39<0,-100/$H$39,$H$39/100))/(1+IF($O$39<0,-100/$O$39,$O$39/100))-1)
A40: 2026-07-04 | B40: Chicago White Sox @ Cleveland Guardians | C40: 23:10 | D40: Spread | E40: Chicago White Sox +1.5 | F40: 0.61786652 | G40: -162 | H40: -121 | I40: =IF($H$40="","",IF($H$40<0,-$H$40/(-$H$40+100),100/($H$40+100))) | J40: =IF($H$40="","",$F$40*IF($H$40<0,-100/$H$40,$H$40/100)-(1-$F$40)) | K40: =IF($H$40="","",MAX(0,($F$40*IF($H$40<0,-100/$H$40,$H$40/100)-(1-$F$40))/IF($H$40<0,-100/$H$40,$H$40/100))*'Settings'!$B$3) | L40: =IF($H$40="","",ROUND(MIN($K$40,'Settings'!$B$5)*'Settings'!$B$2,2)) | M40: =IF($J$40="","",IF($J$40<0,"Pass",IF($J$40<'Settings'!$B$4,"Thin",IF($J$40<0.06,"✅ Sharp band",IF($J$40<0.08,"Strong","⚠ Verify (stale?)"))))) | N40: Model 61.8% (fair -162). Your call. | P40: =IF(OR($H$40="",$O$40=""),"",(1+IF($H$40<0,-100/$H$40,$H$40/100))/(1+IF($O$40<0,-100/$O$40,$O$40/100))-1)
A41: 2026-07-04 | B41: St. Louis Cardinals @ Chicago Cubs | C41: 00:08 | D41: Moneyline | E41: St. Louis Cardinals | F41: 0.42844 | G41: 133 | H41: 150 | I41: =IF($H$41="","",IF($H$41<0,-$H$41/(-$H$41+100),100/($H$41+100))) | J41: =IF($H$41="","",$F$41*IF($H$41<0,-100/$H$41,$H$41/100)-(1-$F$41)) | K41: =IF($H$41="","",MAX(0,($F$41*IF($H$41<0,-100/$H$41,$H$41/100)-(1-$F$41))/IF($H$41<0,-100/$H$41,$H$41/100))*'Settings'!$B$3) | L41: =IF($H$41="","",ROUND(MIN($K$41,'Settings'!$B$5)*'Settings'!$B$2,2)) | M41: =IF($J$41="","",IF($J$41<0,"Pass",IF($J$41<'Settings'!$B$4,"Thin",IF($J$41<0.06,"✅ Sharp band",IF($J$41<0.08,"Strong","⚠ Verify (stale?)"))))) | N41: Model 42.8% (fair +133). Your call. | P41: =IF(OR($H$41="",$O$41=""),"",(1+IF($H$41<0,-100/$H$41,$H$41/100))/(1+IF($O$41<0,-100/$O$41,$O$41/100))-1)
...

Sheet Track Record
A1: 📒 Track Record — receipts, losses included
A2: Graded in the open. A process you can audit beats a hot streak you can't.
A4: Scope | B4: Graded games | C4: Model Brier | D4: Bets | E4: Win % | F4: Units | G4: ROI % | H4: Avg CLV % | I4: CLV beat %
A5: Overall | B5: 326 | C5: 0.2497 | D5: 221 | E5: 0.448 | F5: -6.82 | G5: -3.09 | H5: 2.2 | I5: 0.4975
A6: MLB | B6: 296 | C6: 0.2512 | D6: 182 | E6: 0.4615 | F6: -4.17 | G6: -2.29 | H6: 2.97 | I6: 0.515
A7: WNBA | B7: 29 | C7: 0.2371 | D7: 37 | E7: 0.3784 | F7: -3.45 | G7: -9.33 | H7: -2.61 | I7: 0.3929
A8: NBA | B8: 1 | C8: 0.1979 | D8: 2 | E8: 0.5 | F8: 0.8 | G8: 40 | H8: 4.92 | I8: 0.5
A10: Brier: lower is better (0.25 = a coin flip). CLV beat %: how often we beat the closing line — the earliest honest sign an edge is real, before win/loss catches up.
A13: Calibration — honesty check
A14: When the model said X%, how often it actually happened (n=286, ECE 0.048 — lower is better; a calibrated model's bars sit on the diagonal).
A16: Model said | B16: Games | C16: We predicted | D16: Actually won | E16: Gap
A17: 10–20% | B17: 1 | C17: 0.1885 | D17: 0 | E17: -0.1885
A18: 20–30% | B18: 7 | C18: 0.2599 | D18: 0.4286 | E18: 0.1687
A19: 30–40% | B19: 28 | C19: 0.3729 | D19: 0.5714 | E19: 0.1985
A20: 40–50% | B20: 93 | C20: 0.4588 | D20: 0.4624 | E20: 0.0036
A21: 50–60% | B21: 107 | C21: 0.5421 | D21: 0.5234 | E21: -0.0187
A22: 60–70% | B22: 39 | C22: 0.6412 | D22: 0.5897 | E22: -0.0515
A23: 70–80% | B23: 9 | C23: 0.74 | D23: 0.5556 | E23: -0.1844
A24: 80–90% | B24: 2 | C24: 0.8538 | D24: 0.5 | E24: -0.3538

Sheet Research Hub
A1: 🔬 Research Hub
A2: Premium matchup breakdowns · 2026-07-04 · L5 window. Each game has its own tab.
A4: MLB: Pittsburgh Pirates @ Washington Nationals
A5: MLB: Minnesota Twins @ New York Yankees
A6: MLB: Detroit Tigers @ Texas Rangers
A7: MLB: Toronto Blue Jays @ Seattle Mariners
A8: MLB: Baltimore Orioles @ Cincinnati Reds
A9: MLB: Tampa Bay Rays @ Houston Astros
A10: MLB: Chicago White Sox @ Cleveland Guardians
A11: MLB: St. Louis Cardinals @ Chicago Cubs
A12: MLB: New York Mets @ Atlanta Braves
A13: MLB: San Francisco Giants @ Colorado Rockies
A15: Tip: the website's research view lets you flip the L5/L10/L15/L20/L30/Season window live; here every window is in the table so you can read any of them.

Sheet MLB Pirates @ Nationals
A1: Pittsburgh Pirates @ Washington Nationals
A2: MLB · 2026-07-04 · L5 window
A69: Pittsburgh Pirates offense vs Washington Nationals defense
A70: Stat | B70: A Season | C70: A L30 | D70: A L20 | E70: A L15 | F70: A L10 | G70: A L5 | H70: A Rk | I70: Adv | J70: H Rk | K70: H L5 | L70: H L10 | M70: H L15 | N70: H L20 | O70: H L30 | P70: H Season | Q70: Opp stat
A71: Runs/G | B71: 5.062 | C71: 5.5 | D71: 5.3 | E71: 6 | F71: 6.4 | G71: 5.6 | H71: 9th | J71: 5th | K71: 3.6 | L71: 5.3 | M71: 4.8 | N71: 4.65 | O71: 4.567 | P71: 5.101 | Q71: Opp Runs/G
A72: Hits/G | B72: 8.812 | C72: 10.5 | D72: — | E72: — | F72: — | G72: — | H72: — | J72: — | K72: — | L72: — | M72: — | N72: — | O72: 8 | P72: 9.04 | Q72: Opp Hits/G
A73: HR/G | B73: 1.188 | C73: 2.5 | D73: — | E73: — | F73: — | G73: — | H73: — | J73: — | K73: — | L73: — | M73: — | N73: — | O73: 2.333 | P73: 1.56 | Q73: Opp HR/G
A74: Batter K/G | B74: 9.708 | C74: 10.5 | D74: — | E74: — | F74: — | G74: — | H74: — | J74: — | K74: — | L74: — | M74: — | N74: — | O74: 8 | P74: 8.2 | Q74: Opp Batter K/G
A75: 1st Inn R/G | B75: 0.539 | C75: 0.367 | D75: 0.35 | E75: 0.4 | F75: 0.2 | G75: 0 | H75: 30th | J75: 29th | K75: 1.4 | L75: 0.7 | M75: 0.6 | N75: 0.5 | O75: 0.4 | P75: 0.403 | Q75: Opp 1st Inn R/G
A77: Washington Nationals offense vs Pittsburgh Pirates defense
A78: Stat | B78: A Season | C78: A L30 | D78: A L20 | E78: A L15 | F78: A L10 | G78: A L5 | H78: A Rk | I78: Adv | J78: H Rk | K78: H L5 | L78: H L10 | M78: H L15 | N78: H L20 | O78: H L30 | P78: H Season | Q78: Opp stat
A79: Runs/G | B79: 5.329 | C79: 5.3 | D79: 5.35 | E79: 4.933 | F79: 5.9 | G79: 7.2 | H79: 3rd | I79: ★★★ | J79: 29th | K79: 7 | L79: 5.6 | M79: 5 | N79: 5.25 | O79: 5.633 | P79: 4.815 | Q79: Opp Runs/G
A80: Hits/G | B80: 8.52 | C80: 7.667 | D80: — | E80: — | F80: — | G80: — | H80: — | J80: — | K80: — | L80: — | M80: — | N80: — | O80: 7 | P80: 7.792 | Q80: Opp Hits/G
A81: HR/G | B81: 1.26 | C81: 1 | D81: — | E81: — | F81: — | G81: — | H81: — | J81: — | K81: — | L81: — | M81: — | N81: — | O81: 1.5 | P81: 0.896 | Q81: Opp HR/G
A82: Batter K/G | B82: 7.98 | C82: 7.667 | D82: — | E82: — | F82: — | G82: — | H82: — | J82: — | K82: — | L82: — | M82: — | N82: — | O82: 11.5 | P82: 9.292 | Q82: Opp Batter K/G
A83: 1st Inn R/G | B83: 0.831 | C83: 0.667 | D83: 0.7 | E83: 0.667 | F83: 0.9 | G83: 0.8 | H83: 8th | I83: ★★★ | J83: 20th | K83: 0.6 | L83: 0.5 | M83: 0.4 | N83: 0.5 | O83: 0.467 | P83: 0.408 | Q83: Opp 1st Inn R/G

Sheet MLB Twins @ Yankees
A1: Minnesota Twins @ New York Yankees
A2: MLB · 2026-07-04 · L5 window
A68: Minnesota Twins offense vs New York Yankees defense
A69: Stat | B69: A Season | C69: A L30 | D69: A L20 | E69: A L15 | F69: A L10 | G69: A L5 | H69: A Rk | I69: Adv | J69: H Rk | K69: H L5 | L69: H L10 | M69: H L15 | N69: H L20 | O69: H L30 | P69: H Season | Q69: Opp stat
A70: Runs/G | B70: 4.776 | C70: 5.3 | D70: 5.65 | E70: 5.933 | F70: 4.3 | G70: 4.4 | H70: 15th | I70: ★★ | J70: 24th | K70: 5.8 | L70: 5 | M70: 4.933 | N70: 4.65 | O70: 4.633 | P70: 3.744 | Q70: Opp Runs/G
A71: Hits/G | B71: 7.776 | C71: 8.667 | D71: — | E71: — | F71: — | G71: — | H71: — | J71: — | K71: — | L71: — | M71: — | N71: — | O71: 10.667 | P71: 7.609 | Q71: Opp Hits/G
A72: HR/G | B72: 1.061 | C72: 1 | D72: — | E72: — | F72: — | G72: — | H72: — | J72: — | K72: — | L72: — | M72: — | N72: — | O72: 2 | P72: 0.913 | Q72: Opp HR/G
A73: Batter K/G | B73: 8.939 | C73: 8 | D73: — | E73: — | F73: — | G73: — | H73: — | J73: — | K73: — | L73: — | M73: — | N73: — | O73: 9.667 | P73: 8.435 | Q73: Opp Batter K/G
A74: 1st Inn R/G | B74: 0.684 | C74: 0.833 | D74: 1.1 | E74: 1.2 | F74: 1 | G74: 1.2 | H74: 2nd | I74: ★★★ | J74: 27th | K74: 1.2 | L74: 0.8 | M74: 0.533 | N74: 0.6 | O74: 0.6 | P74: 0.479 | Q74: Opp 1st Inn R/G
A76: New York Yankees offense vs Minnesota Twins defense
A77: Stat | B77: A Season | C77: A L30 | D77: A L20 | E77: A L15 | F77: A L10 | G77: A L5 | H77: A Rk | I77: Adv | J77: H Rk | K77: H L5 | L77: H L10 | M77: H L15 | N77: H L20 | O77: H L30 | P77: H Season | Q77: Opp stat
A78: Runs/G | B78: 4.744 | C78: 4.467 | D78: 4 | E78: 2.8 | F78: 3 | G78: 3.4 | H78: 26th | J78: 7th | K78: 4 | L78: 5.4 | M78: 5.2 | N78: 5.6 | O78: 5.767 | P78: 5.132 | Q78: Opp Runs/G
A79: Hits/G | B79: 8.109 | C79: 8.333 | D79: — | E79: — | F79: — | G79: — | H79: — | J79: — | K79: — | L79: — | M79: — | N79: — | O79: 9 | P79: 8.306 | Q79: Opp Hits/G
A80: HR/G | B80: 1.413 | C80: 0.333 | D80: — | E80: — | F80: — | G80: — | H80: — | J80: — | K80: — | L80: — | M80: — | N80: — | O80: 1.667 | P80: 0.918 | Q80: Opp HR/G
A81: Batter K/G | B81: 9.13 | C81: 9.667 | D81: — | E81: — | F81: — | G81: — | H81: — | J81: — | K81: — | L81: — | M81: — | N81: — | O81: 11.667 | P81: 8.265 | Q81: Opp Batter K/G
A82: 1st Inn R/G | B82: 0.63 | C82: 0.333 | D82: 0.35 | E82: 0.333 | F82: 0.4 | G82: 0.4 | H82: 19th | J82: 17th | K82: 0.6 | L82: 0.6 | M82: 0.4 | N82: 0.5 | O82: 0.633 | P82: 0.605 | Q82: Opp 1st Inn R/G

Sheet MLB Tigers @ Rangers
A1: Detroit Tigers @ Texas Rangers
A2: MLB · 2026-07-04 · L5 window
A69: Detroit Tigers offense vs Texas Rangers defense
