Workbook

Sheet Read Me
A1: 🎯 Project 54.7 — Daily Wager Workbook
A2: 52.4% pays the house. 54.7% pays you.
A5: Built | B5: 2026-06-27 17:03
A7: HOW IT WORKS
A8: 1. | B8: The model's win probability for every market is locked. It does not change when odds move.
A9: 2. | B9: Type the price YOUR sportsbook is showing into the yellow “✏ Your Odds” cells (American odds, e.g. -110 or +135).
A10: 3. | B10: Implied %, Your Edge (EV), the ¼-Kelly stake and the Verdict recompute instantly — in Excel or Google Sheets, offline.
A11: 4. | B11: Set your Bankroll and Kelly fraction once on the Settings tab; every stake on every tab follows it.
A12: 5. | B12: After a game, type the closing line into the ✏ Closing column on the Games tab — CLV % shows whether you beat the close (the earliest honest sign an edge is real).
A14: READING THE VERDICT
A15: Pass | B15: Model says there's no edge at your price — skip it.
A16: Thin | B16: Positive but below your min-edge threshold.
A17: ✅ Sharp band | B17: 2–6% EV — where the model's edge has actually held up (good closing-line value). The sweet spot.
A18: Strong | B18: 6–8% EV — bigger, rarer.
A19: ⚠ Verify | B19: 8%+ EV usually means a stale or oddball price, not free money. Double-check the line before trusting it.
A21: WHY EDIT YOUR OWN ODDS?
B22: Every other tool de-vigs a sharp book for you and locks the math in an app whose lines go stale. Here the number is yours, so nothing can be out of date — and the math is in front of you.
A24: THE DEAL | B24: Personal research. Not financial advice. No bankroll promises. If gambling stops being fun, stop — call 1-800-GAMBLER.
B25: We publish our losses too — see the Track Record tab. We tell you when to pass. The trigger is always yours.

Sheet Settings
A1: ⚙ Settings
A2: Bankroll ($) | B2: 1000
A3: Kelly fraction | B3: 0.25
A4: Min edge to flag (EV) | B4: 0.02
A5: Max stake (% of bankroll) | B5: 0.05
A7: Default ¼-Kelly is deliberate: full Kelly is mathematically optimal but brutal on variance, and edges are always overestimated. Quarter-Kelly keeps ~most of the growth at a fraction of the risk.

Sheet Top Plays
A1: ⭐ Top Plays — biggest model edges today
A2: Ranked at the posted price. Swap in your book's number and watch the edge update. Nothing here is a lock.
A4: Date | B4: Matchup | C4: Start | D4: Market | E4: Selection | F4: Model Win% | G4: Model Fair | H4: ✏ Your Odds | I4: Implied% | J4: Your Edge (EV) | K4: ¼-Kelly % | L4: Stake $ | M4: Verdict | N4: Model read | O4: ✏ Closing | P4: CLV %
A5: 2026-06-27 | B5: Los Angeles Sparks @ Indiana Fever | C5: 00:00 | D5: Total | E5: Over 179.5 | F5: 0.715 | G5: -251 | H5: -104 | I5: =IF($H$5="","",IF($H$5<0,-$H$5/(-$H$5+100),100/($H$5+100))) | J5: =IF($H$5="","",$F$5*IF($H$5<0,-100/$H$5,$H$5/100)-(1-$F$5)) | K5: =IF($H$5="","",MAX(0,($F$5*IF($H$5<0,-100/$H$5,$H$5/100)-(1-$F$5))/IF($H$5<0,-100/$H$5,$H$5/100))*'Settings'!$B$3) | L5: =IF($H$5="","",ROUND(MIN($K$5,'Settings'!$B$5)*'Settings'!$B$2,2)) | M5: =IF($J$5="","",IF($J$5<0,"Pass",IF($J$5<'Settings'!$B$4,"Thin",IF($J$5<0.06,"✅ Sharp band",IF($J$5<0.08,"Strong","⚠ Verify (stale?)"))))) | N5: Model 71.5% (fair -251). Your call. | P5: =IF(OR($H$5="",$O$5=""),"",(1+IF($H$5<0,-100/$H$5,$H$5/100))/(1+IF($O$5<0,-100/$O$5,$O$5/100))-1)
A6: 2026-06-28 | B6: Cincinnati Reds @ Pittsburgh Pirates | C6: 17:35 | D6: Spread | E6: Pittsburgh Pirates -1.5 | F6: 0.49665441 | G6: 101 | H6: 172 | I6: =IF($H$6="","",IF($H$6<0,-$H$6/(-$H$6+100),100/($H$6+100))) | J6: =IF($H$6="","",$F$6*IF($H$6<0,-100/$H$6,$H$6/100)-(1-$F$6)) | K6: =IF($H$6="","",MAX(0,($F$6*IF($H$6<0,-100/$H$6,$H$6/100)-(1-$F$6))/IF($H$6<0,-100/$H$6,$H$6/100))*'Settings'!$B$3) | L6: =IF($H$6="","",ROUND(MIN($K$6,'Settings'!$B$5)*'Settings'!$B$2,2)) | M6: =IF($J$6="","",IF($J$6<0,"Pass",IF($J$6<'Settings'!$B$4,"Thin",IF($J$6<0.06,"✅ Sharp band",IF($J$6<0.08,"Strong","⚠ Verify (stale?)"))))) | N6: Model 49.7% (fair +101). Your call. | P6: =IF(OR($H$6="",$O$6=""),"",(1+IF($H$6<0,-100/$H$6,$H$6/100))/(1+IF($O$6<0,-100/$O$6,$O$6/100))-1)
A7: 2026-06-28 | B7: Cincinnati Reds @ Pittsburgh Pirates | C7: 17:35 | D7: Moneyline | E7: Pittsburgh Pirates | F7: 0.67143964 | G7: -204 | H7: -122 | I7: =IF($H$7="","",IF($H$7<0,-$H$7/(-$H$7+100),100/($H$7+100))) | J7: =IF($H$7="","",$F$7*IF($H$7<0,-100/$H$7,$H$7/100)-(1-$F$7)) | K7: =IF($H$7="","",MAX(0,($F$7*IF($H$7<0,-100/$H$7,$H$7/100)-(1-$F$7))/IF($H$7<0,-100/$H$7,$H$7/100))*'Settings'!$B$3) | L7: =IF($H$7="","",ROUND(MIN($K$7,'Settings'!$B$5)*'Settings'!$B$2,2)) | M7: =IF($J$7="","",IF($J$7<0,"Pass",IF($J$7<'Settings'!$B$4,"Thin",IF($J$7<0.06,"✅ Sharp band",IF($J$7<0.08,"Strong","⚠ Verify (stale?)"))))) | N7: Model 67.1% (fair -204). Your call. | P7: =IF(OR($H$7="",$O$7=""),"",(1+IF($H$7<0,-100/$H$7,$H$7/100))/(1+IF($O$7<0,-100/$O$7,$O$7/100))-1)
A8: 2026-06-28 | B8: Washington Nationals @ Baltimore Orioles | C8: 17:35 | D8: Total | E8: Over 9.5 | F8: 0.5857561 | G8: -141 | H8: 105 | I8: =IF($H$8="","",IF($H$8<0,-$H$8/(-$H$8+100),100/($H$8+100))) | J8: =IF($H$8="","",$F$8*IF($H$8<0,-100/$H$8,$H$8/100)-(1-$F$8)) | K8: =IF($H$8="","",MAX(0,($F$8*IF($H$8<0,-100/$H$8,$H$8/100)-(1-$F$8))/IF($H$8<0,-100/$H$8,$H$8/100))*'Settings'!$B$3) | L8: =IF($H$8="","",ROUND(MIN($K$8,'Settings'!$B$5)*'Settings'!$B$2,2)) | M8: =IF($J$8="","",IF($J$8<0,"Pass",IF($J$8<'Settings'!$B$4,"Thin",IF($J$8<0.06,"✅ Sharp band",IF($J$8<0.08,"Strong","⚠ Verify (stale?)"))))) | N8: Model 58.6% (fair -141). Your call. | P8: =IF(OR($H$8="",$O$8=""),"",(1+IF($H$8<0,-100/$H$8,$H$8/100))/(1+IF($O$8<0,-100/$O$8,$O$8/100))-1)
A9: 2026-06-28 | B9: Portland Fire @ Washington Mystics | C9: 19:00 | D9: Total | E9: Over 166.5 | F9: 0.57745098 | G9: -137 | H9: 104 | I9: =IF($H$9="","",IF($H$9<0,-$H$9/(-$H$9+100),100/($H$9+100))) | J9: =IF($H$9="","",$F$9*IF($H$9<0,-100/$H$9,$H$9/100)-(1-$F$9)) | K9: =IF($H$9="","",MAX(0,($F$9*IF($H$9<0,-100/$H$9,$H$9/100)-(1-$F$9))/IF($H$9<0,-100/$H$9,$H$9/100))*'Settings'!$B$3) | L9: =IF($H$9="","",ROUND(MIN($K$9,'Settings'!$B$5)*'Settings'!$B$2,2)) | M9: =IF($J$9="","",IF($J$9<0,"Pass",IF($J$9<'Settings'!$B$4,"Thin",IF($J$9<0.06,"✅ Sharp band",IF($J$9<0.08,"Strong","⚠ Verify (stale?)"))))) | N9: Model 57.7% (fair -137). Your call. | P9: =IF(OR($H$9="",$O$9=""),"",(1+IF($H$9<0,-100/$H$9,$H$9/100))/(1+IF($O$9<0,-100/$O$9,$O$9/100))-1)
A10: 2026-06-28 | B10: Houston Astros @ Detroit Tigers | C10: 17:40 | D10: Total | E10: Over 8.5 | F10: 0.5746 | G10: -135 | H10: 100 | I10: =IF($H$10="","",IF($H$10<0,-$H$10/(-$H$10+100),100/($H$10+100))) | J10: =IF($H$10="","",$F$10*IF($H$10<0,-100/$H$10,$H$10/100)-(1-$F$10)) | K10: =IF($H$10="","",MAX(0,($F$10*IF($H$10<0,-100/$H$10,$H$10/100)-(1-$F$10))/IF($H$10<0,-100/$H$10,$H$10/100))*'Settings'!$B$3) | L10: =IF($H$10="","",ROUND(MIN($K$10,'Settings'!$B$5)*'Settings'!$B$2,2)) | M10: =IF($J$10="","",IF($J$10<0,"Pass",IF($J$10<'Settings'!$B$4,"Thin",IF($J$10<0.06,"✅ Sharp band",IF($J$10<0.08,"Strong","⚠ Verify (stale?)"))))) | N10: Model 57.5% (fair -135). Your call. | P10: =IF(OR($H$10="",$O$10=""),"",(1+IF($H$10<0,-100/$H$10,$H$10/100))/(1+IF($O$10<0,-100/$O$10,$O$10/100))-1)
A11: 2026-06-28 | B11: Kansas City Royals @ Chicago White Sox | C11: 18:10 | D11: Total | E11: Over 9 | F11: 0.58666829 | G11: -142 | H11: -105 | I11: =IF($H$11="","",IF($H$11<0,-$H$11/(-$H$11+100),100/($H$11+100))) | J11: =IF($H$11="","",$F$11*IF($H$11<0,-100/$H$11,$H$11/100)-(1-$F$11)) | K11: =IF($H$11="","",MAX(0,($F$11*IF($H$11<0,-100/$H$11,$H$11/100)-(1-$F$11))/IF($H$11<0,-100/$H$11,$H$11/100))*'Settings'!$B$3) | L11: =IF($H$11="","",ROUND(MIN($K$11,'Settings'!$B$5)*'Settings'!$B$2,2)) | M11: =IF($J$11="","",IF($J$11<0,"Pass",IF($J$11<'Settings'!$B$4,"Thin",IF($J$11<0.06,"✅ Sharp band",IF($J$11<0.08,"Strong","⚠ Verify (stale?)"))))) | N11: Model 58.7% (fair -142). Your call. | P11: =IF(OR($H$11="",$O$11=""),"",(1+IF($H$11<0,-100/$H$11,$H$11/100))/(1+IF($O$11<0,-100/$O$11,$O$11/100))-1)
A12: 2026-06-27 | B12: Cincinnati Reds @ Pittsburgh Pirates | C12: 20:05 | D12: Moneyline | E12: Pittsburgh Pirates | F12: 0.55601942 | G12: -125 | H12: 106 | I12: =IF($H$12="","",IF($H$12<0,-$H$12/(-$H$12+100),100/($H$12+100))) | J12: =IF($H$12="","",$F$12*IF($H$12<0,-100/$H$12,$H$12/100)-(1-$F$12)) | K12: =IF($H$12="","",MAX(0,($F$12*IF($H$12<0,-100/$H$12,$H$12/100)-(1-$F$12))/IF($H$12<0,-100/$H$12,$H$12/100))*'Settings'!$B$3) | L12: =IF($H$12="","",ROUND(MIN($K$12,'Settings'!$B$5)*'Settings'!$B$2,2)) | M12: =IF($J$12="","",IF($J$12<0,"Pass",IF($J$12<'Settings'!$B$4,"Thin",IF($J$12<0.06,"✅ Sharp band",IF($J$12<0.08,"Strong","⚠ Verify (stale?)"))))) | N12: Model 55.6% (fair -125). Your call. | P12: =IF(OR($H$12="",$O$12=""),"",(1+IF($H$12<0,-100/$H$12,$H$12/100))/(1+IF($O$12<0,-100/$O$12,$O$12/100))-1)
A13: 2026-06-28 | B13: New York Liberty @ Golden State Valkyries | C13: 23:00 | D13: Spread | E13: Golden State Valkyries +1.5 | F13: 0.5795451 | G13: -138 | H13: -104 | I13: =IF($H$13="","",IF($H$13<0,-$H$13/(-$H$13+100),100/($H$13+100))) | J13: =IF($H$13="","",$F$13*IF($H$13<0,-100/$H$13,$H$13/100)-(1-$F$13)) | K13: =IF($H$13="","",MAX(0,($F$13*IF($H$13<0,-100/$H$13,$H$13/100)-(1-$F$13))/IF($H$13<0,-100/$H$13,$H$13/100))*'Settings'!$B$3) | L13: =IF($H$13="","",ROUND(MIN($K$13,'Settings'!$B$5)*'Settings'!$B$2,2)) | M13: =IF($J$13="","",IF($J$13<0,"Pass",IF($J$13<'Settings'!$B$4,"Thin",IF($J$13<0.06,"✅ Sharp band",IF($J$13<0.08,"Strong","⚠ Verify (stale?)"))))) | N13: Model 58.0% (fair -138). Your call. | P13: =IF(OR($H$13="",$O$13=""),"",(1+IF($H$13<0,-100/$H$13,$H$13/100))/(1+IF($O$13<0,-100/$O$13,$O$13/100))-1)
A14: 2026-06-28 | B14: New York Liberty @ Golden State Valkyries | C14: 23:00 | D14: Moneyline | E14: Golden State Valkyries | F14: 0.57832157 | G14: -137 | H14: -104 | I14: =IF($H$14="","",IF($H$14<0,-$H$14/(-$H$14+100),100/($H$14+100))) | J14: =IF($H$14="","",$F$14*IF($H$14<0,-100/$H$14,$H$14/100)-(1-$F$14)) | K14: =IF($H$14="","",MAX(0,($F$14*IF($H$14<0,-100/$H$14,$H$14/100)-(1-$F$14))/IF($H$14<0,-100/$H$14,$H$14/100))*'Settings'!$B$3) | L14: =IF($H$14="","",ROUND(MIN($K$14,'Settings'!$B$5)*'Settings'!$B$2,2)) | M14: =IF($J$14="","",IF($J$14<0,"Pass",IF($J$14<'Settings'!$B$4,"Thin",IF($J$14<0.06,"✅ Sharp band",IF($J$14<0.08,"Strong","⚠ Verify (stale?)"))))) | N14: Model 57.8% (fair -137). Your call. | P14: =IF(OR($H$14="",$O$14=""),"",(1+IF($H$14<0,-100/$H$14,$H$14/100))/(1+IF($O$14<0,-100/$O$14,$O$14/100))-1)
A15: 2026-06-28 | B15: Seattle Mariners @ Cleveland Guardians | C15: 17:40 | D15: Moneyline | E15: Seattle Mariners | F15: 0.54375 | G15: -119 | H15: 108 | I15: =IF($H$15="","",IF($H$15<0,-$H$15/(-$H$15+100),100/($H$15+100))) | J15: =IF($H$15="","",$F$15*IF($H$15<0,-100/$H$15,$H$15/100)-(1-$F$15)) | K15: =IF($H$15="","",MAX(0,($F$15*IF($H$15<0,-100/$H$15,$H$15/100)-(1-$F$15))/IF($H$15<0,-100/$H$15,$H$15/100))*'Settings'!$B$3) | L15: =IF($H$15="","",ROUND(MIN($K$15,'Settings'!$B$5)*'Settings'!$B$2,2)) | M15: =IF($J$15="","",IF($J$15<0,"Pass",IF($J$15<'Settings'!$B$4,"Thin",IF($J$15<0.06,"✅ Sharp band",IF($J$15<0.08,"Strong","⚠ Verify (stale?)"))))) | N15: Model 54.4% (fair -119). Your call. | P15: =IF(OR($H$15="",$O$15=""),"",(1+IF($H$15<0,-100/$H$15,$H$15/100))/(1+IF($O$15<0,-100/$O$15,$O$15/100))-1)
A16: 2026-06-28 | B16: Arizona Diamondbacks @ Tampa Bay Rays | C16: 17:40 | D16: Total | E16: Over 7.5 | F16: 0.59580698 | G16: -147 | H16: -115 | I16: =IF($H$16="","",IF($H$16<0,-$H$16/(-$H$16+100),100/($H$16+100))) | J16: =IF($H$16="","",$F$16*IF($H$16<0,-100/$H$16,$H$16/100)-(1-$F$16)) | K16: =IF($H$16="","",MAX(0,($F$16*IF($H$16<0,-100/$H$16,$H$16/100)-(1-$F$16))/IF($H$16<0,-100/$H$16,$H$16/100))*'Settings'!$B$3) | L16: =IF($H$16="","",ROUND(MIN($K$16,'Settings'!$B$5)*'Settings'!$B$2,2)) | M16: =IF($J$16="","",IF($J$16<0,"Pass",IF($J$16<'Settings'!$B$4,"Thin",IF($J$16<0.06,"✅ Sharp band",IF($J$16<0.08,"Strong","⚠ Verify (stale?)"))))) | N16: Model 59.6% (fair -147). Your call. | P16: =IF(OR($H$16="",$O$16=""),"",(1+IF($H$16<0,-100/$H$16,$H$16/100))/(1+IF($O$16<0,-100/$O$16,$O$16/100))-1)
A17: 2026-06-28 | B17: Las Vegas Aces @ Chicago Sky | C17: 20:00 | D17: Spread | E17: Chicago Sky +7.5 | F17: 0.57676154 | G17: -136 | H17: -108 | I17: =IF($H$17="","",IF($H$17<0,-$H$17/(-$H$17+100),100/($H$17+100))) | J17: =IF($H$17="","",$F$17*IF($H$17<0,-100/$H$17,$H$17/100)-(1-$F$17)) | K17: =IF($H$17="","",MAX(0,($F$17*IF($H$17<0,-100/$H$17,$H$17/100)-(1-$F$17))/IF($H$17<0,-100/$H$17,$H$17/100))*'Settings'!$B$3) | L17: =IF($H$17="","",ROUND(MIN($K$17,'Settings'!$B$5)*'Settings'!$B$2,2)) | M17: =IF($J$17="","",IF($J$17<0,"Pass",IF($J$17<'Settings'!$B$4,"Thin",IF($J$17<0.06,"✅ Sharp band",IF($J$17<0.08,"Strong","⚠ Verify (stale?)"))))) | N17: Model 57.7% (fair -136). Your call. | P17: =IF(OR($H$17="",$O$17=""),"",(1+IF($H$17<0,-100/$H$17,$H$17/100))/(1+IF($O$17<0,-100/$O$17,$O$17/100))-1)
A18: 2026-06-28 | B18: Washington Nationals @ Baltimore Orioles | C18: 17:35 | D18: Spread | E18: Baltimore Orioles -1.5 | F18: 0.52738095 | G18: -112 | H18: 110 | I18: =IF($H$18="","",IF($H$18<0,-$H$18/(-$H$18+100),100/($H$18+100))) | J18: =IF($H$18="","",$F$18*IF($H$18<0,-100/$H$18,$H$18/100)-(1-$F$18)) | K18: =IF($H$18="","",MAX(0,($F$18*IF($H$18<0,-100/$H$18,$H$18/100)-(1-$F$18))/IF($H$18<0,-100/$H$18,$H$18/100))*'Settings'!$B$3) | L18: =IF($H$18="","",ROUND(MIN($K$18,'Settings'!$B$5)*'Settings'!$B$2,2)) | M18: =IF($J$18="","",IF($J$18<0,"Pass",IF($J$18<'Settings'!$B$4,"Thin",IF($J$18<0.06,"✅ Sharp band",IF($J$18<0.08,"Strong","⚠ Verify (stale?)"))))) | N18: Model 52.7% (fair -112). Your call. | P18: =IF(OR($H$18="",$O$18=""),"",(1+IF($H$18<0,-100/$H$18,$H$18/100))/(1+IF($O$18<0,-100/$O$18,$O$18/100))-1)
A19: 2026-06-28 | B19: Washington Nationals @ Baltimore Orioles | C19: 17:35 | D19: Moneyline | E19: Baltimore Orioles | F19: 0.6854057 | G19: -218 | H19: -163 | I19: =IF($H$19="","",IF($H$19<0,-$H$19/(-$H$19+100),100/($H$19+100))) | J19: =IF($H$19="","",$F$19*IF($H$19<0,-100/$H$19,$H$19/100)-(1-$F$19)) | K19: =IF($H$19="","",MAX(0,($F$19*IF($H$19<0,-100/$H$19,$H$19/100)-(1-$F$19))/IF($H$19<0,-100/$H$19,$H$19/100))*'Settings'!$B$3) | L19: =IF($H$19="","",ROUND(MIN($K$19,'Settings'!$B$5)*'Settings'!$B$2,2)) | M19: =IF($J$19="","",IF($J$19<0,"Pass",IF($J$19<'Settings'!$B$4,"Thin",IF($J$19<0.06,"✅ Sharp band",IF($J$19<0.08,"Strong","⚠ Verify (stale?)"))))) | N19: Model 68.5% (fair -218). Your call. | P19: =IF(OR($H$19="",$O$19=""),"",(1+IF($H$19<0,-100/$H$19,$H$19/100))/(1+IF($O$19<0,-100/$O$19,$O$19/100))-1)
A20: 2026-06-28 | B20: Las Vegas Aces @ Chicago Sky | C20: 20:00 | D20: Total | E20: Over 178.5 | F20: 0.55275 | G20: -124 | H20: 100 | I20: =IF($H$20="","",IF($H$20<0,-$H$20/(-$H$20+100),100/($H$20+100))) | J20: =IF($H$20="","",$F$20*IF($H$20<0,-100/$H$20,$H$20/100)-(1-$F$20)) | K20: =IF($H$20="","",MAX(0,($F$20*IF($H$20<0,-100/$H$20,$H$20/100)-(1-$F$20))/IF($H$20<0,-100/$H$20,$H$20/100))*'Settings'!$B$3) | L20: =IF($H$20="","",ROUND(MIN($K$20,'Settings'!$B$5)*'Settings'!$B$2,2)) | M20: =IF($J$20="","",IF($J$20<0,"Pass",IF($J$20<'Settings'!$B$4,"Thin",IF($J$20<0.06,"✅ Sharp band",IF($J$20<0.08,"Strong","⚠ Verify (stale?)"))))) | N20: Model 55.3% (fair -124). Your call. | P20: =IF(OR($H$20="",$O$20=""),"",(1+IF($H$20<0,-100/$H$20,$H$20/100))/(1+IF($O$20<0,-100/$O$20,$O$20/100))-1)
A21: 2026-06-28 | B21: Texas Rangers @ Toronto Blue Jays | C21: 17:37 | D21: Total | E21: Over 8.5 | F21: 0.55175 | G21: -123 | H21: 100 | I21: =IF($H$21="","",IF($H$21<0,-$H$21/(-$H$21+100),100/($H$21+100))) | J21: =IF($H$21="","",$F$21*IF($H$21<0,-100/$H$21,$H$21/100)-(1-$F$21)) | K21: =IF($H$21="","",MAX(0,($F$21*IF($H$21<0,-100/$H$21,$H$21/100)-(1-$F$21))/IF($H$21<0,-100/$H$21,$H$21/100))*'Settings'!$B$3) | L21: =IF($H$21="","",ROUND(MIN($K$21,'Settings'!$B$5)*'Settings'!$B$2,2)) | M21: =IF($J$21="","",IF($J$21<0,"Pass",IF($J$21<'Settings'!$B$4,"Thin",IF($J$21<0.06,"✅ Sharp band",IF($J$21<0.08,"Strong","⚠ Verify (stale?)"))))) | N21: Model 55.2% (fair -123). Your call. | P21: =IF(OR($H$21="",$O$21=""),"",(1+IF($H$21<0,-100/$H$21,$H$21/100))/(1+IF($O$21<0,-100/$O$21,$O$21/100))-1)
A22: 2026-06-28 | B22: New York Liberty @ Golden State Valkyries | C22: 23:00 | D22: Total | E22: Over 163.5 | F22: 0.57692381 | G22: -136 | H22: -110 | I22: =IF($H$22="","",IF($H$22<0,-$H$22/(-$H$22+100),100/($H$22+100))) | J22: =IF($H$22="","",$F$22*IF($H$22<0,-100/$H$22,$H$22/100)-(1-$F$22)) | K22: =IF($H$22="","",MAX(0,($F$22*IF($H$22<0,-100/$H$22,$H$22/100)-(1-$F$22))/IF($H$22<0,-100/$H$22,$H$22/100))*'Settings'!$B$3) | L22: =IF($H$22="","",ROUND(MIN($K$22,'Settings'!$B$5)*'Settings'!$B$2,2)) | M22: =IF($J$22="","",IF($J$22<0,"Pass",IF($J$22<'Settings'!$B$4,"Thin",IF($J$22<0.06,"✅ Sharp band",IF($J$22<0.08,"Strong","⚠ Verify (stale?)"))))) | N22: Model 57.7% (fair -136). Your call. | P22: =IF(OR($H$22="",$O$22=""),"",(1+IF($H$22<0,-100/$H$22,$H$22/100))/(1+IF($O$22<0,-100/$O$22,$O$22/100))-1)
A23: 2026-06-28 | B23: Atlanta Braves @ San Francisco Giants | C23: 20:05 | D23: Total | E23: Over 7.5 | F23: 0.56367073 | G23: -129 | H23: -105 | I23: =IF($H$23="","",IF($H$23<0,-$H$23/(-$H$23+100),100/($H$23+100))) | J23: =IF($H$23="","",$F$23*IF($H$23<0,-100/$H$23,$H$23/100)-(1-$F$23)) | K23: =IF($H$23="","",MAX(0,($F$23*IF($H$23<0,-100/$H$23,$H$23/100)-(1-$F$23))/IF($H$23<0,-100/$H$23,$H$23/100))*'Settings'!$B$3) | L23: =IF($H$23="","",ROUND(MIN($K$23,'Settings'!$B$5)*'Settings'!$B$2,2)) | M23: =IF($J$23="","",IF($J$23<0,"Pass",IF($J$23<'Settings'!$B$4,"Thin",IF($J$23<0.06,"✅ Sharp band",IF($J$23<0.08,"Strong","⚠ Verify (stale?)"))))) | N23: Model 56.4% (fair -129). Your call. | P23: =IF(OR($H$23="",$O$23=""),"",(1+IF($H$23<0,-100/$H$23,$H$23/100))/(1+IF($O$23<0,-100/$O$23,$O$23/100))-1)
A24: 2026-06-27 | B24: Washington Nationals @ Baltimore Orioles | C24: 23:05 | D24: Moneyline | E24: Baltimore Orioles | F24: 0.55104706 | G24: -123 | H24: -104 | I24: =IF($H$24="","",IF($H$24<0,-$H$24/(-$H$24+100),100/($H$24+100))) | J24: =IF($H$24="","",$F$24*IF($H$24<0,-100/$H$24,$H$24/100)-(1-$F$24)) | K24: =IF($H$24="","",MAX(0,($F$24*IF($H$24<0,-100/$H$24,$H$24/100)-(1-$F$24))/IF($H$24<0,-100/$H$24,$H$24/100))*'Settings'!$B$3) | L24: =IF($H$24="","",ROUND(MIN($K$24,'Settings'!$B$5)*'Settings'!$B$2,2)) | M24: =IF($J$24="","",IF($J$24<0,"Pass",IF($J$24<'Settings'!$B$4,"Thin",IF($J$24<0.06,"✅ Sharp band",IF($J$24<0.08,"Strong","⚠ Verify (stale?)"))))) | N24: Model 55.1% (fair -123). Your call. | P24: =IF(OR($H$24="",$O$24=""),"",(1+IF($H$24<0,-100/$H$24,$H$24/100))/(1+IF($O$24<0,-100/$O$24,$O$24/100))-1)
A25: 2026-06-27 | B25: Arizona Diamondbacks @ Tampa Bay Rays | C25: 22:10 | D25: Moneyline | E25: Arizona Diamondbacks | F25: 0.47528634 | G25: 110 | H25: 127 | I25: =IF($H$25="","",IF($H$25<0,-$H$25/(-$H$25+100),100/($H$25+100))) | J25: =IF($H$25="","",$F$25*IF($H$25<0,-100/$H$25,$H$25/100)-(1-$F$25)) | K25: =IF($H$25="","",MAX(0,($F$25*IF($H$25<0,-100/$H$25,$H$25/100)-(1-$F$25))/IF($H$25<0,-100/$H$25,$H$25/100))*'Settings'!$B$3) | L25: =IF($H$25="","",ROUND(MIN($K$25,'Settings'!$B$5)*'Settings'!$B$2,2)) | M25: =IF($J$25="","",IF($J$25<0,"Pass",IF($J$25<'Settings'!$B$4,"Thin",IF($J$25<0.06,"✅ Sharp band",IF($J$25<0.08,"Strong","⚠ Verify (stale?)"))))) | N25: Model 47.5% (fair +110). Your call. | P25: =IF(OR($H$25="",$O$25=""),"",(1+IF($H$25<0,-100/$H$25,$H$25/100))/(1+IF($O$25<0,-100/$O$25,$O$25/100))-1)
A26: 2026-06-28 | B26: Kansas City Royals @ Chicago White Sox | C26: 18:10 | D26: Spread | E26: Chicago White Sox -1.5 | F26: 0.42235294 | G26: 137 | H26: 155 | I26: =IF($H$26="","",IF($H$26<0,-$H$26/(-$H$26+100),100/($H$26+100))) | J26: =IF($H$26="","",$F$26*IF($H$26<0,-100/$H$26,$H$26/100)-(1-$F$26)) | K26: =IF($H$26="","",MAX(0,($F$26*IF($H$26<0,-100/$H$26,$H$26/100)-(1-$F$26))/IF($H$26<0,-100/$H$26,$H$26/100))*'Settings'!$B$3) | L26: =IF($H$26="","",ROUND(MIN($K$26,'Settings'!$B$5)*'Settings'!$B$2,2)) | M26: =IF($J$26="","",IF($J$26<0,"Pass",IF($J$26<'Settings'!$B$4,"Thin",IF($J$26<0.06,"✅ Sharp band",IF($J$26<0.08,"Strong","⚠ Verify (stale?)"))))) | N26: Model 42.2% (fair +137). Your call. | P26: =IF(OR($H$26="",$O$26=""),"",(1+IF($H$26<0,-100/$H$26,$H$26/100))/(1+IF($O$26<0,-100/$O$26,$O$26/100))-1)
A27: 2026-06-28 | B27: New York Yankees @ Boston Red Sox | C27: 23:20 | D27: Total | E27: Under 9 | F27: 0.51725962 | G27: -107 | H27: 108 | I27: =IF($H$27="","",IF($H$27<0,-$H$27/(-$H$27+100),100/($H$27+100))) | J27: =IF($H$27="","",$F$27*IF($H$27<0,-100/$H$27,$H$27/100)-(1-$F$27)) | K27: =IF($H$27="","",MAX(0,($F$27*IF($H$27<0,-100/$H$27,$H$27/100)-(1-$F$27))/IF($H$27<0,-100/$H$27,$H$27/100))*'Settings'!$B$3) | L27: =IF($H$27="","",ROUND(MIN($K$27,'Settings'!$B$5)*'Settings'!$B$2,2)) | M27: =IF($J$27="","",IF($J$27<0,"Pass",IF($J$27<'Settings'!$B$4,"Thin",IF($J$27<0.06,"✅ Sharp band",IF($J$27<0.08,"Strong","⚠ Verify (stale?)"))))) | N27: Model 51.7% (fair -107). Your call. | P27: =IF(OR($H$27="",$O$27=""),"",(1+IF($H$27<0,-100/$H$27,$H$27/100))/(1+IF($O$27<0,-100/$O$27,$O$27/100))-1)
A28: 2026-06-28 | B28: Colorado Rockies @ Minnesota Twins | C28: 18:10 | D28: Total | E28: Over 9.5 | F28: 0.53585 | G28: -115 | H28: 100 | I28: =IF($H$28="","",IF($H$28<0,-$H$28/(-$H$28+100),100/($H$28+100))) | J28: =IF($H$28="","",$F$28*IF($H$28<0,-100/$H$28,$H$28/100)-(1-$F$28)) | K28: =IF($H$28="","",MAX(0,($F$28*IF($H$28<0,-100/$H$28,$H$28/100)-(1-$F$28))/IF($H$28<0,-100/$H$28,$H$28/100))*'Settings'!$B$3) | L28: =IF($H$28="","",ROUND(MIN($K$28,'Settings'!$B$5)*'Settings'!$B$2,2)) | M28: =IF($J$28="","",IF($J$28<0,"Pass",IF($J$28<'Settings'!$B$4,"Thin",IF($J$28<0.06,"✅ Sharp band",IF($J$28<0.08,"Strong","⚠ Verify (stale?)"))))) | N28: Model 53.6% (fair -115). Your call. | P28: =IF(OR($H$28="",$O$28=""),"",(1+IF($H$28<0,-100/$H$28,$H$28/100))/(1+IF($O$28<0,-100/$O$28,$O$28/100))-1)
A29: 2026-06-27 | B29: Chicago Cubs @ Milwaukee Brewers | C29: 23:10 | D29: Moneyline | E29: Milwaukee Brewers | F29: 0.63241967 | G29: -172 | H29: -144 | I29: =IF($H$29="","",IF($H$29<0,-$H$29/(-$H$29+100),100/($H$29+100))) | J29: =IF($H$29="","",$F$29*IF($H$29<0,-100/$H$29,$H$29/100)-(1-$F$29)) | K29: =IF($H$29="","",MAX(0,($F$29*IF($H$29<0,-100/$H$29,$H$29/100)-(1-$F$29))/IF($H$29<0,-100/$H$29,$H$29/100))*'Settings'!$B$3) | L29: =IF($H$29="","",ROUND(MIN($K$29,'Settings'!$B$5)*'Settings'!$B$2,2)) | M29: =IF($J$29="","",IF($J$29<0,"Pass",IF($J$29<'Settings'!$B$4,"Thin",IF($J$29<0.06,"✅ Sharp band",IF($J$29<0.08,"Strong","⚠ Verify (stale?)"))))) | N29: Model 63.2% (fair -172). Your call. | P29: =IF(OR($H$29="",$O$29=""),"",(1+IF($H$29<0,-100/$H$29,$H$29/100))/(1+IF($O$29<0,-100/$O$29,$O$29/100))-1)

Sheet MLB Games
A1: MLB — game markets
A2: Moneyline · Total · Spread. Yellow = your price.
A4: Date | B4: Matchup | C4: Start | D4: Market | E4: Selection | F4: Model Win% | G4: Model Fair | H4: ✏ Your Odds | I4: Implied% | J4: Your Edge (EV) | K4: ¼-Kelly % | L4: Stake $ | M4: Verdict | N4: Model read | O4: ✏ Closing | P4: CLV %
A5: 2026-06-27 | B5: Houston Astros @ Detroit Tigers | C5: 17:10 | D5: Moneyline | E5: Houston Astros | F5: 0.43982063 | G5: 127 | H5: 123 | I5: =IF($H$5="","",IF($H$5<0,-$H$5/(-$H$5+100),100/($H$5+100))) | J5: =IF($H$5="","",$F$5*IF($H$5<0,-100/$H$5,$H$5/100)-(1-$F$5)) | K5: =IF($H$5="","",MAX(0,($F$5*IF($H$5<0,-100/$H$5,$H$5/100)-(1-$F$5))/IF($H$5<0,-100/$H$5,$H$5/100))*'Settings'!$B$3) | L5: =IF($H$5="","",ROUND(MIN($K$5,'Settings'!$B$5)*'Settings'!$B$2,2)) | M5: =IF($J$5="","",IF($J$5<0,"Pass",IF($J$5<'Settings'!$B$4,"Thin",IF($J$5<0.06,"✅ Sharp band",IF($J$5<0.08,"Strong","⚠ Verify (stale?)"))))) | N5: Model 44.0% (fair +127). Your call. | P5: =IF(OR($H$5="",$O$5=""),"",(1+IF($H$5<0,-100/$H$5,$H$5/100))/(1+IF($O$5<0,-100/$O$5,$O$5/100))-1)
A6: 2026-06-27 | B6: Houston Astros @ Detroit Tigers | C6: 17:10 | D6: Moneyline | E6: Detroit Tigers | F6: 0.56019868 | G6: -127 | H6: -127 | I6: =IF($H$6="","",IF($H$6<0,-$H$6/(-$H$6+100),100/($H$6+100))) | J6: =IF($H$6="","",$F$6*IF($H$6<0,-100/$H$6,$H$6/100)-(1-$F$6)) | K6: =IF($H$6="","",MAX(0,($F$6*IF($H$6<0,-100/$H$6,$H$6/100)-(1-$F$6))/IF($H$6<0,-100/$H$6,$H$6/100))*'Settings'!$B$3) | L6: =IF($H$6="","",ROUND(MIN($K$6,'Settings'!$B$5)*'Settings'!$B$2,2)) | M6: =IF($J$6="","",IF($J$6<0,"Pass",IF($J$6<'Settings'!$B$4,"Thin",IF($J$6<0.06,"✅ Sharp band",IF($J$6<0.08,"Strong","⚠ Verify (stale?)"))))) | N6: Model 56.0% (fair -127). Your call. | P6: =IF(OR($H$6="",$O$6=""),"",(1+IF($H$6<0,-100/$H$6,$H$6/100))/(1+IF($O$6<0,-100/$O$6,$O$6/100))-1)
A7: 2026-06-27 | B7: Houston Astros @ Detroit Tigers | C7: 17:10 | D7: Total | E7: Over 9 | F7: 0.5093 | G7: -104 | H7: 125 | I7: =IF($H$7="","",IF($H$7<0,-$H$7/(-$H$7+100),100/($H$7+100))) | J7: =IF($H$7="","",$F$7*IF($H$7<0,-100/$H$7,$H$7/100)-(1-$F$7)) | K7: =IF($H$7="","",MAX(0,($F$7*IF($H$7<0,-100/$H$7,$H$7/100)-(1-$F$7))/IF($H$7<0,-100/$H$7,$H$7/100))*'Settings'!$B$3) | L7: =IF($H$7="","",ROUND(MIN($K$7,'Settings'!$B$5)*'Settings'!$B$2,2)) | M7: =IF($J$7="","",IF($J$7<0,"Pass",IF($J$7<'Settings'!$B$4,"Thin",IF($J$7<0.06,"✅ Sharp band",IF($J$7<0.08,"Strong","⚠ Verify (stale?)"))))) | N7: Model 50.9% (fair -104). Your call. | P7: =IF(OR($H$7="",$O$7=""),"",(1+IF($H$7<0,-100/$H$7,$H$7/100))/(1+IF($O$7<0,-100/$O$7,$O$7/100))-1)
A8: 2026-06-27 | B8: Houston Astros @ Detroit Tigers | C8: 17:10 | D8: Total | E8: Under 9 | F8: 0.4907 | G8: 104 | H8: 100 | I8: =IF($H$8="","",IF($H$8<0,-$H$8/(-$H$8+100),100/($H$8+100))) | J8: =IF($H$8="","",$F$8*IF($H$8<0,-100/$H$8,$H$8/100)-(1-$F$8)) | K8: =IF($H$8="","",MAX(0,($F$8*IF($H$8<0,-100/$H$8,$H$8/100)-(1-$F$8))/IF($H$8<0,-100/$H$8,$H$8/100))*'Settings'!$B$3) | L8: =IF($H$8="","",ROUND(MIN($K$8,'Settings'!$B$5)*'Settings'!$B$2,2)) | M8: =IF($J$8="","",IF($J$8<0,"Pass",IF($J$8<'Settings'!$B$4,"Thin",IF($J$8<0.06,"✅ Sharp band",IF($J$8<0.08,"Strong","⚠ Verify (stale?)"))))) | N8: Model 49.1% (fair +104). Your call. | P8: =IF(OR($H$8="",$O$8=""),"",(1+IF($H$8<0,-100/$H$8,$H$8/100))/(1+IF($O$8<0,-100/$O$8,$O$8/100))-1)
A9: 2026-06-27 | B9: Houston Astros @ Detroit Tigers | C9: 17:10 | D9: Spread | E9: Detroit Tigers -1.5 | F9: 0.38303846 | G9: 161 | H9: 160 | I9: =IF($H$9="","",IF($H$9<0,-$H$9/(-$H$9+100),100/($H$9+100))) | J9: =IF($H$9="","",$F$9*IF($H$9<0,-100/$H$9,$H$9/100)-(1-$F$9)) | K9: =IF($H$9="","",MAX(0,($F$9*IF($H$9<0,-100/$H$9,$H$9/100)-(1-$F$9))/IF($H$9<0,-100/$H$9,$H$9/100))*'Settings'!$B$3) | L9: =IF($H$9="","",ROUND(MIN($K$9,'Settings'!$B$5)*'Settings'!$B$2,2)) | M9: =IF($J$9="","",IF($J$9<0,"Pass",IF($J$9<'Settings'!$B$4,"Thin",IF($J$9<0.06,"✅ Sharp band",IF($J$9<0.08,"Strong","⚠ Verify (stale?)"))))) | N9: Model 38.3% (fair +161). Your call. | P9: =IF(OR($H$9="",$O$9=""),"",(1+IF($H$9<0,-100/$H$9,$H$9/100))/(1+IF($O$9<0,-100/$O$9,$O$9/100))-1)
A10: 2026-06-27 | B10: Houston Astros @ Detroit Tigers | C10: 17:10 | D10: Spread | E10: Houston Astros +1.5 | F10: 0.61698289 | G10: -161 | H10: -163 | I10: =IF($H$10="","",IF($H$10<0,-$H$10/(-$H$10+100),100/($H$10+100))) | J10: =IF($H$10="","",$F$10*IF($H$10<0,-100/$H$10,$H$10/100)-(1-$F$10)) | K10: =IF($H$10="","",MAX(0,($F$10*IF($H$10<0,-100/$H$10,$H$10/100)-(1-$F$10))/IF($H$10<0,-100/$H$10,$H$10/100))*'Settings'!$B$3) | L10: =IF($H$10="","",ROUND(MIN($K$10,'Settings'!$B$5)*'Settings'!$B$2,2)) | M10: =IF($J$10="","",IF($J$10<0,"Pass",IF($J$10<'Settings'!$B$4,"Thin",IF($J$10<0.06,"✅ Sharp band",IF($J$10<0.08,"Strong","⚠ Verify (stale?)"))))) | N10: Model 61.7% (fair -161). Your call. | P10: =IF(OR($H$10="",$O$10=""),"",(1+IF($H$10<0,-100/$H$10,$H$10/100))/(1+IF($O$10<0,-100/$O$10,$O$10/100))-1)
A11: 2026-06-27 | B11: New York Yankees @ Boston Red Sox | C11: 17:10 | D11: Moneyline | E11: New York Yankees | F11: 0.52876863 | G11: -112 | H11: -104 | I11: =IF($H$11="","",IF($H$11<0,-$H$11/(-$H$11+100),100/($H$11+100))) | J11: =IF($H$11="","",$F$11*IF($H$11<0,-100/$H$11,$H$11/100)-(1-$F$11)) | K11: =IF($H$11="","",MAX(0,($F$11*IF($H$11<0,-100/$H$11,$H$11/100)-(1-$F$11))/IF($H$11<0,-100/$H$11,$H$11/100))*'Settings'!$B$3) | L11: =IF($H$11="","",ROUND(MIN($K$11,'Settings'!$B$5)*'Settings'!$B$2,2)) | M11: =IF($J$11="","",IF($J$11<0,"Pass",IF($J$11<'Settings'!$B$4,"Thin",IF($J$11<0.06,"✅ Sharp band",IF($J$11<0.08,"Strong","⚠ Verify (stale?)"))))) | N11: Model 52.9% (fair -112). Your call. | P11: =IF(OR($H$11="",$O$11=""),"",(1+IF($H$11<0,-100/$H$11,$H$11/100))/(1+IF($O$11<0,-100/$O$11,$O$11/100))-1)
A12: 2026-06-27 | B12: New York Yankees @ Boston Red Sox | C12: 17:10 | D12: Moneyline | E12: Boston Red Sox | F12: 0.47122549 | G12: 112 | H12: 104 | I12: =IF($H$12="","",IF($H$12<0,-$H$12/(-$H$12+100),100/($H$12+100))) | J12: =IF($H$12="","",$F$12*IF($H$12<0,-100/$H$12,$H$12/100)-(1-$F$12)) | K12: =IF($H$12="","",MAX(0,($F$12*IF($H$12<0,-100/$H$12,$H$12/100)-(1-$F$12))/IF($H$12<0,-100/$H$12,$H$12/100))*'Settings'!$B$3) | L12: =IF($H$12="","",ROUND(MIN($K$12,'Settings'!$B$5)*'Settings'!$B$2,2)) | M12: =IF($J$12="","",IF($J$12<0,"Pass",IF($J$12<'Settings'!$B$4,"Thin",IF($J$12<0.06,"✅ Sharp band",IF($J$12<0.08,"Strong","⚠ Verify (stale?)"))))) | N12: Model 47.1% (fair +112). Your call. | P12: =IF(OR($H$12="",$O$12=""),"",(1+IF($H$12<0,-100/$H$12,$H$12/100))/(1+IF($O$12<0,-100/$O$12,$O$12/100))-1)
A13: 2026-06-27 | B13: New York Yankees @ Boston Red Sox | C13: 17:10 | D13: Total | E13: Over 8.5 | F13: 0.5897 | G13: -144 | H13: 117 | I13: =IF($H$13="","",IF($H$13<0,-$H$13/(-$H$13+100),100/($H$13+100))) | J13: =IF($H$13="","",$F$13*IF($H$13<0,-100/$H$13,$H$13/100)-(1-$F$13)) | K13: =IF($H$13="","",MAX(0,($F$13*IF($H$13<0,-100/$H$13,$H$13/100)-(1-$F$13))/IF($H$13<0,-100/$H$13,$H$13/100))*'Settings'!$B$3) | L13: =IF($H$13="","",ROUND(MIN($K$13,'Settings'!$B$5)*'Settings'!$B$2,2)) | M13: =IF($J$13="","",IF($J$13<0,"Pass",IF($J$13<'Settings'!$B$4,"Thin",IF($J$13<0.06,"✅ Sharp band",IF($J$13<0.08,"Strong","⚠ Verify (stale?)"))))) | N13: Model 59.0% (fair -144). Your call. | P13: =IF(OR($H$13="",$O$13=""),"",(1+IF($H$13<0,-100/$H$13,$H$13/100))/(1+IF($O$13<0,-100/$O$13,$O$13/100))-1)
A14: 2026-06-27 | B14: New York Yankees @ Boston Red Sox | C14: 17:10 | D14: Total | E14: Under 8.5 | F14: 0.4103 | G14: 144 | H14: 111 | I14: =IF($H$14="","",IF($H$14<0,-$H$14/(-$H$14+100),100/($H$14+100))) | J14: =IF($H$14="","",$F$14*IF($H$14<0,-100/$H$14,$H$14/100)-(1-$F$14)) | K14: =IF($H$14="","",MAX(0,($F$14*IF($H$14<0,-100/$H$14,$H$14/100)-(1-$F$14))/IF($H$14<0,-100/$H$14,$H$14/100))*'Settings'!$B$3) | L14: =IF($H$14="","",ROUND(MIN($K$14,'Settings'!$B$5)*'Settings'!$B$2,2)) | M14: =IF($J$14="","",IF($J$14<0,"Pass",IF($J$14<'Settings'!$B$4,"Thin",IF($J$14<0.06,"✅ Sharp band",IF($J$14<0.08,"Strong","⚠ Verify (stale?)"))))) | N14: Model 41.0% (fair +144). Your call. | P14: =IF(OR($H$14="",$O$14=""),"",(1+IF($H$14<0,-100/$H$14,$H$14/100))/(1+IF($O$14<0,-100/$O$14,$O$14/100))-1)
A15: 2026-06-27 | B15: New York Yankees @ Boston Red Sox | C15: 17:10 | D15: Spread | E15: Boston Red Sox -1.5 | F15: 0.2759 | G15: 262 | H15: 172 | I15: =IF($H$15="","",IF($H$15<0,-$H$15/(-$H$15+100),100/($H$15+100))) | J15: =IF($H$15="","",$F$15*IF($H$15<0,-100/$H$15,$H$15/100)-(1-$F$15)) | K15: =IF($H$15="","",MAX(0,($F$15*IF($H$15<0,-100/$H$15,$H$15/100)-(1-$F$15))/IF($H$15<0,-100/$H$15,$H$15/100))*'Settings'!$B$3) | L15: =IF($H$15="","",ROUND(MIN($K$15,'Settings'!$B$5)*'Settings'!$B$2,2)) | M15: =IF($J$15="","",IF($J$15<0,"Pass",IF($J$15<'Settings'!$B$4,"Thin",IF($J$15<0.06,"✅ Sharp band",IF($J$15<0.08,"Strong","⚠ Verify (stale?)"))))) | N15: Model 27.6% (fair +262). Your call. | P15: =IF(OR($H$15="",$O$15=""),"",(1+IF($H$15<0,-100/$H$15,$H$15/100))/(1+IF($O$15<0,-100/$O$15,$O$15/100))-1)
A16: 2026-06-27 | B16: New York Yankees @ Boston Red Sox | C16: 17:10 | D16: Spread | E16: New York Yankees +1.5 | F16: 0.7241 | G16: -262 | H16: 156 | I16: =IF($H$16="","",IF($H$16<0,-$H$16/(-$H$16+100),100/($H$16+100))) | J16: =IF($H$16="","",$F$16*IF($H$16<0,-100/$H$16,$H$16/100)-(1-$F$16)) | K16: =IF($H$16="","",MAX(0,($F$16*IF($H$16<0,-100/$H$16,$H$16/100)-(1-$F$16))/IF($H$16<0,-100/$H$16,$H$16/100))*'Settings'!$B$3) | L16: =IF($H$16="","",ROUND(MIN($K$16,'Settings'!$B$5)*'Settings'!$B$2,2)) | M16: =IF($J$16="","",IF($J$16<0,"Pass",IF($J$16<'Settings'!$B$4,"Thin",IF($J$16<0.06,"✅ Sharp band",IF($J$16<0.08,"Strong","⚠ Verify (stale?)"))))) | N16: Model 72.4% (fair -262). Your call. | P16: =IF(OR($H$16="",$O$16=""),"",(1+IF($H$16<0,-100/$H$16,$H$16/100))/(1+IF($O$16<0,-100/$O$16,$O$16/100))-1)
A17: 2026-06-27 | B17: Texas Rangers @ Toronto Blue Jays | C17: 19:07 | D17: Moneyline | E17: Texas Rangers | F17: 0.37176259 | G17: 169 | H17: 178 | I17: =IF($H$17="","",IF($H$17<0,-$H$17/(-$H$17+100),100/($H$17+100))) | J17: =IF($H$17="","",$F$17*IF($H$17<0,-100/$H$17,$H$17/100)-(1-$F$17)) | K17: =IF($H$17="","",MAX(0,($F$17*IF($H$17<0,-100/$H$17,$H$17/100)-(1-$F$17))/IF($H$17<0,-100/$H$17,$H$17/100))*'Settings'!$B$3) | L17: =IF($H$17="","",ROUND(MIN($K$17,'Settings'!$B$5)*'Settings'!$B$2,2)) | M17: =IF($J$17="","",IF($J$17<0,"Pass",IF($J$17<'Settings'!$B$4,"Thin",IF($J$17<0.06,"✅ Sharp band",IF($J$17<0.08,"Strong","⚠ Verify (stale?)"))))) | N17: Model 37.2% (fair +169). Your call. | P17: =IF(OR($H$17="",$O$17=""),"",(1+IF($H$17<0,-100/$H$17,$H$17/100))/(1+IF($O$17<0,-100/$O$17,$O$17/100))-1)
A18: 2026-06-27 | B18: Texas Rangers @ Toronto Blue Jays | C18: 19:07 | D18: Moneyline | E18: Toronto Blue Jays | F18: 0.62825036 | G18: -169 | H18: -178 | I18: =IF($H$18="","",IF($H$18<0,-$H$18/(-$H$18+100),100/($H$18+100))) | J18: =IF($H$18="","",$F$18*IF($H$18<0,-100/$H$18,$H$18/100)-(1-$F$18)) | K18: =IF($H$18="","",MAX(0,($F$18*IF($H$18<0,-100/$H$18,$H$18/100)-(1-$F$18))/IF($H$18<0,-100/$H$18,$H$18/100))*'Settings'!$B$3) | L18: =IF($H$18="","",ROUND(MIN($K$18,'Settings'!$B$5)*'Settings'!$B$2,2)) | M18: =IF($J$18="","",IF($J$18<0,"Pass",IF($J$18<'Settings'!$B$4,"Thin",IF($J$18<0.06,"✅ Sharp band",IF($J$18<0.08,"Strong","⚠ Verify (stale?)"))))) | N18: Model 62.8% (fair -169). Your call. | P18: =IF(OR($H$18="",$O$18=""),"",(1+IF($H$18<0,-100/$H$18,$H$18/100))/(1+IF($O$18<0,-100/$O$18,$O$18/100))-1)
A19: 2026-06-27 | B19: Texas Rangers @ Toronto Blue Jays | C19: 19:07 | D19: Total | E19: Over 8 | F19: 0.4846 | G19: 106 | H19: 105 | I19: =IF($H$19="","",IF($H$19<0,-$H$19/(-$H$19+100),100/($H$19+100))) | J19: =IF($H$19="","",$F$19*IF($H$19<0,-100/$H$19,$H$19/100)-(1-$F$19)) | K19: =IF($H$19="","",MAX(0,($F$19*IF($H$19<0,-100/$H$19,$H$19/100)-(1-$F$19))/IF($H$19<0,-100/$H$19,$H$19/100))*'Settings'!$B$3) | L19: =IF($H$19="","",ROUND(MIN($K$19,'Settings'!$B$5)*'Settings'!$B$2,2)) | M19: =IF($J$19="","",IF($J$19<0,"Pass",IF($J$19<'Settings'!$B$4,"Thin",IF($J$19<0.06,"✅ Sharp band",IF($J$19<0.08,"Strong","⚠ Verify (stale?)"))))) | N19: Model 48.5% (fair +106). Your call. | P19: =IF(OR($H$19="",$O$19=""),"",(1+IF($H$19<0,-100/$H$19,$H$19/100))/(1+IF($O$19<0,-100/$O$19,$O$19/100))-1)
A20: 2026-06-27 | B20: Texas Rangers @ Toronto Blue Jays | C20: 19:07 | D20: Total | E20: Under 8 | F20: 0.5154 | G20: -106 | H20: 113 | I20: =IF($H$20="","",IF($H$20<0,-$H$20/(-$H$20+100),100/($H$20+100))) | J20: =IF($H$20="","",$F$20*IF($H$20<0,-100/$H$20,$H$20/100)-(1-$F$20)) | K20: =IF($H$20="","",MAX(0,($F$20*IF($H$20<0,-100/$H$20,$H$20/100)-(1-$F$20))/IF($H$20<0,-100/$H$20,$H$20/100))*'Settings'!$B$3) | L20: =IF($H$20="","",ROUND(MIN($K$20,'Settings'!$B$5)*'Settings'!$B$2,2)) | M20: =IF($J$20="","",IF($J$20<0,"Pass",IF($J$20<'Settings'!$B$4,"Thin",IF($J$20<0.06,"✅ Sharp band",IF($J$20<0.08,"Strong","⚠ Verify (stale?)"))))) | N20: Model 51.5% (fair -106). Your call. | P20: =IF(OR($H$20="",$O$20=""),"",(1+IF($H$20<0,-100/$H$20,$H$20/100))/(1+IF($O$20<0,-100/$O$20,$O$20/100))-1)
A21: 2026-06-27 | B21: Texas Rangers @ Toronto Blue Jays | C21: 19:07 | D21: Spread | E21: Toronto Blue Jays -1.5 | F21: 0.4176 | G21: 139 | H21: 117 | I21: =IF($H$21="","",IF($H$21<0,-$H$21/(-$H$21+100),100/($H$21+100))) | J21: =IF($H$21="","",$F$21*IF($H$21<0,-100/$H$21,$H$21/100)-(1-$F$21)) | K21: =IF($H$21="","",MAX(0,($F$21*IF($H$21<0,-100/$H$21,$H$21/100)-(1-$F$21))/IF($H$21<0,-100/$H$21,$H$21/100))*'Settings'!$B$3) | L21: =IF($H$21="","",ROUND(MIN($K$21,'Settings'!$B$5)*'Settings'!$B$2,2)) | M21: =IF($J$21="","",IF($J$21<0,"Pass",IF($J$21<'Settings'!$B$4,"Thin",IF($J$21<0.06,"✅ Sharp band",IF($J$21<0.08,"Strong","⚠ Verify (stale?)"))))) | N21: Model 41.8% (fair +139). Your call. | P21: =IF(OR($H$21="",$O$21=""),"",(1+IF($H$21<0,-100/$H$21,$H$21/100))/(1+IF($O$21<0,-100/$O$21,$O$21/100))-1)
A22: 2026-06-27 | B22: Texas Rangers @ Toronto Blue Jays | C22: 19:07 | D22: Spread | E22: Texas Rangers +1.5 | F22: 0.5824 | G22: -139 | H22: 126 | I22: =IF($H$22="","",IF($H$22<0,-$H$22/(-$H$22+100),100/($H$22+100))) | J22: =IF($H$22="","",$F$22*IF($H$22<0,-100/$H$22,$H$22/100)-(1-$F$22)) | K22: =IF($H$22="","",MAX(0,($F$22*IF($H$22<0,-100/$H$22,$H$22/100)-(1-$F$22))/IF($H$22<0,-100/$H$22,$H$22/100))*'Settings'!$B$3) | L22: =IF($H$22="","",ROUND(MIN($K$22,'Settings'!$B$5)*'Settings'!$B$2,2)) | M22: =IF($J$22="","",IF($J$22<0,"Pass",IF($J$22<'Settings'!$B$4,"Thin",IF($J$22<0.06,"✅ Sharp band",IF($J$22<0.08,"Strong","⚠ Verify (stale?)"))))) | N22: Model 58.2% (fair -139). Your call. | P22: =IF(OR($H$22="",$O$22=""),"",(1+IF($H$22<0,-100/$H$22,$H$22/100))/(1+IF($O$22<0,-100/$O$22,$O$22/100))-1)
A23: 2026-06-27 | B23: Cincinnati Reds @ Pittsburgh Pirates | C23: 20:05 | D23: Moneyline | E23: Cincinnati Reds | F23: 0.44398824 | G23: 125 | H23: -104 | I23: =IF($H$23="","",IF($H$23<0,-$H$23/(-$H$23+100),100/($H$23+100))) | J23: =IF($H$23="","",$F$23*IF($H$23<0,-100/$H$23,$H$23/100)-(1-$F$23)) | K23: =IF($H$23="","",MAX(0,($F$23*IF($H$23<0,-100/$H$23,$H$23/100)-(1-$F$23))/IF($H$23<0,-100/$H$23,$H$23/100))*'Settings'!$B$3) | L23: =IF($H$23="","",ROUND(MIN($K$23,'Settings'!$B$5)*'Settings'!$B$2,2)) | M23: =IF($J$23="","",IF($J$23<0,"Pass",IF($J$23<'Settings'!$B$4,"Thin",IF($J$23<0.06,"✅ Sharp band",IF($J$23<0.08,"Strong","⚠ Verify (stale?)"))))) | N23: Model 44.4% (fair +125). Your call. | P23: =IF(OR($H$23="",$O$23=""),"",(1+IF($H$23<0,-100/$H$23,$H$23/100))/(1+IF($O$23<0,-100/$O$23,$O$23/100))-1)
A24: 2026-06-27 | B24: Cincinnati Reds @ Pittsburgh Pirates | C24: 20:05 | D24: Moneyline | E24: Pittsburgh Pirates | F24: 0.55601942 | G24: -125 | H24: 106 | I24: =IF($H$24="","",IF($H$24<0,-$H$24/(-$H$24+100),100/($H$24+100))) | J24: =IF($H$24="","",$F$24*IF($H$24<0,-100/$H$24,$H$24/100)-(1-$F$24)) | K24: =IF($H$24="","",MAX(0,($F$24*IF($H$24<0,-100/$H$24,$H$24/100)-(1-$F$24))/IF($H$24<0,-100/$H$24,$H$24/100))*'Settings'!$B$3) | L24: =IF($H$24="","",ROUND(MIN($K$24,'Settings'!$B$5)*'Settings'!$B$2,2)) | M24: =IF($J$24="","",IF($J$24<0,"Pass",IF($J$24<'Settings'!$B$4,"Thin",IF($J$24<0.06,"✅ Sharp band",IF($J$24<0.08,"Strong","⚠ Verify (stale?)"))))) | N24: Model 55.6% (fair -125). Your call. | P24: =IF(OR($H$24="",$O$24=""),"",(1+IF($H$24<0,-100/$H$24,$H$24/100))/(1+IF($O$24<0,-100/$O$24,$O$24/100))-1)
A25: 2026-06-27 | B25: Cincinnati Reds @ Pittsburgh Pirates | C25: 20:05 | D25: Total | E25: Over 8.5 | F25: 0.6534 | G25: -189 | H25: 117 | I25: =IF($H$25="","",IF($H$25<0,-$H$25/(-$H$25+100),100/($H$25+100))) | J25: =IF($H$25="","",$F$25*IF($H$25<0,-100/$H$25,$H$25/100)-(1-$F$25)) | K25: =IF($H$25="","",MAX(0,($F$25*IF($H$25<0,-100/$H$25,$H$25/100)-(1-$F$25))/IF($H$25<0,-100/$H$25,$H$25/100))*'Settings'!$B$3) | L25: =IF($H$25="","",ROUND(MIN($K$25,'Settings'!$B$5)*'Settings'!$B$2,2)) | M25: =IF($J$25="","",IF($J$25<0,"Pass",IF($J$25<'Settings'!$B$4,"Thin",IF($J$25<0.06,"✅ Sharp band",IF($J$25<0.08,"Strong","⚠ Verify (stale?)"))))) | N25: Model 65.3% (fair -189). Your call. | P25: =IF(OR($H$25="",$O$25=""),"",(1+IF($H$25<0,-100/$H$25,$H$25/100))/(1+IF($O$25<0,-100/$O$25,$O$25/100))-1)
A26: 2026-06-27 | B26: Cincinnati Reds @ Pittsburgh Pirates | C26: 20:05 | D26: Total | E26: Under 8.5 | F26: 0.3466 | G26: 189 | H26: 117 | I26: =IF($H$26="","",IF($H$26<0,-$H$26/(-$H$26+100),100/($H$26+100))) | J26: =IF($H$26="","",$F$26*IF($H$26<0,-100/$H$26,$H$26/100)-(1-$F$26)) | K26: =IF($H$26="","",MAX(0,($F$26*IF($H$26<0,-100/$H$26,$H$26/100)-(1-$F$26))/IF($H$26<0,-100/$H$26,$H$26/100))*'Settings'!$B$3) | L26: =IF($H$26="","",ROUND(MIN($K$26,'Settings'!$B$5)*'Settings'!$B$2,2)) | M26: =IF($J$26="","",IF($J$26<0,"Pass",IF($J$26<'Settings'!$B$4,"Thin",IF($J$26<0.06,"✅ Sharp band",IF($J$26<0.08,"Strong","⚠ Verify (stale?)"))))) | N26: Model 34.7% (fair +189). Your call. | P26: =IF(OR($H$26="",$O$26=""),"",(1+IF($H$26<0,-100/$H$26,$H$26/100))/(1+IF($O$26<0,-100/$O$26,$O$26/100))-1)
A27: 2026-06-27 | B27: Philadelphia Phillies @ New York Mets | C27: 20:10 | D27: Moneyline | E27: Philadelphia Phillies | F27: 0.48572727 | G27: 106 | H27: 120 | I27: =IF($H$27="","",IF($H$27<0,-$H$27/(-$H$27+100),100/($H$27+100))) | J27: =IF($H$27="","",$F$27*IF($H$27<0,-100/$H$27,$H$27/100)-(1-$F$27)) | K27: =IF($H$27="","",MAX(0,($F$27*IF($H$27<0,-100/$H$27,$H$27/100)-(1-$F$27))/IF($H$27<0,-100/$H$27,$H$27/100))*'Settings'!$B$3) | L27: =IF($H$27="","",ROUND(MIN($K$27,'Settings'!$B$5)*'Settings'!$B$2,2)) | M27: =IF($J$27="","",IF($J$27<0,"Pass",IF($J$27<'Settings'!$B$4,"Thin",IF($J$27<0.06,"✅ Sharp band",IF($J$27<0.08,"Strong","⚠ Verify (stale?)"))))) | N27: Model 48.6% (fair +106). Your call. | P27: =IF(OR($H$27="",$O$27=""),"",(1+IF($H$27<0,-100/$H$27,$H$27/100))/(1+IF($O$27<0,-100/$O$27,$O$27/100))-1)
A28: 2026-06-27 | B28: Philadelphia Phillies @ New York Mets | C28: 20:10 | D28: Moneyline | E28: New York Mets | F28: 0.51426847 | G28: -106 | H28: -122 | I28: =IF($H$28="","",IF($H$28<0,-$H$28/(-$H$28+100),100/($H$28+100))) | J28: =IF($H$28="","",$F$28*IF($H$28<0,-100/$H$28,$H$28/100)-(1-$F$28)) | K28: =IF($H$28="","",MAX(0,($F$28*IF($H$28<0,-100/$H$28,$H$28/100)-(1-$F$28))/IF($H$28<0,-100/$H$28,$H$28/100))*'Settings'!$B$3) | L28: =IF($H$28="","",ROUND(MIN($K$28,'Settings'!$B$5)*'Settings'!$B$2,2)) | M28: =IF($J$28="","",IF($J$28<0,"Pass",IF($J$28<'Settings'!$B$4,"Thin",IF($J$28<0.06,"✅ Sharp band",IF($J$28<0.08,"Strong","⚠ Verify (stale?)"))))) | N28: Model 51.4% (fair -106). Your call. | P28: =IF(OR($H$28="",$O$28=""),"",(1+IF($H$28<0,-100/$H$28,$H$28/100))/(1+IF($O$28<0,-100/$O$28,$O$28/100))-1)
A29: 2026-06-27 | B29: Philadelphia Phillies @ New York Mets | C29: 20:10 | D29: Total | E29: Over 9 | F29: 0.3159 | G29: 217 | H29: 104 | I29: =IF($H$29="","",IF($H$29<0,-$H$29/(-$H$29+100),100/($H$29+100))) | J29: =IF($H$29="","",$F$29*IF($H$29<0,-100/$H$29,$H$29/100)-(1-$F$29)) | K29: =IF($H$29="","",MAX(0,($F$29*IF($H$29<0,-100/$H$29,$H$29/100)-(1-$F$29))/IF($H$29<0,-100/$H$29,$H$29/100))*'Settings'!$B$3) | L29: =IF($H$29="","",ROUND(MIN($K$29,'Settings'!$B$5)*'Settings'!$B$2,2)) | M29: =IF($J$29="","",IF($J$29<0,"Pass",IF($J$29<'Settings'!$B$4,"Thin",IF($J$29<0.06,"✅ Sharp band",IF($J$29<0.08,"Strong","⚠ Verify (stale?)"))))) | N29: Model 31.6% (fair +217). Your call. | P29: =IF(OR($H$29="",$O$29=""),"",(1+IF($H$29<0,-100/$H$29,$H$29/100))/(1+IF($O$29<0,-100/$O$29,$O$29/100))-1)
A30: 2026-06-27 | B30: Philadelphia Phillies @ New York Mets | C30: 20:10 | D30: Total | E30: Under 9 | F30: 0.6841 | G30: -217 | H30: 117 | I30: =IF($H$30="","",IF($H$30<0,-$H$30/(-$H$30+100),100/($H$30+100))) | J30: =IF($H$30="","",$F$30*IF($H$30<0,-100/$H$30,$H$30/100)-(1-$F$30)) | K30: =IF($H$30="","",MAX(0,($F$30*IF($H$30<0,-100/$H$30,$H$30/100)-(1-$F$30))/IF($H$30<0,-100/$H$30,$H$30/100))*'Settings'!$B$3) | L30: =IF($H$30="","",ROUND(MIN($K$30,'Settings'!$B$5)*'Settings'!$B$2,2)) | M30: =IF($J$30="","",IF($J$30<0,"Pass",IF($J$30<'Settings'!$B$4,"Thin",IF($J$30<0.06,"✅ Sharp band",IF($J$30<0.08,"Strong","⚠ Verify (stale?)"))))) | N30: Model 68.4% (fair -217). Your call. | P30: =IF(OR($H$30="",$O$30=""),"",(1+IF($H$30<0,-100/$H$30,$H$30/100))/(1+IF($O$30<0,-100/$O$30,$O$30/100))-1)
A31: 2026-06-27 | B31: Philadelphia Phillies @ New York Mets | C31: 20:10 | D31: Spread | E31: New York Mets -1.5 | F31: 0.2942 | G31: 240 | H31: 167 | I31: =IF($H$31="","",IF($H$31<0,-$H$31/(-$H$31+100),100/($H$31+100))) | J31: =IF($H$31="","",$F$31*IF($H$31<0,-100/$H$31,$H$31/100)-(1-$F$31)) | K31: =IF($H$31="","",MAX(0,($F$31*IF($H$31<0,-100/$H$31,$H$31/100)-(1-$F$31))/IF($H$31<0,-100/$H$31,$H$31/100))*'Settings'!$B$3) | L31: =IF($H$31="","",ROUND(MIN($K$31,'Settings'!$B$5)*'Settings'!$B$2,2)) | M31: =IF($J$31="","",IF($J$31<0,"Pass",IF($J$31<'Settings'!$B$4,"Thin",IF($J$31<0.06,"✅ Sharp band",IF($J$31<0.08,"Strong","⚠ Verify (stale?)"))))) | N31: Model 29.4% (fair +240). Your call. | P31: =IF(OR($H$31="",$O$31=""),"",(1+IF($H$31<0,-100/$H$31,$H$31/100))/(1+IF($O$31<0,-100/$O$31,$O$31/100))-1)
A32: 2026-06-27 | B32: Philadelphia Phillies @ New York Mets | C32: 20:10 | D32: Spread | E32: Philadelphia Phillies +1.5 | F32: 0.7058 | G32: -240 | H32: -129 | I32: =IF($H$32="","",IF($H$32<0,-$H$32/(-$H$32+100),100/($H$32+100))) | J32: =IF($H$32="","",$F$32*IF($H$32<0,-100/$H$32,$H$32/100)-(1-$F$32)) | K32: =IF($H$32="","",MAX(0,($F$32*IF($H$32<0,-100/$H$32,$H$32/100)-(1-$F$32))/IF($H$32<0,-100/$H$32,$H$32/100))*'Settings'!$B$3) | L32: =IF($H$32="","",ROUND(MIN($K$32,'Settings'!$B$5)*'Settings'!$B$2,2)) | M32: =IF($J$32="","",IF($J$32<0,"Pass",IF($J$32<'Settings'!$B$4,"Thin",IF($J$32<0.06,"✅ Sharp band",IF($J$32<0.08,"Strong","⚠ Verify (stale?)"))))) | N32: Model 70.6% (fair -240). Your call. | P32: =IF(OR($H$32="",$O$32=""),"",(1+IF($H$32<0,-100/$H$32,$H$32/100))/(1+IF($O$32<0,-100/$O$32,$O$32/100))-1)
A33: 2026-06-27 | B33: Kansas City Royals @ Chicago White Sox | C33: 20:10 | D33: Moneyline | E33: Kansas City Royals | F33: 0.3497 | G33: 186 | H33: 115 | I33: =IF($H$33="","",IF($H$33<0,-$H$33/(-$H$33+100),100/($H$33+100))) | J33: =IF($H$33="","",$F$33*IF($H$33<0,-100/$H$33,$H$33/100)-(1-$F$33)) | K33: =IF($H$33="","",MAX(0,($F$33*IF($H$33<0,-100/$H$33,$H$33/100)-(1-$F$33))/IF($H$33<0,-100/$H$33,$H$33/100))*'Settings'!$B$3) | L33: =IF($H$33="","",ROUND(MIN($K$33,'Settings'!$B$5)*'Settings'!$B$2,2)) | M33: =IF($J$33="","",IF($J$33<0,"Pass",IF($J$33<'Settings'!$B$4,"Thin",IF($J$33<0.06,"✅ Sharp band",IF($J$33<0.08,"Strong","⚠ Verify (stale?)"))))) | N33: Model 35.0% (fair +186). Your call. | P33: =IF(OR($H$33="",$O$33=""),"",(1+IF($H$33<0,-100/$H$33,$H$33/100))/(1+IF($O$33<0,-100/$O$33,$O$33/100))-1)
A34: 2026-06-27 | B34: Kansas City Royals @ Chicago White Sox | C34: 20:10 | D34: Moneyline | E34: Chicago White Sox | F34: 0.6503 | G34: -186 | H34: 104 | I34: =IF($H$34="","",IF($H$34<0,-$H$34/(-$H$34+100),100/($H$34+100))) | J34: =IF($H$34="","",$F$34*IF($H$34<0,-100/$H$34,$H$34/100)-(1-$F$34)) | K34: =IF($H$34="","",MAX(0,($F$34*IF($H$34<0,-100/$H$34,$H$34/100)-(1-$F$34))/IF($H$34<0,-100/$H$34,$H$34/100))*'Settings'!$B$3) | L34: =IF($H$34="","",ROUND(MIN($K$34,'Settings'!$B$5)*'Settings'!$B$2,2)) | M34: =IF($J$34="","",IF($J$34<0,"Pass",IF($J$34<'Settings'!$B$4,"Thin",IF($J$34<0.06,"✅ Sharp band",IF($J$34<0.08,"Strong","⚠ Verify (stale?)"))))) | N34: Model 65.0% (fair -186). Your call. | P34: =IF(OR($H$34="",$O$34=""),"",(1+IF($H$34<0,-100/$H$34,$H$34/100))/(1+IF($O$34<0,-100/$O$34,$O$34/100))-1)
A35: 2026-06-27 | B35: Kansas City Royals @ Chicago White Sox | C35: 20:10 | D35: Total | E35: Over 8.5 | F35: 0.6626 | G35: -196 | H35: 117 | I35: =IF($H$35="","",IF($H$35<0,-$H$35/(-$H$35+100),100/($H$35+100))) | J35: =IF($H$35="","",$F$35*IF($H$35<0,-100/$H$35,$H$35/100)-(1-$F$35)) | K35: =IF($H$35="","",MAX(0,($F$35*IF($H$35<0,-100/$H$35,$H$35/100)-(1-$F$35))/IF($H$35<0,-100/$H$35,$H$35/100))*'Settings'!$B$3) | L35: =IF($H$35="","",ROUND(MIN($K$35,'Settings'!$B$5)*'Settings'!$B$2,2)) | M35: =IF($J$35="","",IF($J$35<0,"Pass",IF($J$35<'Settings'!$B$4,"Thin",IF($J$35<0.06,"✅ Sharp band",IF($J$35<0.08,"Strong","⚠ Verify (stale?)"))))) | N35: Model 66.3% (fair -196). Your call. | P35: =IF(OR($H$35="",$O$35=""),"",(1+IF($H$35<0,-100/$H$35,$H$35/100))/(1+IF($O$35<0,-100/$O$35,$O$35/100))-1)
A36: 2026-06-27 | B36: Kansas City Royals @ Chicago White Sox | C36: 20:10 | D36: Total | E36: Under 8.5 | F36: 0.3374 | G36: 196 | H36: 111 | I36: =IF($H$36="","",IF($H$36<0,-$H$36/(-$H$36+100),100/($H$36+100))) | J36: =IF($H$36="","",$F$36*IF($H$36<0,-100/$H$36,$H$36/100)-(1-$F$36)) | K36: =IF($H$36="","",MAX(0,($F$36*IF($H$36<0,-100/$H$36,$H$36/100)-(1-$F$36))/IF($H$36<0,-100/$H$36,$H$36/100))*'Settings'!$B$3) | L36: =IF($H$36="","",ROUND(MIN($K$36,'Settings'!$B$5)*'Settings'!$B$2,2)) | M36: =IF($J$36="","",IF($J$36<0,"Pass",IF($J$36<'Settings'!$B$4,"Thin",IF($J$36<0.06,"✅ Sharp band",IF($J$36<0.08,"Strong","⚠ Verify (stale?)"))))) | N36: Model 33.7% (fair +196). Your call. | P36: =IF(OR($H$36="",$O$36=""),"",(1+IF($H$36<0,-100/$H$36,$H$36/100))/(1+IF($O$36<0,-100/$O$36,$O$36/100))-1)
A37: 2026-06-27 | B37: Kansas City Royals @ Chicago White Sox | C37: 20:10 | D37: Spread | E37: Chicago White Sox -1.5 | F37: 0.4649 | G37: 115 | H37: 172 | I37: =IF($H$37="","",IF($H$37<0,-$H$37/(-$H$37+100),100/($H$37+100))) | J37: =IF($H$37="","",$F$37*IF($H$37<0,-100/$H$37,$H$37/100)-(1-$F$37)) | K37: =IF($H$37="","",MAX(0,($F$37*IF($H$37<0,-100/$H$37,$H$37/100)-(1-$F$37))/IF($H$37<0,-100/$H$37,$H$37/100))*'Settings'!$B$3) | L37: =IF($H$37="","",ROUND(MIN($K$37,'Settings'!$B$5)*'Settings'!$B$2,2)) | M37: =IF($J$37="","",IF($J$37<0,"Pass",IF($J$37<'Settings'!$B$4,"Thin",IF($J$37<0.06,"✅ Sharp band",IF($J$37<0.08,"Strong","⚠ Verify (stale?)"))))) | N37: Model 46.5% (fair +115). Your call. | P37: =IF(OR($H$37="",$O$37=""),"",(1+IF($H$37<0,-100/$H$37,$H$37/100))/(1+IF($O$37<0,-100/$O$37,$O$37/100))-1)
A38: 2026-06-27 | B38: Kansas City Royals @ Chicago White Sox | C38: 20:10 | D38: Spread | E38: Kansas City Royals +1.5 | F38: 0.5351 | G38: -115 | H38: -130 | I38: =IF($H$38="","",IF($H$38<0,-$H$38/(-$H$38+100),100/($H$38+100))) | J38: =IF($H$38="","",$F$38*IF($H$38<0,-100/$H$38,$H$38/100)-(1-$F$38)) | K38: =IF($H$38="","",MAX(0,($F$38*IF($H$38<0,-100/$H$38,$H$38/100)-(1-$F$38))/IF($H$38<0,-100/$H$38,$H$38/100))*'Settings'!$B$3) | L38: =IF($H$38="","",ROUND(MIN($K$38,'Settings'!$B$5)*'Settings'!$B$2,2)) | M38: =IF($J$38="","",IF($J$38<0,"Pass",IF($J$38<'Settings'!$B$4,"Thin",IF($J$38<0.06,"✅ Sharp band",IF($J$38<0.08,"Strong","⚠ Verify (stale?)"))))) | N38: Model 53.5% (fair -115). Your call. | P38: =IF(OR($H$38="",$O$38=""),"",(1+IF($H$38<0,-100/$H$38,$H$38/100))/(1+IF($O$38<0,-100/$O$38,$O$38/100))-1)
A39: 2026-06-27 | B39: Arizona Diamondbacks @ Tampa Bay Rays | C39: 22:10 | D39: Moneyline | E39: Arizona Diamondbacks | F39: 0.47528634 | G39: 110 | H39: 127 | I39: =IF($H$39="","",IF($H$39<0,-$H$39/(-$H$39+100),100/($H$39+100))) | J39: =IF($H$39="","",$F$39*IF($H$39<0,-100/$H$39,$H$39/100)-(1-$F$39)) | K39: =IF($H$39="","",MAX(0,($F$39*IF($H$39<0,-100/$H$39,$H$39/100)-(1-$F$39))/IF($H$39<0,-100/$H$39,$H$39/100))*'Settings'!$B$3) | L39: =IF($H$39="","",ROUND(MIN($K$39,'Settings'!$B$5)*'Settings'!$B$2,2)) | M39: =IF($J$39="","",IF($J$39<0,"Pass",IF($J$39<'Settings'!$B$4,"Thin",IF($J$39<0.06,"✅ Sharp band",IF($J$39<0.08,"Strong","⚠ Verify (stale?)"))))) | N39: Model 47.5% (fair +110). Your call. | P39: =IF(OR($H$39="",$O$39=""),"",(1+IF($H$39<0,-100/$H$39,$H$39/100))/(1+IF($O$39<0,-100/$O$39,$O$39/100))-1)
A40: 2026-06-27 | B40: Arizona Diamondbacks @ Tampa Bay Rays | C40: 22:10 | D40: Moneyline | E40: Tampa Bay Rays | F40: 0.52472819 | G40: -110 | H40: -127 | I40: =IF($H$40="","",IF($H$40<0,-$H$40/(-$H$40+100),100/($H$40+100))) | J40: =IF($H$40="","",$F$40*IF($H$40<0,-100/$H$40,$H$40/100)-(1-$F$40)) | K40: =IF($H$40="","",MAX(0,($F$40*IF($H$40<0,-100/$H$40,$H$40/100)-(1-$F$40))/IF($H$40<0,-100/$H$40,$H$40/100))*'Settings'!$B$3) | L40: =IF($H$40="","",ROUND(MIN($K$40,'Settings'!$B$5)*'Settings'!$B$2,2)) | M40: =IF($J$40="","",IF($J$40<0,"Pass",IF($J$40<'Settings'!$B$4,"Thin",IF($J$40<0.06,"✅ Sharp band",IF($J$40<0.08,"Strong","⚠ Verify (stale?)"))))) | N40: Model 52.5% (fair -110). Your call. | P40: =IF(OR($H$40="",$O$40=""),"",(1+IF($H$40<0,-100/$H$40,$H$40/100))/(1+IF($O$40<0,-100/$O$40,$O$40/100))-1)
A41: 2026-06-27 | B41: Arizona Diamondbacks @ Tampa Bay Rays | C41: 22:10 | D41: Total | E41: Over 8.5 | F41: 0.5026 | G41: -101 | H41: 104 | I41: =IF($H$41="","",IF($H$41<0,-$H$41/(-$H$41+100),100/($H$41+100))) | J41: =IF($H$41="","",$F$41*IF($H$41<0,-100/$H$41,$H$41/100)-(1-$F$41)) | K41: =IF($H$41="","",MAX(0,($F$41*IF($H$41<0,-100/$H$41,$H$41/100)-(1-$F$41))/IF($H$41<0,-100/$H$41,$H$41/100))*'Settings'!$B$3) | L41: =IF($H$41="","",ROUND(MIN($K$41,'Settings'!$B$5)*'Settings'!$B$2,2)) | M41: =IF($J$41="","",IF($J$41<0,"Pass",IF($J$41<'Settings'!$B$4,"Thin",IF($J$41<0.06,"✅ Sharp band",IF($J$41<0.08,"Strong","⚠ Verify (stale?)"))))) | N41: Model 50.3% (fair -101). Your call. | P41: =IF(OR($H$41="",$O$41=""),"",(1+IF($H$41<0,-100/$H$41,$H$41/100))/(1+IF($O$41<0,-100/$O$41,$O$41/100))-1)
...

Sheet WNBA Games
A1: WNBA — game markets
A2: Moneyline · Total · Spread. Yellow = your price.
A4: Date | B4: Matchup | C4: Start | D4: Market | E4: Selection | F4: Model Win% | G4: Model Fair | H4: ✏ Your Odds | I4: Implied% | J4: Your Edge (EV) | K4: ¼-Kelly % | L4: Stake $ | M4: Verdict | N4: Model read | O4: ✏ Closing | P4: CLV %
A5: 2026-06-27 | B5: Los Angeles Sparks @ Indiana Fever | C5: 00:00 | D5: Moneyline | E5: Los Angeles Sparks | F5: 0.29055072 | G5: 244 | H5: 245 | I5: =IF($H$5="","",IF($H$5<0,-$H$5/(-$H$5+100),100/($H$5+100))) | J5: =IF($H$5="","",$F$5*IF($H$5<0,-100/$H$5,$H$5/100)-(1-$F$5)) | K5: =IF($H$5="","",MAX(0,($F$5*IF($H$5<0,-100/$H$5,$H$5/100)-(1-$F$5))/IF($H$5<0,-100/$H$5,$H$5/100))*'Settings'!$B$3) | L5: =IF($H$5="","",ROUND(MIN($K$5,'Settings'!$B$5)*'Settings'!$B$2,2)) | M5: =IF($J$5="","",IF($J$5<0,"Pass",IF($J$5<'Settings'!$B$4,"Thin",IF($J$5<0.06,"✅ Sharp band",IF($J$5<0.08,"Strong","⚠ Verify (stale?)"))))) | N5: Model 29.1% (fair +244). Your call. | P5: =IF(OR($H$5="",$O$5=""),"",(1+IF($H$5<0,-100/$H$5,$H$5/100))/(1+IF($O$5<0,-100/$O$5,$O$5/100))-1)
A6: 2026-06-27 | B6: Los Angeles Sparks @ Indiana Fever | C6: 00:00 | D6: Moneyline | E6: Indiana Fever | F6: 0.70945043 | G6: -244 | H6: -251 | I6: =IF($H$6="","",IF($H$6<0,-$H$6/(-$H$6+100),100/($H$6+100))) | J6: =IF($H$6="","",$F$6*IF($H$6<0,-100/$H$6,$H$6/100)-(1-$F$6)) | K6: =IF($H$6="","",MAX(0,($F$6*IF($H$6<0,-100/$H$6,$H$6/100)-(1-$F$6))/IF($H$6<0,-100/$H$6,$H$6/100))*'Settings'!$B$3) | L6: =IF($H$6="","",ROUND(MIN($K$6,'Settings'!$B$5)*'Settings'!$B$2,2)) | M6: =IF($J$6="","",IF($J$6<0,"Pass",IF($J$6<'Settings'!$B$4,"Thin",IF($J$6<0.06,"✅ Sharp band",IF($J$6<0.08,"Strong","⚠ Verify (stale?)"))))) | N6: Model 70.9% (fair -244). Your call. | P6: =IF(OR($H$6="",$O$6=""),"",(1+IF($H$6<0,-100/$H$6,$H$6/100))/(1+IF($O$6<0,-100/$O$6,$O$6/100))-1)
A7: 2026-06-27 | B7: Los Angeles Sparks @ Indiana Fever | C7: 00:00 | D7: Total | E7: Over 179.5 | F7: 0.715 | G7: -251 | H7: -104 | I7: =IF($H$7="","",IF($H$7<0,-$H$7/(-$H$7+100),100/($H$7+100))) | J7: =IF($H$7="","",$F$7*IF($H$7<0,-100/$H$7,$H$7/100)-(1-$F$7)) | K7: =IF($H$7="","",MAX(0,($F$7*IF($H$7<0,-100/$H$7,$H$7/100)-(1-$F$7))/IF($H$7<0,-100/$H$7,$H$7/100))*'Settings'!$B$3) | L7: =IF($H$7="","",ROUND(MIN($K$7,'Settings'!$B$5)*'Settings'!$B$2,2)) | M7: =IF($J$7="","",IF($J$7<0,"Pass",IF($J$7<'Settings'!$B$4,"Thin",IF($J$7<0.06,"✅ Sharp band",IF($J$7<0.08,"Strong","⚠ Verify (stale?)"))))) | N7: Model 71.5% (fair -251). Your call. | P7: =IF(OR($H$7="",$O$7=""),"",(1+IF($H$7<0,-100/$H$7,$H$7/100))/(1+IF($O$7<0,-100/$O$7,$O$7/100))-1)
A8: 2026-06-27 | B8: Los Angeles Sparks @ Indiana Fever | C8: 00:00 | D8: Total | E8: Under 179.5 | F8: 0.285 | G8: 251 | H8: -104 | I8: =IF($H$8="","",IF($H$8<0,-$H$8/(-$H$8+100),100/($H$8+100))) | J8: =IF($H$8="","",$F$8*IF($H$8<0,-100/$H$8,$H$8/100)-(1-$F$8)) | K8: =IF($H$8="","",MAX(0,($F$8*IF($H$8<0,-100/$H$8,$H$8/100)-(1-$F$8))/IF($H$8<0,-100/$H$8,$H$8/100))*'Settings'!$B$3) | L8: =IF($H$8="","",ROUND(MIN($K$8,'Settings'!$B$5)*'Settings'!$B$2,2)) | M8: =IF($J$8="","",IF($J$8<0,"Pass",IF($J$8<'Settings'!$B$4,"Thin",IF($J$8<0.06,"✅ Sharp band",IF($J$8<0.08,"Strong","⚠ Verify (stale?)"))))) | N8: Model 28.5% (fair +251). Your call. | P8: =IF(OR($H$8="",$O$8=""),"",(1+IF($H$8<0,-100/$H$8,$H$8/100))/(1+IF($O$8<0,-100/$O$8,$O$8/100))-1)
A9: 2026-06-27 | B9: Los Angeles Sparks @ Indiana Fever | C9: 00:00 | D9: Spread | E9: Indiana Fever -6.5 | F9: 0.513 | G9: -105 | H9: -108 | I9: =IF($H$9="","",IF($H$9<0,-$H$9/(-$H$9+100),100/($H$9+100))) | J9: =IF($H$9="","",$F$9*IF($H$9<0,-100/$H$9,$H$9/100)-(1-$F$9)) | K9: =IF($H$9="","",MAX(0,($F$9*IF($H$9<0,-100/$H$9,$H$9/100)-(1-$F$9))/IF($H$9<0,-100/$H$9,$H$9/100))*'Settings'!$B$3) | L9: =IF($H$9="","",ROUND(MIN($K$9,'Settings'!$B$5)*'Settings'!$B$2,2)) | M9: =IF($J$9="","",IF($J$9<0,"Pass",IF($J$9<'Settings'!$B$4,"Thin",IF($J$9<0.06,"✅ Sharp band",IF($J$9<0.08,"Strong","⚠ Verify (stale?)"))))) | N9: Model 51.3% (fair -105). Your call. | P9: =IF(OR($H$9="",$O$9=""),"",(1+IF($H$9<0,-100/$H$9,$H$9/100))/(1+IF($O$9<0,-100/$O$9,$O$9/100))-1)
A10: 2026-06-27 | B10: Los Angeles Sparks @ Indiana Fever | C10: 00:00 | D10: Spread | E10: Los Angeles Sparks +6.5 | F10: 0.48697561 | G10: 105 | H10: 105 | I10: =IF($H$10="","",IF($H$10<0,-$H$10/(-$H$10+100),100/($H$10+100))) | J10: =IF($H$10="","",$F$10*IF($H$10<0,-100/$H$10,$H$10/100)-(1-$F$10)) | K10: =IF($H$10="","",MAX(0,($F$10*IF($H$10<0,-100/$H$10,$H$10/100)-(1-$F$10))/IF($H$10<0,-100/$H$10,$H$10/100))*'Settings'!$B$3) | L10: =IF($H$10="","",ROUND(MIN($K$10,'Settings'!$B$5)*'Settings'!$B$2,2)) | M10: =IF($J$10="","",IF($J$10<0,"Pass",IF($J$10<'Settings'!$B$4,"Thin",IF($J$10<0.06,"✅ Sharp band",IF($J$10<0.08,"Strong","⚠ Verify (stale?)"))))) | N10: Model 48.7% (fair +105). Your call. | P10: =IF(OR($H$10="",$O$10=""),"",(1+IF($H$10<0,-100/$H$10,$H$10/100))/(1+IF($O$10<0,-100/$O$10,$O$10/100))-1)
A11: 2026-06-27 | B11: Atlanta Dream @ Seattle Storm | C11: 01:00 | D11: Moneyline | E11: Atlanta Dream | F11: 0.76121975 | G11: -319 | H11: -305 | I11: =IF($H$11="","",IF($H$11<0,-$H$11/(-$H$11+100),100/($H$11+100))) | J11: =IF($H$11="","",$F$11*IF($H$11<0,-100/$H$11,$H$11/100)-(1-$F$11)) | K11: =IF($H$11="","",MAX(0,($F$11*IF($H$11<0,-100/$H$11,$H$11/100)-(1-$F$11))/IF($H$11<0,-100/$H$11,$H$11/100))*'Settings'!$B$3) | L11: =IF($H$11="","",ROUND(MIN($K$11,'Settings'!$B$5)*'Settings'!$B$2,2)) | M11: =IF($J$11="","",IF($J$11<0,"Pass",IF($J$11<'Settings'!$B$4,"Thin",IF($J$11<0.06,"✅ Sharp band",IF($J$11<0.08,"Strong","⚠ Verify (stale?)"))))) | N11: Model 76.1% (fair -319). Your call. | P11: =IF(OR($H$11="",$O$11=""),"",(1+IF($H$11<0,-100/$H$11,$H$11/100))/(1+IF($O$11<0,-100/$O$11,$O$11/100))-1)
A12: 2026-06-27 | B12: Atlanta Dream @ Seattle Storm | C12: 01:00 | D12: Moneyline | E12: Seattle Storm | F12: 0.238825 | G12: 319 | H12: 300 | I12: =IF($H$12="","",IF($H$12<0,-$H$12/(-$H$12+100),100/($H$12+100))) | J12: =IF($H$12="","",$F$12*IF($H$12<0,-100/$H$12,$H$12/100)-(1-$F$12)) | K12: =IF($H$12="","",MAX(0,($F$12*IF($H$12<0,-100/$H$12,$H$12/100)-(1-$F$12))/IF($H$12<0,-100/$H$12,$H$12/100))*'Settings'!$B$3) | L12: =IF($H$12="","",ROUND(MIN($K$12,'Settings'!$B$5)*'Settings'!$B$2,2)) | M12: =IF($J$12="","",IF($J$12<0,"Pass",IF($J$12<'Settings'!$B$4,"Thin",IF($J$12<0.06,"✅ Sharp band",IF($J$12<0.08,"Strong","⚠ Verify (stale?)"))))) | N12: Model 23.9% (fair +319). Your call. | P12: =IF(OR($H$12="",$O$12=""),"",(1+IF($H$12<0,-100/$H$12,$H$12/100))/(1+IF($O$12<0,-100/$O$12,$O$12/100))-1)
A13: 2026-06-27 | B13: Atlanta Dream @ Seattle Storm | C13: 01:00 | D13: Total | E13: Over 179.5 | F13: 0.26067308 | G13: 284 | H13: 108 | I13: =IF($H$13="","",IF($H$13<0,-$H$13/(-$H$13+100),100/($H$13+100))) | J13: =IF($H$13="","",$F$13*IF($H$13<0,-100/$H$13,$H$13/100)-(1-$F$13)) | K13: =IF($H$13="","",MAX(0,($F$13*IF($H$13<0,-100/$H$13,$H$13/100)-(1-$F$13))/IF($H$13<0,-100/$H$13,$H$13/100))*'Settings'!$B$3) | L13: =IF($H$13="","",ROUND(MIN($K$13,'Settings'!$B$5)*'Settings'!$B$2,2)) | M13: =IF($J$13="","",IF($J$13<0,"Pass",IF($J$13<'Settings'!$B$4,"Thin",IF($J$13<0.06,"✅ Sharp band",IF($J$13<0.08,"Strong","⚠ Verify (stale?)"))))) | N13: Model 26.1% (fair +284). Your call. | P13: =IF(OR($H$13="",$O$13=""),"",(1+IF($H$13<0,-100/$H$13,$H$13/100))/(1+IF($O$13<0,-100/$O$13,$O$13/100))-1)
